2024-05-14 01:30:50,779 INFO    StreamThr :2406543 [internal.py:wandb_internal():86] W&B internal server running at pid: 2406543, started at: 2024-05-14 01:30:50.778687
2024-05-14 01:30:50,781 DEBUG   HandlerThread:2406543 [handler.py:handle_request():146] handle_request: status
2024-05-14 01:30:50,783 INFO    WriterThread:2406543 [datastore.py:open_for_write():85] open: /nfs/datx/lyk/HiFT/wandb/run-20240514_013050-o15pf2qh/run-o15pf2qh.wandb
2024-05-14 01:30:50,794 DEBUG   SenderThread:2406543 [sender.py:send():382] send: header
2024-05-14 01:30:50,794 DEBUG   SenderThread:2406543 [sender.py:send():382] send: run
2024-05-14 01:30:51,251 INFO    SenderThread:2406543 [dir_watcher.py:__init__():211] watching files in: /nfs/datx/lyk/HiFT/wandb/run-20240514_013050-o15pf2qh/files
2024-05-14 01:30:51,251 INFO    SenderThread:2406543 [sender.py:_start_run_threads():1136] run started: o15pf2qh with start time 1715643050.779168
2024-05-14 01:30:51,263 DEBUG   HandlerThread:2406543 [handler.py:handle_request():146] handle_request: check_version
2024-05-14 01:30:51,264 DEBUG   SenderThread:2406543 [sender.py:send_request():409] send_request: check_version
2024-05-14 01:30:51,326 DEBUG   HandlerThread:2406543 [handler.py:handle_request():146] handle_request: run_start
2024-05-14 01:30:51,352 DEBUG   HandlerThread:2406543 [system_info.py:__init__():32] System info init
2024-05-14 01:30:51,352 DEBUG   HandlerThread:2406543 [system_info.py:__init__():47] System info init done
2024-05-14 01:30:51,352 INFO    HandlerThread:2406543 [system_monitor.py:start():194] Starting system monitor
2024-05-14 01:30:51,352 INFO    SystemMonitor:2406543 [system_monitor.py:_start():158] Starting system asset monitoring threads
2024-05-14 01:30:51,354 INFO    HandlerThread:2406543 [system_monitor.py:probe():214] Collecting system info
2024-05-14 01:30:51,354 INFO    SystemMonitor:2406543 [interfaces.py:start():190] Started cpu monitoring
2024-05-14 01:30:51,354 INFO    SystemMonitor:2406543 [interfaces.py:start():190] Started disk monitoring
2024-05-14 01:30:51,355 INFO    SystemMonitor:2406543 [interfaces.py:start():190] Started gpu monitoring
2024-05-14 01:30:51,356 INFO    SystemMonitor:2406543 [interfaces.py:start():190] Started memory monitoring
2024-05-14 01:30:51,356 INFO    SystemMonitor:2406543 [interfaces.py:start():190] Started network monitoring
2024-05-14 01:30:51,413 DEBUG   HandlerThread:2406543 [system_info.py:probe():196] Probing system
2024-05-14 01:30:51,423 DEBUG   HandlerThread:2406543 [gitlib.py:_init_repo():56] git repository is invalid
2024-05-14 01:30:51,423 DEBUG   HandlerThread:2406543 [system_info.py:probe():244] Probing system done
2024-05-14 01:30:51,423 DEBUG   HandlerThread:2406543 [system_monitor.py:probe():223] {'os': 'Linux-5.15.0-97-generic-x86_64-with-glibc2.10', 'python': '3.8.5', 'heartbeatAt': '2024-05-13T23:30:51.413230', 'startedAt': '2024-05-13T23:30:50.760653', 'docker': None, 'cuda': None, 'args': ('--model_type', 'llama', '--HiTaskType', 'CAUSAL_LM', '--optim', 'lamb', '--deepspeed', 'dsconfig/zero0_config.json', '--model_name_or_path', '/mounts/work/lyk/hierFT/llama2-7b', '--dataset_dir', 'data/alpaca_data', '--validation_split_percentage', '0.01', '--per_device_train_batch_size', '8', '--per_device_eval_batch_size', '8', '--do_train', '--do_eval', '--seed', '12345', '--fp16', '--num_train_epochs', '1', '--lr_scheduler_type', 'cosine', '--learning_rate', '2e-5', '--warmup_ratio', '0', '--weight_decay', '0', '--logging_strategy', 'steps', '--logging_steps', '10', '--save_strategy', 'steps', '--save_total_limit', '3', '--evaluation_strategy', 'steps', '--eval_steps', '100', '--save_steps', '200', '--preprocessing_num_workers', '4', '--max_seq_length', '512', '--output_dir', 'outputs/instruct_tuning/model', '--overwrite_output_dir', '--logging_first_step', 'True', '--lora_rank', '8', '--torch_dtype', 'float16', '--ddp_find_unused_parameters', 'False', '--load_best_model_at_end', '--hier_tuning', '--group_element', '1', '--optimizer_strategy', 'down2up'), 'state': 'running', 'program': 'examples/instruct_tuning.py', 'codePathLocal': 'examples/instruct_tuning.py', 'codePath': 'examples/instruct_tuning.py', 'host': 'rho2', 'username': 'yongkang', 'executable': '/mounts/work/lyk/anaconda3/envs/torch2/bin/python', 'cpu_count': 32, 'cpu_count_logical': 64, 'cpu_freq': {'current': 2127.3265624999995, 'min': 1500.0, 'max': 3000.0}, 'cpu_freq_per_core': [{'current': 1500.0, 'min': 1500.0, 'max': 3000.0}, {'current': 3651.314, 'min': 1500.0, 'max': 3000.0}, {'current': 3000.0, 'min': 1500.0, 'max': 3000.0}, {'current': 3000.0, 'min': 1500.0, 'max': 3000.0}, {'current': 3000.0, 'min': 1500.0, 'max': 3000.0}, {'current': 3651.887, 'min': 1500.0, 'max': 3000.0}, {'current': 1500.0, 'min': 1500.0, 'max': 3000.0}, {'current': 3000.0, 'min': 1500.0, 'max': 3000.0}, {'current': 1500.0, 'min': 1500.0, 'max': 3000.0}, {'current': 3000.0, 'min': 1500.0, 'max': 3000.0}, {'current': 1500.0, 'min': 1500.0, 'max': 3000.0}, {'current': 3650.111, 'min': 1500.0, 'max': 3000.0}, {'current': 3000.0, 'min': 1500.0, 'max': 3000.0}, {'current': 2200.0, 'min': 1500.0, 'max': 3000.0}, {'current': 3650.84, 'min': 1500.0, 'max': 3000.0}, {'current': 2920.422, 'min': 1500.0, 'max': 3000.0}, {'current': 3702.049, 'min': 1500.0, 'max': 3000.0}, {'current': 1500.0, 'min': 1500.0, 'max': 3000.0}, {'current': 1500.0, 'min': 1500.0, 'max': 3000.0}, {'current': 1500.0, 'min': 1500.0, 'max': 3000.0}, {'current': 1500.0, 'min': 1500.0, 'max': 3000.0}, {'current': 1500.0, 'min': 1500.0, 'max': 3000.0}, {'current': 1500.0, 'min': 1500.0, 'max': 3000.0}, {'current': 3000.0, 'min': 1500.0, 'max': 3000.0}, {'current': 3701.512, 'min': 1500.0, 'max': 3000.0}, {'current': 1500.0, 'min': 1500.0, 'max': 3000.0}, {'current': 1500.0, 'min': 1500.0, 'max': 3000.0}, {'current': 1500.0, 'min': 1500.0, 'max': 3000.0}, {'current': 3701.528, 'min': 1500.0, 'max': 3000.0}, {'current': 1500.0, 'min': 1500.0, 'max': 3000.0}, {'current': 1500.0, 'min': 1500.0, 'max': 3000.0}, {'current': 3000.0, 'min': 1500.0, 'max': 3000.0}, {'current': 1500.0, 'min': 1500.0, 'max': 3000.0}, {'current': 1500.0, 'min': 1500.0, 'max': 3000.0}, {'current': 1500.0, 'min': 1500.0, 'max': 3000.0}, {'current': 1500.0, 'min': 1500.0, 'max': 3000.0}, {'current': 1500.0, 'min': 1500.0, 'max': 3000.0}, {'current': 1500.0, 'min': 1500.0, 'max': 3000.0}, {'current': 2200.0, 'min': 1500.0, 'max': 3000.0}, {'current': 3000.0, 'min': 1500.0, 'max': 3000.0}, {'current': 1500.0, 'min': 1500.0, 'max': 3000.0}, {'current': 1500.0, 'min': 1500.0, 'max': 3000.0}, {'current': 1500.0, 'min': 1500.0, 'max': 3000.0}, {'current': 1500.0, 'min': 1500.0, 'max': 3000.0}, {'current': 1500.0, 'min': 1500.0, 'max': 3000.0}, {'current': 1500.0, 'min': 1500.0, 'max': 3000.0}, {'current': 1500.0, 'min': 1500.0, 'max': 3000.0}, {'current': 1500.0, 'min': 1500.0, 'max': 3000.0}, {'current': 1500.0, 'min': 1500.0, 'max': 3000.0}, {'current': 3000.0, 'min': 1500.0, 'max': 3000.0}, {'current': 1500.0, 'min': 1500.0, 'max': 3000.0}, {'current': 1500.0, 'min': 1500.0, 'max': 3000.0}, {'current': 3051.433, 'min': 1500.0, 'max': 3000.0}, {'current': 1500.0, 'min': 1500.0, 'max': 3000.0}, {'current': 3702.281, 'min': 1500.0, 'max': 3000.0}, {'current': 1500.0, 'min': 1500.0, 'max': 3000.0}, {'current': 1500.0, 'min': 1500.0, 'max': 3000.0}, {'current': 3000.0, 'min': 1500.0, 'max': 3000.0}, {'current': 1500.0, 'min': 1500.0, 'max': 3000.0}, {'current': 1500.0, 'min': 1500.0, 'max': 3000.0}, {'current': 1500.0, 'min': 1500.0, 'max': 3000.0}, {'current': 1500.0, 'min': 1500.0, 'max': 3000.0}, {'current': 1500.0, 'min': 1500.0, 'max': 3000.0}, {'current': 1500.0, 'min': 1500.0, 'max': 3000.0}], 'disk': {'/': {'total': 878.1072120666504, 'used': 56.62008285522461}}, 'gpu': 'NVIDIA RTX A6000', 'gpu_count': 8, 'gpu_devices': [{'name': 'NVIDIA RTX A6000', 'memory_total': 51527024640}, {'name': 'NVIDIA RTX A6000', 'memory_total': 51527024640}, {'name': 'NVIDIA RTX A6000', 'memory_total': 51527024640}, {'name': 'NVIDIA RTX A6000', 'memory_total': 51527024640}, {'name': 'NVIDIA RTX A6000', 'memory_total': 51527024640}, {'name': 'NVIDIA RTX A6000', 'memory_total': 51527024640}, {'name': 'NVIDIA RTX A6000', 'memory_total': 51527024640}, {'name': 'NVIDIA RTX A6000', 'memory_total': 51527024640}], 'memory': {'total': 251.7312126159668}}
2024-05-14 01:30:51,424 INFO    HandlerThread:2406543 [system_monitor.py:probe():224] Finished collecting system info
2024-05-14 01:30:51,424 INFO    HandlerThread:2406543 [system_monitor.py:probe():227] Publishing system info
2024-05-14 01:30:51,424 DEBUG   HandlerThread:2406543 [system_info.py:_save_pip():52] Saving list of pip packages installed into the current environment
2024-05-14 01:30:51,428 DEBUG   HandlerThread:2406543 [system_info.py:_save_pip():68] Saving pip packages done
2024-05-14 01:30:51,434 DEBUG   HandlerThread:2406543 [system_info.py:_save_conda():75] Saving list of conda packages installed into the current environment
2024-05-14 01:30:52,254 INFO    Thread-12 :2406543 [dir_watcher.py:_on_file_created():271] file/dir created: /nfs/datx/lyk/HiFT/wandb/run-20240514_013050-o15pf2qh/files/conda-environment.yaml
2024-05-14 01:30:52,255 INFO    Thread-12 :2406543 [dir_watcher.py:_on_file_created():271] file/dir created: /nfs/datx/lyk/HiFT/wandb/run-20240514_013050-o15pf2qh/files/requirements.txt
2024-05-14 01:31:07,638 DEBUG   HandlerThread:2406543 [system_info.py:_save_conda():87] Saving conda packages done
2024-05-14 01:31:07,641 INFO    HandlerThread:2406543 [system_monitor.py:probe():229] Finished publishing system info
2024-05-14 01:31:07,698 DEBUG   HandlerThread:2406543 [handler.py:handle_request():146] handle_request: status_report
2024-05-14 01:31:07,698 DEBUG   HandlerThread:2406543 [handler.py:handle_request():146] handle_request: keepalive
2024-05-14 01:31:07,698 DEBUG   HandlerThread:2406543 [handler.py:handle_request():146] handle_request: status_report
2024-05-14 01:31:07,698 DEBUG   HandlerThread:2406543 [handler.py:handle_request():146] handle_request: keepalive
2024-05-14 01:31:07,698 DEBUG   HandlerThread:2406543 [handler.py:handle_request():146] handle_request: status_report
2024-05-14 01:31:07,698 DEBUG   HandlerThread:2406543 [handler.py:handle_request():146] handle_request: keepalive
2024-05-14 01:31:07,699 DEBUG   SenderThread:2406543 [sender.py:send():382] send: files
2024-05-14 01:31:07,699 INFO    SenderThread:2406543 [sender.py:_save_file():1392] saving file wandb-metadata.json with policy now
2024-05-14 01:31:07,709 DEBUG   SenderThread:2406543 [sender.py:send():382] send: telemetry
2024-05-14 01:31:07,713 DEBUG   HandlerThread:2406543 [handler.py:handle_request():146] handle_request: internal_messages
2024-05-14 01:31:07,713 DEBUG   HandlerThread:2406543 [handler.py:handle_request():146] handle_request: stop_status
2024-05-14 01:31:07,715 DEBUG   SenderThread:2406543 [sender.py:send():382] send: config
2024-05-14 01:31:07,716 DEBUG   SenderThread:2406543 [sender.py:send_request():409] send_request: stop_status
2024-05-14 01:31:07,895 DEBUG   SenderThread:2406543 [sender.py:send():382] send: metric
2024-05-14 01:31:07,895 DEBUG   SenderThread:2406543 [sender.py:send():382] send: telemetry
2024-05-14 01:31:07,895 DEBUG   SenderThread:2406543 [sender.py:send():382] send: metric
2024-05-14 01:31:07,895 WARNING SenderThread:2406543 [sender.py:send_metric():1343] Seen metric with glob (shouldn't happen)
2024-05-14 01:31:07,895 DEBUG   SenderThread:2406543 [sender.py:send():382] send: telemetry
2024-05-14 01:31:08,148 ERROR   wandb-upload_0:2406543 [internal_api.py:upload_file():2761] upload_file exception https://storage.googleapis.com/wandb-production.appspot.com/neuzxm/huggingface/o15pf2qh/wandb-metadata.json?Expires=1715729467&GoogleAccessId=gorilla-files-url-signer-man%40wandb-production.iam.gserviceaccount.com&Signature=G2phX9vcQvQ9T3lqedA4ISCKiGaRJ3Rz5F30%2BiHF2AEBG6Gw0XuwQRzqvmwHGp7NLKoyo80A3A8HIRlljertJOcPuT2fJ4d1E3wwC91fR5C3JsNz7Og0Jhf13ONjzPqz095r%2FxwbY57zbGH0nveOGtxGf6sP97UyfkAyaoxtHgWsbtPCw7aauIH%2Bs5IQ8Msu%2Bibd6%2BrAXZtbyN40g7YyVYeWMuKiKAdyNKg19EzlJd6tloD8lvrHcfl90NjuV3BULA4S9P4P7MGNYt2BM6vzn9V%2FcQimTKbTzwU9VR50V1b9%2F80009WmhUMorbwf6QpSa1vZbpyTfZVelWsax0dSKA%3D%3D: 403 Client Error: Forbidden for url: https://storage.googleapis.com/wandb-production.appspot.com/neuzxm/huggingface/o15pf2qh/wandb-metadata.json?Expires=1715729467&GoogleAccessId=gorilla-files-url-signer-man%40wandb-production.iam.gserviceaccount.com&Signature=G2phX9vcQvQ9T3lqedA4ISCKiGaRJ3Rz5F30%2BiHF2AEBG6Gw0XuwQRzqvmwHGp7NLKoyo80A3A8HIRlljertJOcPuT2fJ4d1E3wwC91fR5C3JsNz7Og0Jhf13ONjzPqz095r%2FxwbY57zbGH0nveOGtxGf6sP97UyfkAyaoxtHgWsbtPCw7aauIH%2Bs5IQ8Msu%2Bibd6%2BrAXZtbyN40g7YyVYeWMuKiKAdyNKg19EzlJd6tloD8lvrHcfl90NjuV3BULA4S9P4P7MGNYt2BM6vzn9V%2FcQimTKbTzwU9VR50V1b9%2F80009WmhUMorbwf6QpSa1vZbpyTfZVelWsax0dSKA%3D%3D
2024-05-14 01:31:08,148 ERROR   wandb-upload_0:2406543 [internal_api.py:upload_file():2763] upload_file request headers: {'User-Agent': 'python-requests/2.31.0', 'Accept-Encoding': 'gzip, deflate, br', 'Accept': '*/*', 'Connection': 'keep-alive', 'Content-Length': '10145'}
2024-05-14 01:31:08,148 ERROR   wandb-upload_0:2406543 [internal_api.py:upload_file():2765] upload_file response body: b"<?xml version='1.0' encoding='UTF-8'?><Error><Code>AccessDenied</Code><Message>Access denied.</Message><Details>We're sorry, but this service is not available in your location</Details></Error>"
2024-05-14 01:31:08,223 ERROR   wandb-upload_0:2406543 [upload_job.py:push():134] Failed to upload file: /tmp/tmpyezl0fvcwandb/lm1bkykd-wandb-metadata.json
Traceback (most recent call last):
  File "/mounts/work/lyk/anaconda3/envs/torch2/lib/python3.8/site-packages/wandb/apis/normalize.py", line 41, in wrapper
    return func(*args, **kwargs)
  File "/mounts/work/lyk/anaconda3/envs/torch2/lib/python3.8/site-packages/wandb/sdk/lib/retry.py", line 212, in wrapped_fn
    return retrier(*args, **kargs)
  File "/mounts/work/lyk/anaconda3/envs/torch2/lib/python3.8/site-packages/wandb/sdk/lib/retry.py", line 131, in __call__
    result = self._call_fn(*args, **kwargs)
  File "/mounts/work/lyk/anaconda3/envs/torch2/lib/python3.8/site-packages/wandb/sdk/internal/internal_api.py", line 2787, in upload_file
    wandb._sentry.reraise(e)
  File "/mounts/work/lyk/anaconda3/envs/torch2/lib/python3.8/site-packages/wandb/analytics/sentry.py", line 154, in reraise
    raise exc.with_traceback(sys.exc_info()[2])
  File "/mounts/work/lyk/anaconda3/envs/torch2/lib/python3.8/site-packages/wandb/sdk/internal/internal_api.py", line 2759, in upload_file
    response.raise_for_status()
  File "/mounts/work/lyk/anaconda3/envs/torch2/lib/python3.8/site-packages/requests/models.py", line 1021, in raise_for_status
    raise HTTPError(http_error_msg, response=self)
requests.exceptions.HTTPError: 403 Client Error: Forbidden for url: https://storage.googleapis.com/wandb-production.appspot.com/neuzxm/huggingface/o15pf2qh/wandb-metadata.json?Expires=1715729467&GoogleAccessId=gorilla-files-url-signer-man%40wandb-production.iam.gserviceaccount.com&Signature=G2phX9vcQvQ9T3lqedA4ISCKiGaRJ3Rz5F30%2BiHF2AEBG6Gw0XuwQRzqvmwHGp7NLKoyo80A3A8HIRlljertJOcPuT2fJ4d1E3wwC91fR5C3JsNz7Og0Jhf13ONjzPqz095r%2FxwbY57zbGH0nveOGtxGf6sP97UyfkAyaoxtHgWsbtPCw7aauIH%2Bs5IQ8Msu%2Bibd6%2BrAXZtbyN40g7YyVYeWMuKiKAdyNKg19EzlJd6tloD8lvrHcfl90NjuV3BULA4S9P4P7MGNYt2BM6vzn9V%2FcQimTKbTzwU9VR50V1b9%2F80009WmhUMorbwf6QpSa1vZbpyTfZVelWsax0dSKA%3D%3D

During handling of the above exception, another exception occurred:

Traceback (most recent call last):
  File "/mounts/work/lyk/anaconda3/envs/torch2/lib/python3.8/site-packages/wandb/filesync/upload_job.py", line 125, in push
    self._api.upload_file_retry(
  File "/mounts/work/lyk/anaconda3/envs/torch2/lib/python3.8/site-packages/wandb/apis/normalize.py", line 51, in wrapper
    raise CommError(message, error)
wandb.errors.CommError: <Response [403]>
2024-05-14 01:31:08,276 ERROR   Thread-11 :2406543 [step_upload.py:_handle_event():200] Failed to upload file: /tmp/tmpyezl0fvcwandb/lm1bkykd-wandb-metadata.json
Traceback (most recent call last):
  File "/mounts/work/lyk/anaconda3/envs/torch2/lib/python3.8/site-packages/wandb/apis/normalize.py", line 41, in wrapper
    return func(*args, **kwargs)
  File "/mounts/work/lyk/anaconda3/envs/torch2/lib/python3.8/site-packages/wandb/sdk/lib/retry.py", line 212, in wrapped_fn
    return retrier(*args, **kargs)
  File "/mounts/work/lyk/anaconda3/envs/torch2/lib/python3.8/site-packages/wandb/sdk/lib/retry.py", line 131, in __call__
    result = self._call_fn(*args, **kwargs)
  File "/mounts/work/lyk/anaconda3/envs/torch2/lib/python3.8/site-packages/wandb/sdk/internal/internal_api.py", line 2787, in upload_file
    wandb._sentry.reraise(e)
  File "/mounts/work/lyk/anaconda3/envs/torch2/lib/python3.8/site-packages/wandb/analytics/sentry.py", line 154, in reraise
    raise exc.with_traceback(sys.exc_info()[2])
  File "/mounts/work/lyk/anaconda3/envs/torch2/lib/python3.8/site-packages/wandb/sdk/internal/internal_api.py", line 2759, in upload_file
    response.raise_for_status()
  File "/mounts/work/lyk/anaconda3/envs/torch2/lib/python3.8/site-packages/requests/models.py", line 1021, in raise_for_status
    raise HTTPError(http_error_msg, response=self)
requests.exceptions.HTTPError: 403 Client Error: Forbidden for url: https://storage.googleapis.com/wandb-production.appspot.com/neuzxm/huggingface/o15pf2qh/wandb-metadata.json?Expires=1715729467&GoogleAccessId=gorilla-files-url-signer-man%40wandb-production.iam.gserviceaccount.com&Signature=G2phX9vcQvQ9T3lqedA4ISCKiGaRJ3Rz5F30%2BiHF2AEBG6Gw0XuwQRzqvmwHGp7NLKoyo80A3A8HIRlljertJOcPuT2fJ4d1E3wwC91fR5C3JsNz7Og0Jhf13ONjzPqz095r%2FxwbY57zbGH0nveOGtxGf6sP97UyfkAyaoxtHgWsbtPCw7aauIH%2Bs5IQ8Msu%2Bibd6%2BrAXZtbyN40g7YyVYeWMuKiKAdyNKg19EzlJd6tloD8lvrHcfl90NjuV3BULA4S9P4P7MGNYt2BM6vzn9V%2FcQimTKbTzwU9VR50V1b9%2F80009WmhUMorbwf6QpSa1vZbpyTfZVelWsax0dSKA%3D%3D

During handling of the above exception, another exception occurred:

Traceback (most recent call last):
  File "/mounts/work/lyk/anaconda3/envs/torch2/lib/python3.8/concurrent/futures/thread.py", line 57, in run
    result = self.fn(*self.args, **self.kwargs)
  File "/mounts/work/lyk/anaconda3/envs/torch2/lib/python3.8/site-packages/wandb/filesync/step_upload.py", line 288, in run_and_notify
    self._do_upload_sync(event)
  File "/mounts/work/lyk/anaconda3/envs/torch2/lib/python3.8/site-packages/wandb/filesync/step_upload.py", line 330, in _do_upload_sync
    job.run()
  File "/mounts/work/lyk/anaconda3/envs/torch2/lib/python3.8/site-packages/wandb/filesync/upload_job.py", line 57, in run
    self.push()
  File "/mounts/work/lyk/anaconda3/envs/torch2/lib/python3.8/site-packages/wandb/filesync/upload_job.py", line 125, in push
    self._api.upload_file_retry(
  File "/mounts/work/lyk/anaconda3/envs/torch2/lib/python3.8/site-packages/wandb/apis/normalize.py", line 51, in wrapper
    raise CommError(message, error)
wandb.errors.CommError: <Response [403]>
2024-05-14 01:31:08,282 INFO    Thread-12 :2406543 [dir_watcher.py:_on_file_modified():288] file/dir modified: /nfs/datx/lyk/HiFT/wandb/run-20240514_013050-o15pf2qh/files/conda-environment.yaml
2024-05-14 01:31:08,285 INFO    Thread-12 :2406543 [dir_watcher.py:_on_file_created():271] file/dir created: /nfs/datx/lyk/HiFT/wandb/run-20240514_013050-o15pf2qh/files/wandb-metadata.json
2024-05-14 01:31:08,285 INFO    Thread-12 :2406543 [dir_watcher.py:_on_file_created():271] file/dir created: /nfs/datx/lyk/HiFT/wandb/run-20240514_013050-o15pf2qh/files/output.log
2024-05-14 01:31:09,290 DEBUG   SenderThread:2406543 [sender.py:send():382] send: exit
2024-05-14 01:31:09,290 INFO    SenderThread:2406543 [sender.py:send_exit():589] handling exit code: 1
2024-05-14 01:31:09,290 INFO    SenderThread:2406543 [sender.py:send_exit():591] handling runtime: 17
2024-05-14 01:31:09,294 INFO    SenderThread:2406543 [sender.py:_save_file():1392] saving file wandb-summary.json with policy end
2024-05-14 01:31:09,295 INFO    SenderThread:2406543 [sender.py:send_exit():597] send defer
2024-05-14 01:31:09,295 DEBUG   HandlerThread:2406543 [handler.py:handle_request():146] handle_request: defer
2024-05-14 01:31:09,295 INFO    HandlerThread:2406543 [handler.py:handle_request_defer():172] handle defer: 0
2024-05-14 01:31:09,295 DEBUG   SenderThread:2406543 [sender.py:send_request():409] send_request: defer
2024-05-14 01:31:09,295 INFO    SenderThread:2406543 [sender.py:send_request_defer():613] handle sender defer: 0
2024-05-14 01:31:09,295 INFO    SenderThread:2406543 [sender.py:transition_state():617] send defer: 1
2024-05-14 01:31:09,296 DEBUG   HandlerThread:2406543 [handler.py:handle_request():146] handle_request: defer
2024-05-14 01:31:09,296 INFO    HandlerThread:2406543 [handler.py:handle_request_defer():172] handle defer: 1
2024-05-14 01:31:09,296 DEBUG   SenderThread:2406543 [sender.py:send_request():409] send_request: defer
2024-05-14 01:31:09,296 INFO    SenderThread:2406543 [sender.py:send_request_defer():613] handle sender defer: 1
2024-05-14 01:31:09,296 INFO    SenderThread:2406543 [sender.py:transition_state():617] send defer: 2
2024-05-14 01:31:09,296 DEBUG   HandlerThread:2406543 [handler.py:handle_request():146] handle_request: defer
2024-05-14 01:31:09,296 INFO    HandlerThread:2406543 [handler.py:handle_request_defer():172] handle defer: 2
2024-05-14 01:31:09,296 INFO    HandlerThread:2406543 [system_monitor.py:finish():203] Stopping system monitor
2024-05-14 01:31:09,297 DEBUG   SystemMonitor:2406543 [system_monitor.py:_start():172] Starting system metrics aggregation loop
2024-05-14 01:31:09,297 DEBUG   SystemMonitor:2406543 [system_monitor.py:_start():179] Finished system metrics aggregation loop
2024-05-14 01:31:09,297 DEBUG   SystemMonitor:2406543 [system_monitor.py:_start():183] Publishing last batch of metrics
2024-05-14 01:31:09,298 INFO    HandlerThread:2406543 [interfaces.py:finish():202] Joined cpu monitor
2024-05-14 01:31:09,298 INFO    HandlerThread:2406543 [interfaces.py:finish():202] Joined disk monitor
2024-05-14 01:31:09,904 INFO    HandlerThread:2406543 [interfaces.py:finish():202] Joined gpu monitor
2024-05-14 01:31:09,905 INFO    HandlerThread:2406543 [interfaces.py:finish():202] Joined memory monitor
2024-05-14 01:31:09,905 INFO    HandlerThread:2406543 [interfaces.py:finish():202] Joined network monitor
2024-05-14 01:31:09,905 DEBUG   SenderThread:2406543 [sender.py:send_request():409] send_request: defer
2024-05-14 01:31:09,905 INFO    SenderThread:2406543 [sender.py:send_request_defer():613] handle sender defer: 2
2024-05-14 01:31:09,905 INFO    SenderThread:2406543 [sender.py:transition_state():617] send defer: 3
2024-05-14 01:31:09,906 DEBUG   SenderThread:2406543 [sender.py:send():382] send: stats
2024-05-14 01:31:09,906 DEBUG   HandlerThread:2406543 [handler.py:handle_request():146] handle_request: defer
2024-05-14 01:31:09,906 INFO    HandlerThread:2406543 [handler.py:handle_request_defer():172] handle defer: 3
2024-05-14 01:31:09,906 DEBUG   SenderThread:2406543 [sender.py:send_request():409] send_request: defer
2024-05-14 01:31:09,906 INFO    SenderThread:2406543 [sender.py:send_request_defer():613] handle sender defer: 3
2024-05-14 01:31:09,906 INFO    SenderThread:2406543 [sender.py:transition_state():617] send defer: 4
2024-05-14 01:31:09,906 DEBUG   HandlerThread:2406543 [handler.py:handle_request():146] handle_request: defer
2024-05-14 01:31:09,906 INFO    HandlerThread:2406543 [handler.py:handle_request_defer():172] handle defer: 4
2024-05-14 01:31:09,907 DEBUG   SenderThread:2406543 [sender.py:send_request():409] send_request: defer
2024-05-14 01:31:09,907 INFO    SenderThread:2406543 [sender.py:send_request_defer():613] handle sender defer: 4
2024-05-14 01:31:09,907 INFO    SenderThread:2406543 [sender.py:transition_state():617] send defer: 5
2024-05-14 01:31:09,907 DEBUG   HandlerThread:2406543 [handler.py:handle_request():146] handle_request: defer
2024-05-14 01:31:09,907 INFO    HandlerThread:2406543 [handler.py:handle_request_defer():172] handle defer: 5
2024-05-14 01:31:09,907 DEBUG   SenderThread:2406543 [sender.py:send():382] send: summary
2024-05-14 01:31:09,908 INFO    SenderThread:2406543 [sender.py:_save_file():1392] saving file wandb-summary.json with policy end
2024-05-14 01:31:09,909 DEBUG   SenderThread:2406543 [sender.py:send_request():409] send_request: defer
2024-05-14 01:31:09,909 INFO    SenderThread:2406543 [sender.py:send_request_defer():613] handle sender defer: 5
2024-05-14 01:31:09,909 INFO    SenderThread:2406543 [sender.py:transition_state():617] send defer: 6
2024-05-14 01:31:09,909 DEBUG   HandlerThread:2406543 [handler.py:handle_request():146] handle_request: defer
2024-05-14 01:31:09,909 INFO    HandlerThread:2406543 [handler.py:handle_request_defer():172] handle defer: 6
2024-05-14 01:31:09,909 DEBUG   SenderThread:2406543 [sender.py:send_request():409] send_request: defer
2024-05-14 01:31:09,909 INFO    SenderThread:2406543 [sender.py:send_request_defer():613] handle sender defer: 6
2024-05-14 01:31:09,913 DEBUG   HandlerThread:2406543 [handler.py:handle_request():146] handle_request: status_report
2024-05-14 01:31:10,109 INFO    SenderThread:2406543 [sender.py:transition_state():617] send defer: 7
2024-05-14 01:31:10,109 DEBUG   HandlerThread:2406543 [handler.py:handle_request():146] handle_request: defer
2024-05-14 01:31:10,109 INFO    HandlerThread:2406543 [handler.py:handle_request_defer():172] handle defer: 7
2024-05-14 01:31:10,110 DEBUG   SenderThread:2406543 [sender.py:send_request():409] send_request: defer
2024-05-14 01:31:10,110 INFO    SenderThread:2406543 [sender.py:send_request_defer():613] handle sender defer: 7
2024-05-14 01:31:10,285 INFO    Thread-12 :2406543 [dir_watcher.py:_on_file_modified():288] file/dir modified: /nfs/datx/lyk/HiFT/wandb/run-20240514_013050-o15pf2qh/files/config.yaml
2024-05-14 01:31:10,286 INFO    Thread-12 :2406543 [dir_watcher.py:_on_file_modified():288] file/dir modified: /nfs/datx/lyk/HiFT/wandb/run-20240514_013050-o15pf2qh/files/output.log
2024-05-14 01:31:10,286 INFO    Thread-12 :2406543 [dir_watcher.py:_on_file_created():271] file/dir created: /nfs/datx/lyk/HiFT/wandb/run-20240514_013050-o15pf2qh/files/wandb-summary.json
2024-05-14 01:31:10,290 DEBUG   HandlerThread:2406543 [handler.py:handle_request():146] handle_request: poll_exit
2024-05-14 01:31:11,287 INFO    Thread-12 :2406543 [dir_watcher.py:_on_file_modified():288] file/dir modified: /nfs/datx/lyk/HiFT/wandb/run-20240514_013050-o15pf2qh/files/output.log
2024-05-14 01:31:13,142 INFO    SenderThread:2406543 [sender.py:transition_state():617] send defer: 8
2024-05-14 01:31:13,143 DEBUG   SenderThread:2406543 [sender.py:send_request():409] send_request: poll_exit
2024-05-14 01:31:13,143 DEBUG   HandlerThread:2406543 [handler.py:handle_request():146] handle_request: defer
2024-05-14 01:31:13,143 INFO    HandlerThread:2406543 [handler.py:handle_request_defer():172] handle defer: 8
2024-05-14 01:31:13,144 DEBUG   SenderThread:2406543 [sender.py:send_request():409] send_request: defer
2024-05-14 01:31:13,144 INFO    SenderThread:2406543 [sender.py:send_request_defer():613] handle sender defer: 8
2024-05-14 01:31:13,144 INFO    SenderThread:2406543 [job_builder.py:build():298] Attempting to build job artifact
2024-05-14 01:31:13,146 INFO    SenderThread:2406543 [job_builder.py:_get_source_type():439] no source found
2024-05-14 01:31:13,147 INFO    SenderThread:2406543 [sender.py:transition_state():617] send defer: 9
2024-05-14 01:31:13,147 DEBUG   HandlerThread:2406543 [handler.py:handle_request():146] handle_request: defer
2024-05-14 01:31:13,147 INFO    HandlerThread:2406543 [handler.py:handle_request_defer():172] handle defer: 9
2024-05-14 01:31:13,147 DEBUG   SenderThread:2406543 [sender.py:send_request():409] send_request: defer
2024-05-14 01:31:13,147 INFO    SenderThread:2406543 [sender.py:send_request_defer():613] handle sender defer: 9
2024-05-14 01:31:13,147 INFO    SenderThread:2406543 [dir_watcher.py:finish():358] shutting down directory watcher
2024-05-14 01:31:13,292 INFO    SenderThread:2406543 [dir_watcher.py:_on_file_modified():288] file/dir modified: /nfs/datx/lyk/HiFT/wandb/run-20240514_013050-o15pf2qh/files/output.log
2024-05-14 01:31:13,293 INFO    SenderThread:2406543 [dir_watcher.py:finish():388] scan: /nfs/datx/lyk/HiFT/wandb/run-20240514_013050-o15pf2qh/files
2024-05-14 01:31:13,294 INFO    SenderThread:2406543 [dir_watcher.py:finish():402] scan save: /nfs/datx/lyk/HiFT/wandb/run-20240514_013050-o15pf2qh/files/wandb-summary.json wandb-summary.json
2024-05-14 01:31:13,294 INFO    SenderThread:2406543 [dir_watcher.py:finish():402] scan save: /nfs/datx/lyk/HiFT/wandb/run-20240514_013050-o15pf2qh/files/requirements.txt requirements.txt
2024-05-14 01:31:13,295 INFO    SenderThread:2406543 [dir_watcher.py:finish():402] scan save: /nfs/datx/lyk/HiFT/wandb/run-20240514_013050-o15pf2qh/files/conda-environment.yaml conda-environment.yaml
2024-05-14 01:31:13,295 INFO    SenderThread:2406543 [dir_watcher.py:finish():402] scan save: /nfs/datx/lyk/HiFT/wandb/run-20240514_013050-o15pf2qh/files/config.yaml config.yaml
2024-05-14 01:31:13,295 INFO    SenderThread:2406543 [dir_watcher.py:finish():402] scan save: /nfs/datx/lyk/HiFT/wandb/run-20240514_013050-o15pf2qh/files/wandb-metadata.json wandb-metadata.json
2024-05-14 01:31:13,295 INFO    SenderThread:2406543 [dir_watcher.py:finish():402] scan save: /nfs/datx/lyk/HiFT/wandb/run-20240514_013050-o15pf2qh/files/output.log output.log
2024-05-14 01:31:13,297 INFO    SenderThread:2406543 [sender.py:transition_state():617] send defer: 10
2024-05-14 01:31:13,297 DEBUG   HandlerThread:2406543 [handler.py:handle_request():146] handle_request: defer
2024-05-14 01:31:13,297 INFO    HandlerThread:2406543 [handler.py:handle_request_defer():172] handle defer: 10
2024-05-14 01:31:13,298 DEBUG   SenderThread:2406543 [sender.py:send_request():409] send_request: defer
2024-05-14 01:31:13,298 INFO    SenderThread:2406543 [sender.py:send_request_defer():613] handle sender defer: 10
2024-05-14 01:31:13,299 INFO    SenderThread:2406543 [file_pusher.py:finish():175] shutting down file pusher
2024-05-14 01:31:13,543 ERROR   wandb-upload_0:2406543 [internal_api.py:upload_file():2761] upload_file exception https://storage.googleapis.com/wandb-production.appspot.com/neuzxm/huggingface/o15pf2qh/wandb-summary.json?Expires=1715729473&GoogleAccessId=gorilla-files-url-signer-man%40wandb-production.iam.gserviceaccount.com&Signature=g1yoaiFYcqVtnJFw6VvPXvOtRf1R9hWvTlna9E7Xw0xNd5PFwEfCi0IKNbt3%2BW%2F%2F%2B1pMJMKnQiy36j7tPLtq2X0DD%2B0dieP%2F82PgCU3I9dPHoc0NPlmxW1WmizGWc0SNDFvERHIUdINtOk9xeEgASQ2njQaquQK3Prb0QHcynmcsdjyXY%2FFa4YpIhOQNaWcbchkhGS38s%2F0g2PiUSeBPVk7WzkTg8K08ScBqDCwnNX9P4g16vTnRtRhXvihV6su7o3xlfKxH9dvzM69tNLbT0SPe4prMKqbMIjgife1JoxGFvs7Yobil0rEzwCJbB2ky%2BI8Lp6syXUX4yiGRj40IbA%3D%3D: 403 Client Error: Forbidden for url: https://storage.googleapis.com/wandb-production.appspot.com/neuzxm/huggingface/o15pf2qh/wandb-summary.json?Expires=1715729473&GoogleAccessId=gorilla-files-url-signer-man%40wandb-production.iam.gserviceaccount.com&Signature=g1yoaiFYcqVtnJFw6VvPXvOtRf1R9hWvTlna9E7Xw0xNd5PFwEfCi0IKNbt3%2BW%2F%2F%2B1pMJMKnQiy36j7tPLtq2X0DD%2B0dieP%2F82PgCU3I9dPHoc0NPlmxW1WmizGWc0SNDFvERHIUdINtOk9xeEgASQ2njQaquQK3Prb0QHcynmcsdjyXY%2FFa4YpIhOQNaWcbchkhGS38s%2F0g2PiUSeBPVk7WzkTg8K08ScBqDCwnNX9P4g16vTnRtRhXvihV6su7o3xlfKxH9dvzM69tNLbT0SPe4prMKqbMIjgife1JoxGFvs7Yobil0rEzwCJbB2ky%2BI8Lp6syXUX4yiGRj40IbA%3D%3D
2024-05-14 01:31:13,543 ERROR   wandb-upload_0:2406543 [internal_api.py:upload_file():2763] upload_file request headers: {'User-Agent': 'python-requests/2.31.0', 'Accept-Encoding': 'gzip, deflate, br', 'Accept': '*/*', 'Connection': 'keep-alive', 'Content-Length': '27'}
2024-05-14 01:31:13,543 ERROR   wandb-upload_0:2406543 [internal_api.py:upload_file():2765] upload_file response body: b"<?xml version='1.0' encoding='UTF-8'?><Error><Code>AccessDenied</Code><Message>Access denied.</Message><Details>We're sorry, but this service is not available in your location</Details></Error>"
2024-05-14 01:31:13,562 ERROR   wandb-upload_0:2406543 [upload_job.py:push():134] Failed to upload file: /nfs/datx/lyk/HiFT/wandb/run-20240514_013050-o15pf2qh/files/wandb-summary.json
Traceback (most recent call last):
  File "/mounts/work/lyk/anaconda3/envs/torch2/lib/python3.8/site-packages/wandb/apis/normalize.py", line 41, in wrapper
    return func(*args, **kwargs)
  File "/mounts/work/lyk/anaconda3/envs/torch2/lib/python3.8/site-packages/wandb/sdk/lib/retry.py", line 212, in wrapped_fn
    return retrier(*args, **kargs)
  File "/mounts/work/lyk/anaconda3/envs/torch2/lib/python3.8/site-packages/wandb/sdk/lib/retry.py", line 131, in __call__
    result = self._call_fn(*args, **kwargs)
  File "/mounts/work/lyk/anaconda3/envs/torch2/lib/python3.8/site-packages/wandb/sdk/internal/internal_api.py", line 2787, in upload_file
    wandb._sentry.reraise(e)
  File "/mounts/work/lyk/anaconda3/envs/torch2/lib/python3.8/site-packages/wandb/analytics/sentry.py", line 154, in reraise
    raise exc.with_traceback(sys.exc_info()[2])
  File "/mounts/work/lyk/anaconda3/envs/torch2/lib/python3.8/site-packages/wandb/sdk/internal/internal_api.py", line 2759, in upload_file
    response.raise_for_status()
  File "/mounts/work/lyk/anaconda3/envs/torch2/lib/python3.8/site-packages/requests/models.py", line 1021, in raise_for_status
    raise HTTPError(http_error_msg, response=self)
requests.exceptions.HTTPError: 403 Client Error: Forbidden for url: https://storage.googleapis.com/wandb-production.appspot.com/neuzxm/huggingface/o15pf2qh/wandb-summary.json?Expires=1715729473&GoogleAccessId=gorilla-files-url-signer-man%40wandb-production.iam.gserviceaccount.com&Signature=g1yoaiFYcqVtnJFw6VvPXvOtRf1R9hWvTlna9E7Xw0xNd5PFwEfCi0IKNbt3%2BW%2F%2F%2B1pMJMKnQiy36j7tPLtq2X0DD%2B0dieP%2F82PgCU3I9dPHoc0NPlmxW1WmizGWc0SNDFvERHIUdINtOk9xeEgASQ2njQaquQK3Prb0QHcynmcsdjyXY%2FFa4YpIhOQNaWcbchkhGS38s%2F0g2PiUSeBPVk7WzkTg8K08ScBqDCwnNX9P4g16vTnRtRhXvihV6su7o3xlfKxH9dvzM69tNLbT0SPe4prMKqbMIjgife1JoxGFvs7Yobil0rEzwCJbB2ky%2BI8Lp6syXUX4yiGRj40IbA%3D%3D

During handling of the above exception, another exception occurred:

Traceback (most recent call last):
  File "/mounts/work/lyk/anaconda3/envs/torch2/lib/python3.8/site-packages/wandb/filesync/upload_job.py", line 125, in push
    self._api.upload_file_retry(
  File "/mounts/work/lyk/anaconda3/envs/torch2/lib/python3.8/site-packages/wandb/apis/normalize.py", line 51, in wrapper
    raise CommError(message, error)
wandb.errors.CommError: <Response [403]>
2024-05-14 01:31:13,586 ERROR   Thread-11 :2406543 [step_upload.py:_handle_event():200] Failed to upload file: /nfs/datx/lyk/HiFT/wandb/run-20240514_013050-o15pf2qh/files/wandb-summary.json
Traceback (most recent call last):
  File "/mounts/work/lyk/anaconda3/envs/torch2/lib/python3.8/site-packages/wandb/apis/normalize.py", line 41, in wrapper
    return func(*args, **kwargs)
  File "/mounts/work/lyk/anaconda3/envs/torch2/lib/python3.8/site-packages/wandb/sdk/lib/retry.py", line 212, in wrapped_fn
    return retrier(*args, **kargs)
  File "/mounts/work/lyk/anaconda3/envs/torch2/lib/python3.8/site-packages/wandb/sdk/lib/retry.py", line 131, in __call__
    result = self._call_fn(*args, **kwargs)
  File "/mounts/work/lyk/anaconda3/envs/torch2/lib/python3.8/site-packages/wandb/sdk/internal/internal_api.py", line 2787, in upload_file
    wandb._sentry.reraise(e)
  File "/mounts/work/lyk/anaconda3/envs/torch2/lib/python3.8/site-packages/wandb/analytics/sentry.py", line 154, in reraise
    raise exc.with_traceback(sys.exc_info()[2])
  File "/mounts/work/lyk/anaconda3/envs/torch2/lib/python3.8/site-packages/wandb/sdk/internal/internal_api.py", line 2759, in upload_file
    response.raise_for_status()
  File "/mounts/work/lyk/anaconda3/envs/torch2/lib/python3.8/site-packages/requests/models.py", line 1021, in raise_for_status
    raise HTTPError(http_error_msg, response=self)
requests.exceptions.HTTPError: 403 Client Error: Forbidden for url: https://storage.googleapis.com/wandb-production.appspot.com/neuzxm/huggingface/o15pf2qh/wandb-summary.json?Expires=1715729473&GoogleAccessId=gorilla-files-url-signer-man%40wandb-production.iam.gserviceaccount.com&Signature=g1yoaiFYcqVtnJFw6VvPXvOtRf1R9hWvTlna9E7Xw0xNd5PFwEfCi0IKNbt3%2BW%2F%2F%2B1pMJMKnQiy36j7tPLtq2X0DD%2B0dieP%2F82PgCU3I9dPHoc0NPlmxW1WmizGWc0SNDFvERHIUdINtOk9xeEgASQ2njQaquQK3Prb0QHcynmcsdjyXY%2FFa4YpIhOQNaWcbchkhGS38s%2F0g2PiUSeBPVk7WzkTg8K08ScBqDCwnNX9P4g16vTnRtRhXvihV6su7o3xlfKxH9dvzM69tNLbT0SPe4prMKqbMIjgife1JoxGFvs7Yobil0rEzwCJbB2ky%2BI8Lp6syXUX4yiGRj40IbA%3D%3D

During handling of the above exception, another exception occurred:

Traceback (most recent call last):
  File "/mounts/work/lyk/anaconda3/envs/torch2/lib/python3.8/concurrent/futures/thread.py", line 57, in run
    result = self.fn(*self.args, **self.kwargs)
  File "/mounts/work/lyk/anaconda3/envs/torch2/lib/python3.8/site-packages/wandb/filesync/step_upload.py", line 288, in run_and_notify
    self._do_upload_sync(event)
  File "/mounts/work/lyk/anaconda3/envs/torch2/lib/python3.8/site-packages/wandb/filesync/step_upload.py", line 330, in _do_upload_sync
    job.run()
  File "/mounts/work/lyk/anaconda3/envs/torch2/lib/python3.8/site-packages/wandb/filesync/upload_job.py", line 57, in run
    self.push()
  File "/mounts/work/lyk/anaconda3/envs/torch2/lib/python3.8/site-packages/wandb/filesync/upload_job.py", line 125, in push
    self._api.upload_file_retry(
  File "/mounts/work/lyk/anaconda3/envs/torch2/lib/python3.8/site-packages/wandb/apis/normalize.py", line 51, in wrapper
    raise CommError(message, error)
wandb.errors.CommError: <Response [403]>
2024-05-14 01:31:13,606 ERROR   wandb-upload_1:2406543 [internal_api.py:upload_file():2761] upload_file exception https://storage.googleapis.com/wandb-production.appspot.com/neuzxm/huggingface/o15pf2qh/requirements.txt?Expires=1715729473&GoogleAccessId=gorilla-files-url-signer-man%40wandb-production.iam.gserviceaccount.com&Signature=JEEqBltdmpn1JXZaFrzFM73IUb1ptQH%2Fugtr%2FVRstL6%2FZXr6Wan%2FrgYGJjNDUFxId%2Fm8x4Kwar%2FVIBLylTO0ymBQ2BZA8dkfhUlQFQQmT6fJvRWavDBAGueeMfB6waJOByP6eEuU3Xl8jgoN0VbEtcd6C3OrM%2B9cz14T7EukJd%2FiEJgX13nIrCKsM9ctrFBsfwCqX8O7vK1ZrwyblzEbBwIYuTsHwswfk8ohA4nLXnog80khgMI46T%2BXRmSxDvV5ybQf%2F2SsIiT19DSM9TPgyLTM4qCrDQDkwPc0PvYc1Bd4RDYu9hiEW3PFIl7D99zy%2BljZkN8M6GtNz%2B56UvIsgA%3D%3D: 403 Client Error: Forbidden for url: https://storage.googleapis.com/wandb-production.appspot.com/neuzxm/huggingface/o15pf2qh/requirements.txt?Expires=1715729473&GoogleAccessId=gorilla-files-url-signer-man%40wandb-production.iam.gserviceaccount.com&Signature=JEEqBltdmpn1JXZaFrzFM73IUb1ptQH%2Fugtr%2FVRstL6%2FZXr6Wan%2FrgYGJjNDUFxId%2Fm8x4Kwar%2FVIBLylTO0ymBQ2BZA8dkfhUlQFQQmT6fJvRWavDBAGueeMfB6waJOByP6eEuU3Xl8jgoN0VbEtcd6C3OrM%2B9cz14T7EukJd%2FiEJgX13nIrCKsM9ctrFBsfwCqX8O7vK1ZrwyblzEbBwIYuTsHwswfk8ohA4nLXnog80khgMI46T%2BXRmSxDvV5ybQf%2F2SsIiT19DSM9TPgyLTM4qCrDQDkwPc0PvYc1Bd4RDYu9hiEW3PFIl7D99zy%2BljZkN8M6GtNz%2B56UvIsgA%3D%3D
2024-05-14 01:31:13,606 ERROR   wandb-upload_1:2406543 [internal_api.py:upload_file():2763] upload_file request headers: {'User-Agent': 'python-requests/2.31.0', 'Accept-Encoding': 'gzip, deflate, br', 'Accept': '*/*', 'Connection': 'keep-alive', 'Content-Length': '2434'}
2024-05-14 01:31:13,606 ERROR   wandb-upload_1:2406543 [internal_api.py:upload_file():2765] upload_file response body: b"<?xml version='1.0' encoding='UTF-8'?><Error><Code>AccessDenied</Code><Message>Access denied.</Message><Details>We're sorry, but this service is not available in your location</Details></Error>"
2024-05-14 01:31:13,625 ERROR   wandb-upload_1:2406543 [upload_job.py:push():134] Failed to upload file: /nfs/datx/lyk/HiFT/wandb/run-20240514_013050-o15pf2qh/files/requirements.txt
Traceback (most recent call last):
  File "/mounts/work/lyk/anaconda3/envs/torch2/lib/python3.8/site-packages/wandb/apis/normalize.py", line 41, in wrapper
    return func(*args, **kwargs)
  File "/mounts/work/lyk/anaconda3/envs/torch2/lib/python3.8/site-packages/wandb/sdk/lib/retry.py", line 212, in wrapped_fn
    return retrier(*args, **kargs)
  File "/mounts/work/lyk/anaconda3/envs/torch2/lib/python3.8/site-packages/wandb/sdk/lib/retry.py", line 131, in __call__
    result = self._call_fn(*args, **kwargs)
  File "/mounts/work/lyk/anaconda3/envs/torch2/lib/python3.8/site-packages/wandb/sdk/internal/internal_api.py", line 2787, in upload_file
    wandb._sentry.reraise(e)
  File "/mounts/work/lyk/anaconda3/envs/torch2/lib/python3.8/site-packages/wandb/analytics/sentry.py", line 154, in reraise
    raise exc.with_traceback(sys.exc_info()[2])
  File "/mounts/work/lyk/anaconda3/envs/torch2/lib/python3.8/site-packages/wandb/sdk/internal/internal_api.py", line 2759, in upload_file
    response.raise_for_status()
  File "/mounts/work/lyk/anaconda3/envs/torch2/lib/python3.8/site-packages/requests/models.py", line 1021, in raise_for_status
    raise HTTPError(http_error_msg, response=self)
requests.exceptions.HTTPError: 403 Client Error: Forbidden for url: https://storage.googleapis.com/wandb-production.appspot.com/neuzxm/huggingface/o15pf2qh/requirements.txt?Expires=1715729473&GoogleAccessId=gorilla-files-url-signer-man%40wandb-production.iam.gserviceaccount.com&Signature=JEEqBltdmpn1JXZaFrzFM73IUb1ptQH%2Fugtr%2FVRstL6%2FZXr6Wan%2FrgYGJjNDUFxId%2Fm8x4Kwar%2FVIBLylTO0ymBQ2BZA8dkfhUlQFQQmT6fJvRWavDBAGueeMfB6waJOByP6eEuU3Xl8jgoN0VbEtcd6C3OrM%2B9cz14T7EukJd%2FiEJgX13nIrCKsM9ctrFBsfwCqX8O7vK1ZrwyblzEbBwIYuTsHwswfk8ohA4nLXnog80khgMI46T%2BXRmSxDvV5ybQf%2F2SsIiT19DSM9TPgyLTM4qCrDQDkwPc0PvYc1Bd4RDYu9hiEW3PFIl7D99zy%2BljZkN8M6GtNz%2B56UvIsgA%3D%3D

During handling of the above exception, another exception occurred:

Traceback (most recent call last):
  File "/mounts/work/lyk/anaconda3/envs/torch2/lib/python3.8/site-packages/wandb/filesync/upload_job.py", line 125, in push
    self._api.upload_file_retry(
  File "/mounts/work/lyk/anaconda3/envs/torch2/lib/python3.8/site-packages/wandb/apis/normalize.py", line 51, in wrapper
    raise CommError(message, error)
wandb.errors.CommError: <Response [403]>
2024-05-14 01:31:13,637 ERROR   wandb-upload_2:2406543 [internal_api.py:upload_file():2761] upload_file exception https://storage.googleapis.com/wandb-production.appspot.com/neuzxm/huggingface/o15pf2qh/conda-environment.yaml?Expires=1715729473&GoogleAccessId=gorilla-files-url-signer-man%40wandb-production.iam.gserviceaccount.com&Signature=aUXLGDkW2STCKcoJI%2BNQPr%2BX%2BT6EyJWW3DG5FsduQGDmXFtRtw18fKQhsHej20V2HoRaigr4UYF1AOrq6U%2F4nOXfFDiZ6kGJ2i6dNOvHA%2FrSMhMSqmne1r8VQljypIh1RNrTDROPkltXeRp5olC6hVps0Iu2G41jrnOMjzdYOK%2BViOc6C07GUhkNbfcEIO9aNnGZCnwa7%2FeL2Q6e0yPHYHxamte93Lt1AqWJyWuBv%2FOWXouHZ8zme8R%2FPGUyrtOOCUZK%2F%2BzU3mmYvvmGOPu4G1OuYsIEfZ4VyXi9JRb3in5SWzJt0lcNl2VL%2BwtdPvTA6A813Fa9cs%2F1YGhtLSvBLA%3D%3D: 403 Client Error: Forbidden for url: https://storage.googleapis.com/wandb-production.appspot.com/neuzxm/huggingface/o15pf2qh/conda-environment.yaml?Expires=1715729473&GoogleAccessId=gorilla-files-url-signer-man%40wandb-production.iam.gserviceaccount.com&Signature=aUXLGDkW2STCKcoJI%2BNQPr%2BX%2BT6EyJWW3DG5FsduQGDmXFtRtw18fKQhsHej20V2HoRaigr4UYF1AOrq6U%2F4nOXfFDiZ6kGJ2i6dNOvHA%2FrSMhMSqmne1r8VQljypIh1RNrTDROPkltXeRp5olC6hVps0Iu2G41jrnOMjzdYOK%2BViOc6C07GUhkNbfcEIO9aNnGZCnwa7%2FeL2Q6e0yPHYHxamte93Lt1AqWJyWuBv%2FOWXouHZ8zme8R%2FPGUyrtOOCUZK%2F%2BzU3mmYvvmGOPu4G1OuYsIEfZ4VyXi9JRb3in5SWzJt0lcNl2VL%2BwtdPvTA6A813Fa9cs%2F1YGhtLSvBLA%3D%3D
2024-05-14 01:31:13,638 ERROR   wandb-upload_2:2406543 [internal_api.py:upload_file():2763] upload_file request headers: {'User-Agent': 'python-requests/2.31.0', 'Accept-Encoding': 'gzip, deflate, br', 'Accept': '*/*', 'Connection': 'keep-alive', 'Content-Length': '5415'}
2024-05-14 01:31:13,638 ERROR   wandb-upload_2:2406543 [internal_api.py:upload_file():2765] upload_file response body: b"<?xml version='1.0' encoding='UTF-8'?><Error><Code>AccessDenied</Code><Message>Access denied.</Message><Details>We're sorry, but this service is not available in your location</Details></Error>"
2024-05-14 01:31:13,644 ERROR   wandb-upload_4:2406543 [internal_api.py:upload_file():2761] upload_file exception https://storage.googleapis.com/wandb-production.appspot.com/neuzxm/huggingface/o15pf2qh/output.log?Expires=1715729473&GoogleAccessId=gorilla-files-url-signer-man%40wandb-production.iam.gserviceaccount.com&Signature=J%2FppAwEEewixWlFmCFTd9%2FLQnAL%2FYoLQcK2JhVQW3an6BIbiZC6pk1crhxdLnb3Lp0DuYUcapUcoevgCYFaa3FQc0xsXzEDvwp23rzocxOf7WzHWoLy3TzHFvwUapi5Nf%2F%2F5fJ83HfHtExhtXqi2MBBbIsB3MoxiqY1fJXl3riT8%2B1DrBk72xlzFAw4vkUQ80%2FjSo6tFPk9x3h%2Fnu84bIlAq4jWUfbKvp6WH5hyzJU5wAzizXSarq2oUPzrBujxZhQRSJpikZdg5lAKZ6%2F2Jgx7hkqwTjm7qZpqg0agM40Hw6UBWVeHSuvcSRWZm8%2FDAA6HxkEHtlKHYSaDOxnOogA%3D%3D: 403 Client Error: Forbidden for url: https://storage.googleapis.com/wandb-production.appspot.com/neuzxm/huggingface/o15pf2qh/output.log?Expires=1715729473&GoogleAccessId=gorilla-files-url-signer-man%40wandb-production.iam.gserviceaccount.com&Signature=J%2FppAwEEewixWlFmCFTd9%2FLQnAL%2FYoLQcK2JhVQW3an6BIbiZC6pk1crhxdLnb3Lp0DuYUcapUcoevgCYFaa3FQc0xsXzEDvwp23rzocxOf7WzHWoLy3TzHFvwUapi5Nf%2F%2F5fJ83HfHtExhtXqi2MBBbIsB3MoxiqY1fJXl3riT8%2B1DrBk72xlzFAw4vkUQ80%2FjSo6tFPk9x3h%2Fnu84bIlAq4jWUfbKvp6WH5hyzJU5wAzizXSarq2oUPzrBujxZhQRSJpikZdg5lAKZ6%2F2Jgx7hkqwTjm7qZpqg0agM40Hw6UBWVeHSuvcSRWZm8%2FDAA6HxkEHtlKHYSaDOxnOogA%3D%3D
2024-05-14 01:31:13,644 ERROR   wandb-upload_4:2406543 [internal_api.py:upload_file():2763] upload_file request headers: {'User-Agent': 'python-requests/2.31.0', 'Accept-Encoding': 'gzip, deflate, br', 'Accept': '*/*', 'Connection': 'keep-alive', 'Content-Length': '3521'}
2024-05-14 01:31:13,644 ERROR   wandb-upload_4:2406543 [internal_api.py:upload_file():2765] upload_file response body: b"<?xml version='1.0' encoding='UTF-8'?><Error><Code>AccessDenied</Code><Message>Access denied.</Message><Details>We're sorry, but this service is not available in your location</Details></Error>"
2024-05-14 01:31:13,645 ERROR   wandb-upload_3:2406543 [internal_api.py:upload_file():2761] upload_file exception https://storage.googleapis.com/wandb-production.appspot.com/neuzxm/huggingface/o15pf2qh/config.yaml?Expires=1715729473&GoogleAccessId=gorilla-files-url-signer-man%40wandb-production.iam.gserviceaccount.com&Signature=pgIkYwSOJYJjo3Q3a4S34nhC1TG6oMPKHOzxwNp3he%2FCkGEPYTSL7oHruKW1uxTpS0TM1JwCgyT6Xo2NlDZERDyDjj3BEmjE03pJZe8%2F84vUDDMBSNQEsq8LUkl%2BinVVzsb53hZWWcFuSwMDMNiHviOw9m%2FBwhs2RRvzGVw82YR8aY09JsYbuWnE%2BX9FGd4JuKvm6GANXo2JrKk%2BhIqgspy9tkDzpUAW1yBUufrEiTLCtkITrpkNtVM1JnkGFe7leJryyNgc5sN5omLuvO4E%2Fn1URjomVUQ7OaWA%2BO2dOUCe3wzo7vMa%2B4X%2BFkLQBcaWylJWqyUNUpdpWRk5tD7tBQ%3D%3D: 403 Client Error: Forbidden for url: https://storage.googleapis.com/wandb-production.appspot.com/neuzxm/huggingface/o15pf2qh/config.yaml?Expires=1715729473&GoogleAccessId=gorilla-files-url-signer-man%40wandb-production.iam.gserviceaccount.com&Signature=pgIkYwSOJYJjo3Q3a4S34nhC1TG6oMPKHOzxwNp3he%2FCkGEPYTSL7oHruKW1uxTpS0TM1JwCgyT6Xo2NlDZERDyDjj3BEmjE03pJZe8%2F84vUDDMBSNQEsq8LUkl%2BinVVzsb53hZWWcFuSwMDMNiHviOw9m%2FBwhs2RRvzGVw82YR8aY09JsYbuWnE%2BX9FGd4JuKvm6GANXo2JrKk%2BhIqgspy9tkDzpUAW1yBUufrEiTLCtkITrpkNtVM1JnkGFe7leJryyNgc5sN5omLuvO4E%2Fn1URjomVUQ7OaWA%2BO2dOUCe3wzo7vMa%2B4X%2BFkLQBcaWylJWqyUNUpdpWRk5tD7tBQ%3D%3D
2024-05-14 01:31:13,645 ERROR   wandb-upload_3:2406543 [internal_api.py:upload_file():2763] upload_file request headers: {'User-Agent': 'python-requests/2.31.0', 'Accept-Encoding': 'gzip, deflate, br', 'Accept': '*/*', 'Connection': 'keep-alive', 'Content-Length': '9669'}
2024-05-14 01:31:13,645 ERROR   wandb-upload_3:2406543 [internal_api.py:upload_file():2765] upload_file response body: b"<?xml version='1.0' encoding='UTF-8'?><Error><Code>AccessDenied</Code><Message>Access denied.</Message><Details>We're sorry, but this service is not available in your location</Details></Error>"
2024-05-14 01:31:13,692 ERROR   Thread-11 :2406543 [step_upload.py:_handle_event():200] Failed to upload file: /nfs/datx/lyk/HiFT/wandb/run-20240514_013050-o15pf2qh/files/requirements.txt
Traceback (most recent call last):
  File "/mounts/work/lyk/anaconda3/envs/torch2/lib/python3.8/site-packages/wandb/apis/normalize.py", line 41, in wrapper
    return func(*args, **kwargs)
  File "/mounts/work/lyk/anaconda3/envs/torch2/lib/python3.8/site-packages/wandb/sdk/lib/retry.py", line 212, in wrapped_fn
    return retrier(*args, **kargs)
  File "/mounts/work/lyk/anaconda3/envs/torch2/lib/python3.8/site-packages/wandb/sdk/lib/retry.py", line 131, in __call__
    result = self._call_fn(*args, **kwargs)
  File "/mounts/work/lyk/anaconda3/envs/torch2/lib/python3.8/site-packages/wandb/sdk/internal/internal_api.py", line 2787, in upload_file
    wandb._sentry.reraise(e)
  File "/mounts/work/lyk/anaconda3/envs/torch2/lib/python3.8/site-packages/wandb/analytics/sentry.py", line 154, in reraise
    raise exc.with_traceback(sys.exc_info()[2])
  File "/mounts/work/lyk/anaconda3/envs/torch2/lib/python3.8/site-packages/wandb/sdk/internal/internal_api.py", line 2759, in upload_file
    response.raise_for_status()
  File "/mounts/work/lyk/anaconda3/envs/torch2/lib/python3.8/site-packages/requests/models.py", line 1021, in raise_for_status
    raise HTTPError(http_error_msg, response=self)
requests.exceptions.HTTPError: 403 Client Error: Forbidden for url: https://storage.googleapis.com/wandb-production.appspot.com/neuzxm/huggingface/o15pf2qh/requirements.txt?Expires=1715729473&GoogleAccessId=gorilla-files-url-signer-man%40wandb-production.iam.gserviceaccount.com&Signature=JEEqBltdmpn1JXZaFrzFM73IUb1ptQH%2Fugtr%2FVRstL6%2FZXr6Wan%2FrgYGJjNDUFxId%2Fm8x4Kwar%2FVIBLylTO0ymBQ2BZA8dkfhUlQFQQmT6fJvRWavDBAGueeMfB6waJOByP6eEuU3Xl8jgoN0VbEtcd6C3OrM%2B9cz14T7EukJd%2FiEJgX13nIrCKsM9ctrFBsfwCqX8O7vK1ZrwyblzEbBwIYuTsHwswfk8ohA4nLXnog80khgMI46T%2BXRmSxDvV5ybQf%2F2SsIiT19DSM9TPgyLTM4qCrDQDkwPc0PvYc1Bd4RDYu9hiEW3PFIl7D99zy%2BljZkN8M6GtNz%2B56UvIsgA%3D%3D

During handling of the above exception, another exception occurred:

Traceback (most recent call last):
  File "/mounts/work/lyk/anaconda3/envs/torch2/lib/python3.8/concurrent/futures/thread.py", line 57, in run
    result = self.fn(*self.args, **self.kwargs)
  File "/mounts/work/lyk/anaconda3/envs/torch2/lib/python3.8/site-packages/wandb/filesync/step_upload.py", line 288, in run_and_notify
    self._do_upload_sync(event)
  File "/mounts/work/lyk/anaconda3/envs/torch2/lib/python3.8/site-packages/wandb/filesync/step_upload.py", line 330, in _do_upload_sync
    job.run()
  File "/mounts/work/lyk/anaconda3/envs/torch2/lib/python3.8/site-packages/wandb/filesync/upload_job.py", line 57, in run
    self.push()
  File "/mounts/work/lyk/anaconda3/envs/torch2/lib/python3.8/site-packages/wandb/filesync/upload_job.py", line 125, in push
    self._api.upload_file_retry(
  File "/mounts/work/lyk/anaconda3/envs/torch2/lib/python3.8/site-packages/wandb/apis/normalize.py", line 51, in wrapper
    raise CommError(message, error)
wandb.errors.CommError: <Response [403]>
2024-05-14 01:31:13,693 ERROR   wandb-upload_2:2406543 [upload_job.py:push():134] Failed to upload file: /nfs/datx/lyk/HiFT/wandb/run-20240514_013050-o15pf2qh/files/conda-environment.yaml
Traceback (most recent call last):
  File "/mounts/work/lyk/anaconda3/envs/torch2/lib/python3.8/site-packages/wandb/apis/normalize.py", line 41, in wrapper
    return func(*args, **kwargs)
  File "/mounts/work/lyk/anaconda3/envs/torch2/lib/python3.8/site-packages/wandb/sdk/lib/retry.py", line 212, in wrapped_fn
    return retrier(*args, **kargs)
  File "/mounts/work/lyk/anaconda3/envs/torch2/lib/python3.8/site-packages/wandb/sdk/lib/retry.py", line 131, in __call__
    result = self._call_fn(*args, **kwargs)
  File "/mounts/work/lyk/anaconda3/envs/torch2/lib/python3.8/site-packages/wandb/sdk/internal/internal_api.py", line 2787, in upload_file
    wandb._sentry.reraise(e)
  File "/mounts/work/lyk/anaconda3/envs/torch2/lib/python3.8/site-packages/wandb/analytics/sentry.py", line 154, in reraise
    raise exc.with_traceback(sys.exc_info()[2])
  File "/mounts/work/lyk/anaconda3/envs/torch2/lib/python3.8/site-packages/wandb/sdk/internal/internal_api.py", line 2759, in upload_file
    response.raise_for_status()
  File "/mounts/work/lyk/anaconda3/envs/torch2/lib/python3.8/site-packages/requests/models.py", line 1021, in raise_for_status
    raise HTTPError(http_error_msg, response=self)
requests.exceptions.HTTPError: 403 Client Error: Forbidden for url: https://storage.googleapis.com/wandb-production.appspot.com/neuzxm/huggingface/o15pf2qh/conda-environment.yaml?Expires=1715729473&GoogleAccessId=gorilla-files-url-signer-man%40wandb-production.iam.gserviceaccount.com&Signature=aUXLGDkW2STCKcoJI%2BNQPr%2BX%2BT6EyJWW3DG5FsduQGDmXFtRtw18fKQhsHej20V2HoRaigr4UYF1AOrq6U%2F4nOXfFDiZ6kGJ2i6dNOvHA%2FrSMhMSqmne1r8VQljypIh1RNrTDROPkltXeRp5olC6hVps0Iu2G41jrnOMjzdYOK%2BViOc6C07GUhkNbfcEIO9aNnGZCnwa7%2FeL2Q6e0yPHYHxamte93Lt1AqWJyWuBv%2FOWXouHZ8zme8R%2FPGUyrtOOCUZK%2F%2BzU3mmYvvmGOPu4G1OuYsIEfZ4VyXi9JRb3in5SWzJt0lcNl2VL%2BwtdPvTA6A813Fa9cs%2F1YGhtLSvBLA%3D%3D

During handling of the above exception, another exception occurred:

Traceback (most recent call last):
  File "/mounts/work/lyk/anaconda3/envs/torch2/lib/python3.8/site-packages/wandb/filesync/upload_job.py", line 125, in push
    self._api.upload_file_retry(
  File "/mounts/work/lyk/anaconda3/envs/torch2/lib/python3.8/site-packages/wandb/apis/normalize.py", line 51, in wrapper
    raise CommError(message, error)
wandb.errors.CommError: <Response [403]>
2024-05-14 01:31:13,694 ERROR   wandb-upload_4:2406543 [upload_job.py:push():134] Failed to upload file: /nfs/datx/lyk/HiFT/wandb/run-20240514_013050-o15pf2qh/files/output.log
Traceback (most recent call last):
  File "/mounts/work/lyk/anaconda3/envs/torch2/lib/python3.8/site-packages/wandb/apis/normalize.py", line 41, in wrapper
    return func(*args, **kwargs)
  File "/mounts/work/lyk/anaconda3/envs/torch2/lib/python3.8/site-packages/wandb/sdk/lib/retry.py", line 212, in wrapped_fn
    return retrier(*args, **kargs)
  File "/mounts/work/lyk/anaconda3/envs/torch2/lib/python3.8/site-packages/wandb/sdk/lib/retry.py", line 131, in __call__
    result = self._call_fn(*args, **kwargs)
  File "/mounts/work/lyk/anaconda3/envs/torch2/lib/python3.8/site-packages/wandb/sdk/internal/internal_api.py", line 2787, in upload_file
    wandb._sentry.reraise(e)
  File "/mounts/work/lyk/anaconda3/envs/torch2/lib/python3.8/site-packages/wandb/analytics/sentry.py", line 154, in reraise
    raise exc.with_traceback(sys.exc_info()[2])
  File "/mounts/work/lyk/anaconda3/envs/torch2/lib/python3.8/site-packages/wandb/sdk/internal/internal_api.py", line 2759, in upload_file
    response.raise_for_status()
  File "/mounts/work/lyk/anaconda3/envs/torch2/lib/python3.8/site-packages/requests/models.py", line 1021, in raise_for_status
    raise HTTPError(http_error_msg, response=self)
requests.exceptions.HTTPError: 403 Client Error: Forbidden for url: https://storage.googleapis.com/wandb-production.appspot.com/neuzxm/huggingface/o15pf2qh/output.log?Expires=1715729473&GoogleAccessId=gorilla-files-url-signer-man%40wandb-production.iam.gserviceaccount.com&Signature=J%2FppAwEEewixWlFmCFTd9%2FLQnAL%2FYoLQcK2JhVQW3an6BIbiZC6pk1crhxdLnb3Lp0DuYUcapUcoevgCYFaa3FQc0xsXzEDvwp23rzocxOf7WzHWoLy3TzHFvwUapi5Nf%2F%2F5fJ83HfHtExhtXqi2MBBbIsB3MoxiqY1fJXl3riT8%2B1DrBk72xlzFAw4vkUQ80%2FjSo6tFPk9x3h%2Fnu84bIlAq4jWUfbKvp6WH5hyzJU5wAzizXSarq2oUPzrBujxZhQRSJpikZdg5lAKZ6%2F2Jgx7hkqwTjm7qZpqg0agM40Hw6UBWVeHSuvcSRWZm8%2FDAA6HxkEHtlKHYSaDOxnOogA%3D%3D

During handling of the above exception, another exception occurred:

Traceback (most recent call last):
  File "/mounts/work/lyk/anaconda3/envs/torch2/lib/python3.8/site-packages/wandb/filesync/upload_job.py", line 125, in push
    self._api.upload_file_retry(
  File "/mounts/work/lyk/anaconda3/envs/torch2/lib/python3.8/site-packages/wandb/apis/normalize.py", line 51, in wrapper
    raise CommError(message, error)
wandb.errors.CommError: <Response [403]>
2024-05-14 01:31:13,694 ERROR   wandb-upload_3:2406543 [upload_job.py:push():134] Failed to upload file: /nfs/datx/lyk/HiFT/wandb/run-20240514_013050-o15pf2qh/files/config.yaml
Traceback (most recent call last):
  File "/mounts/work/lyk/anaconda3/envs/torch2/lib/python3.8/site-packages/wandb/apis/normalize.py", line 41, in wrapper
    return func(*args, **kwargs)
  File "/mounts/work/lyk/anaconda3/envs/torch2/lib/python3.8/site-packages/wandb/sdk/lib/retry.py", line 212, in wrapped_fn
    return retrier(*args, **kargs)
  File "/mounts/work/lyk/anaconda3/envs/torch2/lib/python3.8/site-packages/wandb/sdk/lib/retry.py", line 131, in __call__
    result = self._call_fn(*args, **kwargs)
  File "/mounts/work/lyk/anaconda3/envs/torch2/lib/python3.8/site-packages/wandb/sdk/internal/internal_api.py", line 2787, in upload_file
    wandb._sentry.reraise(e)
  File "/mounts/work/lyk/anaconda3/envs/torch2/lib/python3.8/site-packages/wandb/analytics/sentry.py", line 154, in reraise
    raise exc.with_traceback(sys.exc_info()[2])
  File "/mounts/work/lyk/anaconda3/envs/torch2/lib/python3.8/site-packages/wandb/sdk/internal/internal_api.py", line 2759, in upload_file
    response.raise_for_status()
  File "/mounts/work/lyk/anaconda3/envs/torch2/lib/python3.8/site-packages/requests/models.py", line 1021, in raise_for_status
    raise HTTPError(http_error_msg, response=self)
requests.exceptions.HTTPError: 403 Client Error: Forbidden for url: https://storage.googleapis.com/wandb-production.appspot.com/neuzxm/huggingface/o15pf2qh/config.yaml?Expires=1715729473&GoogleAccessId=gorilla-files-url-signer-man%40wandb-production.iam.gserviceaccount.com&Signature=pgIkYwSOJYJjo3Q3a4S34nhC1TG6oMPKHOzxwNp3he%2FCkGEPYTSL7oHruKW1uxTpS0TM1JwCgyT6Xo2NlDZERDyDjj3BEmjE03pJZe8%2F84vUDDMBSNQEsq8LUkl%2BinVVzsb53hZWWcFuSwMDMNiHviOw9m%2FBwhs2RRvzGVw82YR8aY09JsYbuWnE%2BX9FGd4JuKvm6GANXo2JrKk%2BhIqgspy9tkDzpUAW1yBUufrEiTLCtkITrpkNtVM1JnkGFe7leJryyNgc5sN5omLuvO4E%2Fn1URjomVUQ7OaWA%2BO2dOUCe3wzo7vMa%2B4X%2BFkLQBcaWylJWqyUNUpdpWRk5tD7tBQ%3D%3D

During handling of the above exception, another exception occurred:

Traceback (most recent call last):
  File "/mounts/work/lyk/anaconda3/envs/torch2/lib/python3.8/site-packages/wandb/filesync/upload_job.py", line 125, in push
    self._api.upload_file_retry(
  File "/mounts/work/lyk/anaconda3/envs/torch2/lib/python3.8/site-packages/wandb/apis/normalize.py", line 51, in wrapper
    raise CommError(message, error)
wandb.errors.CommError: <Response [403]>
2024-05-14 01:31:13,751 ERROR   Thread-11 :2406543 [step_upload.py:_handle_event():200] Failed to upload file: /nfs/datx/lyk/HiFT/wandb/run-20240514_013050-o15pf2qh/files/output.log
Traceback (most recent call last):
  File "/mounts/work/lyk/anaconda3/envs/torch2/lib/python3.8/site-packages/wandb/apis/normalize.py", line 41, in wrapper
    return func(*args, **kwargs)
  File "/mounts/work/lyk/anaconda3/envs/torch2/lib/python3.8/site-packages/wandb/sdk/lib/retry.py", line 212, in wrapped_fn
    return retrier(*args, **kargs)
  File "/mounts/work/lyk/anaconda3/envs/torch2/lib/python3.8/site-packages/wandb/sdk/lib/retry.py", line 131, in __call__
    result = self._call_fn(*args, **kwargs)
  File "/mounts/work/lyk/anaconda3/envs/torch2/lib/python3.8/site-packages/wandb/sdk/internal/internal_api.py", line 2787, in upload_file
    wandb._sentry.reraise(e)
  File "/mounts/work/lyk/anaconda3/envs/torch2/lib/python3.8/site-packages/wandb/analytics/sentry.py", line 154, in reraise
    raise exc.with_traceback(sys.exc_info()[2])
  File "/mounts/work/lyk/anaconda3/envs/torch2/lib/python3.8/site-packages/wandb/sdk/internal/internal_api.py", line 2759, in upload_file
    response.raise_for_status()
  File "/mounts/work/lyk/anaconda3/envs/torch2/lib/python3.8/site-packages/requests/models.py", line 1021, in raise_for_status
    raise HTTPError(http_error_msg, response=self)
requests.exceptions.HTTPError: 403 Client Error: Forbidden for url: https://storage.googleapis.com/wandb-production.appspot.com/neuzxm/huggingface/o15pf2qh/output.log?Expires=1715729473&GoogleAccessId=gorilla-files-url-signer-man%40wandb-production.iam.gserviceaccount.com&Signature=J%2FppAwEEewixWlFmCFTd9%2FLQnAL%2FYoLQcK2JhVQW3an6BIbiZC6pk1crhxdLnb3Lp0DuYUcapUcoevgCYFaa3FQc0xsXzEDvwp23rzocxOf7WzHWoLy3TzHFvwUapi5Nf%2F%2F5fJ83HfHtExhtXqi2MBBbIsB3MoxiqY1fJXl3riT8%2B1DrBk72xlzFAw4vkUQ80%2FjSo6tFPk9x3h%2Fnu84bIlAq4jWUfbKvp6WH5hyzJU5wAzizXSarq2oUPzrBujxZhQRSJpikZdg5lAKZ6%2F2Jgx7hkqwTjm7qZpqg0agM40Hw6UBWVeHSuvcSRWZm8%2FDAA6HxkEHtlKHYSaDOxnOogA%3D%3D

During handling of the above exception, another exception occurred:

Traceback (most recent call last):
  File "/mounts/work/lyk/anaconda3/envs/torch2/lib/python3.8/concurrent/futures/thread.py", line 57, in run
    result = self.fn(*self.args, **self.kwargs)
  File "/mounts/work/lyk/anaconda3/envs/torch2/lib/python3.8/site-packages/wandb/filesync/step_upload.py", line 288, in run_and_notify
    self._do_upload_sync(event)
  File "/mounts/work/lyk/anaconda3/envs/torch2/lib/python3.8/site-packages/wandb/filesync/step_upload.py", line 330, in _do_upload_sync
    job.run()
  File "/mounts/work/lyk/anaconda3/envs/torch2/lib/python3.8/site-packages/wandb/filesync/upload_job.py", line 57, in run
    self.push()
  File "/mounts/work/lyk/anaconda3/envs/torch2/lib/python3.8/site-packages/wandb/filesync/upload_job.py", line 125, in push
    self._api.upload_file_retry(
  File "/mounts/work/lyk/anaconda3/envs/torch2/lib/python3.8/site-packages/wandb/apis/normalize.py", line 51, in wrapper
    raise CommError(message, error)
wandb.errors.CommError: <Response [403]>
2024-05-14 01:31:13,753 ERROR   Thread-11 :2406543 [step_upload.py:_handle_event():200] Failed to upload file: /nfs/datx/lyk/HiFT/wandb/run-20240514_013050-o15pf2qh/files/conda-environment.yaml
Traceback (most recent call last):
  File "/mounts/work/lyk/anaconda3/envs/torch2/lib/python3.8/site-packages/wandb/apis/normalize.py", line 41, in wrapper
    return func(*args, **kwargs)
  File "/mounts/work/lyk/anaconda3/envs/torch2/lib/python3.8/site-packages/wandb/sdk/lib/retry.py", line 212, in wrapped_fn
    return retrier(*args, **kargs)
  File "/mounts/work/lyk/anaconda3/envs/torch2/lib/python3.8/site-packages/wandb/sdk/lib/retry.py", line 131, in __call__
    result = self._call_fn(*args, **kwargs)
  File "/mounts/work/lyk/anaconda3/envs/torch2/lib/python3.8/site-packages/wandb/sdk/internal/internal_api.py", line 2787, in upload_file
    wandb._sentry.reraise(e)
  File "/mounts/work/lyk/anaconda3/envs/torch2/lib/python3.8/site-packages/wandb/analytics/sentry.py", line 154, in reraise
    raise exc.with_traceback(sys.exc_info()[2])
  File "/mounts/work/lyk/anaconda3/envs/torch2/lib/python3.8/site-packages/wandb/sdk/internal/internal_api.py", line 2759, in upload_file
    response.raise_for_status()
  File "/mounts/work/lyk/anaconda3/envs/torch2/lib/python3.8/site-packages/requests/models.py", line 1021, in raise_for_status
    raise HTTPError(http_error_msg, response=self)
requests.exceptions.HTTPError: 403 Client Error: Forbidden for url: https://storage.googleapis.com/wandb-production.appspot.com/neuzxm/huggingface/o15pf2qh/conda-environment.yaml?Expires=1715729473&GoogleAccessId=gorilla-files-url-signer-man%40wandb-production.iam.gserviceaccount.com&Signature=aUXLGDkW2STCKcoJI%2BNQPr%2BX%2BT6EyJWW3DG5FsduQGDmXFtRtw18fKQhsHej20V2HoRaigr4UYF1AOrq6U%2F4nOXfFDiZ6kGJ2i6dNOvHA%2FrSMhMSqmne1r8VQljypIh1RNrTDROPkltXeRp5olC6hVps0Iu2G41jrnOMjzdYOK%2BViOc6C07GUhkNbfcEIO9aNnGZCnwa7%2FeL2Q6e0yPHYHxamte93Lt1AqWJyWuBv%2FOWXouHZ8zme8R%2FPGUyrtOOCUZK%2F%2BzU3mmYvvmGOPu4G1OuYsIEfZ4VyXi9JRb3in5SWzJt0lcNl2VL%2BwtdPvTA6A813Fa9cs%2F1YGhtLSvBLA%3D%3D

During handling of the above exception, another exception occurred:

Traceback (most recent call last):
  File "/mounts/work/lyk/anaconda3/envs/torch2/lib/python3.8/concurrent/futures/thread.py", line 57, in run
    result = self.fn(*self.args, **self.kwargs)
  File "/mounts/work/lyk/anaconda3/envs/torch2/lib/python3.8/site-packages/wandb/filesync/step_upload.py", line 288, in run_and_notify
    self._do_upload_sync(event)
  File "/mounts/work/lyk/anaconda3/envs/torch2/lib/python3.8/site-packages/wandb/filesync/step_upload.py", line 330, in _do_upload_sync
    job.run()
  File "/mounts/work/lyk/anaconda3/envs/torch2/lib/python3.8/site-packages/wandb/filesync/upload_job.py", line 57, in run
    self.push()
  File "/mounts/work/lyk/anaconda3/envs/torch2/lib/python3.8/site-packages/wandb/filesync/upload_job.py", line 125, in push
    self._api.upload_file_retry(
  File "/mounts/work/lyk/anaconda3/envs/torch2/lib/python3.8/site-packages/wandb/apis/normalize.py", line 51, in wrapper
    raise CommError(message, error)
wandb.errors.CommError: <Response [403]>
2024-05-14 01:31:13,753 ERROR   Thread-11 :2406543 [step_upload.py:_handle_event():200] Failed to upload file: /nfs/datx/lyk/HiFT/wandb/run-20240514_013050-o15pf2qh/files/config.yaml
Traceback (most recent call last):
  File "/mounts/work/lyk/anaconda3/envs/torch2/lib/python3.8/site-packages/wandb/apis/normalize.py", line 41, in wrapper
    return func(*args, **kwargs)
  File "/mounts/work/lyk/anaconda3/envs/torch2/lib/python3.8/site-packages/wandb/sdk/lib/retry.py", line 212, in wrapped_fn
    return retrier(*args, **kargs)
  File "/mounts/work/lyk/anaconda3/envs/torch2/lib/python3.8/site-packages/wandb/sdk/lib/retry.py", line 131, in __call__
    result = self._call_fn(*args, **kwargs)
  File "/mounts/work/lyk/anaconda3/envs/torch2/lib/python3.8/site-packages/wandb/sdk/internal/internal_api.py", line 2787, in upload_file
    wandb._sentry.reraise(e)
  File "/mounts/work/lyk/anaconda3/envs/torch2/lib/python3.8/site-packages/wandb/analytics/sentry.py", line 154, in reraise
    raise exc.with_traceback(sys.exc_info()[2])
  File "/mounts/work/lyk/anaconda3/envs/torch2/lib/python3.8/site-packages/wandb/sdk/internal/internal_api.py", line 2759, in upload_file
    response.raise_for_status()
  File "/mounts/work/lyk/anaconda3/envs/torch2/lib/python3.8/site-packages/requests/models.py", line 1021, in raise_for_status
    raise HTTPError(http_error_msg, response=self)
requests.exceptions.HTTPError: 403 Client Error: Forbidden for url: https://storage.googleapis.com/wandb-production.appspot.com/neuzxm/huggingface/o15pf2qh/config.yaml?Expires=1715729473&GoogleAccessId=gorilla-files-url-signer-man%40wandb-production.iam.gserviceaccount.com&Signature=pgIkYwSOJYJjo3Q3a4S34nhC1TG6oMPKHOzxwNp3he%2FCkGEPYTSL7oHruKW1uxTpS0TM1JwCgyT6Xo2NlDZERDyDjj3BEmjE03pJZe8%2F84vUDDMBSNQEsq8LUkl%2BinVVzsb53hZWWcFuSwMDMNiHviOw9m%2FBwhs2RRvzGVw82YR8aY09JsYbuWnE%2BX9FGd4JuKvm6GANXo2JrKk%2BhIqgspy9tkDzpUAW1yBUufrEiTLCtkITrpkNtVM1JnkGFe7leJryyNgc5sN5omLuvO4E%2Fn1URjomVUQ7OaWA%2BO2dOUCe3wzo7vMa%2B4X%2BFkLQBcaWylJWqyUNUpdpWRk5tD7tBQ%3D%3D

During handling of the above exception, another exception occurred:

Traceback (most recent call last):
  File "/mounts/work/lyk/anaconda3/envs/torch2/lib/python3.8/concurrent/futures/thread.py", line 57, in run
    result = self.fn(*self.args, **self.kwargs)
  File "/mounts/work/lyk/anaconda3/envs/torch2/lib/python3.8/site-packages/wandb/filesync/step_upload.py", line 288, in run_and_notify
    self._do_upload_sync(event)
  File "/mounts/work/lyk/anaconda3/envs/torch2/lib/python3.8/site-packages/wandb/filesync/step_upload.py", line 330, in _do_upload_sync
    job.run()
  File "/mounts/work/lyk/anaconda3/envs/torch2/lib/python3.8/site-packages/wandb/filesync/upload_job.py", line 57, in run
    self.push()
  File "/mounts/work/lyk/anaconda3/envs/torch2/lib/python3.8/site-packages/wandb/filesync/upload_job.py", line 125, in push
    self._api.upload_file_retry(
  File "/mounts/work/lyk/anaconda3/envs/torch2/lib/python3.8/site-packages/wandb/apis/normalize.py", line 51, in wrapper
    raise CommError(message, error)
wandb.errors.CommError: <Response [403]>
2024-05-14 01:31:13,954 INFO    Thread-11 :2406543 [sender.py:transition_state():617] send defer: 11
2024-05-14 01:31:13,954 DEBUG   HandlerThread:2406543 [handler.py:handle_request():146] handle_request: defer
2024-05-14 01:31:13,954 INFO    HandlerThread:2406543 [handler.py:handle_request_defer():172] handle defer: 11
2024-05-14 01:31:13,955 DEBUG   SenderThread:2406543 [sender.py:send_request():409] send_request: defer
2024-05-14 01:31:13,955 INFO    SenderThread:2406543 [sender.py:send_request_defer():613] handle sender defer: 11
2024-05-14 01:31:13,955 INFO    SenderThread:2406543 [file_pusher.py:join():181] waiting for file pusher
2024-05-14 01:31:13,955 INFO    SenderThread:2406543 [sender.py:transition_state():617] send defer: 12
2024-05-14 01:31:13,955 DEBUG   HandlerThread:2406543 [handler.py:handle_request():146] handle_request: defer
2024-05-14 01:31:13,955 INFO    HandlerThread:2406543 [handler.py:handle_request_defer():172] handle defer: 12
2024-05-14 01:31:13,955 DEBUG   SenderThread:2406543 [sender.py:send_request():409] send_request: defer
2024-05-14 01:31:13,955 INFO    SenderThread:2406543 [sender.py:send_request_defer():613] handle sender defer: 12
2024-05-14 01:31:13,955 INFO    SenderThread:2406543 [file_stream.py:finish():595] file stream finish called
2024-05-14 01:31:14,100 INFO    SenderThread:2406543 [file_stream.py:finish():599] file stream finish is done
2024-05-14 01:31:14,100 INFO    SenderThread:2406543 [sender.py:transition_state():617] send defer: 13
2024-05-14 01:31:14,100 DEBUG   HandlerThread:2406543 [handler.py:handle_request():146] handle_request: defer
2024-05-14 01:31:14,100 INFO    HandlerThread:2406543 [handler.py:handle_request_defer():172] handle defer: 13
2024-05-14 01:31:14,100 DEBUG   SenderThread:2406543 [sender.py:send_request():409] send_request: defer
2024-05-14 01:31:14,100 INFO    SenderThread:2406543 [sender.py:send_request_defer():613] handle sender defer: 13
2024-05-14 01:31:14,100 INFO    SenderThread:2406543 [sender.py:transition_state():617] send defer: 14
2024-05-14 01:31:14,100 DEBUG   HandlerThread:2406543 [handler.py:handle_request():146] handle_request: defer
2024-05-14 01:31:14,101 INFO    HandlerThread:2406543 [handler.py:handle_request_defer():172] handle defer: 14
2024-05-14 01:31:14,101 DEBUG   SenderThread:2406543 [sender.py:send():382] send: final
2024-05-14 01:31:14,101 DEBUG   SenderThread:2406543 [sender.py:send():382] send: footer
2024-05-14 01:31:14,101 DEBUG   SenderThread:2406543 [sender.py:send_request():409] send_request: defer
2024-05-14 01:31:14,101 INFO    SenderThread:2406543 [sender.py:send_request_defer():613] handle sender defer: 14
2024-05-14 01:31:14,102 DEBUG   HandlerThread:2406543 [handler.py:handle_request():146] handle_request: poll_exit
2024-05-14 01:31:14,102 DEBUG   SenderThread:2406543 [sender.py:send_request():409] send_request: poll_exit
2024-05-14 01:31:14,103 DEBUG   HandlerThread:2406543 [handler.py:handle_request():146] handle_request: server_info
2024-05-14 01:31:14,103 DEBUG   SenderThread:2406543 [sender.py:send_request():409] send_request: server_info
2024-05-14 01:31:14,105 DEBUG   HandlerThread:2406543 [handler.py:handle_request():146] handle_request: get_summary
2024-05-14 01:31:14,106 DEBUG   HandlerThread:2406543 [handler.py:handle_request():146] handle_request: sampled_history
2024-05-14 01:31:14,106 DEBUG   HandlerThread:2406543 [handler.py:handle_request():146] handle_request: internal_messages
2024-05-14 01:31:14,106 DEBUG   HandlerThread:2406543 [handler.py:handle_request():146] handle_request: job_info
2024-05-14 01:31:14,255 DEBUG   SenderThread:2406543 [sender.py:send_request():409] send_request: job_info
2024-05-14 01:31:14,256 INFO    MainThread:2406543 [wandb_run.py:_footer_history_summary_info():3837] rendering history
2024-05-14 01:31:14,256 INFO    MainThread:2406543 [wandb_run.py:_footer_history_summary_info():3869] rendering summary
2024-05-14 01:31:14,256 INFO    MainThread:2406543 [wandb_run.py:_footer_sync_info():3796] logging synced files
2024-05-14 01:31:14,256 DEBUG   HandlerThread:2406543 [handler.py:handle_request():146] handle_request: shutdown
2024-05-14 01:31:14,257 INFO    HandlerThread:2406543 [handler.py:finish():866] shutting down handler
2024-05-14 01:31:15,107 INFO    WriterThread:2406543 [datastore.py:close():294] close: /nfs/datx/lyk/HiFT/wandb/run-20240514_013050-o15pf2qh/run-o15pf2qh.wandb
2024-05-14 01:31:15,255 INFO    SenderThread:2406543 [sender.py:finish():1548] shutting down sender
2024-05-14 01:31:15,256 INFO    SenderThread:2406543 [file_pusher.py:finish():175] shutting down file pusher
2024-05-14 01:31:15,256 INFO    SenderThread:2406543 [file_pusher.py:join():181] waiting for file pusher
