2024-05-13 14:14:19,092 INFO    StreamThr :521625 [internal.py:wandb_internal():86] W&B internal server running at pid: 521625, started at: 2024-05-13 14:14:19.091951
2024-05-13 14:14:19,094 DEBUG   HandlerThread:521625 [handler.py:handle_request():146] handle_request: status
2024-05-13 14:14:19,097 INFO    WriterThread:521625 [datastore.py:open_for_write():85] open: /nfs/datx/lyk/HiFT/wandb/run-20240513_141419-2bmnu66o/run-2bmnu66o.wandb
2024-05-13 14:14:19,099 DEBUG   SenderThread:521625 [sender.py:send():382] send: header
2024-05-13 14:14:19,099 DEBUG   SenderThread:521625 [sender.py:send():382] send: run
2024-05-13 14:14:19,492 INFO    SenderThread:521625 [dir_watcher.py:__init__():211] watching files in: /nfs/datx/lyk/HiFT/wandb/run-20240513_141419-2bmnu66o/files
2024-05-13 14:14:19,492 INFO    SenderThread:521625 [sender.py:_start_run_threads():1136] run started: 2bmnu66o with start time 1715602459.092152
2024-05-13 14:14:19,510 DEBUG   HandlerThread:521625 [handler.py:handle_request():146] handle_request: check_version
2024-05-13 14:14:19,511 DEBUG   SenderThread:521625 [sender.py:send_request():409] send_request: check_version
2024-05-13 14:14:19,574 DEBUG   HandlerThread:521625 [handler.py:handle_request():146] handle_request: run_start
2024-05-13 14:14:19,607 DEBUG   HandlerThread:521625 [system_info.py:__init__():32] System info init
2024-05-13 14:14:19,607 DEBUG   HandlerThread:521625 [system_info.py:__init__():47] System info init done
2024-05-13 14:14:19,608 INFO    HandlerThread:521625 [system_monitor.py:start():194] Starting system monitor
2024-05-13 14:14:19,608 INFO    SystemMonitor:521625 [system_monitor.py:_start():158] Starting system asset monitoring threads
2024-05-13 14:14:19,609 INFO    HandlerThread:521625 [system_monitor.py:probe():214] Collecting system info
2024-05-13 14:14:19,610 INFO    SystemMonitor:521625 [interfaces.py:start():190] Started cpu monitoring
2024-05-13 14:14:19,610 INFO    SystemMonitor:521625 [interfaces.py:start():190] Started disk monitoring
2024-05-13 14:14:19,611 INFO    SystemMonitor:521625 [interfaces.py:start():190] Started gpu monitoring
2024-05-13 14:14:19,612 INFO    SystemMonitor:521625 [interfaces.py:start():190] Started memory monitoring
2024-05-13 14:14:19,612 INFO    SystemMonitor:521625 [interfaces.py:start():190] Started network monitoring
2024-05-13 14:14:19,674 DEBUG   HandlerThread:521625 [system_info.py:probe():196] Probing system
2024-05-13 14:14:19,682 DEBUG   HandlerThread:521625 [gitlib.py:_init_repo():56] git repository is invalid
2024-05-13 14:14:19,682 DEBUG   HandlerThread:521625 [system_info.py:probe():244] Probing system done
2024-05-13 14:14:19,682 DEBUG   HandlerThread:521625 [system_monitor.py:probe():223] {'os': 'Linux-5.15.0-91-generic-x86_64-with-glibc2.10', 'python': '3.8.5', 'heartbeatAt': '2024-05-13T12:14:19.675010', 'startedAt': '2024-05-13T12:14:19.076863', 'docker': None, 'cuda': None, 'args': ('--model_type', 'llama', '--HiTaskType', 'CAUSAL_LM', '--optim', 'lion_32bit', '--deepspeed', 'dsconfig/zero0_config.json', '--model_name_or_path', '/mounts/work/lyk/hierFT/llama2-7b', '--data_path', 'data/dummy_conversation.json', '--eval_data_path', 'data/sharegpt_clean.json', '--output_dir', 'outputs/output_vicuna/model', '--num_train_epochs', '3', '--do_train', '--per_device_train_batch_size', '1', '--per_device_eval_batch_size', '8', '--evaluation_strategy', 'steps', '--eval_steps', '1500', '--save_strategy', 'steps', '--save_steps', '1500', '--save_total_limit', '8', '--learning_rate', '2e-5', '--weight_decay', '0.', '--warmup_ratio', '0', '--lr_scheduler_type', 'linear', '--logging_steps', '10', '--model_max_length', '2900', '--lazy_preprocess', 'True', '--torch_dtype', 'float16', '--ddp_find_unused_parameters', 'False', '--load_best_model_at_end', '--hier_tuning', '--group_element', '1', '--optimizer_strategy', 'down2up'), 'state': 'running', 'program': 'examples/vicuna_train.py', 'codePathLocal': 'examples/vicuna_train.py', 'codePath': 'examples/vicuna_train.py', 'host': 'rho1', 'username': 'yongkang', 'executable': '/mounts/work/lyk/anaconda3/envs/torch2/bin/python', 'cpu_count': 32, 'cpu_count_logical': 64, 'cpu_freq': {'current': 1877.8151093749998, 'min': 1500.0, 'max': 3000.0}, 'cpu_freq_per_core': [{'current': 1709.684, 'min': 1500.0, 'max': 3000.0}, {'current': 1500.0, 'min': 1500.0, 'max': 3000.0}, {'current': 1500.0, 'min': 1500.0, 'max': 3000.0}, {'current': 1500.0, 'min': 1500.0, 'max': 3000.0}, {'current': 1500.0, 'min': 1500.0, 'max': 3000.0}, {'current': 1500.0, 'min': 1500.0, 'max': 3000.0}, {'current': 3000.0, 'min': 1500.0, 'max': 3000.0}, {'current': 1500.0, 'min': 1500.0, 'max': 3000.0}, {'current': 1500.0, 'min': 1500.0, 'max': 3000.0}, {'current': 1500.0, 'min': 1500.0, 'max': 3000.0}, {'current': 1500.0, 'min': 1500.0, 'max': 3000.0}, {'current': 1500.0, 'min': 1500.0, 'max': 3000.0}, {'current': 3000.0, 'min': 1500.0, 'max': 3000.0}, {'current': 3000.0, 'min': 1500.0, 'max': 3000.0}, {'current': 3000.0, 'min': 1500.0, 'max': 3000.0}, {'current': 1500.0, 'min': 1500.0, 'max': 3000.0}, {'current': 3723.732, 'min': 1500.0, 'max': 3000.0}, {'current': 1500.0, 'min': 1500.0, 'max': 3000.0}, {'current': 3000.0, 'min': 1500.0, 'max': 3000.0}, {'current': 1500.0, 'min': 1500.0, 'max': 3000.0}, {'current': 3723.021, 'min': 1500.0, 'max': 3000.0}, {'current': 1500.0, 'min': 1500.0, 'max': 3000.0}, {'current': 1500.0, 'min': 1500.0, 'max': 3000.0}, {'current': 1500.0, 'min': 1500.0, 'max': 3000.0}, {'current': 1500.0, 'min': 1500.0, 'max': 3000.0}, {'current': 1500.0, 'min': 1500.0, 'max': 3000.0}, {'current': 1500.0, 'min': 1500.0, 'max': 3000.0}, {'current': 1500.0, 'min': 1500.0, 'max': 3000.0}, {'current': 3000.0, 'min': 1500.0, 'max': 3000.0}, {'current': 1500.0, 'min': 1500.0, 'max': 3000.0}, {'current': 1500.0, 'min': 1500.0, 'max': 3000.0}, {'current': 1500.0, 'min': 1500.0, 'max': 3000.0}, {'current': 1500.0, 'min': 1500.0, 'max': 3000.0}, {'current': 2200.0, 'min': 1500.0, 'max': 3000.0}, {'current': 2200.0, 'min': 1500.0, 'max': 3000.0}, {'current': 2200.0, 'min': 1500.0, 'max': 3000.0}, {'current': 1500.0, 'min': 1500.0, 'max': 3000.0}, {'current': 1500.0, 'min': 1500.0, 'max': 3000.0}, {'current': 1500.0, 'min': 1500.0, 'max': 3000.0}, {'current': 3000.0, 'min': 1500.0, 'max': 3000.0}, {'current': 1500.0, 'min': 1500.0, 'max': 3000.0}, {'current': 1500.0, 'min': 1500.0, 'max': 3000.0}, {'current': 1500.0, 'min': 1500.0, 'max': 3000.0}, {'current': 3000.0, 'min': 1500.0, 'max': 3000.0}, {'current': 1500.0, 'min': 1500.0, 'max': 3000.0}, {'current': 1500.0, 'min': 1500.0, 'max': 3000.0}, {'current': 1500.0, 'min': 1500.0, 'max': 3000.0}, {'current': 1500.0, 'min': 1500.0, 'max': 3000.0}, {'current': 1500.0, 'min': 1500.0, 'max': 3000.0}, {'current': 1500.0, 'min': 1500.0, 'max': 3000.0}, {'current': 1500.0, 'min': 1500.0, 'max': 3000.0}, {'current': 1500.0, 'min': 1500.0, 'max': 3000.0}, {'current': 1500.0, 'min': 1500.0, 'max': 3000.0}, {'current': 1500.0, 'min': 1500.0, 'max': 3000.0}, {'current': 1500.0, 'min': 1500.0, 'max': 3000.0}, {'current': 1500.0, 'min': 1500.0, 'max': 3000.0}, {'current': 1500.0, 'min': 1500.0, 'max': 3000.0}, {'current': 1500.0, 'min': 1500.0, 'max': 3000.0}, {'current': 1500.0, 'min': 1500.0, 'max': 3000.0}, {'current': 1500.0, 'min': 1500.0, 'max': 3000.0}, {'current': 1500.0, 'min': 1500.0, 'max': 3000.0}, {'current': 1500.0, 'min': 1500.0, 'max': 3000.0}, {'current': 1500.0, 'min': 1500.0, 'max': 3000.0}, {'current': 1500.0, 'min': 1500.0, 'max': 3000.0}], 'disk': {'/': {'total': 878.1072120666504, 'used': 583.3175392150879}}, 'gpu': 'NVIDIA RTX A6000', 'gpu_count': 8, 'gpu_devices': [{'name': 'NVIDIA RTX A6000', 'memory_total': 51527024640}, {'name': 'NVIDIA RTX A6000', 'memory_total': 51527024640}, {'name': 'NVIDIA RTX A6000', 'memory_total': 51527024640}, {'name': 'NVIDIA RTX A6000', 'memory_total': 51527024640}, {'name': 'NVIDIA RTX A6000', 'memory_total': 51527024640}, {'name': 'NVIDIA RTX A6000', 'memory_total': 51527024640}, {'name': 'NVIDIA RTX A6000', 'memory_total': 51527024640}, {'name': 'NVIDIA RTX A6000', 'memory_total': 51527024640}], 'memory': {'total': 251.73123168945312}}
2024-05-13 14:14:19,683 INFO    HandlerThread:521625 [system_monitor.py:probe():224] Finished collecting system info
2024-05-13 14:14:19,683 INFO    HandlerThread:521625 [system_monitor.py:probe():227] Publishing system info
2024-05-13 14:14:19,683 DEBUG   HandlerThread:521625 [system_info.py:_save_pip():52] Saving list of pip packages installed into the current environment
2024-05-13 14:14:19,684 DEBUG   HandlerThread:521625 [system_info.py:_save_pip():68] Saving pip packages done
2024-05-13 14:14:19,684 DEBUG   HandlerThread:521625 [system_info.py:_save_conda():75] Saving list of conda packages installed into the current environment
2024-05-13 14:14:20,495 INFO    Thread-12 :521625 [dir_watcher.py:_on_file_created():271] file/dir created: /nfs/datx/lyk/HiFT/wandb/run-20240513_141419-2bmnu66o/files/conda-environment.yaml
2024-05-13 14:14:20,496 INFO    Thread-12 :521625 [dir_watcher.py:_on_file_created():271] file/dir created: /nfs/datx/lyk/HiFT/wandb/run-20240513_141419-2bmnu66o/files/requirements.txt
2024-05-13 14:14:22,049 DEBUG   HandlerThread:521625 [system_info.py:_save_conda():87] Saving conda packages done
2024-05-13 14:14:22,052 INFO    HandlerThread:521625 [system_monitor.py:probe():229] Finished publishing system info
2024-05-13 14:14:22,058 DEBUG   SenderThread:521625 [sender.py:send():382] send: files
2024-05-13 14:14:22,059 INFO    SenderThread:521625 [sender.py:_save_file():1392] saving file wandb-metadata.json with policy now
2024-05-13 14:14:22,071 DEBUG   SenderThread:521625 [sender.py:send():382] send: telemetry
2024-05-13 14:14:22,071 DEBUG   HandlerThread:521625 [handler.py:handle_request():146] handle_request: stop_status
2024-05-13 14:14:22,071 DEBUG   SenderThread:521625 [sender.py:send_request():409] send_request: stop_status
2024-05-13 14:14:22,075 DEBUG   HandlerThread:521625 [handler.py:handle_request():146] handle_request: internal_messages
2024-05-13 14:14:22,280 DEBUG   SenderThread:521625 [sender.py:send():382] send: config
2024-05-13 14:14:22,281 DEBUG   SenderThread:521625 [sender.py:send():382] send: metric
2024-05-13 14:14:22,281 DEBUG   SenderThread:521625 [sender.py:send():382] send: telemetry
2024-05-13 14:14:22,281 DEBUG   SenderThread:521625 [sender.py:send():382] send: metric
2024-05-13 14:14:22,281 WARNING SenderThread:521625 [sender.py:send_metric():1343] Seen metric with glob (shouldn't happen)
2024-05-13 14:14:22,281 DEBUG   SenderThread:521625 [sender.py:send():382] send: telemetry
2024-05-13 14:14:22,496 INFO    Thread-12 :521625 [dir_watcher.py:_on_file_modified():288] file/dir modified: /nfs/datx/lyk/HiFT/wandb/run-20240513_141419-2bmnu66o/files/conda-environment.yaml
2024-05-13 14:14:22,497 INFO    Thread-12 :521625 [dir_watcher.py:_on_file_created():271] file/dir created: /nfs/datx/lyk/HiFT/wandb/run-20240513_141419-2bmnu66o/files/output.log
2024-05-13 14:14:22,497 INFO    Thread-12 :521625 [dir_watcher.py:_on_file_created():271] file/dir created: /nfs/datx/lyk/HiFT/wandb/run-20240513_141419-2bmnu66o/files/wandb-metadata.json
2024-05-13 14:14:22,502 ERROR   wandb-upload_0:521625 [internal_api.py:upload_file():2761] upload_file exception https://storage.googleapis.com/wandb-production.appspot.com/neuzxm/huggingface/2bmnu66o/wandb-metadata.json?Expires=1715688862&GoogleAccessId=gorilla-files-url-signer-man%40wandb-production.iam.gserviceaccount.com&Signature=D%2FkhU4RTRtBXmr%2FhY2GtYJeL0EaL0tP8CTiD3xXmmkg%2FQvtJmh%2BoXT6kglRq8IUXiW%2FEMOtmz9p%2FgrqrRdpvtJC73o4JaUqrsOqv0DsOA9%2BcFRMug4NnBlisjsW7eq7rCTrnGYlpBfxI1p1hSdtm7sXabgeBUipylLYBlHFeAJu4tswZfw1ZQmxT%2FAHFS0GVaDG60VaNdxZ0itMyHgETMiZ%2FHHLZp3P3Zhb74PneYF6A6v7j5AA6kthr7LFib9YM%2Fvh8qJmEhehqOHY6jFlaI0FsCoyEAQu9JPMIBOE9YLLrfobIkU91sS4Jr6ptYWOKyoLxs8skoUAGt2RuqVScnw%3D%3D: 403 Client Error: Forbidden for url: https://storage.googleapis.com/wandb-production.appspot.com/neuzxm/huggingface/2bmnu66o/wandb-metadata.json?Expires=1715688862&GoogleAccessId=gorilla-files-url-signer-man%40wandb-production.iam.gserviceaccount.com&Signature=D%2FkhU4RTRtBXmr%2FhY2GtYJeL0EaL0tP8CTiD3xXmmkg%2FQvtJmh%2BoXT6kglRq8IUXiW%2FEMOtmz9p%2FgrqrRdpvtJC73o4JaUqrsOqv0DsOA9%2BcFRMug4NnBlisjsW7eq7rCTrnGYlpBfxI1p1hSdtm7sXabgeBUipylLYBlHFeAJu4tswZfw1ZQmxT%2FAHFS0GVaDG60VaNdxZ0itMyHgETMiZ%2FHHLZp3P3Zhb74PneYF6A6v7j5AA6kthr7LFib9YM%2Fvh8qJmEhehqOHY6jFlaI0FsCoyEAQu9JPMIBOE9YLLrfobIkU91sS4Jr6ptYWOKyoLxs8skoUAGt2RuqVScnw%3D%3D
2024-05-13 14:14:22,502 ERROR   wandb-upload_0:521625 [internal_api.py:upload_file():2763] upload_file request headers: {'User-Agent': 'python-requests/2.31.0', 'Accept-Encoding': 'gzip, deflate, br', 'Accept': '*/*', 'Connection': 'keep-alive', 'Content-Length': '9905'}
2024-05-13 14:14:22,502 ERROR   wandb-upload_0:521625 [internal_api.py:upload_file():2765] upload_file response body: b"<?xml version='1.0' encoding='UTF-8'?><Error><Code>AccessDenied</Code><Message>Access denied.</Message><Details>We're sorry, but this service is not available in your location</Details></Error>"
2024-05-13 14:14:22,584 ERROR   wandb-upload_0:521625 [upload_job.py:push():134] Failed to upload file: /tmp/tmpxqz348lqwandb/phnuf1y9-wandb-metadata.json
Traceback (most recent call last):
  File "/mounts/work/lyk/anaconda3/envs/torch2/lib/python3.8/site-packages/wandb/apis/normalize.py", line 41, in wrapper
    return func(*args, **kwargs)
  File "/mounts/work/lyk/anaconda3/envs/torch2/lib/python3.8/site-packages/wandb/sdk/lib/retry.py", line 212, in wrapped_fn
    return retrier(*args, **kargs)
  File "/mounts/work/lyk/anaconda3/envs/torch2/lib/python3.8/site-packages/wandb/sdk/lib/retry.py", line 131, in __call__
    result = self._call_fn(*args, **kwargs)
  File "/mounts/work/lyk/anaconda3/envs/torch2/lib/python3.8/site-packages/wandb/sdk/internal/internal_api.py", line 2787, in upload_file
    wandb._sentry.reraise(e)
  File "/mounts/work/lyk/anaconda3/envs/torch2/lib/python3.8/site-packages/wandb/analytics/sentry.py", line 154, in reraise
    raise exc.with_traceback(sys.exc_info()[2])
  File "/mounts/work/lyk/anaconda3/envs/torch2/lib/python3.8/site-packages/wandb/sdk/internal/internal_api.py", line 2759, in upload_file
    response.raise_for_status()
  File "/mounts/work/lyk/anaconda3/envs/torch2/lib/python3.8/site-packages/requests/models.py", line 1021, in raise_for_status
    raise HTTPError(http_error_msg, response=self)
requests.exceptions.HTTPError: 403 Client Error: Forbidden for url: https://storage.googleapis.com/wandb-production.appspot.com/neuzxm/huggingface/2bmnu66o/wandb-metadata.json?Expires=1715688862&GoogleAccessId=gorilla-files-url-signer-man%40wandb-production.iam.gserviceaccount.com&Signature=D%2FkhU4RTRtBXmr%2FhY2GtYJeL0EaL0tP8CTiD3xXmmkg%2FQvtJmh%2BoXT6kglRq8IUXiW%2FEMOtmz9p%2FgrqrRdpvtJC73o4JaUqrsOqv0DsOA9%2BcFRMug4NnBlisjsW7eq7rCTrnGYlpBfxI1p1hSdtm7sXabgeBUipylLYBlHFeAJu4tswZfw1ZQmxT%2FAHFS0GVaDG60VaNdxZ0itMyHgETMiZ%2FHHLZp3P3Zhb74PneYF6A6v7j5AA6kthr7LFib9YM%2Fvh8qJmEhehqOHY6jFlaI0FsCoyEAQu9JPMIBOE9YLLrfobIkU91sS4Jr6ptYWOKyoLxs8skoUAGt2RuqVScnw%3D%3D

During handling of the above exception, another exception occurred:

Traceback (most recent call last):
  File "/mounts/work/lyk/anaconda3/envs/torch2/lib/python3.8/site-packages/wandb/filesync/upload_job.py", line 125, in push
    self._api.upload_file_retry(
  File "/mounts/work/lyk/anaconda3/envs/torch2/lib/python3.8/site-packages/wandb/apis/normalize.py", line 51, in wrapper
    raise CommError(message, error)
wandb.errors.CommError: <Response [403]>
2024-05-13 14:14:22,604 ERROR   Thread-11 :521625 [step_upload.py:_handle_event():200] Failed to upload file: /tmp/tmpxqz348lqwandb/phnuf1y9-wandb-metadata.json
Traceback (most recent call last):
  File "/mounts/work/lyk/anaconda3/envs/torch2/lib/python3.8/site-packages/wandb/apis/normalize.py", line 41, in wrapper
    return func(*args, **kwargs)
  File "/mounts/work/lyk/anaconda3/envs/torch2/lib/python3.8/site-packages/wandb/sdk/lib/retry.py", line 212, in wrapped_fn
    return retrier(*args, **kargs)
  File "/mounts/work/lyk/anaconda3/envs/torch2/lib/python3.8/site-packages/wandb/sdk/lib/retry.py", line 131, in __call__
    result = self._call_fn(*args, **kwargs)
  File "/mounts/work/lyk/anaconda3/envs/torch2/lib/python3.8/site-packages/wandb/sdk/internal/internal_api.py", line 2787, in upload_file
    wandb._sentry.reraise(e)
  File "/mounts/work/lyk/anaconda3/envs/torch2/lib/python3.8/site-packages/wandb/analytics/sentry.py", line 154, in reraise
    raise exc.with_traceback(sys.exc_info()[2])
  File "/mounts/work/lyk/anaconda3/envs/torch2/lib/python3.8/site-packages/wandb/sdk/internal/internal_api.py", line 2759, in upload_file
    response.raise_for_status()
  File "/mounts/work/lyk/anaconda3/envs/torch2/lib/python3.8/site-packages/requests/models.py", line 1021, in raise_for_status
    raise HTTPError(http_error_msg, response=self)
requests.exceptions.HTTPError: 403 Client Error: Forbidden for url: https://storage.googleapis.com/wandb-production.appspot.com/neuzxm/huggingface/2bmnu66o/wandb-metadata.json?Expires=1715688862&GoogleAccessId=gorilla-files-url-signer-man%40wandb-production.iam.gserviceaccount.com&Signature=D%2FkhU4RTRtBXmr%2FhY2GtYJeL0EaL0tP8CTiD3xXmmkg%2FQvtJmh%2BoXT6kglRq8IUXiW%2FEMOtmz9p%2FgrqrRdpvtJC73o4JaUqrsOqv0DsOA9%2BcFRMug4NnBlisjsW7eq7rCTrnGYlpBfxI1p1hSdtm7sXabgeBUipylLYBlHFeAJu4tswZfw1ZQmxT%2FAHFS0GVaDG60VaNdxZ0itMyHgETMiZ%2FHHLZp3P3Zhb74PneYF6A6v7j5AA6kthr7LFib9YM%2Fvh8qJmEhehqOHY6jFlaI0FsCoyEAQu9JPMIBOE9YLLrfobIkU91sS4Jr6ptYWOKyoLxs8skoUAGt2RuqVScnw%3D%3D

During handling of the above exception, another exception occurred:

Traceback (most recent call last):
  File "/mounts/work/lyk/anaconda3/envs/torch2/lib/python3.8/concurrent/futures/thread.py", line 57, in run
    result = self.fn(*self.args, **self.kwargs)
  File "/mounts/work/lyk/anaconda3/envs/torch2/lib/python3.8/site-packages/wandb/filesync/step_upload.py", line 288, in run_and_notify
    self._do_upload_sync(event)
  File "/mounts/work/lyk/anaconda3/envs/torch2/lib/python3.8/site-packages/wandb/filesync/step_upload.py", line 330, in _do_upload_sync
    job.run()
  File "/mounts/work/lyk/anaconda3/envs/torch2/lib/python3.8/site-packages/wandb/filesync/upload_job.py", line 57, in run
    self.push()
  File "/mounts/work/lyk/anaconda3/envs/torch2/lib/python3.8/site-packages/wandb/filesync/upload_job.py", line 125, in push
    self._api.upload_file_retry(
  File "/mounts/work/lyk/anaconda3/envs/torch2/lib/python3.8/site-packages/wandb/apis/normalize.py", line 51, in wrapper
    raise CommError(message, error)
wandb.errors.CommError: <Response [403]>
2024-05-13 14:14:23,258 DEBUG   SenderThread:521625 [sender.py:send():382] send: exit
2024-05-13 14:14:23,259 INFO    SenderThread:521625 [sender.py:send_exit():589] handling exit code: 1
2024-05-13 14:14:23,259 INFO    SenderThread:521625 [sender.py:send_exit():591] handling runtime: 3
2024-05-13 14:14:23,261 INFO    SenderThread:521625 [sender.py:_save_file():1392] saving file wandb-summary.json with policy end
2024-05-13 14:14:23,262 INFO    SenderThread:521625 [sender.py:send_exit():597] send defer
2024-05-13 14:14:23,262 DEBUG   HandlerThread:521625 [handler.py:handle_request():146] handle_request: defer
2024-05-13 14:14:23,262 INFO    HandlerThread:521625 [handler.py:handle_request_defer():172] handle defer: 0
2024-05-13 14:14:23,263 DEBUG   SenderThread:521625 [sender.py:send_request():409] send_request: defer
2024-05-13 14:14:23,263 INFO    SenderThread:521625 [sender.py:send_request_defer():613] handle sender defer: 0
2024-05-13 14:14:23,263 INFO    SenderThread:521625 [sender.py:transition_state():617] send defer: 1
2024-05-13 14:14:23,263 DEBUG   HandlerThread:521625 [handler.py:handle_request():146] handle_request: defer
2024-05-13 14:14:23,263 INFO    HandlerThread:521625 [handler.py:handle_request_defer():172] handle defer: 1
2024-05-13 14:14:23,264 DEBUG   SenderThread:521625 [sender.py:send_request():409] send_request: defer
2024-05-13 14:14:23,264 INFO    SenderThread:521625 [sender.py:send_request_defer():613] handle sender defer: 1
2024-05-13 14:14:23,264 INFO    SenderThread:521625 [sender.py:transition_state():617] send defer: 2
2024-05-13 14:14:23,264 DEBUG   HandlerThread:521625 [handler.py:handle_request():146] handle_request: defer
2024-05-13 14:14:23,264 INFO    HandlerThread:521625 [handler.py:handle_request_defer():172] handle defer: 2
2024-05-13 14:14:23,264 INFO    HandlerThread:521625 [system_monitor.py:finish():203] Stopping system monitor
2024-05-13 14:14:23,264 DEBUG   SystemMonitor:521625 [system_monitor.py:_start():172] Starting system metrics aggregation loop
2024-05-13 14:14:23,264 DEBUG   SystemMonitor:521625 [system_monitor.py:_start():179] Finished system metrics aggregation loop
2024-05-13 14:14:23,264 DEBUG   SystemMonitor:521625 [system_monitor.py:_start():183] Publishing last batch of metrics
2024-05-13 14:14:23,265 INFO    HandlerThread:521625 [interfaces.py:finish():202] Joined cpu monitor
2024-05-13 14:14:23,265 INFO    HandlerThread:521625 [interfaces.py:finish():202] Joined disk monitor
2024-05-13 14:14:23,498 INFO    Thread-12 :521625 [dir_watcher.py:_on_file_created():271] file/dir created: /nfs/datx/lyk/HiFT/wandb/run-20240513_141419-2bmnu66o/files/wandb-summary.json
2024-05-13 14:14:23,943 INFO    HandlerThread:521625 [interfaces.py:finish():202] Joined gpu monitor
2024-05-13 14:14:23,943 INFO    HandlerThread:521625 [interfaces.py:finish():202] Joined memory monitor
2024-05-13 14:14:23,943 INFO    HandlerThread:521625 [interfaces.py:finish():202] Joined network monitor
2024-05-13 14:14:23,944 DEBUG   SenderThread:521625 [sender.py:send_request():409] send_request: defer
2024-05-13 14:14:23,944 INFO    SenderThread:521625 [sender.py:send_request_defer():613] handle sender defer: 2
2024-05-13 14:14:23,944 INFO    SenderThread:521625 [sender.py:transition_state():617] send defer: 3
2024-05-13 14:14:23,944 DEBUG   HandlerThread:521625 [handler.py:handle_request():146] handle_request: defer
2024-05-13 14:14:23,944 INFO    HandlerThread:521625 [handler.py:handle_request_defer():172] handle defer: 3
2024-05-13 14:14:23,945 DEBUG   SenderThread:521625 [sender.py:send_request():409] send_request: defer
2024-05-13 14:14:23,945 INFO    SenderThread:521625 [sender.py:send_request_defer():613] handle sender defer: 3
2024-05-13 14:14:23,945 INFO    SenderThread:521625 [sender.py:transition_state():617] send defer: 4
2024-05-13 14:14:23,945 DEBUG   HandlerThread:521625 [handler.py:handle_request():146] handle_request: defer
2024-05-13 14:14:23,945 INFO    HandlerThread:521625 [handler.py:handle_request_defer():172] handle defer: 4
2024-05-13 14:14:23,945 DEBUG   SenderThread:521625 [sender.py:send_request():409] send_request: defer
2024-05-13 14:14:23,945 INFO    SenderThread:521625 [sender.py:send_request_defer():613] handle sender defer: 4
2024-05-13 14:14:23,945 INFO    SenderThread:521625 [sender.py:transition_state():617] send defer: 5
2024-05-13 14:14:23,946 DEBUG   HandlerThread:521625 [handler.py:handle_request():146] handle_request: defer
2024-05-13 14:14:23,946 INFO    HandlerThread:521625 [handler.py:handle_request_defer():172] handle defer: 5
2024-05-13 14:14:23,946 DEBUG   SenderThread:521625 [sender.py:send():382] send: summary
2024-05-13 14:14:23,947 INFO    SenderThread:521625 [sender.py:_save_file():1392] saving file wandb-summary.json with policy end
2024-05-13 14:14:23,947 DEBUG   SenderThread:521625 [sender.py:send_request():409] send_request: defer
2024-05-13 14:14:23,948 INFO    SenderThread:521625 [sender.py:send_request_defer():613] handle sender defer: 5
2024-05-13 14:14:23,948 INFO    SenderThread:521625 [sender.py:transition_state():617] send defer: 6
2024-05-13 14:14:23,948 DEBUG   HandlerThread:521625 [handler.py:handle_request():146] handle_request: defer
2024-05-13 14:14:23,948 INFO    HandlerThread:521625 [handler.py:handle_request_defer():172] handle defer: 6
2024-05-13 14:14:23,948 DEBUG   SenderThread:521625 [sender.py:send_request():409] send_request: defer
2024-05-13 14:14:23,948 INFO    SenderThread:521625 [sender.py:send_request_defer():613] handle sender defer: 6
2024-05-13 14:14:23,952 DEBUG   HandlerThread:521625 [handler.py:handle_request():146] handle_request: status_report
2024-05-13 14:14:24,152 INFO    SenderThread:521625 [sender.py:transition_state():617] send defer: 7
2024-05-13 14:14:24,152 DEBUG   HandlerThread:521625 [handler.py:handle_request():146] handle_request: defer
2024-05-13 14:14:24,152 INFO    HandlerThread:521625 [handler.py:handle_request_defer():172] handle defer: 7
2024-05-13 14:14:24,153 DEBUG   SenderThread:521625 [sender.py:send_request():409] send_request: defer
2024-05-13 14:14:24,153 INFO    SenderThread:521625 [sender.py:send_request_defer():613] handle sender defer: 7
2024-05-13 14:14:24,258 DEBUG   HandlerThread:521625 [handler.py:handle_request():146] handle_request: poll_exit
2024-05-13 14:14:24,295 INFO    SenderThread:521625 [sender.py:transition_state():617] send defer: 8
2024-05-13 14:14:24,296 DEBUG   SenderThread:521625 [sender.py:send_request():409] send_request: poll_exit
2024-05-13 14:14:24,296 DEBUG   HandlerThread:521625 [handler.py:handle_request():146] handle_request: defer
2024-05-13 14:14:24,296 INFO    HandlerThread:521625 [handler.py:handle_request_defer():172] handle defer: 8
2024-05-13 14:14:24,297 DEBUG   SenderThread:521625 [sender.py:send_request():409] send_request: defer
2024-05-13 14:14:24,297 INFO    SenderThread:521625 [sender.py:send_request_defer():613] handle sender defer: 8
2024-05-13 14:14:24,297 INFO    SenderThread:521625 [job_builder.py:build():298] Attempting to build job artifact
2024-05-13 14:14:24,299 INFO    SenderThread:521625 [job_builder.py:_get_source_type():439] no source found
2024-05-13 14:14:24,299 INFO    SenderThread:521625 [sender.py:transition_state():617] send defer: 9
2024-05-13 14:14:24,299 DEBUG   HandlerThread:521625 [handler.py:handle_request():146] handle_request: defer
2024-05-13 14:14:24,299 INFO    HandlerThread:521625 [handler.py:handle_request_defer():172] handle defer: 9
2024-05-13 14:14:24,299 DEBUG   SenderThread:521625 [sender.py:send_request():409] send_request: defer
2024-05-13 14:14:24,300 INFO    SenderThread:521625 [sender.py:send_request_defer():613] handle sender defer: 9
2024-05-13 14:14:24,300 INFO    SenderThread:521625 [dir_watcher.py:finish():358] shutting down directory watcher
2024-05-13 14:14:24,500 INFO    SenderThread:521625 [dir_watcher.py:_on_file_modified():288] file/dir modified: /nfs/datx/lyk/HiFT/wandb/run-20240513_141419-2bmnu66o/files/output.log
2024-05-13 14:14:24,500 INFO    SenderThread:521625 [dir_watcher.py:_on_file_modified():288] file/dir modified: /nfs/datx/lyk/HiFT/wandb/run-20240513_141419-2bmnu66o/files/wandb-summary.json
2024-05-13 14:14:24,500 INFO    SenderThread:521625 [dir_watcher.py:_on_file_modified():288] file/dir modified: /nfs/datx/lyk/HiFT/wandb/run-20240513_141419-2bmnu66o/files/config.yaml
2024-05-13 14:14:24,500 INFO    SenderThread:521625 [dir_watcher.py:finish():388] scan: /nfs/datx/lyk/HiFT/wandb/run-20240513_141419-2bmnu66o/files
2024-05-13 14:14:24,500 INFO    SenderThread:521625 [dir_watcher.py:finish():402] scan save: /nfs/datx/lyk/HiFT/wandb/run-20240513_141419-2bmnu66o/files/wandb-summary.json wandb-summary.json
2024-05-13 14:14:24,501 INFO    SenderThread:521625 [dir_watcher.py:finish():402] scan save: /nfs/datx/lyk/HiFT/wandb/run-20240513_141419-2bmnu66o/files/requirements.txt requirements.txt
2024-05-13 14:14:24,501 INFO    SenderThread:521625 [dir_watcher.py:finish():402] scan save: /nfs/datx/lyk/HiFT/wandb/run-20240513_141419-2bmnu66o/files/conda-environment.yaml conda-environment.yaml
2024-05-13 14:14:24,501 INFO    SenderThread:521625 [dir_watcher.py:finish():402] scan save: /nfs/datx/lyk/HiFT/wandb/run-20240513_141419-2bmnu66o/files/config.yaml config.yaml
2024-05-13 14:14:24,501 INFO    SenderThread:521625 [dir_watcher.py:finish():402] scan save: /nfs/datx/lyk/HiFT/wandb/run-20240513_141419-2bmnu66o/files/wandb-metadata.json wandb-metadata.json
2024-05-13 14:14:24,501 INFO    SenderThread:521625 [dir_watcher.py:finish():402] scan save: /nfs/datx/lyk/HiFT/wandb/run-20240513_141419-2bmnu66o/files/output.log output.log
2024-05-13 14:14:24,502 INFO    SenderThread:521625 [sender.py:transition_state():617] send defer: 10
2024-05-13 14:14:24,503 DEBUG   HandlerThread:521625 [handler.py:handle_request():146] handle_request: defer
2024-05-13 14:14:24,504 INFO    HandlerThread:521625 [handler.py:handle_request_defer():172] handle defer: 10
2024-05-13 14:14:24,518 DEBUG   SenderThread:521625 [sender.py:send_request():409] send_request: defer
2024-05-13 14:14:24,519 INFO    SenderThread:521625 [sender.py:send_request_defer():613] handle sender defer: 10
2024-05-13 14:14:24,519 INFO    SenderThread:521625 [file_pusher.py:finish():175] shutting down file pusher
2024-05-13 14:14:24,750 ERROR   wandb-upload_0:521625 [internal_api.py:upload_file():2761] upload_file exception https://storage.googleapis.com/wandb-production.appspot.com/neuzxm/huggingface/2bmnu66o/wandb-summary.json?Expires=1715688864&GoogleAccessId=gorilla-files-url-signer-man%40wandb-production.iam.gserviceaccount.com&Signature=Dpqq3G3lz4ITWo%2FliayE4g0yqedwtEAZ0oy%2B6%2Fg99OXAnosiAg%2BlbyCfdkwTgmf%2FS1u0JvroL6hU%2F1HNzSXsZ2EbC1zS5NM2qJhsdfqkKeeIfLhZVxw3kS3klOAIxbGVAUOmEszGGHiAOxvP19gdcX7iz7FrG5sxvsdu1w0Y5DQtc3CPdbwZfIj4jU7cI0FLkt5iigwFCvzioRvbrwpcHWh7JwYx97%2BfvVBHTl9DHVaKn4kVkO5A9bhVbP3E8T9AY%2BlLKiXqZgNup3DdspDSsMv40KFy%2BNsjST9OqyLtv4C2tbodI3Ev%2Bq0meuFiKybXIn6W%2B5kRb0qZDLj%2FxOwLiw%3D%3D: 403 Client Error: Forbidden for url: https://storage.googleapis.com/wandb-production.appspot.com/neuzxm/huggingface/2bmnu66o/wandb-summary.json?Expires=1715688864&GoogleAccessId=gorilla-files-url-signer-man%40wandb-production.iam.gserviceaccount.com&Signature=Dpqq3G3lz4ITWo%2FliayE4g0yqedwtEAZ0oy%2B6%2Fg99OXAnosiAg%2BlbyCfdkwTgmf%2FS1u0JvroL6hU%2F1HNzSXsZ2EbC1zS5NM2qJhsdfqkKeeIfLhZVxw3kS3klOAIxbGVAUOmEszGGHiAOxvP19gdcX7iz7FrG5sxvsdu1w0Y5DQtc3CPdbwZfIj4jU7cI0FLkt5iigwFCvzioRvbrwpcHWh7JwYx97%2BfvVBHTl9DHVaKn4kVkO5A9bhVbP3E8T9AY%2BlLKiXqZgNup3DdspDSsMv40KFy%2BNsjST9OqyLtv4C2tbodI3Ev%2Bq0meuFiKybXIn6W%2B5kRb0qZDLj%2FxOwLiw%3D%3D
2024-05-13 14:14:24,750 ERROR   wandb-upload_0:521625 [internal_api.py:upload_file():2763] upload_file request headers: {'User-Agent': 'python-requests/2.31.0', 'Accept-Encoding': 'gzip, deflate, br', 'Accept': '*/*', 'Connection': 'keep-alive', 'Content-Length': '26'}
2024-05-13 14:14:24,750 ERROR   wandb-upload_0:521625 [internal_api.py:upload_file():2765] upload_file response body: b"<?xml version='1.0' encoding='UTF-8'?><Error><Code>AccessDenied</Code><Message>Access denied.</Message><Details>We're sorry, but this service is not available in your location</Details></Error>"
2024-05-13 14:14:24,767 ERROR   wandb-upload_0:521625 [upload_job.py:push():134] Failed to upload file: /nfs/datx/lyk/HiFT/wandb/run-20240513_141419-2bmnu66o/files/wandb-summary.json
Traceback (most recent call last):
  File "/mounts/work/lyk/anaconda3/envs/torch2/lib/python3.8/site-packages/wandb/apis/normalize.py", line 41, in wrapper
    return func(*args, **kwargs)
  File "/mounts/work/lyk/anaconda3/envs/torch2/lib/python3.8/site-packages/wandb/sdk/lib/retry.py", line 212, in wrapped_fn
    return retrier(*args, **kargs)
  File "/mounts/work/lyk/anaconda3/envs/torch2/lib/python3.8/site-packages/wandb/sdk/lib/retry.py", line 131, in __call__
    result = self._call_fn(*args, **kwargs)
  File "/mounts/work/lyk/anaconda3/envs/torch2/lib/python3.8/site-packages/wandb/sdk/internal/internal_api.py", line 2787, in upload_file
    wandb._sentry.reraise(e)
  File "/mounts/work/lyk/anaconda3/envs/torch2/lib/python3.8/site-packages/wandb/analytics/sentry.py", line 154, in reraise
    raise exc.with_traceback(sys.exc_info()[2])
  File "/mounts/work/lyk/anaconda3/envs/torch2/lib/python3.8/site-packages/wandb/sdk/internal/internal_api.py", line 2759, in upload_file
    response.raise_for_status()
  File "/mounts/work/lyk/anaconda3/envs/torch2/lib/python3.8/site-packages/requests/models.py", line 1021, in raise_for_status
    raise HTTPError(http_error_msg, response=self)
requests.exceptions.HTTPError: 403 Client Error: Forbidden for url: https://storage.googleapis.com/wandb-production.appspot.com/neuzxm/huggingface/2bmnu66o/wandb-summary.json?Expires=1715688864&GoogleAccessId=gorilla-files-url-signer-man%40wandb-production.iam.gserviceaccount.com&Signature=Dpqq3G3lz4ITWo%2FliayE4g0yqedwtEAZ0oy%2B6%2Fg99OXAnosiAg%2BlbyCfdkwTgmf%2FS1u0JvroL6hU%2F1HNzSXsZ2EbC1zS5NM2qJhsdfqkKeeIfLhZVxw3kS3klOAIxbGVAUOmEszGGHiAOxvP19gdcX7iz7FrG5sxvsdu1w0Y5DQtc3CPdbwZfIj4jU7cI0FLkt5iigwFCvzioRvbrwpcHWh7JwYx97%2BfvVBHTl9DHVaKn4kVkO5A9bhVbP3E8T9AY%2BlLKiXqZgNup3DdspDSsMv40KFy%2BNsjST9OqyLtv4C2tbodI3Ev%2Bq0meuFiKybXIn6W%2B5kRb0qZDLj%2FxOwLiw%3D%3D

During handling of the above exception, another exception occurred:

Traceback (most recent call last):
  File "/mounts/work/lyk/anaconda3/envs/torch2/lib/python3.8/site-packages/wandb/filesync/upload_job.py", line 125, in push
    self._api.upload_file_retry(
  File "/mounts/work/lyk/anaconda3/envs/torch2/lib/python3.8/site-packages/wandb/apis/normalize.py", line 51, in wrapper
    raise CommError(message, error)
wandb.errors.CommError: <Response [403]>
2024-05-13 14:14:24,787 ERROR   Thread-11 :521625 [step_upload.py:_handle_event():200] Failed to upload file: /nfs/datx/lyk/HiFT/wandb/run-20240513_141419-2bmnu66o/files/wandb-summary.json
Traceback (most recent call last):
  File "/mounts/work/lyk/anaconda3/envs/torch2/lib/python3.8/site-packages/wandb/apis/normalize.py", line 41, in wrapper
    return func(*args, **kwargs)
  File "/mounts/work/lyk/anaconda3/envs/torch2/lib/python3.8/site-packages/wandb/sdk/lib/retry.py", line 212, in wrapped_fn
    return retrier(*args, **kargs)
  File "/mounts/work/lyk/anaconda3/envs/torch2/lib/python3.8/site-packages/wandb/sdk/lib/retry.py", line 131, in __call__
    result = self._call_fn(*args, **kwargs)
  File "/mounts/work/lyk/anaconda3/envs/torch2/lib/python3.8/site-packages/wandb/sdk/internal/internal_api.py", line 2787, in upload_file
    wandb._sentry.reraise(e)
  File "/mounts/work/lyk/anaconda3/envs/torch2/lib/python3.8/site-packages/wandb/analytics/sentry.py", line 154, in reraise
    raise exc.with_traceback(sys.exc_info()[2])
  File "/mounts/work/lyk/anaconda3/envs/torch2/lib/python3.8/site-packages/wandb/sdk/internal/internal_api.py", line 2759, in upload_file
    response.raise_for_status()
  File "/mounts/work/lyk/anaconda3/envs/torch2/lib/python3.8/site-packages/requests/models.py", line 1021, in raise_for_status
    raise HTTPError(http_error_msg, response=self)
requests.exceptions.HTTPError: 403 Client Error: Forbidden for url: https://storage.googleapis.com/wandb-production.appspot.com/neuzxm/huggingface/2bmnu66o/wandb-summary.json?Expires=1715688864&GoogleAccessId=gorilla-files-url-signer-man%40wandb-production.iam.gserviceaccount.com&Signature=Dpqq3G3lz4ITWo%2FliayE4g0yqedwtEAZ0oy%2B6%2Fg99OXAnosiAg%2BlbyCfdkwTgmf%2FS1u0JvroL6hU%2F1HNzSXsZ2EbC1zS5NM2qJhsdfqkKeeIfLhZVxw3kS3klOAIxbGVAUOmEszGGHiAOxvP19gdcX7iz7FrG5sxvsdu1w0Y5DQtc3CPdbwZfIj4jU7cI0FLkt5iigwFCvzioRvbrwpcHWh7JwYx97%2BfvVBHTl9DHVaKn4kVkO5A9bhVbP3E8T9AY%2BlLKiXqZgNup3DdspDSsMv40KFy%2BNsjST9OqyLtv4C2tbodI3Ev%2Bq0meuFiKybXIn6W%2B5kRb0qZDLj%2FxOwLiw%3D%3D

During handling of the above exception, another exception occurred:

Traceback (most recent call last):
  File "/mounts/work/lyk/anaconda3/envs/torch2/lib/python3.8/concurrent/futures/thread.py", line 57, in run
    result = self.fn(*self.args, **self.kwargs)
  File "/mounts/work/lyk/anaconda3/envs/torch2/lib/python3.8/site-packages/wandb/filesync/step_upload.py", line 288, in run_and_notify
    self._do_upload_sync(event)
  File "/mounts/work/lyk/anaconda3/envs/torch2/lib/python3.8/site-packages/wandb/filesync/step_upload.py", line 330, in _do_upload_sync
    job.run()
  File "/mounts/work/lyk/anaconda3/envs/torch2/lib/python3.8/site-packages/wandb/filesync/upload_job.py", line 57, in run
    self.push()
  File "/mounts/work/lyk/anaconda3/envs/torch2/lib/python3.8/site-packages/wandb/filesync/upload_job.py", line 125, in push
    self._api.upload_file_retry(
  File "/mounts/work/lyk/anaconda3/envs/torch2/lib/python3.8/site-packages/wandb/apis/normalize.py", line 51, in wrapper
    raise CommError(message, error)
wandb.errors.CommError: <Response [403]>
2024-05-13 14:14:24,808 ERROR   wandb-upload_2:521625 [internal_api.py:upload_file():2761] upload_file exception https://storage.googleapis.com/wandb-production.appspot.com/neuzxm/huggingface/2bmnu66o/conda-environment.yaml?Expires=1715688864&GoogleAccessId=gorilla-files-url-signer-man%40wandb-production.iam.gserviceaccount.com&Signature=OXzPRuKbSMjGTolhL0eqo8kizc1Sp7u8UFXH1o97dwC6X9ncmcwM5CAUyPRAGyxldjJxMdQBtneoPtvZyPSEHuVVFBvKe1VTGQvPOPqy1E93aNNtRNvH20LKfxaYQsEA7Sh%2Bm5HKlr2xBuXedRvFsj5BNBj2mq1n70gz0hMmDRTxzjOI39pciKqaUoDTahs7IQrJjZFjjS4EHriANU2yGXazBjtM3FaNRKCIZNhrPAiGasKxpN9e1Lwh5kjPMQl1PNL65Jvwg8T05mDM52sCsFpyD4l3fP%2FwbchqnTioEw2Q9odMyxNYqCLmpvOzBJtqh%2F1LnySRiv4MU7odjvAQVw%3D%3D: 403 Client Error: Forbidden for url: https://storage.googleapis.com/wandb-production.appspot.com/neuzxm/huggingface/2bmnu66o/conda-environment.yaml?Expires=1715688864&GoogleAccessId=gorilla-files-url-signer-man%40wandb-production.iam.gserviceaccount.com&Signature=OXzPRuKbSMjGTolhL0eqo8kizc1Sp7u8UFXH1o97dwC6X9ncmcwM5CAUyPRAGyxldjJxMdQBtneoPtvZyPSEHuVVFBvKe1VTGQvPOPqy1E93aNNtRNvH20LKfxaYQsEA7Sh%2Bm5HKlr2xBuXedRvFsj5BNBj2mq1n70gz0hMmDRTxzjOI39pciKqaUoDTahs7IQrJjZFjjS4EHriANU2yGXazBjtM3FaNRKCIZNhrPAiGasKxpN9e1Lwh5kjPMQl1PNL65Jvwg8T05mDM52sCsFpyD4l3fP%2FwbchqnTioEw2Q9odMyxNYqCLmpvOzBJtqh%2F1LnySRiv4MU7odjvAQVw%3D%3D
2024-05-13 14:14:24,808 ERROR   wandb-upload_2:521625 [internal_api.py:upload_file():2763] upload_file request headers: {'User-Agent': 'python-requests/2.31.0', 'Accept-Encoding': 'gzip, deflate, br', 'Accept': '*/*', 'Connection': 'keep-alive', 'Content-Length': '5433'}
2024-05-13 14:14:24,808 ERROR   wandb-upload_2:521625 [internal_api.py:upload_file():2765] upload_file response body: b"<?xml version='1.0' encoding='UTF-8'?><Error><Code>AccessDenied</Code><Message>Access denied.</Message><Details>We're sorry, but this service is not available in your location</Details></Error>"
2024-05-13 14:14:24,824 ERROR   wandb-upload_2:521625 [upload_job.py:push():134] Failed to upload file: /nfs/datx/lyk/HiFT/wandb/run-20240513_141419-2bmnu66o/files/conda-environment.yaml
Traceback (most recent call last):
  File "/mounts/work/lyk/anaconda3/envs/torch2/lib/python3.8/site-packages/wandb/apis/normalize.py", line 41, in wrapper
    return func(*args, **kwargs)
  File "/mounts/work/lyk/anaconda3/envs/torch2/lib/python3.8/site-packages/wandb/sdk/lib/retry.py", line 212, in wrapped_fn
    return retrier(*args, **kargs)
  File "/mounts/work/lyk/anaconda3/envs/torch2/lib/python3.8/site-packages/wandb/sdk/lib/retry.py", line 131, in __call__
    result = self._call_fn(*args, **kwargs)
  File "/mounts/work/lyk/anaconda3/envs/torch2/lib/python3.8/site-packages/wandb/sdk/internal/internal_api.py", line 2787, in upload_file
    wandb._sentry.reraise(e)
  File "/mounts/work/lyk/anaconda3/envs/torch2/lib/python3.8/site-packages/wandb/analytics/sentry.py", line 154, in reraise
    raise exc.with_traceback(sys.exc_info()[2])
  File "/mounts/work/lyk/anaconda3/envs/torch2/lib/python3.8/site-packages/wandb/sdk/internal/internal_api.py", line 2759, in upload_file
    response.raise_for_status()
  File "/mounts/work/lyk/anaconda3/envs/torch2/lib/python3.8/site-packages/requests/models.py", line 1021, in raise_for_status
    raise HTTPError(http_error_msg, response=self)
requests.exceptions.HTTPError: 403 Client Error: Forbidden for url: https://storage.googleapis.com/wandb-production.appspot.com/neuzxm/huggingface/2bmnu66o/conda-environment.yaml?Expires=1715688864&GoogleAccessId=gorilla-files-url-signer-man%40wandb-production.iam.gserviceaccount.com&Signature=OXzPRuKbSMjGTolhL0eqo8kizc1Sp7u8UFXH1o97dwC6X9ncmcwM5CAUyPRAGyxldjJxMdQBtneoPtvZyPSEHuVVFBvKe1VTGQvPOPqy1E93aNNtRNvH20LKfxaYQsEA7Sh%2Bm5HKlr2xBuXedRvFsj5BNBj2mq1n70gz0hMmDRTxzjOI39pciKqaUoDTahs7IQrJjZFjjS4EHriANU2yGXazBjtM3FaNRKCIZNhrPAiGasKxpN9e1Lwh5kjPMQl1PNL65Jvwg8T05mDM52sCsFpyD4l3fP%2FwbchqnTioEw2Q9odMyxNYqCLmpvOzBJtqh%2F1LnySRiv4MU7odjvAQVw%3D%3D

During handling of the above exception, another exception occurred:

Traceback (most recent call last):
  File "/mounts/work/lyk/anaconda3/envs/torch2/lib/python3.8/site-packages/wandb/filesync/upload_job.py", line 125, in push
    self._api.upload_file_retry(
  File "/mounts/work/lyk/anaconda3/envs/torch2/lib/python3.8/site-packages/wandb/apis/normalize.py", line 51, in wrapper
    raise CommError(message, error)
wandb.errors.CommError: <Response [403]>
2024-05-13 14:14:24,829 ERROR   wandb-upload_4:521625 [internal_api.py:upload_file():2761] upload_file exception https://storage.googleapis.com/wandb-production.appspot.com/neuzxm/huggingface/2bmnu66o/output.log?Expires=1715688864&GoogleAccessId=gorilla-files-url-signer-man%40wandb-production.iam.gserviceaccount.com&Signature=a2dnEhNi0f8z5OoQWtNtvB2vqoGG%2BNF5xyRAVMUHWaz%2B1KHXUUFMW9qwbS33RRYSRHFJW6V%2F3LeZ6w9d%2BaHKYakDHN6CPwXZFoYzIBy0%2Bb4cntyJNJ8PfE7BKmlpne6kNkswwPvUHh%2BLGWEWuYvqvkMVPD7TDwwI9AAzpuSv%2B6gfD5%2BfhtufFKXKnfnm%2F0SbsCQd7z%2FMM0Zx50gHzCtneThwWn%2FD97q8un3dHPQBhRyzRTBeaoSYDifBLguMDemNviG%2BvNUbmBwk9R0TNpqJOqNEEhs4w2l3zZT15AFWCBcdvzmXfYB%2B%2B7U19xx61THDGD3DmnEXy3WDlfM4dFkocA%3D%3D: 403 Client Error: Forbidden for url: https://storage.googleapis.com/wandb-production.appspot.com/neuzxm/huggingface/2bmnu66o/output.log?Expires=1715688864&GoogleAccessId=gorilla-files-url-signer-man%40wandb-production.iam.gserviceaccount.com&Signature=a2dnEhNi0f8z5OoQWtNtvB2vqoGG%2BNF5xyRAVMUHWaz%2B1KHXUUFMW9qwbS33RRYSRHFJW6V%2F3LeZ6w9d%2BaHKYakDHN6CPwXZFoYzIBy0%2Bb4cntyJNJ8PfE7BKmlpne6kNkswwPvUHh%2BLGWEWuYvqvkMVPD7TDwwI9AAzpuSv%2B6gfD5%2BfhtufFKXKnfnm%2F0SbsCQd7z%2FMM0Zx50gHzCtneThwWn%2FD97q8un3dHPQBhRyzRTBeaoSYDifBLguMDemNviG%2BvNUbmBwk9R0TNpqJOqNEEhs4w2l3zZT15AFWCBcdvzmXfYB%2B%2B7U19xx61THDGD3DmnEXy3WDlfM4dFkocA%3D%3D
2024-05-13 14:14:24,829 ERROR   wandb-upload_4:521625 [internal_api.py:upload_file():2763] upload_file request headers: {'User-Agent': 'python-requests/2.31.0', 'Accept-Encoding': 'gzip, deflate, br', 'Accept': '*/*', 'Connection': 'keep-alive', 'Content-Length': '2437'}
2024-05-13 14:14:24,829 ERROR   wandb-upload_4:521625 [internal_api.py:upload_file():2765] upload_file response body: b"<?xml version='1.0' encoding='UTF-8'?><Error><Code>AccessDenied</Code><Message>Access denied.</Message><Details>We're sorry, but this service is not available in your location</Details></Error>"
2024-05-13 14:14:24,843 ERROR   wandb-upload_3:521625 [internal_api.py:upload_file():2761] upload_file exception https://storage.googleapis.com/wandb-production.appspot.com/neuzxm/huggingface/2bmnu66o/config.yaml?Expires=1715688864&GoogleAccessId=gorilla-files-url-signer-man%40wandb-production.iam.gserviceaccount.com&Signature=QuqiRF19h%2FY6gZgU%2F3ki%2FtuZYvHJCOXNFnCGYhK3SCwUwO3Jxx7uJ3wm9bCoL1ejnRgWvH3k%2FOnZEOc5n%2BwPk%2BxUR8VozoObXN59L8s6NWZanXxiw3xHo9yTM%2FiHXQlHDtcT0Iw3OGdR50kA8e0zhQ5240UAy1aPjjrZMzc81EYQq7vVPkpX7JpKyPk%2BEqA7Q5aflua90ZFxaLa1y8i8BqtPcRlD0sEfObKqc%2B7DCOu16X6Y7A9ORK9Da6BrU5Ux7nO4aG8VZJ2AC8j6xzjvp%2BDOR9TUNGTHAyoW5rK7Xf2n%2F3I7IJm7IzHTEtmMUAxk8N9vDVQmhCIP3sWpdbG0WQ%3D%3D: 403 Client Error: Forbidden for url: https://storage.googleapis.com/wandb-production.appspot.com/neuzxm/huggingface/2bmnu66o/config.yaml?Expires=1715688864&GoogleAccessId=gorilla-files-url-signer-man%40wandb-production.iam.gserviceaccount.com&Signature=QuqiRF19h%2FY6gZgU%2F3ki%2FtuZYvHJCOXNFnCGYhK3SCwUwO3Jxx7uJ3wm9bCoL1ejnRgWvH3k%2FOnZEOc5n%2BwPk%2BxUR8VozoObXN59L8s6NWZanXxiw3xHo9yTM%2FiHXQlHDtcT0Iw3OGdR50kA8e0zhQ5240UAy1aPjjrZMzc81EYQq7vVPkpX7JpKyPk%2BEqA7Q5aflua90ZFxaLa1y8i8BqtPcRlD0sEfObKqc%2B7DCOu16X6Y7A9ORK9Da6BrU5Ux7nO4aG8VZJ2AC8j6xzjvp%2BDOR9TUNGTHAyoW5rK7Xf2n%2F3I7IJm7IzHTEtmMUAxk8N9vDVQmhCIP3sWpdbG0WQ%3D%3D
2024-05-13 14:14:24,843 ERROR   wandb-upload_3:521625 [internal_api.py:upload_file():2763] upload_file request headers: {'User-Agent': 'python-requests/2.31.0', 'Accept-Encoding': 'gzip, deflate, br', 'Accept': '*/*', 'Connection': 'keep-alive', 'Content-Length': '9673'}
2024-05-13 14:14:24,843 ERROR   wandb-upload_3:521625 [internal_api.py:upload_file():2765] upload_file response body: b"<?xml version='1.0' encoding='UTF-8'?><Error><Code>AccessDenied</Code><Message>Access denied.</Message><Details>We're sorry, but this service is not available in your location</Details></Error>"
2024-05-13 14:14:24,846 ERROR   wandb-upload_1:521625 [internal_api.py:upload_file():2761] upload_file exception https://storage.googleapis.com/wandb-production.appspot.com/neuzxm/huggingface/2bmnu66o/requirements.txt?Expires=1715688864&GoogleAccessId=gorilla-files-url-signer-man%40wandb-production.iam.gserviceaccount.com&Signature=LlEle9nfqKZ8wJAIGYKkXQpPdKAM2Q9jfv1VB8lONlY8IhKvO4VHPY6BrY67rkdO7qTMCG69ENRkyumevnn%2FnxfRDGCbh0SRwDapTkm9L14BRc4%2F%2F%2BDDXfQ2AT4nEqXcFhYOr5n5Gh%2FRWwCeoqw40Vr2CS%2Fb5ynAxTmQ3KSA3qRyaEZJEhFMYe5jJm6JpsUhrY3W2e%2F%2BV61Uf6sjBM66bCbFEZiTIb7SzEBv4wh9DZ%2FMKkp7RaeWI1rMJcyDGY8Z%2B0l3Fo07uUmqrkft%2FAUQf9Q3nYDGvwlyVG2p0684%2BFE%2Bf%2Fj%2Fy9eToXMyodfvxPFVhVoCAKwBqZDR%2F%2BDi5AzNHA%3D%3D: 403 Client Error: Forbidden for url: https://storage.googleapis.com/wandb-production.appspot.com/neuzxm/huggingface/2bmnu66o/requirements.txt?Expires=1715688864&GoogleAccessId=gorilla-files-url-signer-man%40wandb-production.iam.gserviceaccount.com&Signature=LlEle9nfqKZ8wJAIGYKkXQpPdKAM2Q9jfv1VB8lONlY8IhKvO4VHPY6BrY67rkdO7qTMCG69ENRkyumevnn%2FnxfRDGCbh0SRwDapTkm9L14BRc4%2F%2F%2BDDXfQ2AT4nEqXcFhYOr5n5Gh%2FRWwCeoqw40Vr2CS%2Fb5ynAxTmQ3KSA3qRyaEZJEhFMYe5jJm6JpsUhrY3W2e%2F%2BV61Uf6sjBM66bCbFEZiTIb7SzEBv4wh9DZ%2FMKkp7RaeWI1rMJcyDGY8Z%2B0l3Fo07uUmqrkft%2FAUQf9Q3nYDGvwlyVG2p0684%2BFE%2Bf%2Fj%2Fy9eToXMyodfvxPFVhVoCAKwBqZDR%2F%2BDi5AzNHA%3D%3D
2024-05-13 14:14:24,846 ERROR   wandb-upload_1:521625 [internal_api.py:upload_file():2763] upload_file request headers: {'User-Agent': 'python-requests/2.31.0', 'Accept-Encoding': 'gzip, deflate, br', 'Accept': '*/*', 'Connection': 'keep-alive', 'Content-Length': '2434'}
2024-05-13 14:14:24,846 ERROR   wandb-upload_1:521625 [internal_api.py:upload_file():2765] upload_file response body: b"<?xml version='1.0' encoding='UTF-8'?><Error><Code>AccessDenied</Code><Message>Access denied.</Message><Details>We're sorry, but this service is not available in your location</Details></Error>"
2024-05-13 14:14:24,884 ERROR   Thread-11 :521625 [step_upload.py:_handle_event():200] Failed to upload file: /nfs/datx/lyk/HiFT/wandb/run-20240513_141419-2bmnu66o/files/conda-environment.yaml
Traceback (most recent call last):
  File "/mounts/work/lyk/anaconda3/envs/torch2/lib/python3.8/site-packages/wandb/apis/normalize.py", line 41, in wrapper
    return func(*args, **kwargs)
  File "/mounts/work/lyk/anaconda3/envs/torch2/lib/python3.8/site-packages/wandb/sdk/lib/retry.py", line 212, in wrapped_fn
    return retrier(*args, **kargs)
  File "/mounts/work/lyk/anaconda3/envs/torch2/lib/python3.8/site-packages/wandb/sdk/lib/retry.py", line 131, in __call__
    result = self._call_fn(*args, **kwargs)
  File "/mounts/work/lyk/anaconda3/envs/torch2/lib/python3.8/site-packages/wandb/sdk/internal/internal_api.py", line 2787, in upload_file
    wandb._sentry.reraise(e)
  File "/mounts/work/lyk/anaconda3/envs/torch2/lib/python3.8/site-packages/wandb/analytics/sentry.py", line 154, in reraise
    raise exc.with_traceback(sys.exc_info()[2])
  File "/mounts/work/lyk/anaconda3/envs/torch2/lib/python3.8/site-packages/wandb/sdk/internal/internal_api.py", line 2759, in upload_file
    response.raise_for_status()
  File "/mounts/work/lyk/anaconda3/envs/torch2/lib/python3.8/site-packages/requests/models.py", line 1021, in raise_for_status
    raise HTTPError(http_error_msg, response=self)
requests.exceptions.HTTPError: 403 Client Error: Forbidden for url: https://storage.googleapis.com/wandb-production.appspot.com/neuzxm/huggingface/2bmnu66o/conda-environment.yaml?Expires=1715688864&GoogleAccessId=gorilla-files-url-signer-man%40wandb-production.iam.gserviceaccount.com&Signature=OXzPRuKbSMjGTolhL0eqo8kizc1Sp7u8UFXH1o97dwC6X9ncmcwM5CAUyPRAGyxldjJxMdQBtneoPtvZyPSEHuVVFBvKe1VTGQvPOPqy1E93aNNtRNvH20LKfxaYQsEA7Sh%2Bm5HKlr2xBuXedRvFsj5BNBj2mq1n70gz0hMmDRTxzjOI39pciKqaUoDTahs7IQrJjZFjjS4EHriANU2yGXazBjtM3FaNRKCIZNhrPAiGasKxpN9e1Lwh5kjPMQl1PNL65Jvwg8T05mDM52sCsFpyD4l3fP%2FwbchqnTioEw2Q9odMyxNYqCLmpvOzBJtqh%2F1LnySRiv4MU7odjvAQVw%3D%3D

During handling of the above exception, another exception occurred:

Traceback (most recent call last):
  File "/mounts/work/lyk/anaconda3/envs/torch2/lib/python3.8/concurrent/futures/thread.py", line 57, in run
    result = self.fn(*self.args, **self.kwargs)
  File "/mounts/work/lyk/anaconda3/envs/torch2/lib/python3.8/site-packages/wandb/filesync/step_upload.py", line 288, in run_and_notify
    self._do_upload_sync(event)
  File "/mounts/work/lyk/anaconda3/envs/torch2/lib/python3.8/site-packages/wandb/filesync/step_upload.py", line 330, in _do_upload_sync
    job.run()
  File "/mounts/work/lyk/anaconda3/envs/torch2/lib/python3.8/site-packages/wandb/filesync/upload_job.py", line 57, in run
    self.push()
  File "/mounts/work/lyk/anaconda3/envs/torch2/lib/python3.8/site-packages/wandb/filesync/upload_job.py", line 125, in push
    self._api.upload_file_retry(
  File "/mounts/work/lyk/anaconda3/envs/torch2/lib/python3.8/site-packages/wandb/apis/normalize.py", line 51, in wrapper
    raise CommError(message, error)
wandb.errors.CommError: <Response [403]>
2024-05-13 14:14:24,885 ERROR   wandb-upload_4:521625 [upload_job.py:push():134] Failed to upload file: /nfs/datx/lyk/HiFT/wandb/run-20240513_141419-2bmnu66o/files/output.log
Traceback (most recent call last):
  File "/mounts/work/lyk/anaconda3/envs/torch2/lib/python3.8/site-packages/wandb/apis/normalize.py", line 41, in wrapper
    return func(*args, **kwargs)
  File "/mounts/work/lyk/anaconda3/envs/torch2/lib/python3.8/site-packages/wandb/sdk/lib/retry.py", line 212, in wrapped_fn
    return retrier(*args, **kargs)
  File "/mounts/work/lyk/anaconda3/envs/torch2/lib/python3.8/site-packages/wandb/sdk/lib/retry.py", line 131, in __call__
    result = self._call_fn(*args, **kwargs)
  File "/mounts/work/lyk/anaconda3/envs/torch2/lib/python3.8/site-packages/wandb/sdk/internal/internal_api.py", line 2787, in upload_file
    wandb._sentry.reraise(e)
  File "/mounts/work/lyk/anaconda3/envs/torch2/lib/python3.8/site-packages/wandb/analytics/sentry.py", line 154, in reraise
    raise exc.with_traceback(sys.exc_info()[2])
  File "/mounts/work/lyk/anaconda3/envs/torch2/lib/python3.8/site-packages/wandb/sdk/internal/internal_api.py", line 2759, in upload_file
    response.raise_for_status()
  File "/mounts/work/lyk/anaconda3/envs/torch2/lib/python3.8/site-packages/requests/models.py", line 1021, in raise_for_status
    raise HTTPError(http_error_msg, response=self)
requests.exceptions.HTTPError: 403 Client Error: Forbidden for url: https://storage.googleapis.com/wandb-production.appspot.com/neuzxm/huggingface/2bmnu66o/output.log?Expires=1715688864&GoogleAccessId=gorilla-files-url-signer-man%40wandb-production.iam.gserviceaccount.com&Signature=a2dnEhNi0f8z5OoQWtNtvB2vqoGG%2BNF5xyRAVMUHWaz%2B1KHXUUFMW9qwbS33RRYSRHFJW6V%2F3LeZ6w9d%2BaHKYakDHN6CPwXZFoYzIBy0%2Bb4cntyJNJ8PfE7BKmlpne6kNkswwPvUHh%2BLGWEWuYvqvkMVPD7TDwwI9AAzpuSv%2B6gfD5%2BfhtufFKXKnfnm%2F0SbsCQd7z%2FMM0Zx50gHzCtneThwWn%2FD97q8un3dHPQBhRyzRTBeaoSYDifBLguMDemNviG%2BvNUbmBwk9R0TNpqJOqNEEhs4w2l3zZT15AFWCBcdvzmXfYB%2B%2B7U19xx61THDGD3DmnEXy3WDlfM4dFkocA%3D%3D

During handling of the above exception, another exception occurred:

Traceback (most recent call last):
  File "/mounts/work/lyk/anaconda3/envs/torch2/lib/python3.8/site-packages/wandb/filesync/upload_job.py", line 125, in push
    self._api.upload_file_retry(
  File "/mounts/work/lyk/anaconda3/envs/torch2/lib/python3.8/site-packages/wandb/apis/normalize.py", line 51, in wrapper
    raise CommError(message, error)
wandb.errors.CommError: <Response [403]>
2024-05-13 14:14:24,885 ERROR   wandb-upload_1:521625 [upload_job.py:push():134] Failed to upload file: /nfs/datx/lyk/HiFT/wandb/run-20240513_141419-2bmnu66o/files/requirements.txt
Traceback (most recent call last):
  File "/mounts/work/lyk/anaconda3/envs/torch2/lib/python3.8/site-packages/wandb/apis/normalize.py", line 41, in wrapper
    return func(*args, **kwargs)
  File "/mounts/work/lyk/anaconda3/envs/torch2/lib/python3.8/site-packages/wandb/sdk/lib/retry.py", line 212, in wrapped_fn
    return retrier(*args, **kargs)
  File "/mounts/work/lyk/anaconda3/envs/torch2/lib/python3.8/site-packages/wandb/sdk/lib/retry.py", line 131, in __call__
    result = self._call_fn(*args, **kwargs)
  File "/mounts/work/lyk/anaconda3/envs/torch2/lib/python3.8/site-packages/wandb/sdk/internal/internal_api.py", line 2787, in upload_file
    wandb._sentry.reraise(e)
  File "/mounts/work/lyk/anaconda3/envs/torch2/lib/python3.8/site-packages/wandb/analytics/sentry.py", line 154, in reraise
    raise exc.with_traceback(sys.exc_info()[2])
  File "/mounts/work/lyk/anaconda3/envs/torch2/lib/python3.8/site-packages/wandb/sdk/internal/internal_api.py", line 2759, in upload_file
    response.raise_for_status()
  File "/mounts/work/lyk/anaconda3/envs/torch2/lib/python3.8/site-packages/requests/models.py", line 1021, in raise_for_status
    raise HTTPError(http_error_msg, response=self)
requests.exceptions.HTTPError: 403 Client Error: Forbidden for url: https://storage.googleapis.com/wandb-production.appspot.com/neuzxm/huggingface/2bmnu66o/requirements.txt?Expires=1715688864&GoogleAccessId=gorilla-files-url-signer-man%40wandb-production.iam.gserviceaccount.com&Signature=LlEle9nfqKZ8wJAIGYKkXQpPdKAM2Q9jfv1VB8lONlY8IhKvO4VHPY6BrY67rkdO7qTMCG69ENRkyumevnn%2FnxfRDGCbh0SRwDapTkm9L14BRc4%2F%2F%2BDDXfQ2AT4nEqXcFhYOr5n5Gh%2FRWwCeoqw40Vr2CS%2Fb5ynAxTmQ3KSA3qRyaEZJEhFMYe5jJm6JpsUhrY3W2e%2F%2BV61Uf6sjBM66bCbFEZiTIb7SzEBv4wh9DZ%2FMKkp7RaeWI1rMJcyDGY8Z%2B0l3Fo07uUmqrkft%2FAUQf9Q3nYDGvwlyVG2p0684%2BFE%2Bf%2Fj%2Fy9eToXMyodfvxPFVhVoCAKwBqZDR%2F%2BDi5AzNHA%3D%3D

During handling of the above exception, another exception occurred:

Traceback (most recent call last):
  File "/mounts/work/lyk/anaconda3/envs/torch2/lib/python3.8/site-packages/wandb/filesync/upload_job.py", line 125, in push
    self._api.upload_file_retry(
  File "/mounts/work/lyk/anaconda3/envs/torch2/lib/python3.8/site-packages/wandb/apis/normalize.py", line 51, in wrapper
    raise CommError(message, error)
wandb.errors.CommError: <Response [403]>
2024-05-13 14:14:24,885 ERROR   wandb-upload_3:521625 [upload_job.py:push():134] Failed to upload file: /nfs/datx/lyk/HiFT/wandb/run-20240513_141419-2bmnu66o/files/config.yaml
Traceback (most recent call last):
  File "/mounts/work/lyk/anaconda3/envs/torch2/lib/python3.8/site-packages/wandb/apis/normalize.py", line 41, in wrapper
    return func(*args, **kwargs)
  File "/mounts/work/lyk/anaconda3/envs/torch2/lib/python3.8/site-packages/wandb/sdk/lib/retry.py", line 212, in wrapped_fn
    return retrier(*args, **kargs)
  File "/mounts/work/lyk/anaconda3/envs/torch2/lib/python3.8/site-packages/wandb/sdk/lib/retry.py", line 131, in __call__
    result = self._call_fn(*args, **kwargs)
  File "/mounts/work/lyk/anaconda3/envs/torch2/lib/python3.8/site-packages/wandb/sdk/internal/internal_api.py", line 2787, in upload_file
    wandb._sentry.reraise(e)
  File "/mounts/work/lyk/anaconda3/envs/torch2/lib/python3.8/site-packages/wandb/analytics/sentry.py", line 154, in reraise
    raise exc.with_traceback(sys.exc_info()[2])
  File "/mounts/work/lyk/anaconda3/envs/torch2/lib/python3.8/site-packages/wandb/sdk/internal/internal_api.py", line 2759, in upload_file
    response.raise_for_status()
  File "/mounts/work/lyk/anaconda3/envs/torch2/lib/python3.8/site-packages/requests/models.py", line 1021, in raise_for_status
    raise HTTPError(http_error_msg, response=self)
requests.exceptions.HTTPError: 403 Client Error: Forbidden for url: https://storage.googleapis.com/wandb-production.appspot.com/neuzxm/huggingface/2bmnu66o/config.yaml?Expires=1715688864&GoogleAccessId=gorilla-files-url-signer-man%40wandb-production.iam.gserviceaccount.com&Signature=QuqiRF19h%2FY6gZgU%2F3ki%2FtuZYvHJCOXNFnCGYhK3SCwUwO3Jxx7uJ3wm9bCoL1ejnRgWvH3k%2FOnZEOc5n%2BwPk%2BxUR8VozoObXN59L8s6NWZanXxiw3xHo9yTM%2FiHXQlHDtcT0Iw3OGdR50kA8e0zhQ5240UAy1aPjjrZMzc81EYQq7vVPkpX7JpKyPk%2BEqA7Q5aflua90ZFxaLa1y8i8BqtPcRlD0sEfObKqc%2B7DCOu16X6Y7A9ORK9Da6BrU5Ux7nO4aG8VZJ2AC8j6xzjvp%2BDOR9TUNGTHAyoW5rK7Xf2n%2F3I7IJm7IzHTEtmMUAxk8N9vDVQmhCIP3sWpdbG0WQ%3D%3D

During handling of the above exception, another exception occurred:

Traceback (most recent call last):
  File "/mounts/work/lyk/anaconda3/envs/torch2/lib/python3.8/site-packages/wandb/filesync/upload_job.py", line 125, in push
    self._api.upload_file_retry(
  File "/mounts/work/lyk/anaconda3/envs/torch2/lib/python3.8/site-packages/wandb/apis/normalize.py", line 51, in wrapper
    raise CommError(message, error)
wandb.errors.CommError: <Response [403]>
2024-05-13 14:14:24,937 ERROR   Thread-11 :521625 [step_upload.py:_handle_event():200] Failed to upload file: /nfs/datx/lyk/HiFT/wandb/run-20240513_141419-2bmnu66o/files/output.log
Traceback (most recent call last):
  File "/mounts/work/lyk/anaconda3/envs/torch2/lib/python3.8/site-packages/wandb/apis/normalize.py", line 41, in wrapper
    return func(*args, **kwargs)
  File "/mounts/work/lyk/anaconda3/envs/torch2/lib/python3.8/site-packages/wandb/sdk/lib/retry.py", line 212, in wrapped_fn
    return retrier(*args, **kargs)
  File "/mounts/work/lyk/anaconda3/envs/torch2/lib/python3.8/site-packages/wandb/sdk/lib/retry.py", line 131, in __call__
    result = self._call_fn(*args, **kwargs)
  File "/mounts/work/lyk/anaconda3/envs/torch2/lib/python3.8/site-packages/wandb/sdk/internal/internal_api.py", line 2787, in upload_file
    wandb._sentry.reraise(e)
  File "/mounts/work/lyk/anaconda3/envs/torch2/lib/python3.8/site-packages/wandb/analytics/sentry.py", line 154, in reraise
    raise exc.with_traceback(sys.exc_info()[2])
  File "/mounts/work/lyk/anaconda3/envs/torch2/lib/python3.8/site-packages/wandb/sdk/internal/internal_api.py", line 2759, in upload_file
    response.raise_for_status()
  File "/mounts/work/lyk/anaconda3/envs/torch2/lib/python3.8/site-packages/requests/models.py", line 1021, in raise_for_status
    raise HTTPError(http_error_msg, response=self)
requests.exceptions.HTTPError: 403 Client Error: Forbidden for url: https://storage.googleapis.com/wandb-production.appspot.com/neuzxm/huggingface/2bmnu66o/output.log?Expires=1715688864&GoogleAccessId=gorilla-files-url-signer-man%40wandb-production.iam.gserviceaccount.com&Signature=a2dnEhNi0f8z5OoQWtNtvB2vqoGG%2BNF5xyRAVMUHWaz%2B1KHXUUFMW9qwbS33RRYSRHFJW6V%2F3LeZ6w9d%2BaHKYakDHN6CPwXZFoYzIBy0%2Bb4cntyJNJ8PfE7BKmlpne6kNkswwPvUHh%2BLGWEWuYvqvkMVPD7TDwwI9AAzpuSv%2B6gfD5%2BfhtufFKXKnfnm%2F0SbsCQd7z%2FMM0Zx50gHzCtneThwWn%2FD97q8un3dHPQBhRyzRTBeaoSYDifBLguMDemNviG%2BvNUbmBwk9R0TNpqJOqNEEhs4w2l3zZT15AFWCBcdvzmXfYB%2B%2B7U19xx61THDGD3DmnEXy3WDlfM4dFkocA%3D%3D

During handling of the above exception, another exception occurred:

Traceback (most recent call last):
  File "/mounts/work/lyk/anaconda3/envs/torch2/lib/python3.8/concurrent/futures/thread.py", line 57, in run
    result = self.fn(*self.args, **self.kwargs)
  File "/mounts/work/lyk/anaconda3/envs/torch2/lib/python3.8/site-packages/wandb/filesync/step_upload.py", line 288, in run_and_notify
    self._do_upload_sync(event)
  File "/mounts/work/lyk/anaconda3/envs/torch2/lib/python3.8/site-packages/wandb/filesync/step_upload.py", line 330, in _do_upload_sync
    job.run()
  File "/mounts/work/lyk/anaconda3/envs/torch2/lib/python3.8/site-packages/wandb/filesync/upload_job.py", line 57, in run
    self.push()
  File "/mounts/work/lyk/anaconda3/envs/torch2/lib/python3.8/site-packages/wandb/filesync/upload_job.py", line 125, in push
    self._api.upload_file_retry(
  File "/mounts/work/lyk/anaconda3/envs/torch2/lib/python3.8/site-packages/wandb/apis/normalize.py", line 51, in wrapper
    raise CommError(message, error)
wandb.errors.CommError: <Response [403]>
2024-05-13 14:14:24,937 ERROR   Thread-11 :521625 [step_upload.py:_handle_event():200] Failed to upload file: /nfs/datx/lyk/HiFT/wandb/run-20240513_141419-2bmnu66o/files/requirements.txt
Traceback (most recent call last):
  File "/mounts/work/lyk/anaconda3/envs/torch2/lib/python3.8/site-packages/wandb/apis/normalize.py", line 41, in wrapper
    return func(*args, **kwargs)
  File "/mounts/work/lyk/anaconda3/envs/torch2/lib/python3.8/site-packages/wandb/sdk/lib/retry.py", line 212, in wrapped_fn
    return retrier(*args, **kargs)
  File "/mounts/work/lyk/anaconda3/envs/torch2/lib/python3.8/site-packages/wandb/sdk/lib/retry.py", line 131, in __call__
    result = self._call_fn(*args, **kwargs)
  File "/mounts/work/lyk/anaconda3/envs/torch2/lib/python3.8/site-packages/wandb/sdk/internal/internal_api.py", line 2787, in upload_file
    wandb._sentry.reraise(e)
  File "/mounts/work/lyk/anaconda3/envs/torch2/lib/python3.8/site-packages/wandb/analytics/sentry.py", line 154, in reraise
    raise exc.with_traceback(sys.exc_info()[2])
  File "/mounts/work/lyk/anaconda3/envs/torch2/lib/python3.8/site-packages/wandb/sdk/internal/internal_api.py", line 2759, in upload_file
    response.raise_for_status()
  File "/mounts/work/lyk/anaconda3/envs/torch2/lib/python3.8/site-packages/requests/models.py", line 1021, in raise_for_status
    raise HTTPError(http_error_msg, response=self)
requests.exceptions.HTTPError: 403 Client Error: Forbidden for url: https://storage.googleapis.com/wandb-production.appspot.com/neuzxm/huggingface/2bmnu66o/requirements.txt?Expires=1715688864&GoogleAccessId=gorilla-files-url-signer-man%40wandb-production.iam.gserviceaccount.com&Signature=LlEle9nfqKZ8wJAIGYKkXQpPdKAM2Q9jfv1VB8lONlY8IhKvO4VHPY6BrY67rkdO7qTMCG69ENRkyumevnn%2FnxfRDGCbh0SRwDapTkm9L14BRc4%2F%2F%2BDDXfQ2AT4nEqXcFhYOr5n5Gh%2FRWwCeoqw40Vr2CS%2Fb5ynAxTmQ3KSA3qRyaEZJEhFMYe5jJm6JpsUhrY3W2e%2F%2BV61Uf6sjBM66bCbFEZiTIb7SzEBv4wh9DZ%2FMKkp7RaeWI1rMJcyDGY8Z%2B0l3Fo07uUmqrkft%2FAUQf9Q3nYDGvwlyVG2p0684%2BFE%2Bf%2Fj%2Fy9eToXMyodfvxPFVhVoCAKwBqZDR%2F%2BDi5AzNHA%3D%3D

During handling of the above exception, another exception occurred:

Traceback (most recent call last):
  File "/mounts/work/lyk/anaconda3/envs/torch2/lib/python3.8/concurrent/futures/thread.py", line 57, in run
    result = self.fn(*self.args, **self.kwargs)
  File "/mounts/work/lyk/anaconda3/envs/torch2/lib/python3.8/site-packages/wandb/filesync/step_upload.py", line 288, in run_and_notify
    self._do_upload_sync(event)
  File "/mounts/work/lyk/anaconda3/envs/torch2/lib/python3.8/site-packages/wandb/filesync/step_upload.py", line 330, in _do_upload_sync
    job.run()
  File "/mounts/work/lyk/anaconda3/envs/torch2/lib/python3.8/site-packages/wandb/filesync/upload_job.py", line 57, in run
    self.push()
  File "/mounts/work/lyk/anaconda3/envs/torch2/lib/python3.8/site-packages/wandb/filesync/upload_job.py", line 125, in push
    self._api.upload_file_retry(
  File "/mounts/work/lyk/anaconda3/envs/torch2/lib/python3.8/site-packages/wandb/apis/normalize.py", line 51, in wrapper
    raise CommError(message, error)
wandb.errors.CommError: <Response [403]>
2024-05-13 14:14:24,938 ERROR   Thread-11 :521625 [step_upload.py:_handle_event():200] Failed to upload file: /nfs/datx/lyk/HiFT/wandb/run-20240513_141419-2bmnu66o/files/config.yaml
Traceback (most recent call last):
  File "/mounts/work/lyk/anaconda3/envs/torch2/lib/python3.8/site-packages/wandb/apis/normalize.py", line 41, in wrapper
    return func(*args, **kwargs)
  File "/mounts/work/lyk/anaconda3/envs/torch2/lib/python3.8/site-packages/wandb/sdk/lib/retry.py", line 212, in wrapped_fn
    return retrier(*args, **kargs)
  File "/mounts/work/lyk/anaconda3/envs/torch2/lib/python3.8/site-packages/wandb/sdk/lib/retry.py", line 131, in __call__
    result = self._call_fn(*args, **kwargs)
  File "/mounts/work/lyk/anaconda3/envs/torch2/lib/python3.8/site-packages/wandb/sdk/internal/internal_api.py", line 2787, in upload_file
    wandb._sentry.reraise(e)
  File "/mounts/work/lyk/anaconda3/envs/torch2/lib/python3.8/site-packages/wandb/analytics/sentry.py", line 154, in reraise
    raise exc.with_traceback(sys.exc_info()[2])
  File "/mounts/work/lyk/anaconda3/envs/torch2/lib/python3.8/site-packages/wandb/sdk/internal/internal_api.py", line 2759, in upload_file
    response.raise_for_status()
  File "/mounts/work/lyk/anaconda3/envs/torch2/lib/python3.8/site-packages/requests/models.py", line 1021, in raise_for_status
    raise HTTPError(http_error_msg, response=self)
requests.exceptions.HTTPError: 403 Client Error: Forbidden for url: https://storage.googleapis.com/wandb-production.appspot.com/neuzxm/huggingface/2bmnu66o/config.yaml?Expires=1715688864&GoogleAccessId=gorilla-files-url-signer-man%40wandb-production.iam.gserviceaccount.com&Signature=QuqiRF19h%2FY6gZgU%2F3ki%2FtuZYvHJCOXNFnCGYhK3SCwUwO3Jxx7uJ3wm9bCoL1ejnRgWvH3k%2FOnZEOc5n%2BwPk%2BxUR8VozoObXN59L8s6NWZanXxiw3xHo9yTM%2FiHXQlHDtcT0Iw3OGdR50kA8e0zhQ5240UAy1aPjjrZMzc81EYQq7vVPkpX7JpKyPk%2BEqA7Q5aflua90ZFxaLa1y8i8BqtPcRlD0sEfObKqc%2B7DCOu16X6Y7A9ORK9Da6BrU5Ux7nO4aG8VZJ2AC8j6xzjvp%2BDOR9TUNGTHAyoW5rK7Xf2n%2F3I7IJm7IzHTEtmMUAxk8N9vDVQmhCIP3sWpdbG0WQ%3D%3D

During handling of the above exception, another exception occurred:

Traceback (most recent call last):
  File "/mounts/work/lyk/anaconda3/envs/torch2/lib/python3.8/concurrent/futures/thread.py", line 57, in run
    result = self.fn(*self.args, **self.kwargs)
  File "/mounts/work/lyk/anaconda3/envs/torch2/lib/python3.8/site-packages/wandb/filesync/step_upload.py", line 288, in run_and_notify
    self._do_upload_sync(event)
  File "/mounts/work/lyk/anaconda3/envs/torch2/lib/python3.8/site-packages/wandb/filesync/step_upload.py", line 330, in _do_upload_sync
    job.run()
  File "/mounts/work/lyk/anaconda3/envs/torch2/lib/python3.8/site-packages/wandb/filesync/upload_job.py", line 57, in run
    self.push()
  File "/mounts/work/lyk/anaconda3/envs/torch2/lib/python3.8/site-packages/wandb/filesync/upload_job.py", line 125, in push
    self._api.upload_file_retry(
  File "/mounts/work/lyk/anaconda3/envs/torch2/lib/python3.8/site-packages/wandb/apis/normalize.py", line 51, in wrapper
    raise CommError(message, error)
wandb.errors.CommError: <Response [403]>
2024-05-13 14:14:25,138 INFO    Thread-11 :521625 [sender.py:transition_state():617] send defer: 11
2024-05-13 14:14:25,139 DEBUG   HandlerThread:521625 [handler.py:handle_request():146] handle_request: defer
2024-05-13 14:14:25,139 INFO    HandlerThread:521625 [handler.py:handle_request_defer():172] handle defer: 11
2024-05-13 14:14:25,139 DEBUG   SenderThread:521625 [sender.py:send_request():409] send_request: defer
2024-05-13 14:14:25,140 INFO    SenderThread:521625 [sender.py:send_request_defer():613] handle sender defer: 11
2024-05-13 14:14:25,140 INFO    SenderThread:521625 [file_pusher.py:join():181] waiting for file pusher
2024-05-13 14:14:25,140 INFO    SenderThread:521625 [sender.py:transition_state():617] send defer: 12
2024-05-13 14:14:25,140 DEBUG   HandlerThread:521625 [handler.py:handle_request():146] handle_request: defer
2024-05-13 14:14:25,140 INFO    HandlerThread:521625 [handler.py:handle_request_defer():172] handle defer: 12
2024-05-13 14:14:25,141 DEBUG   SenderThread:521625 [sender.py:send_request():409] send_request: defer
2024-05-13 14:14:25,141 INFO    SenderThread:521625 [sender.py:send_request_defer():613] handle sender defer: 12
2024-05-13 14:14:25,141 INFO    SenderThread:521625 [file_stream.py:finish():595] file stream finish called
2024-05-13 14:14:25,260 DEBUG   HandlerThread:521625 [handler.py:handle_request():146] handle_request: poll_exit
2024-05-13 14:14:25,442 INFO    SenderThread:521625 [file_stream.py:finish():599] file stream finish is done
2024-05-13 14:14:25,442 INFO    SenderThread:521625 [sender.py:transition_state():617] send defer: 13
2024-05-13 14:14:25,442 DEBUG   SenderThread:521625 [sender.py:send_request():409] send_request: poll_exit
2024-05-13 14:14:25,443 DEBUG   HandlerThread:521625 [handler.py:handle_request():146] handle_request: defer
2024-05-13 14:14:25,443 INFO    HandlerThread:521625 [handler.py:handle_request_defer():172] handle defer: 13
2024-05-13 14:14:25,443 DEBUG   SenderThread:521625 [sender.py:send_request():409] send_request: defer
2024-05-13 14:14:25,443 INFO    SenderThread:521625 [sender.py:send_request_defer():613] handle sender defer: 13
2024-05-13 14:14:25,443 INFO    SenderThread:521625 [sender.py:transition_state():617] send defer: 14
2024-05-13 14:14:25,444 DEBUG   HandlerThread:521625 [handler.py:handle_request():146] handle_request: defer
2024-05-13 14:14:25,444 INFO    HandlerThread:521625 [handler.py:handle_request_defer():172] handle defer: 14
2024-05-13 14:14:25,444 DEBUG   SenderThread:521625 [sender.py:send():382] send: final
2024-05-13 14:14:25,445 DEBUG   SenderThread:521625 [sender.py:send():382] send: footer
2024-05-13 14:14:25,445 DEBUG   SenderThread:521625 [sender.py:send_request():409] send_request: defer
2024-05-13 14:14:25,445 INFO    SenderThread:521625 [sender.py:send_request_defer():613] handle sender defer: 14
2024-05-13 14:14:25,446 DEBUG   HandlerThread:521625 [handler.py:handle_request():146] handle_request: poll_exit
2024-05-13 14:14:25,446 DEBUG   HandlerThread:521625 [handler.py:handle_request():146] handle_request: poll_exit
2024-05-13 14:14:25,447 DEBUG   SenderThread:521625 [sender.py:send_request():409] send_request: poll_exit
2024-05-13 14:14:25,447 DEBUG   SenderThread:521625 [sender.py:send_request():409] send_request: poll_exit
2024-05-13 14:14:25,447 DEBUG   HandlerThread:521625 [handler.py:handle_request():146] handle_request: server_info
2024-05-13 14:14:25,448 DEBUG   SenderThread:521625 [sender.py:send_request():409] send_request: server_info
2024-05-13 14:14:25,451 DEBUG   HandlerThread:521625 [handler.py:handle_request():146] handle_request: get_summary
2024-05-13 14:14:25,452 DEBUG   HandlerThread:521625 [handler.py:handle_request():146] handle_request: sampled_history
2024-05-13 14:14:25,452 DEBUG   HandlerThread:521625 [handler.py:handle_request():146] handle_request: internal_messages
2024-05-13 14:14:25,453 DEBUG   HandlerThread:521625 [handler.py:handle_request():146] handle_request: job_info
2024-05-13 14:14:25,584 DEBUG   SenderThread:521625 [sender.py:send_request():409] send_request: job_info
2024-05-13 14:14:25,584 INFO    MainThread:521625 [wandb_run.py:_footer_history_summary_info():3837] rendering history
2024-05-13 14:14:25,585 INFO    MainThread:521625 [wandb_run.py:_footer_history_summary_info():3869] rendering summary
2024-05-13 14:14:25,585 INFO    MainThread:521625 [wandb_run.py:_footer_sync_info():3796] logging synced files
2024-05-13 14:14:25,585 DEBUG   HandlerThread:521625 [handler.py:handle_request():146] handle_request: shutdown
2024-05-13 14:14:25,586 INFO    HandlerThread:521625 [handler.py:finish():866] shutting down handler
2024-05-13 14:14:26,453 INFO    WriterThread:521625 [datastore.py:close():294] close: /nfs/datx/lyk/HiFT/wandb/run-20240513_141419-2bmnu66o/run-2bmnu66o.wandb
2024-05-13 14:14:26,584 INFO    SenderThread:521625 [sender.py:finish():1548] shutting down sender
2024-05-13 14:14:26,584 INFO    SenderThread:521625 [file_pusher.py:finish():175] shutting down file pusher
2024-05-13 14:14:26,585 INFO    SenderThread:521625 [file_pusher.py:join():181] waiting for file pusher
