2024-05-13 22:40:21,045 INFO    StreamThr :2329230 [internal.py:wandb_internal():86] W&B internal server running at pid: 2329230, started at: 2024-05-13 22:40:21.044803
2024-05-13 22:40:21,047 DEBUG   HandlerThread:2329230 [handler.py:handle_request():146] handle_request: status
2024-05-13 22:40:21,051 INFO    WriterThread:2329230 [datastore.py:open_for_write():85] open: /nfs/datx/lyk/HiFT/wandb/run-20240513_224021-4xcljpov/run-4xcljpov.wandb
2024-05-13 22:40:21,052 DEBUG   SenderThread:2329230 [sender.py:send():382] send: header
2024-05-13 22:40:21,052 DEBUG   SenderThread:2329230 [sender.py:send():382] send: run
2024-05-13 22:40:21,456 INFO    SenderThread:2329230 [dir_watcher.py:__init__():211] watching files in: /nfs/datx/lyk/HiFT/wandb/run-20240513_224021-4xcljpov/files
2024-05-13 22:40:21,456 INFO    SenderThread:2329230 [sender.py:_start_run_threads():1136] run started: 4xcljpov with start time 1715632821.047112
2024-05-13 22:40:21,467 DEBUG   HandlerThread:2329230 [handler.py:handle_request():146] handle_request: check_version
2024-05-13 22:40:21,468 DEBUG   SenderThread:2329230 [sender.py:send_request():409] send_request: check_version
2024-05-13 22:40:21,542 DEBUG   HandlerThread:2329230 [handler.py:handle_request():146] handle_request: run_start
2024-05-13 22:40:21,569 DEBUG   HandlerThread:2329230 [system_info.py:__init__():32] System info init
2024-05-13 22:40:21,569 DEBUG   HandlerThread:2329230 [system_info.py:__init__():47] System info init done
2024-05-13 22:40:21,570 INFO    HandlerThread:2329230 [system_monitor.py:start():194] Starting system monitor
2024-05-13 22:40:21,570 INFO    SystemMonitor:2329230 [system_monitor.py:_start():158] Starting system asset monitoring threads
2024-05-13 22:40:21,571 INFO    HandlerThread:2329230 [system_monitor.py:probe():214] Collecting system info
2024-05-13 22:40:21,573 INFO    SystemMonitor:2329230 [interfaces.py:start():190] Started cpu monitoring
2024-05-13 22:40:21,574 INFO    SystemMonitor:2329230 [interfaces.py:start():190] Started disk monitoring
2024-05-13 22:40:21,575 INFO    SystemMonitor:2329230 [interfaces.py:start():190] Started gpu monitoring
2024-05-13 22:40:21,575 INFO    SystemMonitor:2329230 [interfaces.py:start():190] Started memory monitoring
2024-05-13 22:40:21,576 INFO    SystemMonitor:2329230 [interfaces.py:start():190] Started network monitoring
2024-05-13 22:40:21,661 DEBUG   HandlerThread:2329230 [system_info.py:probe():196] Probing system
2024-05-13 22:40:21,669 DEBUG   HandlerThread:2329230 [gitlib.py:_init_repo():56] git repository is invalid
2024-05-13 22:40:21,669 DEBUG   HandlerThread:2329230 [system_info.py:probe():244] Probing system done
2024-05-13 22:40:21,670 DEBUG   HandlerThread:2329230 [system_monitor.py:probe():223] {'os': 'Linux-5.15.0-97-generic-x86_64-with-glibc2.10', 'python': '3.8.5', 'heartbeatAt': '2024-05-13T20:40:21.661796', 'startedAt': '2024-05-13T20:40:21.004586', 'docker': None, 'cuda': None, 'args': ('--model_type', 'llama', '--HiTaskType', 'CAUSAL_LM', '--optim', 'lamb_32bit', '--deepspeed', 'dsconfig/zero0_config.json', '--model_name_or_path', '/mounts/work/lyk/hierFT/llama2-7b', '--dataset_dir', 'data/alpaca_data', '--validation_split_percentage', '0.01', '--per_device_train_batch_size', '8', '--per_device_eval_batch_size', '8', '--do_train', '--do_eval', '--seed', '12345', '--fp16', '--num_train_epochs', '1', '--lr_scheduler_type', 'cosine', '--learning_rate', '2e-5', '--warmup_ratio', '0', '--weight_decay', '0', '--logging_strategy', 'steps', '--logging_steps', '10', '--save_strategy', 'steps', '--save_total_limit', '3', '--evaluation_strategy', 'steps', '--eval_steps', '100', '--save_steps', '200', '--preprocessing_num_workers', '4', '--max_seq_length', '512', '--output_dir', 'outputs/instruct_tuning/model', '--overwrite_output_dir', '--logging_first_step', 'True', '--lora_rank', '8', '--torch_dtype', 'float16', '--ddp_find_unused_parameters', 'False', '--load_best_model_at_end', '--hier_tuning', '--group_element', '1', '--optimizer_strategy', 'down2up'), 'state': 'running', 'program': 'examples/instruct_tuning.py', 'codePathLocal': 'examples/instruct_tuning.py', 'codePath': 'examples/instruct_tuning.py', 'host': 'rho2', 'username': 'yongkang', 'executable': '/mounts/work/lyk/anaconda3/envs/torch2/bin/python', 'cpu_count': 32, 'cpu_count_logical': 64, 'cpu_freq': {'current': 2187.517734375, 'min': 1500.0, 'max': 3000.0}, 'cpu_freq_per_core': [{'current': 1500.0, 'min': 1500.0, 'max': 3000.0}, {'current': 1500.0, 'min': 1500.0, 'max': 3000.0}, {'current': 1500.0, 'min': 1500.0, 'max': 3000.0}, {'current': 1500.0, 'min': 1500.0, 'max': 3000.0}, {'current': 1500.0, 'min': 1500.0, 'max': 3000.0}, {'current': 1500.0, 'min': 1500.0, 'max': 3000.0}, {'current': 1500.0, 'min': 1500.0, 'max': 3000.0}, {'current': 3000.0, 'min': 1500.0, 'max': 3000.0}, {'current': 3675.676, 'min': 1500.0, 'max': 3000.0}, {'current': 1500.0, 'min': 1500.0, 'max': 3000.0}, {'current': 1500.0, 'min': 1500.0, 'max': 3000.0}, {'current': 3474.674, 'min': 1500.0, 'max': 3000.0}, {'current': 1500.0, 'min': 1500.0, 'max': 3000.0}, {'current': 1500.0, 'min': 1500.0, 'max': 3000.0}, {'current': 3000.0, 'min': 1500.0, 'max': 3000.0}, {'current': 1500.0, 'min': 1500.0, 'max': 3000.0}, {'current': 1500.0, 'min': 1500.0, 'max': 3000.0}, {'current': 3000.0, 'min': 1500.0, 'max': 3000.0}, {'current': 1500.0, 'min': 1500.0, 'max': 3000.0}, {'current': 1500.0, 'min': 1500.0, 'max': 3000.0}, {'current': 1500.0, 'min': 1500.0, 'max': 3000.0}, {'current': 1500.0, 'min': 1500.0, 'max': 3000.0}, {'current': 1500.0, 'min': 1500.0, 'max': 3000.0}, {'current': 1500.0, 'min': 1500.0, 'max': 3000.0}, {'current': 1500.0, 'min': 1500.0, 'max': 3000.0}, {'current': 1500.0, 'min': 1500.0, 'max': 3000.0}, {'current': 1500.0, 'min': 1500.0, 'max': 3000.0}, {'current': 3699.859, 'min': 1500.0, 'max': 3000.0}, {'current': 1500.0, 'min': 1500.0, 'max': 3000.0}, {'current': 1500.0, 'min': 1500.0, 'max': 3000.0}, {'current': 1500.0, 'min': 1500.0, 'max': 3000.0}, {'current': 3000.0, 'min': 1500.0, 'max': 3000.0}, {'current': 3675.432, 'min': 1500.0, 'max': 3000.0}, {'current': 1500.0, 'min': 1500.0, 'max': 3000.0}, {'current': 1500.0, 'min': 1500.0, 'max': 3000.0}, {'current': 1500.0, 'min': 1500.0, 'max': 3000.0}, {'current': 1500.0, 'min': 1500.0, 'max': 3000.0}, {'current': 2958.806, 'min': 1500.0, 'max': 3000.0}, {'current': 2200.0, 'min': 1500.0, 'max': 3000.0}, {'current': 3675.33, 'min': 1500.0, 'max': 3000.0}, {'current': 1500.0, 'min': 1500.0, 'max': 3000.0}, {'current': 1500.0, 'min': 1500.0, 'max': 3000.0}, {'current': 1500.0, 'min': 1500.0, 'max': 3000.0}, {'current': 3000.0, 'min': 1500.0, 'max': 3000.0}, {'current': 1500.0, 'min': 1500.0, 'max': 3000.0}, {'current': 1500.0, 'min': 1500.0, 'max': 3000.0}, {'current': 3675.552, 'min': 1500.0, 'max': 3000.0}, {'current': 1500.0, 'min': 1500.0, 'max': 3000.0}, {'current': 1500.0, 'min': 1500.0, 'max': 3000.0}, {'current': 3700.1, 'min': 1500.0, 'max': 3000.0}, {'current': 1500.0, 'min': 1500.0, 'max': 3000.0}, {'current': 1500.0, 'min': 1500.0, 'max': 3000.0}, {'current': 3700.222, 'min': 1500.0, 'max': 3000.0}, {'current': 3000.0, 'min': 1500.0, 'max': 3000.0}, {'current': 1500.0, 'min': 1500.0, 'max': 3000.0}, {'current': 1500.0, 'min': 1500.0, 'max': 3000.0}, {'current': 1500.0, 'min': 1500.0, 'max': 3000.0}, {'current': 1500.0, 'min': 1500.0, 'max': 3000.0}, {'current': 1500.0, 'min': 1500.0, 'max': 3000.0}, {'current': 1500.0, 'min': 1500.0, 'max': 3000.0}, {'current': 3699.667, 'min': 1500.0, 'max': 3000.0}, {'current': 3000.0, 'min': 1500.0, 'max': 3000.0}, {'current': 1500.0, 'min': 1500.0, 'max': 3000.0}, {'current': 3000.0, 'min': 1500.0, 'max': 3000.0}], 'disk': {'/': {'total': 878.1072120666504, 'used': 56.610557556152344}}, 'gpu': 'NVIDIA RTX A6000', 'gpu_count': 8, 'gpu_devices': [{'name': 'NVIDIA RTX A6000', 'memory_total': 51527024640}, {'name': 'NVIDIA RTX A6000', 'memory_total': 51527024640}, {'name': 'NVIDIA RTX A6000', 'memory_total': 51527024640}, {'name': 'NVIDIA RTX A6000', 'memory_total': 51527024640}, {'name': 'NVIDIA RTX A6000', 'memory_total': 51527024640}, {'name': 'NVIDIA RTX A6000', 'memory_total': 51527024640}, {'name': 'NVIDIA RTX A6000', 'memory_total': 51527024640}, {'name': 'NVIDIA RTX A6000', 'memory_total': 51527024640}], 'memory': {'total': 251.7312126159668}}
2024-05-13 22:40:21,670 INFO    HandlerThread:2329230 [system_monitor.py:probe():224] Finished collecting system info
2024-05-13 22:40:21,670 INFO    HandlerThread:2329230 [system_monitor.py:probe():227] Publishing system info
2024-05-13 22:40:21,670 DEBUG   HandlerThread:2329230 [system_info.py:_save_pip():52] Saving list of pip packages installed into the current environment
2024-05-13 22:40:21,672 DEBUG   HandlerThread:2329230 [system_info.py:_save_pip():68] Saving pip packages done
2024-05-13 22:40:21,672 DEBUG   HandlerThread:2329230 [system_info.py:_save_conda():75] Saving list of conda packages installed into the current environment
2024-05-13 22:40:22,459 INFO    Thread-12 :2329230 [dir_watcher.py:_on_file_created():271] file/dir created: /nfs/datx/lyk/HiFT/wandb/run-20240513_224021-4xcljpov/files/requirements.txt
2024-05-13 22:40:22,459 INFO    Thread-12 :2329230 [dir_watcher.py:_on_file_created():271] file/dir created: /nfs/datx/lyk/HiFT/wandb/run-20240513_224021-4xcljpov/files/conda-environment.yaml
2024-05-13 22:40:25,221 DEBUG   HandlerThread:2329230 [system_info.py:_save_conda():87] Saving conda packages done
2024-05-13 22:40:25,224 INFO    HandlerThread:2329230 [system_monitor.py:probe():229] Finished publishing system info
2024-05-13 22:40:25,237 DEBUG   SenderThread:2329230 [sender.py:send():382] send: files
2024-05-13 22:40:25,237 INFO    SenderThread:2329230 [sender.py:_save_file():1392] saving file wandb-metadata.json with policy now
2024-05-13 22:40:25,249 DEBUG   HandlerThread:2329230 [handler.py:handle_request():146] handle_request: internal_messages
2024-05-13 22:40:25,249 DEBUG   HandlerThread:2329230 [handler.py:handle_request():146] handle_request: stop_status
2024-05-13 22:40:25,250 DEBUG   SenderThread:2329230 [sender.py:send():382] send: telemetry
2024-05-13 22:40:25,250 DEBUG   SenderThread:2329230 [sender.py:send_request():409] send_request: stop_status
2024-05-13 22:40:25,461 INFO    Thread-12 :2329230 [dir_watcher.py:_on_file_modified():288] file/dir modified: /nfs/datx/lyk/HiFT/wandb/run-20240513_224021-4xcljpov/files/conda-environment.yaml
2024-05-13 22:40:25,461 INFO    Thread-12 :2329230 [dir_watcher.py:_on_file_created():271] file/dir created: /nfs/datx/lyk/HiFT/wandb/run-20240513_224021-4xcljpov/files/wandb-metadata.json
2024-05-13 22:40:25,463 DEBUG   SenderThread:2329230 [sender.py:send():382] send: config
2024-05-13 22:40:25,463 DEBUG   SenderThread:2329230 [sender.py:send():382] send: metric
2024-05-13 22:40:25,463 DEBUG   SenderThread:2329230 [sender.py:send():382] send: telemetry
2024-05-13 22:40:25,464 DEBUG   SenderThread:2329230 [sender.py:send():382] send: metric
2024-05-13 22:40:25,464 WARNING SenderThread:2329230 [sender.py:send_metric():1343] Seen metric with glob (shouldn't happen)
2024-05-13 22:40:25,464 DEBUG   SenderThread:2329230 [sender.py:send():382] send: telemetry
2024-05-13 22:40:25,685 ERROR   wandb-upload_0:2329230 [internal_api.py:upload_file():2761] upload_file exception https://storage.googleapis.com/wandb-production.appspot.com/neuzxm/huggingface/4xcljpov/wandb-metadata.json?Expires=1715719225&GoogleAccessId=gorilla-files-url-signer-man%40wandb-production.iam.gserviceaccount.com&Signature=INBnHYzJavOuouh91NyRc5IhqJ0pSHte%2BEnqXEalgsBzXKVTuPDqu7QW48IXpiIa2uwd%2F1h9kZn9L1iZWlOIVzu5LBwUdUEfdnIx3VmvRYjA6p3ClhLbq%2BrY0XkLEZoO9S7bpSanl3MSF6nBiA5bgqckqkj1zLTxplGXyG8vQPpT8cOY3y5XsopkvtdueIS6iML7zviyrVJgArHCc7sAynr%2BA9KtKr31Q5nDKlJ98SSqUUJGQjjlPxzAV0x2%2BiAEvhqzP1XwZSgLdIOyEnljsS0vmjyGJx6Q9H3vkPnrN9RXSkxMf1Aqc3e8Y7gDpcQ8iaCt9zLVW9M11V3B455JBQ%3D%3D: 403 Client Error: Forbidden for url: https://storage.googleapis.com/wandb-production.appspot.com/neuzxm/huggingface/4xcljpov/wandb-metadata.json?Expires=1715719225&GoogleAccessId=gorilla-files-url-signer-man%40wandb-production.iam.gserviceaccount.com&Signature=INBnHYzJavOuouh91NyRc5IhqJ0pSHte%2BEnqXEalgsBzXKVTuPDqu7QW48IXpiIa2uwd%2F1h9kZn9L1iZWlOIVzu5LBwUdUEfdnIx3VmvRYjA6p3ClhLbq%2BrY0XkLEZoO9S7bpSanl3MSF6nBiA5bgqckqkj1zLTxplGXyG8vQPpT8cOY3y5XsopkvtdueIS6iML7zviyrVJgArHCc7sAynr%2BA9KtKr31Q5nDKlJ98SSqUUJGQjjlPxzAV0x2%2BiAEvhqzP1XwZSgLdIOyEnljsS0vmjyGJx6Q9H3vkPnrN9RXSkxMf1Aqc3e8Y7gDpcQ8iaCt9zLVW9M11V3B455JBQ%3D%3D
2024-05-13 22:40:25,686 ERROR   wandb-upload_0:2329230 [internal_api.py:upload_file():2763] upload_file request headers: {'User-Agent': 'python-requests/2.31.0', 'Accept-Encoding': 'gzip, deflate, br', 'Accept': '*/*', 'Connection': 'keep-alive', 'Content-Length': '10146'}
2024-05-13 22:40:25,686 ERROR   wandb-upload_0:2329230 [internal_api.py:upload_file():2765] upload_file response body: b"<?xml version='1.0' encoding='UTF-8'?><Error><Code>AccessDenied</Code><Message>Access denied.</Message><Details>We're sorry, but this service is not available in your location</Details></Error>"
2024-05-13 22:40:25,735 ERROR   wandb-upload_0:2329230 [upload_job.py:push():134] Failed to upload file: /tmp/tmpekz0ezkwwandb/lck3p0bh-wandb-metadata.json
Traceback (most recent call last):
  File "/mounts/work/lyk/anaconda3/envs/torch2/lib/python3.8/site-packages/wandb/apis/normalize.py", line 41, in wrapper
    return func(*args, **kwargs)
  File "/mounts/work/lyk/anaconda3/envs/torch2/lib/python3.8/site-packages/wandb/sdk/lib/retry.py", line 212, in wrapped_fn
    return retrier(*args, **kargs)
  File "/mounts/work/lyk/anaconda3/envs/torch2/lib/python3.8/site-packages/wandb/sdk/lib/retry.py", line 131, in __call__
    result = self._call_fn(*args, **kwargs)
  File "/mounts/work/lyk/anaconda3/envs/torch2/lib/python3.8/site-packages/wandb/sdk/internal/internal_api.py", line 2787, in upload_file
    wandb._sentry.reraise(e)
  File "/mounts/work/lyk/anaconda3/envs/torch2/lib/python3.8/site-packages/wandb/analytics/sentry.py", line 154, in reraise
    raise exc.with_traceback(sys.exc_info()[2])
  File "/mounts/work/lyk/anaconda3/envs/torch2/lib/python3.8/site-packages/wandb/sdk/internal/internal_api.py", line 2759, in upload_file
    response.raise_for_status()
  File "/mounts/work/lyk/anaconda3/envs/torch2/lib/python3.8/site-packages/requests/models.py", line 1021, in raise_for_status
    raise HTTPError(http_error_msg, response=self)
requests.exceptions.HTTPError: 403 Client Error: Forbidden for url: https://storage.googleapis.com/wandb-production.appspot.com/neuzxm/huggingface/4xcljpov/wandb-metadata.json?Expires=1715719225&GoogleAccessId=gorilla-files-url-signer-man%40wandb-production.iam.gserviceaccount.com&Signature=INBnHYzJavOuouh91NyRc5IhqJ0pSHte%2BEnqXEalgsBzXKVTuPDqu7QW48IXpiIa2uwd%2F1h9kZn9L1iZWlOIVzu5LBwUdUEfdnIx3VmvRYjA6p3ClhLbq%2BrY0XkLEZoO9S7bpSanl3MSF6nBiA5bgqckqkj1zLTxplGXyG8vQPpT8cOY3y5XsopkvtdueIS6iML7zviyrVJgArHCc7sAynr%2BA9KtKr31Q5nDKlJ98SSqUUJGQjjlPxzAV0x2%2BiAEvhqzP1XwZSgLdIOyEnljsS0vmjyGJx6Q9H3vkPnrN9RXSkxMf1Aqc3e8Y7gDpcQ8iaCt9zLVW9M11V3B455JBQ%3D%3D

During handling of the above exception, another exception occurred:

Traceback (most recent call last):
  File "/mounts/work/lyk/anaconda3/envs/torch2/lib/python3.8/site-packages/wandb/filesync/upload_job.py", line 125, in push
    self._api.upload_file_retry(
  File "/mounts/work/lyk/anaconda3/envs/torch2/lib/python3.8/site-packages/wandb/apis/normalize.py", line 51, in wrapper
    raise CommError(message, error)
wandb.errors.CommError: <Response [403]>
2024-05-13 22:40:25,762 ERROR   Thread-11 :2329230 [step_upload.py:_handle_event():200] Failed to upload file: /tmp/tmpekz0ezkwwandb/lck3p0bh-wandb-metadata.json
Traceback (most recent call last):
  File "/mounts/work/lyk/anaconda3/envs/torch2/lib/python3.8/site-packages/wandb/apis/normalize.py", line 41, in wrapper
    return func(*args, **kwargs)
  File "/mounts/work/lyk/anaconda3/envs/torch2/lib/python3.8/site-packages/wandb/sdk/lib/retry.py", line 212, in wrapped_fn
    return retrier(*args, **kargs)
  File "/mounts/work/lyk/anaconda3/envs/torch2/lib/python3.8/site-packages/wandb/sdk/lib/retry.py", line 131, in __call__
    result = self._call_fn(*args, **kwargs)
  File "/mounts/work/lyk/anaconda3/envs/torch2/lib/python3.8/site-packages/wandb/sdk/internal/internal_api.py", line 2787, in upload_file
    wandb._sentry.reraise(e)
  File "/mounts/work/lyk/anaconda3/envs/torch2/lib/python3.8/site-packages/wandb/analytics/sentry.py", line 154, in reraise
    raise exc.with_traceback(sys.exc_info()[2])
  File "/mounts/work/lyk/anaconda3/envs/torch2/lib/python3.8/site-packages/wandb/sdk/internal/internal_api.py", line 2759, in upload_file
    response.raise_for_status()
  File "/mounts/work/lyk/anaconda3/envs/torch2/lib/python3.8/site-packages/requests/models.py", line 1021, in raise_for_status
    raise HTTPError(http_error_msg, response=self)
requests.exceptions.HTTPError: 403 Client Error: Forbidden for url: https://storage.googleapis.com/wandb-production.appspot.com/neuzxm/huggingface/4xcljpov/wandb-metadata.json?Expires=1715719225&GoogleAccessId=gorilla-files-url-signer-man%40wandb-production.iam.gserviceaccount.com&Signature=INBnHYzJavOuouh91NyRc5IhqJ0pSHte%2BEnqXEalgsBzXKVTuPDqu7QW48IXpiIa2uwd%2F1h9kZn9L1iZWlOIVzu5LBwUdUEfdnIx3VmvRYjA6p3ClhLbq%2BrY0XkLEZoO9S7bpSanl3MSF6nBiA5bgqckqkj1zLTxplGXyG8vQPpT8cOY3y5XsopkvtdueIS6iML7zviyrVJgArHCc7sAynr%2BA9KtKr31Q5nDKlJ98SSqUUJGQjjlPxzAV0x2%2BiAEvhqzP1XwZSgLdIOyEnljsS0vmjyGJx6Q9H3vkPnrN9RXSkxMf1Aqc3e8Y7gDpcQ8iaCt9zLVW9M11V3B455JBQ%3D%3D

During handling of the above exception, another exception occurred:

Traceback (most recent call last):
  File "/mounts/work/lyk/anaconda3/envs/torch2/lib/python3.8/concurrent/futures/thread.py", line 57, in run
    result = self.fn(*self.args, **self.kwargs)
  File "/mounts/work/lyk/anaconda3/envs/torch2/lib/python3.8/site-packages/wandb/filesync/step_upload.py", line 288, in run_and_notify
    self._do_upload_sync(event)
  File "/mounts/work/lyk/anaconda3/envs/torch2/lib/python3.8/site-packages/wandb/filesync/step_upload.py", line 330, in _do_upload_sync
    job.run()
  File "/mounts/work/lyk/anaconda3/envs/torch2/lib/python3.8/site-packages/wandb/filesync/upload_job.py", line 57, in run
    self.push()
  File "/mounts/work/lyk/anaconda3/envs/torch2/lib/python3.8/site-packages/wandb/filesync/upload_job.py", line 125, in push
    self._api.upload_file_retry(
  File "/mounts/work/lyk/anaconda3/envs/torch2/lib/python3.8/site-packages/wandb/apis/normalize.py", line 51, in wrapper
    raise CommError(message, error)
wandb.errors.CommError: <Response [403]>
2024-05-13 22:40:26,463 INFO    Thread-12 :2329230 [dir_watcher.py:_on_file_created():271] file/dir created: /nfs/datx/lyk/HiFT/wandb/run-20240513_224021-4xcljpov/files/output.log
2024-05-13 22:40:26,465 DEBUG   HandlerThread:2329230 [handler.py:handle_request():146] handle_request: status_report
2024-05-13 22:40:26,594 DEBUG   SenderThread:2329230 [sender.py:send():382] send: exit
2024-05-13 22:40:26,594 INFO    SenderThread:2329230 [sender.py:send_exit():589] handling exit code: 1
2024-05-13 22:40:26,594 INFO    SenderThread:2329230 [sender.py:send_exit():591] handling runtime: 5
2024-05-13 22:40:26,596 INFO    SenderThread:2329230 [sender.py:_save_file():1392] saving file wandb-summary.json with policy end
2024-05-13 22:40:26,597 INFO    SenderThread:2329230 [sender.py:send_exit():597] send defer
2024-05-13 22:40:26,597 DEBUG   HandlerThread:2329230 [handler.py:handle_request():146] handle_request: defer
2024-05-13 22:40:26,597 INFO    HandlerThread:2329230 [handler.py:handle_request_defer():172] handle defer: 0
2024-05-13 22:40:26,598 DEBUG   SenderThread:2329230 [sender.py:send_request():409] send_request: defer
2024-05-13 22:40:26,598 INFO    SenderThread:2329230 [sender.py:send_request_defer():613] handle sender defer: 0
2024-05-13 22:40:26,598 INFO    SenderThread:2329230 [sender.py:transition_state():617] send defer: 1
2024-05-13 22:40:26,598 DEBUG   HandlerThread:2329230 [handler.py:handle_request():146] handle_request: defer
2024-05-13 22:40:26,598 INFO    HandlerThread:2329230 [handler.py:handle_request_defer():172] handle defer: 1
2024-05-13 22:40:26,599 DEBUG   SenderThread:2329230 [sender.py:send_request():409] send_request: defer
2024-05-13 22:40:26,599 INFO    SenderThread:2329230 [sender.py:send_request_defer():613] handle sender defer: 1
2024-05-13 22:40:26,599 INFO    SenderThread:2329230 [sender.py:transition_state():617] send defer: 2
2024-05-13 22:40:26,599 DEBUG   HandlerThread:2329230 [handler.py:handle_request():146] handle_request: defer
2024-05-13 22:40:26,599 INFO    HandlerThread:2329230 [handler.py:handle_request_defer():172] handle defer: 2
2024-05-13 22:40:26,599 INFO    HandlerThread:2329230 [system_monitor.py:finish():203] Stopping system monitor
2024-05-13 22:40:26,600 INFO    HandlerThread:2329230 [interfaces.py:finish():202] Joined cpu monitor
2024-05-13 22:40:26,601 INFO    HandlerThread:2329230 [interfaces.py:finish():202] Joined disk monitor
2024-05-13 22:40:26,601 DEBUG   SystemMonitor:2329230 [system_monitor.py:_start():172] Starting system metrics aggregation loop
2024-05-13 22:40:26,601 DEBUG   SystemMonitor:2329230 [system_monitor.py:_start():179] Finished system metrics aggregation loop
2024-05-13 22:40:26,601 DEBUG   SystemMonitor:2329230 [system_monitor.py:_start():183] Publishing last batch of metrics
2024-05-13 22:40:27,203 INFO    HandlerThread:2329230 [interfaces.py:finish():202] Joined gpu monitor
2024-05-13 22:40:27,203 INFO    HandlerThread:2329230 [interfaces.py:finish():202] Joined memory monitor
2024-05-13 22:40:27,203 INFO    HandlerThread:2329230 [interfaces.py:finish():202] Joined network monitor
2024-05-13 22:40:27,204 DEBUG   SenderThread:2329230 [sender.py:send_request():409] send_request: defer
2024-05-13 22:40:27,204 INFO    SenderThread:2329230 [sender.py:send_request_defer():613] handle sender defer: 2
2024-05-13 22:40:27,204 INFO    SenderThread:2329230 [sender.py:transition_state():617] send defer: 3
2024-05-13 22:40:27,205 DEBUG   SenderThread:2329230 [sender.py:send():382] send: stats
2024-05-13 22:40:27,205 DEBUG   HandlerThread:2329230 [handler.py:handle_request():146] handle_request: defer
2024-05-13 22:40:27,205 INFO    HandlerThread:2329230 [handler.py:handle_request_defer():172] handle defer: 3
2024-05-13 22:40:27,206 DEBUG   SenderThread:2329230 [sender.py:send_request():409] send_request: defer
2024-05-13 22:40:27,206 INFO    SenderThread:2329230 [sender.py:send_request_defer():613] handle sender defer: 3
2024-05-13 22:40:27,206 INFO    SenderThread:2329230 [sender.py:transition_state():617] send defer: 4
2024-05-13 22:40:27,206 DEBUG   HandlerThread:2329230 [handler.py:handle_request():146] handle_request: defer
2024-05-13 22:40:27,206 INFO    HandlerThread:2329230 [handler.py:handle_request_defer():172] handle defer: 4
2024-05-13 22:40:27,206 DEBUG   SenderThread:2329230 [sender.py:send_request():409] send_request: defer
2024-05-13 22:40:27,206 INFO    SenderThread:2329230 [sender.py:send_request_defer():613] handle sender defer: 4
2024-05-13 22:40:27,206 INFO    SenderThread:2329230 [sender.py:transition_state():617] send defer: 5
2024-05-13 22:40:27,207 DEBUG   HandlerThread:2329230 [handler.py:handle_request():146] handle_request: defer
2024-05-13 22:40:27,207 INFO    HandlerThread:2329230 [handler.py:handle_request_defer():172] handle defer: 5
2024-05-13 22:40:27,207 DEBUG   SenderThread:2329230 [sender.py:send():382] send: summary
2024-05-13 22:40:27,209 INFO    SenderThread:2329230 [sender.py:_save_file():1392] saving file wandb-summary.json with policy end
2024-05-13 22:40:27,209 DEBUG   SenderThread:2329230 [sender.py:send_request():409] send_request: defer
2024-05-13 22:40:27,209 INFO    SenderThread:2329230 [sender.py:send_request_defer():613] handle sender defer: 5
2024-05-13 22:40:27,209 INFO    SenderThread:2329230 [sender.py:transition_state():617] send defer: 6
2024-05-13 22:40:27,209 DEBUG   HandlerThread:2329230 [handler.py:handle_request():146] handle_request: defer
2024-05-13 22:40:27,209 INFO    HandlerThread:2329230 [handler.py:handle_request_defer():172] handle defer: 6
2024-05-13 22:40:27,209 DEBUG   SenderThread:2329230 [sender.py:send_request():409] send_request: defer
2024-05-13 22:40:27,209 INFO    SenderThread:2329230 [sender.py:send_request_defer():613] handle sender defer: 6
2024-05-13 22:40:27,213 DEBUG   HandlerThread:2329230 [handler.py:handle_request():146] handle_request: status_report
2024-05-13 22:40:27,406 INFO    SenderThread:2329230 [sender.py:transition_state():617] send defer: 7
2024-05-13 22:40:27,406 DEBUG   HandlerThread:2329230 [handler.py:handle_request():146] handle_request: defer
2024-05-13 22:40:27,406 INFO    HandlerThread:2329230 [handler.py:handle_request_defer():172] handle defer: 7
2024-05-13 22:40:27,407 DEBUG   SenderThread:2329230 [sender.py:send_request():409] send_request: defer
2024-05-13 22:40:27,407 INFO    SenderThread:2329230 [sender.py:send_request_defer():613] handle sender defer: 7
2024-05-13 22:40:27,464 INFO    Thread-12 :2329230 [dir_watcher.py:_on_file_modified():288] file/dir modified: /nfs/datx/lyk/HiFT/wandb/run-20240513_224021-4xcljpov/files/config.yaml
2024-05-13 22:40:27,464 INFO    Thread-12 :2329230 [dir_watcher.py:_on_file_created():271] file/dir created: /nfs/datx/lyk/HiFT/wandb/run-20240513_224021-4xcljpov/files/wandb-summary.json
2024-05-13 22:40:27,594 DEBUG   HandlerThread:2329230 [handler.py:handle_request():146] handle_request: poll_exit
2024-05-13 22:40:28,466 INFO    Thread-12 :2329230 [dir_watcher.py:_on_file_modified():288] file/dir modified: /nfs/datx/lyk/HiFT/wandb/run-20240513_224021-4xcljpov/files/output.log
2024-05-13 22:40:28,554 INFO    SenderThread:2329230 [sender.py:transition_state():617] send defer: 8
2024-05-13 22:40:28,554 DEBUG   SenderThread:2329230 [sender.py:send_request():409] send_request: poll_exit
2024-05-13 22:40:28,555 DEBUG   HandlerThread:2329230 [handler.py:handle_request():146] handle_request: defer
2024-05-13 22:40:28,555 INFO    HandlerThread:2329230 [handler.py:handle_request_defer():172] handle defer: 8
2024-05-13 22:40:28,556 DEBUG   SenderThread:2329230 [sender.py:send_request():409] send_request: defer
2024-05-13 22:40:28,556 INFO    SenderThread:2329230 [sender.py:send_request_defer():613] handle sender defer: 8
2024-05-13 22:40:28,556 INFO    SenderThread:2329230 [job_builder.py:build():298] Attempting to build job artifact
2024-05-13 22:40:28,557 INFO    SenderThread:2329230 [job_builder.py:_get_source_type():439] no source found
2024-05-13 22:40:28,558 INFO    SenderThread:2329230 [sender.py:transition_state():617] send defer: 9
2024-05-13 22:40:28,558 DEBUG   HandlerThread:2329230 [handler.py:handle_request():146] handle_request: defer
2024-05-13 22:40:28,558 INFO    HandlerThread:2329230 [handler.py:handle_request_defer():172] handle defer: 9
2024-05-13 22:40:28,558 DEBUG   SenderThread:2329230 [sender.py:send_request():409] send_request: defer
2024-05-13 22:40:28,558 INFO    SenderThread:2329230 [sender.py:send_request_defer():613] handle sender defer: 9
2024-05-13 22:40:28,558 INFO    SenderThread:2329230 [dir_watcher.py:finish():358] shutting down directory watcher
2024-05-13 22:40:28,595 DEBUG   HandlerThread:2329230 [handler.py:handle_request():146] handle_request: poll_exit
2024-05-13 22:40:29,467 INFO    SenderThread:2329230 [dir_watcher.py:_on_file_modified():288] file/dir modified: /nfs/datx/lyk/HiFT/wandb/run-20240513_224021-4xcljpov/files/output.log
2024-05-13 22:40:29,468 INFO    SenderThread:2329230 [dir_watcher.py:finish():388] scan: /nfs/datx/lyk/HiFT/wandb/run-20240513_224021-4xcljpov/files
2024-05-13 22:40:29,468 INFO    SenderThread:2329230 [dir_watcher.py:finish():402] scan save: /nfs/datx/lyk/HiFT/wandb/run-20240513_224021-4xcljpov/files/wandb-summary.json wandb-summary.json
2024-05-13 22:40:29,468 INFO    SenderThread:2329230 [dir_watcher.py:finish():402] scan save: /nfs/datx/lyk/HiFT/wandb/run-20240513_224021-4xcljpov/files/requirements.txt requirements.txt
2024-05-13 22:40:29,468 INFO    SenderThread:2329230 [dir_watcher.py:finish():402] scan save: /nfs/datx/lyk/HiFT/wandb/run-20240513_224021-4xcljpov/files/conda-environment.yaml conda-environment.yaml
2024-05-13 22:40:29,470 INFO    SenderThread:2329230 [dir_watcher.py:finish():402] scan save: /nfs/datx/lyk/HiFT/wandb/run-20240513_224021-4xcljpov/files/config.yaml config.yaml
2024-05-13 22:40:29,471 INFO    SenderThread:2329230 [dir_watcher.py:finish():402] scan save: /nfs/datx/lyk/HiFT/wandb/run-20240513_224021-4xcljpov/files/wandb-metadata.json wandb-metadata.json
2024-05-13 22:40:29,473 INFO    SenderThread:2329230 [dir_watcher.py:finish():402] scan save: /nfs/datx/lyk/HiFT/wandb/run-20240513_224021-4xcljpov/files/output.log output.log
2024-05-13 22:40:29,473 INFO    SenderThread:2329230 [sender.py:transition_state():617] send defer: 10
2024-05-13 22:40:29,473 DEBUG   SenderThread:2329230 [sender.py:send_request():409] send_request: poll_exit
2024-05-13 22:40:29,476 DEBUG   HandlerThread:2329230 [handler.py:handle_request():146] handle_request: defer
2024-05-13 22:40:29,478 INFO    HandlerThread:2329230 [handler.py:handle_request_defer():172] handle defer: 10
2024-05-13 22:40:29,481 DEBUG   SenderThread:2329230 [sender.py:send_request():409] send_request: defer
2024-05-13 22:40:29,481 INFO    SenderThread:2329230 [sender.py:send_request_defer():613] handle sender defer: 10
2024-05-13 22:40:29,481 INFO    SenderThread:2329230 [file_pusher.py:finish():175] shutting down file pusher
2024-05-13 22:40:29,596 DEBUG   HandlerThread:2329230 [handler.py:handle_request():146] handle_request: poll_exit
2024-05-13 22:40:29,597 DEBUG   SenderThread:2329230 [sender.py:send_request():409] send_request: poll_exit
2024-05-13 22:40:29,723 ERROR   wandb-upload_1:2329230 [internal_api.py:upload_file():2761] upload_file exception https://storage.googleapis.com/wandb-production.appspot.com/neuzxm/huggingface/4xcljpov/requirements.txt?Expires=1715719229&GoogleAccessId=gorilla-files-url-signer-man%40wandb-production.iam.gserviceaccount.com&Signature=WbC6%2F1NvVkjdayCZrES8QDMoWyw6NzIYzg5vR1RZrj8RDGJHgZBx%2Bdziza5Y1u%2FWiDo0Hr%2BKPBL3rMdk%2BEStudEkZtSI1FP0ue33BHQxMhw8HtD0pHrL52w%2FoAoTUy%2FPlcOP%2F5gPkVsDK2txUoroD7W4iGov8MfsBZoVoZJhEO8pwCIl6oR1DSB3LIbx7Fb2FDUc6xNjPXZgxtBy0CMZdS4A15gh5WcgyomL97bHUOb5NaFeKqqZtDD9jCgPS%2FaYCWfUWrSmKwTG9txuBU4WzWpRkRbAfAZYJfmEv4GLgbxF0%2FI1tCYprsIgwSdqVlYwVtrcNMiKgcnzNwo8TO98Cw%3D%3D: 403 Client Error: Forbidden for url: https://storage.googleapis.com/wandb-production.appspot.com/neuzxm/huggingface/4xcljpov/requirements.txt?Expires=1715719229&GoogleAccessId=gorilla-files-url-signer-man%40wandb-production.iam.gserviceaccount.com&Signature=WbC6%2F1NvVkjdayCZrES8QDMoWyw6NzIYzg5vR1RZrj8RDGJHgZBx%2Bdziza5Y1u%2FWiDo0Hr%2BKPBL3rMdk%2BEStudEkZtSI1FP0ue33BHQxMhw8HtD0pHrL52w%2FoAoTUy%2FPlcOP%2F5gPkVsDK2txUoroD7W4iGov8MfsBZoVoZJhEO8pwCIl6oR1DSB3LIbx7Fb2FDUc6xNjPXZgxtBy0CMZdS4A15gh5WcgyomL97bHUOb5NaFeKqqZtDD9jCgPS%2FaYCWfUWrSmKwTG9txuBU4WzWpRkRbAfAZYJfmEv4GLgbxF0%2FI1tCYprsIgwSdqVlYwVtrcNMiKgcnzNwo8TO98Cw%3D%3D
2024-05-13 22:40:29,723 ERROR   wandb-upload_1:2329230 [internal_api.py:upload_file():2763] upload_file request headers: {'User-Agent': 'python-requests/2.31.0', 'Accept-Encoding': 'gzip, deflate, br', 'Accept': '*/*', 'Connection': 'keep-alive', 'Content-Length': '2434'}
2024-05-13 22:40:29,723 ERROR   wandb-upload_1:2329230 [internal_api.py:upload_file():2765] upload_file response body: b"<?xml version='1.0' encoding='UTF-8'?><Error><Code>AccessDenied</Code><Message>Access denied.</Message><Details>We're sorry, but this service is not available in your location</Details></Error>"
2024-05-13 22:40:29,741 ERROR   wandb-upload_1:2329230 [upload_job.py:push():134] Failed to upload file: /nfs/datx/lyk/HiFT/wandb/run-20240513_224021-4xcljpov/files/requirements.txt
Traceback (most recent call last):
  File "/mounts/work/lyk/anaconda3/envs/torch2/lib/python3.8/site-packages/wandb/apis/normalize.py", line 41, in wrapper
    return func(*args, **kwargs)
  File "/mounts/work/lyk/anaconda3/envs/torch2/lib/python3.8/site-packages/wandb/sdk/lib/retry.py", line 212, in wrapped_fn
    return retrier(*args, **kargs)
  File "/mounts/work/lyk/anaconda3/envs/torch2/lib/python3.8/site-packages/wandb/sdk/lib/retry.py", line 131, in __call__
    result = self._call_fn(*args, **kwargs)
  File "/mounts/work/lyk/anaconda3/envs/torch2/lib/python3.8/site-packages/wandb/sdk/internal/internal_api.py", line 2787, in upload_file
    wandb._sentry.reraise(e)
  File "/mounts/work/lyk/anaconda3/envs/torch2/lib/python3.8/site-packages/wandb/analytics/sentry.py", line 154, in reraise
    raise exc.with_traceback(sys.exc_info()[2])
  File "/mounts/work/lyk/anaconda3/envs/torch2/lib/python3.8/site-packages/wandb/sdk/internal/internal_api.py", line 2759, in upload_file
    response.raise_for_status()
  File "/mounts/work/lyk/anaconda3/envs/torch2/lib/python3.8/site-packages/requests/models.py", line 1021, in raise_for_status
    raise HTTPError(http_error_msg, response=self)
requests.exceptions.HTTPError: 403 Client Error: Forbidden for url: https://storage.googleapis.com/wandb-production.appspot.com/neuzxm/huggingface/4xcljpov/requirements.txt?Expires=1715719229&GoogleAccessId=gorilla-files-url-signer-man%40wandb-production.iam.gserviceaccount.com&Signature=WbC6%2F1NvVkjdayCZrES8QDMoWyw6NzIYzg5vR1RZrj8RDGJHgZBx%2Bdziza5Y1u%2FWiDo0Hr%2BKPBL3rMdk%2BEStudEkZtSI1FP0ue33BHQxMhw8HtD0pHrL52w%2FoAoTUy%2FPlcOP%2F5gPkVsDK2txUoroD7W4iGov8MfsBZoVoZJhEO8pwCIl6oR1DSB3LIbx7Fb2FDUc6xNjPXZgxtBy0CMZdS4A15gh5WcgyomL97bHUOb5NaFeKqqZtDD9jCgPS%2FaYCWfUWrSmKwTG9txuBU4WzWpRkRbAfAZYJfmEv4GLgbxF0%2FI1tCYprsIgwSdqVlYwVtrcNMiKgcnzNwo8TO98Cw%3D%3D

During handling of the above exception, another exception occurred:

Traceback (most recent call last):
  File "/mounts/work/lyk/anaconda3/envs/torch2/lib/python3.8/site-packages/wandb/filesync/upload_job.py", line 125, in push
    self._api.upload_file_retry(
  File "/mounts/work/lyk/anaconda3/envs/torch2/lib/python3.8/site-packages/wandb/apis/normalize.py", line 51, in wrapper
    raise CommError(message, error)
wandb.errors.CommError: <Response [403]>
2024-05-13 22:40:29,758 ERROR   wandb-upload_0:2329230 [internal_api.py:upload_file():2761] upload_file exception https://storage.googleapis.com/wandb-production.appspot.com/neuzxm/huggingface/4xcljpov/wandb-summary.json?Expires=1715719229&GoogleAccessId=gorilla-files-url-signer-man%40wandb-production.iam.gserviceaccount.com&Signature=pvsxrT1uclUTUWuNRnGOFjaG4sAg8qDWlXnmFH4k5V%2FLOqsVJISnq57aiBGMj%2Fo9ZBTq6yH9eAbq3LAign1%2BtIzzOc%2FAy6VgzWgYLfpgfnf7RauAzX8WBzO0Avi2v58SMJJAEJK%2BbVzIfd6oUca0tDdBqRoBT7M7RQe%2FnJT%2F11wvk62bIi0HC%2FT8pnaRahxNtfLxoLRYngbaBP6%2BB7LOnubsoHjUiKMNytrune4NfR%2FL88awFguFSoqfkfPgoytd4IaRN6oSeAAzA7gDayOVLLU%2BwZvWeb1%2B9R413tiXVyjvPKlg93qO3usSw8oiPhfohDNpvmiEb8MVQ8nOOFMJHw%3D%3D: 403 Client Error: Forbidden for url: https://storage.googleapis.com/wandb-production.appspot.com/neuzxm/huggingface/4xcljpov/wandb-summary.json?Expires=1715719229&GoogleAccessId=gorilla-files-url-signer-man%40wandb-production.iam.gserviceaccount.com&Signature=pvsxrT1uclUTUWuNRnGOFjaG4sAg8qDWlXnmFH4k5V%2FLOqsVJISnq57aiBGMj%2Fo9ZBTq6yH9eAbq3LAign1%2BtIzzOc%2FAy6VgzWgYLfpgfnf7RauAzX8WBzO0Avi2v58SMJJAEJK%2BbVzIfd6oUca0tDdBqRoBT7M7RQe%2FnJT%2F11wvk62bIi0HC%2FT8pnaRahxNtfLxoLRYngbaBP6%2BB7LOnubsoHjUiKMNytrune4NfR%2FL88awFguFSoqfkfPgoytd4IaRN6oSeAAzA7gDayOVLLU%2BwZvWeb1%2B9R413tiXVyjvPKlg93qO3usSw8oiPhfohDNpvmiEb8MVQ8nOOFMJHw%3D%3D
2024-05-13 22:40:29,758 ERROR   wandb-upload_0:2329230 [internal_api.py:upload_file():2763] upload_file request headers: {'User-Agent': 'python-requests/2.31.0', 'Accept-Encoding': 'gzip, deflate, br', 'Accept': '*/*', 'Connection': 'keep-alive', 'Content-Length': '26'}
2024-05-13 22:40:29,758 ERROR   wandb-upload_0:2329230 [internal_api.py:upload_file():2765] upload_file response body: b"<?xml version='1.0' encoding='UTF-8'?><Error><Code>AccessDenied</Code><Message>Access denied.</Message><Details>We're sorry, but this service is not available in your location</Details></Error>"
2024-05-13 22:40:29,776 ERROR   Thread-11 :2329230 [step_upload.py:_handle_event():200] Failed to upload file: /nfs/datx/lyk/HiFT/wandb/run-20240513_224021-4xcljpov/files/requirements.txt
Traceback (most recent call last):
  File "/mounts/work/lyk/anaconda3/envs/torch2/lib/python3.8/site-packages/wandb/apis/normalize.py", line 41, in wrapper
    return func(*args, **kwargs)
  File "/mounts/work/lyk/anaconda3/envs/torch2/lib/python3.8/site-packages/wandb/sdk/lib/retry.py", line 212, in wrapped_fn
    return retrier(*args, **kargs)
  File "/mounts/work/lyk/anaconda3/envs/torch2/lib/python3.8/site-packages/wandb/sdk/lib/retry.py", line 131, in __call__
    result = self._call_fn(*args, **kwargs)
  File "/mounts/work/lyk/anaconda3/envs/torch2/lib/python3.8/site-packages/wandb/sdk/internal/internal_api.py", line 2787, in upload_file
    wandb._sentry.reraise(e)
  File "/mounts/work/lyk/anaconda3/envs/torch2/lib/python3.8/site-packages/wandb/analytics/sentry.py", line 154, in reraise
    raise exc.with_traceback(sys.exc_info()[2])
  File "/mounts/work/lyk/anaconda3/envs/torch2/lib/python3.8/site-packages/wandb/sdk/internal/internal_api.py", line 2759, in upload_file
    response.raise_for_status()
  File "/mounts/work/lyk/anaconda3/envs/torch2/lib/python3.8/site-packages/requests/models.py", line 1021, in raise_for_status
    raise HTTPError(http_error_msg, response=self)
requests.exceptions.HTTPError: 403 Client Error: Forbidden for url: https://storage.googleapis.com/wandb-production.appspot.com/neuzxm/huggingface/4xcljpov/requirements.txt?Expires=1715719229&GoogleAccessId=gorilla-files-url-signer-man%40wandb-production.iam.gserviceaccount.com&Signature=WbC6%2F1NvVkjdayCZrES8QDMoWyw6NzIYzg5vR1RZrj8RDGJHgZBx%2Bdziza5Y1u%2FWiDo0Hr%2BKPBL3rMdk%2BEStudEkZtSI1FP0ue33BHQxMhw8HtD0pHrL52w%2FoAoTUy%2FPlcOP%2F5gPkVsDK2txUoroD7W4iGov8MfsBZoVoZJhEO8pwCIl6oR1DSB3LIbx7Fb2FDUc6xNjPXZgxtBy0CMZdS4A15gh5WcgyomL97bHUOb5NaFeKqqZtDD9jCgPS%2FaYCWfUWrSmKwTG9txuBU4WzWpRkRbAfAZYJfmEv4GLgbxF0%2FI1tCYprsIgwSdqVlYwVtrcNMiKgcnzNwo8TO98Cw%3D%3D

During handling of the above exception, another exception occurred:

Traceback (most recent call last):
  File "/mounts/work/lyk/anaconda3/envs/torch2/lib/python3.8/concurrent/futures/thread.py", line 57, in run
    result = self.fn(*self.args, **self.kwargs)
  File "/mounts/work/lyk/anaconda3/envs/torch2/lib/python3.8/site-packages/wandb/filesync/step_upload.py", line 288, in run_and_notify
    self._do_upload_sync(event)
  File "/mounts/work/lyk/anaconda3/envs/torch2/lib/python3.8/site-packages/wandb/filesync/step_upload.py", line 330, in _do_upload_sync
    job.run()
  File "/mounts/work/lyk/anaconda3/envs/torch2/lib/python3.8/site-packages/wandb/filesync/upload_job.py", line 57, in run
    self.push()
  File "/mounts/work/lyk/anaconda3/envs/torch2/lib/python3.8/site-packages/wandb/filesync/upload_job.py", line 125, in push
    self._api.upload_file_retry(
  File "/mounts/work/lyk/anaconda3/envs/torch2/lib/python3.8/site-packages/wandb/apis/normalize.py", line 51, in wrapper
    raise CommError(message, error)
wandb.errors.CommError: <Response [403]>
2024-05-13 22:40:29,777 ERROR   wandb-upload_0:2329230 [upload_job.py:push():134] Failed to upload file: /nfs/datx/lyk/HiFT/wandb/run-20240513_224021-4xcljpov/files/wandb-summary.json
Traceback (most recent call last):
  File "/mounts/work/lyk/anaconda3/envs/torch2/lib/python3.8/site-packages/wandb/apis/normalize.py", line 41, in wrapper
    return func(*args, **kwargs)
  File "/mounts/work/lyk/anaconda3/envs/torch2/lib/python3.8/site-packages/wandb/sdk/lib/retry.py", line 212, in wrapped_fn
    return retrier(*args, **kargs)
  File "/mounts/work/lyk/anaconda3/envs/torch2/lib/python3.8/site-packages/wandb/sdk/lib/retry.py", line 131, in __call__
    result = self._call_fn(*args, **kwargs)
  File "/mounts/work/lyk/anaconda3/envs/torch2/lib/python3.8/site-packages/wandb/sdk/internal/internal_api.py", line 2787, in upload_file
    wandb._sentry.reraise(e)
  File "/mounts/work/lyk/anaconda3/envs/torch2/lib/python3.8/site-packages/wandb/analytics/sentry.py", line 154, in reraise
    raise exc.with_traceback(sys.exc_info()[2])
  File "/mounts/work/lyk/anaconda3/envs/torch2/lib/python3.8/site-packages/wandb/sdk/internal/internal_api.py", line 2759, in upload_file
    response.raise_for_status()
  File "/mounts/work/lyk/anaconda3/envs/torch2/lib/python3.8/site-packages/requests/models.py", line 1021, in raise_for_status
    raise HTTPError(http_error_msg, response=self)
requests.exceptions.HTTPError: 403 Client Error: Forbidden for url: https://storage.googleapis.com/wandb-production.appspot.com/neuzxm/huggingface/4xcljpov/wandb-summary.json?Expires=1715719229&GoogleAccessId=gorilla-files-url-signer-man%40wandb-production.iam.gserviceaccount.com&Signature=pvsxrT1uclUTUWuNRnGOFjaG4sAg8qDWlXnmFH4k5V%2FLOqsVJISnq57aiBGMj%2Fo9ZBTq6yH9eAbq3LAign1%2BtIzzOc%2FAy6VgzWgYLfpgfnf7RauAzX8WBzO0Avi2v58SMJJAEJK%2BbVzIfd6oUca0tDdBqRoBT7M7RQe%2FnJT%2F11wvk62bIi0HC%2FT8pnaRahxNtfLxoLRYngbaBP6%2BB7LOnubsoHjUiKMNytrune4NfR%2FL88awFguFSoqfkfPgoytd4IaRN6oSeAAzA7gDayOVLLU%2BwZvWeb1%2B9R413tiXVyjvPKlg93qO3usSw8oiPhfohDNpvmiEb8MVQ8nOOFMJHw%3D%3D

During handling of the above exception, another exception occurred:

Traceback (most recent call last):
  File "/mounts/work/lyk/anaconda3/envs/torch2/lib/python3.8/site-packages/wandb/filesync/upload_job.py", line 125, in push
    self._api.upload_file_retry(
  File "/mounts/work/lyk/anaconda3/envs/torch2/lib/python3.8/site-packages/wandb/apis/normalize.py", line 51, in wrapper
    raise CommError(message, error)
wandb.errors.CommError: <Response [403]>
2024-05-13 22:40:29,790 ERROR   wandb-upload_4:2329230 [internal_api.py:upload_file():2761] upload_file exception https://storage.googleapis.com/wandb-production.appspot.com/neuzxm/huggingface/4xcljpov/output.log?Expires=1715719229&GoogleAccessId=gorilla-files-url-signer-man%40wandb-production.iam.gserviceaccount.com&Signature=xP897xTk2L40j6WcTZKxfvBCAKT3VLSYtCiHce66lMyV5qUKZvHbGX0xIHGxF%2Bp7WVg1m4U0hRV%2BvI%2F%2By78QD3mdJN8wJx7cLaHnOfwLQW4Y1mJFiUC5rk%2BaJ3Xq6zgMuXQppLWL5KniPMCXuUNu88KcLlH2nzG5q9uo16MnQx3SPmr%2FWcQQbe0DE3zXRjSXalQW7wbzr0AShY8Vd%2FPZLclfgvrrtzgSl6ymRUH5p%2FTzHdtz4W7qI%2BRNUOqU9Mp0R0qcPfER51jTBvZEq9cnv9Q3qOLlLQWaG%2F4gSEMn4rA1GUvU9Ng5q4QZW207X61Psi6V29N3FdOR3ou77U8L5w%3D%3D: 403 Client Error: Forbidden for url: https://storage.googleapis.com/wandb-production.appspot.com/neuzxm/huggingface/4xcljpov/output.log?Expires=1715719229&GoogleAccessId=gorilla-files-url-signer-man%40wandb-production.iam.gserviceaccount.com&Signature=xP897xTk2L40j6WcTZKxfvBCAKT3VLSYtCiHce66lMyV5qUKZvHbGX0xIHGxF%2Bp7WVg1m4U0hRV%2BvI%2F%2By78QD3mdJN8wJx7cLaHnOfwLQW4Y1mJFiUC5rk%2BaJ3Xq6zgMuXQppLWL5KniPMCXuUNu88KcLlH2nzG5q9uo16MnQx3SPmr%2FWcQQbe0DE3zXRjSXalQW7wbzr0AShY8Vd%2FPZLclfgvrrtzgSl6ymRUH5p%2FTzHdtz4W7qI%2BRNUOqU9Mp0R0qcPfER51jTBvZEq9cnv9Q3qOLlLQWaG%2F4gSEMn4rA1GUvU9Ng5q4QZW207X61Psi6V29N3FdOR3ou77U8L5w%3D%3D
2024-05-13 22:40:29,790 ERROR   wandb-upload_4:2329230 [internal_api.py:upload_file():2763] upload_file request headers: {'User-Agent': 'python-requests/2.31.0', 'Accept-Encoding': 'gzip, deflate, br', 'Accept': '*/*', 'Connection': 'keep-alive', 'Content-Length': '3521'}
2024-05-13 22:40:29,790 ERROR   wandb-upload_4:2329230 [internal_api.py:upload_file():2765] upload_file response body: b"<?xml version='1.0' encoding='UTF-8'?><Error><Code>AccessDenied</Code><Message>Access denied.</Message><Details>We're sorry, but this service is not available in your location</Details></Error>"
2024-05-13 22:40:29,800 ERROR   wandb-upload_2:2329230 [internal_api.py:upload_file():2761] upload_file exception https://storage.googleapis.com/wandb-production.appspot.com/neuzxm/huggingface/4xcljpov/conda-environment.yaml?Expires=1715719229&GoogleAccessId=gorilla-files-url-signer-man%40wandb-production.iam.gserviceaccount.com&Signature=XORCGDtdVH36hqJ1ZjLwx7FOjZCS3n%2FhWK27S%2BMOnpxEsFNj7pridgc3DJUTdQH%2FM6V0O8rj7Yt2ivm9U8QujAUW%2BhZWfTBaaWz66qUlxT3yaVvu5UA5WmUG%2BPgWs8kE%2Bxrit2IFk7fvQADBs%2B7%2BXbQJ5aNgtwxHLZUnSc9J9ESCYIX84OpGc157naLfDoEknpg1xTnfaO1yVfnEYbnVO5SqNXq0HGLt3B8FeoTA%2FULR8YvHpOEMA%2F2tbbVLrJKKN8hq%2FD9bf1swhz%2BQ1ZKxR9HPWCd%2Fv3DhGLEU7Yht5sh36SncHJGLXAUa%2FfflVZ7%2F4lrC7woAvt3V0EVo%2BNj8pg%3D%3D: 403 Client Error: Forbidden for url: https://storage.googleapis.com/wandb-production.appspot.com/neuzxm/huggingface/4xcljpov/conda-environment.yaml?Expires=1715719229&GoogleAccessId=gorilla-files-url-signer-man%40wandb-production.iam.gserviceaccount.com&Signature=XORCGDtdVH36hqJ1ZjLwx7FOjZCS3n%2FhWK27S%2BMOnpxEsFNj7pridgc3DJUTdQH%2FM6V0O8rj7Yt2ivm9U8QujAUW%2BhZWfTBaaWz66qUlxT3yaVvu5UA5WmUG%2BPgWs8kE%2Bxrit2IFk7fvQADBs%2B7%2BXbQJ5aNgtwxHLZUnSc9J9ESCYIX84OpGc157naLfDoEknpg1xTnfaO1yVfnEYbnVO5SqNXq0HGLt3B8FeoTA%2FULR8YvHpOEMA%2F2tbbVLrJKKN8hq%2FD9bf1swhz%2BQ1ZKxR9HPWCd%2Fv3DhGLEU7Yht5sh36SncHJGLXAUa%2FfflVZ7%2F4lrC7woAvt3V0EVo%2BNj8pg%3D%3D
2024-05-13 22:40:29,800 ERROR   wandb-upload_2:2329230 [internal_api.py:upload_file():2763] upload_file request headers: {'User-Agent': 'python-requests/2.31.0', 'Accept-Encoding': 'gzip, deflate, br', 'Accept': '*/*', 'Connection': 'keep-alive', 'Content-Length': '5415'}
2024-05-13 22:40:29,800 ERROR   wandb-upload_2:2329230 [internal_api.py:upload_file():2765] upload_file response body: b"<?xml version='1.0' encoding='UTF-8'?><Error><Code>AccessDenied</Code><Message>Access denied.</Message><Details>We're sorry, but this service is not available in your location</Details></Error>"
2024-05-13 22:40:29,811 ERROR   wandb-upload_3:2329230 [internal_api.py:upload_file():2761] upload_file exception https://storage.googleapis.com/wandb-production.appspot.com/neuzxm/huggingface/4xcljpov/config.yaml?Expires=1715719229&GoogleAccessId=gorilla-files-url-signer-man%40wandb-production.iam.gserviceaccount.com&Signature=Nn2cWLL8LLlrgOVv4klv3U5fHRTqpnYbYlppOILk%2FRNrCXIpYBQRlprcadViFHjwSDf4yVjSePmYEGFBR5dhUs4aYbneh7Hxp7MSs2w47EriWwOQnjLxWChLQwjrMaLgVrFRDsKqPC6qLoKV6P%2F5JtlvfkULJt6yU354z4Qvfh9FvdJHLRHY4LobiAcNirSuJDtkZ9RA%2BKUnEWCbCCG%2FFic0IXYPVKKoWc%2FiHLzBetcTS4yBI%2Bg0IlAo%2BRfxn7zymQOntFwpb5J8YXi06aLSpWpkbrs5Z7bfyCYT0IhyDoc1LNLxZUlHY4qtkez515yWuRltF0hLL3Qp6KVdHhGzwQ%3D%3D: 403 Client Error: Forbidden for url: https://storage.googleapis.com/wandb-production.appspot.com/neuzxm/huggingface/4xcljpov/config.yaml?Expires=1715719229&GoogleAccessId=gorilla-files-url-signer-man%40wandb-production.iam.gserviceaccount.com&Signature=Nn2cWLL8LLlrgOVv4klv3U5fHRTqpnYbYlppOILk%2FRNrCXIpYBQRlprcadViFHjwSDf4yVjSePmYEGFBR5dhUs4aYbneh7Hxp7MSs2w47EriWwOQnjLxWChLQwjrMaLgVrFRDsKqPC6qLoKV6P%2F5JtlvfkULJt6yU354z4Qvfh9FvdJHLRHY4LobiAcNirSuJDtkZ9RA%2BKUnEWCbCCG%2FFic0IXYPVKKoWc%2FiHLzBetcTS4yBI%2Bg0IlAo%2BRfxn7zymQOntFwpb5J8YXi06aLSpWpkbrs5Z7bfyCYT0IhyDoc1LNLxZUlHY4qtkez515yWuRltF0hLL3Qp6KVdHhGzwQ%3D%3D
2024-05-13 22:40:29,811 ERROR   wandb-upload_3:2329230 [internal_api.py:upload_file():2763] upload_file request headers: {'User-Agent': 'python-requests/2.31.0', 'Accept-Encoding': 'gzip, deflate, br', 'Accept': '*/*', 'Connection': 'keep-alive', 'Content-Length': '9675'}
2024-05-13 22:40:29,811 ERROR   wandb-upload_3:2329230 [internal_api.py:upload_file():2765] upload_file response body: b"<?xml version='1.0' encoding='UTF-8'?><Error><Code>AccessDenied</Code><Message>Access denied.</Message><Details>We're sorry, but this service is not available in your location</Details></Error>"
2024-05-13 22:40:29,842 ERROR   Thread-11 :2329230 [step_upload.py:_handle_event():200] Failed to upload file: /nfs/datx/lyk/HiFT/wandb/run-20240513_224021-4xcljpov/files/wandb-summary.json
Traceback (most recent call last):
  File "/mounts/work/lyk/anaconda3/envs/torch2/lib/python3.8/site-packages/wandb/apis/normalize.py", line 41, in wrapper
    return func(*args, **kwargs)
  File "/mounts/work/lyk/anaconda3/envs/torch2/lib/python3.8/site-packages/wandb/sdk/lib/retry.py", line 212, in wrapped_fn
    return retrier(*args, **kargs)
  File "/mounts/work/lyk/anaconda3/envs/torch2/lib/python3.8/site-packages/wandb/sdk/lib/retry.py", line 131, in __call__
    result = self._call_fn(*args, **kwargs)
  File "/mounts/work/lyk/anaconda3/envs/torch2/lib/python3.8/site-packages/wandb/sdk/internal/internal_api.py", line 2787, in upload_file
    wandb._sentry.reraise(e)
  File "/mounts/work/lyk/anaconda3/envs/torch2/lib/python3.8/site-packages/wandb/analytics/sentry.py", line 154, in reraise
    raise exc.with_traceback(sys.exc_info()[2])
  File "/mounts/work/lyk/anaconda3/envs/torch2/lib/python3.8/site-packages/wandb/sdk/internal/internal_api.py", line 2759, in upload_file
    response.raise_for_status()
  File "/mounts/work/lyk/anaconda3/envs/torch2/lib/python3.8/site-packages/requests/models.py", line 1021, in raise_for_status
    raise HTTPError(http_error_msg, response=self)
requests.exceptions.HTTPError: 403 Client Error: Forbidden for url: https://storage.googleapis.com/wandb-production.appspot.com/neuzxm/huggingface/4xcljpov/wandb-summary.json?Expires=1715719229&GoogleAccessId=gorilla-files-url-signer-man%40wandb-production.iam.gserviceaccount.com&Signature=pvsxrT1uclUTUWuNRnGOFjaG4sAg8qDWlXnmFH4k5V%2FLOqsVJISnq57aiBGMj%2Fo9ZBTq6yH9eAbq3LAign1%2BtIzzOc%2FAy6VgzWgYLfpgfnf7RauAzX8WBzO0Avi2v58SMJJAEJK%2BbVzIfd6oUca0tDdBqRoBT7M7RQe%2FnJT%2F11wvk62bIi0HC%2FT8pnaRahxNtfLxoLRYngbaBP6%2BB7LOnubsoHjUiKMNytrune4NfR%2FL88awFguFSoqfkfPgoytd4IaRN6oSeAAzA7gDayOVLLU%2BwZvWeb1%2B9R413tiXVyjvPKlg93qO3usSw8oiPhfohDNpvmiEb8MVQ8nOOFMJHw%3D%3D

During handling of the above exception, another exception occurred:

Traceback (most recent call last):
  File "/mounts/work/lyk/anaconda3/envs/torch2/lib/python3.8/concurrent/futures/thread.py", line 57, in run
    result = self.fn(*self.args, **self.kwargs)
  File "/mounts/work/lyk/anaconda3/envs/torch2/lib/python3.8/site-packages/wandb/filesync/step_upload.py", line 288, in run_and_notify
    self._do_upload_sync(event)
  File "/mounts/work/lyk/anaconda3/envs/torch2/lib/python3.8/site-packages/wandb/filesync/step_upload.py", line 330, in _do_upload_sync
    job.run()
  File "/mounts/work/lyk/anaconda3/envs/torch2/lib/python3.8/site-packages/wandb/filesync/upload_job.py", line 57, in run
    self.push()
  File "/mounts/work/lyk/anaconda3/envs/torch2/lib/python3.8/site-packages/wandb/filesync/upload_job.py", line 125, in push
    self._api.upload_file_retry(
  File "/mounts/work/lyk/anaconda3/envs/torch2/lib/python3.8/site-packages/wandb/apis/normalize.py", line 51, in wrapper
    raise CommError(message, error)
wandb.errors.CommError: <Response [403]>
2024-05-13 22:40:29,842 ERROR   wandb-upload_2:2329230 [upload_job.py:push():134] Failed to upload file: /nfs/datx/lyk/HiFT/wandb/run-20240513_224021-4xcljpov/files/conda-environment.yaml
Traceback (most recent call last):
  File "/mounts/work/lyk/anaconda3/envs/torch2/lib/python3.8/site-packages/wandb/apis/normalize.py", line 41, in wrapper
    return func(*args, **kwargs)
  File "/mounts/work/lyk/anaconda3/envs/torch2/lib/python3.8/site-packages/wandb/sdk/lib/retry.py", line 212, in wrapped_fn
    return retrier(*args, **kargs)
  File "/mounts/work/lyk/anaconda3/envs/torch2/lib/python3.8/site-packages/wandb/sdk/lib/retry.py", line 131, in __call__
    result = self._call_fn(*args, **kwargs)
  File "/mounts/work/lyk/anaconda3/envs/torch2/lib/python3.8/site-packages/wandb/sdk/internal/internal_api.py", line 2787, in upload_file
    wandb._sentry.reraise(e)
  File "/mounts/work/lyk/anaconda3/envs/torch2/lib/python3.8/site-packages/wandb/analytics/sentry.py", line 154, in reraise
    raise exc.with_traceback(sys.exc_info()[2])
  File "/mounts/work/lyk/anaconda3/envs/torch2/lib/python3.8/site-packages/wandb/sdk/internal/internal_api.py", line 2759, in upload_file
    response.raise_for_status()
  File "/mounts/work/lyk/anaconda3/envs/torch2/lib/python3.8/site-packages/requests/models.py", line 1021, in raise_for_status
    raise HTTPError(http_error_msg, response=self)
requests.exceptions.HTTPError: 403 Client Error: Forbidden for url: https://storage.googleapis.com/wandb-production.appspot.com/neuzxm/huggingface/4xcljpov/conda-environment.yaml?Expires=1715719229&GoogleAccessId=gorilla-files-url-signer-man%40wandb-production.iam.gserviceaccount.com&Signature=XORCGDtdVH36hqJ1ZjLwx7FOjZCS3n%2FhWK27S%2BMOnpxEsFNj7pridgc3DJUTdQH%2FM6V0O8rj7Yt2ivm9U8QujAUW%2BhZWfTBaaWz66qUlxT3yaVvu5UA5WmUG%2BPgWs8kE%2Bxrit2IFk7fvQADBs%2B7%2BXbQJ5aNgtwxHLZUnSc9J9ESCYIX84OpGc157naLfDoEknpg1xTnfaO1yVfnEYbnVO5SqNXq0HGLt3B8FeoTA%2FULR8YvHpOEMA%2F2tbbVLrJKKN8hq%2FD9bf1swhz%2BQ1ZKxR9HPWCd%2Fv3DhGLEU7Yht5sh36SncHJGLXAUa%2FfflVZ7%2F4lrC7woAvt3V0EVo%2BNj8pg%3D%3D

During handling of the above exception, another exception occurred:

Traceback (most recent call last):
  File "/mounts/work/lyk/anaconda3/envs/torch2/lib/python3.8/site-packages/wandb/filesync/upload_job.py", line 125, in push
    self._api.upload_file_retry(
  File "/mounts/work/lyk/anaconda3/envs/torch2/lib/python3.8/site-packages/wandb/apis/normalize.py", line 51, in wrapper
    raise CommError(message, error)
wandb.errors.CommError: <Response [403]>
2024-05-13 22:40:29,842 ERROR   wandb-upload_4:2329230 [upload_job.py:push():134] Failed to upload file: /nfs/datx/lyk/HiFT/wandb/run-20240513_224021-4xcljpov/files/output.log
Traceback (most recent call last):
  File "/mounts/work/lyk/anaconda3/envs/torch2/lib/python3.8/site-packages/wandb/apis/normalize.py", line 41, in wrapper
    return func(*args, **kwargs)
  File "/mounts/work/lyk/anaconda3/envs/torch2/lib/python3.8/site-packages/wandb/sdk/lib/retry.py", line 212, in wrapped_fn
    return retrier(*args, **kargs)
  File "/mounts/work/lyk/anaconda3/envs/torch2/lib/python3.8/site-packages/wandb/sdk/lib/retry.py", line 131, in __call__
    result = self._call_fn(*args, **kwargs)
  File "/mounts/work/lyk/anaconda3/envs/torch2/lib/python3.8/site-packages/wandb/sdk/internal/internal_api.py", line 2787, in upload_file
    wandb._sentry.reraise(e)
  File "/mounts/work/lyk/anaconda3/envs/torch2/lib/python3.8/site-packages/wandb/analytics/sentry.py", line 154, in reraise
    raise exc.with_traceback(sys.exc_info()[2])
  File "/mounts/work/lyk/anaconda3/envs/torch2/lib/python3.8/site-packages/wandb/sdk/internal/internal_api.py", line 2759, in upload_file
    response.raise_for_status()
  File "/mounts/work/lyk/anaconda3/envs/torch2/lib/python3.8/site-packages/requests/models.py", line 1021, in raise_for_status
    raise HTTPError(http_error_msg, response=self)
requests.exceptions.HTTPError: 403 Client Error: Forbidden for url: https://storage.googleapis.com/wandb-production.appspot.com/neuzxm/huggingface/4xcljpov/output.log?Expires=1715719229&GoogleAccessId=gorilla-files-url-signer-man%40wandb-production.iam.gserviceaccount.com&Signature=xP897xTk2L40j6WcTZKxfvBCAKT3VLSYtCiHce66lMyV5qUKZvHbGX0xIHGxF%2Bp7WVg1m4U0hRV%2BvI%2F%2By78QD3mdJN8wJx7cLaHnOfwLQW4Y1mJFiUC5rk%2BaJ3Xq6zgMuXQppLWL5KniPMCXuUNu88KcLlH2nzG5q9uo16MnQx3SPmr%2FWcQQbe0DE3zXRjSXalQW7wbzr0AShY8Vd%2FPZLclfgvrrtzgSl6ymRUH5p%2FTzHdtz4W7qI%2BRNUOqU9Mp0R0qcPfER51jTBvZEq9cnv9Q3qOLlLQWaG%2F4gSEMn4rA1GUvU9Ng5q4QZW207X61Psi6V29N3FdOR3ou77U8L5w%3D%3D

During handling of the above exception, another exception occurred:

Traceback (most recent call last):
  File "/mounts/work/lyk/anaconda3/envs/torch2/lib/python3.8/site-packages/wandb/filesync/upload_job.py", line 125, in push
    self._api.upload_file_retry(
  File "/mounts/work/lyk/anaconda3/envs/torch2/lib/python3.8/site-packages/wandb/apis/normalize.py", line 51, in wrapper
    raise CommError(message, error)
wandb.errors.CommError: <Response [403]>
2024-05-13 22:40:29,842 ERROR   wandb-upload_3:2329230 [upload_job.py:push():134] Failed to upload file: /nfs/datx/lyk/HiFT/wandb/run-20240513_224021-4xcljpov/files/config.yaml
Traceback (most recent call last):
  File "/mounts/work/lyk/anaconda3/envs/torch2/lib/python3.8/site-packages/wandb/apis/normalize.py", line 41, in wrapper
    return func(*args, **kwargs)
  File "/mounts/work/lyk/anaconda3/envs/torch2/lib/python3.8/site-packages/wandb/sdk/lib/retry.py", line 212, in wrapped_fn
    return retrier(*args, **kargs)
  File "/mounts/work/lyk/anaconda3/envs/torch2/lib/python3.8/site-packages/wandb/sdk/lib/retry.py", line 131, in __call__
    result = self._call_fn(*args, **kwargs)
  File "/mounts/work/lyk/anaconda3/envs/torch2/lib/python3.8/site-packages/wandb/sdk/internal/internal_api.py", line 2787, in upload_file
    wandb._sentry.reraise(e)
  File "/mounts/work/lyk/anaconda3/envs/torch2/lib/python3.8/site-packages/wandb/analytics/sentry.py", line 154, in reraise
    raise exc.with_traceback(sys.exc_info()[2])
  File "/mounts/work/lyk/anaconda3/envs/torch2/lib/python3.8/site-packages/wandb/sdk/internal/internal_api.py", line 2759, in upload_file
    response.raise_for_status()
  File "/mounts/work/lyk/anaconda3/envs/torch2/lib/python3.8/site-packages/requests/models.py", line 1021, in raise_for_status
    raise HTTPError(http_error_msg, response=self)
requests.exceptions.HTTPError: 403 Client Error: Forbidden for url: https://storage.googleapis.com/wandb-production.appspot.com/neuzxm/huggingface/4xcljpov/config.yaml?Expires=1715719229&GoogleAccessId=gorilla-files-url-signer-man%40wandb-production.iam.gserviceaccount.com&Signature=Nn2cWLL8LLlrgOVv4klv3U5fHRTqpnYbYlppOILk%2FRNrCXIpYBQRlprcadViFHjwSDf4yVjSePmYEGFBR5dhUs4aYbneh7Hxp7MSs2w47EriWwOQnjLxWChLQwjrMaLgVrFRDsKqPC6qLoKV6P%2F5JtlvfkULJt6yU354z4Qvfh9FvdJHLRHY4LobiAcNirSuJDtkZ9RA%2BKUnEWCbCCG%2FFic0IXYPVKKoWc%2FiHLzBetcTS4yBI%2Bg0IlAo%2BRfxn7zymQOntFwpb5J8YXi06aLSpWpkbrs5Z7bfyCYT0IhyDoc1LNLxZUlHY4qtkez515yWuRltF0hLL3Qp6KVdHhGzwQ%3D%3D

During handling of the above exception, another exception occurred:

Traceback (most recent call last):
  File "/mounts/work/lyk/anaconda3/envs/torch2/lib/python3.8/site-packages/wandb/filesync/upload_job.py", line 125, in push
    self._api.upload_file_retry(
  File "/mounts/work/lyk/anaconda3/envs/torch2/lib/python3.8/site-packages/wandb/apis/normalize.py", line 51, in wrapper
    raise CommError(message, error)
wandb.errors.CommError: <Response [403]>
2024-05-13 22:40:29,899 ERROR   Thread-11 :2329230 [step_upload.py:_handle_event():200] Failed to upload file: /nfs/datx/lyk/HiFT/wandb/run-20240513_224021-4xcljpov/files/config.yaml
Traceback (most recent call last):
  File "/mounts/work/lyk/anaconda3/envs/torch2/lib/python3.8/site-packages/wandb/apis/normalize.py", line 41, in wrapper
    return func(*args, **kwargs)
  File "/mounts/work/lyk/anaconda3/envs/torch2/lib/python3.8/site-packages/wandb/sdk/lib/retry.py", line 212, in wrapped_fn
    return retrier(*args, **kargs)
  File "/mounts/work/lyk/anaconda3/envs/torch2/lib/python3.8/site-packages/wandb/sdk/lib/retry.py", line 131, in __call__
    result = self._call_fn(*args, **kwargs)
  File "/mounts/work/lyk/anaconda3/envs/torch2/lib/python3.8/site-packages/wandb/sdk/internal/internal_api.py", line 2787, in upload_file
    wandb._sentry.reraise(e)
  File "/mounts/work/lyk/anaconda3/envs/torch2/lib/python3.8/site-packages/wandb/analytics/sentry.py", line 154, in reraise
    raise exc.with_traceback(sys.exc_info()[2])
  File "/mounts/work/lyk/anaconda3/envs/torch2/lib/python3.8/site-packages/wandb/sdk/internal/internal_api.py", line 2759, in upload_file
    response.raise_for_status()
  File "/mounts/work/lyk/anaconda3/envs/torch2/lib/python3.8/site-packages/requests/models.py", line 1021, in raise_for_status
    raise HTTPError(http_error_msg, response=self)
requests.exceptions.HTTPError: 403 Client Error: Forbidden for url: https://storage.googleapis.com/wandb-production.appspot.com/neuzxm/huggingface/4xcljpov/config.yaml?Expires=1715719229&GoogleAccessId=gorilla-files-url-signer-man%40wandb-production.iam.gserviceaccount.com&Signature=Nn2cWLL8LLlrgOVv4klv3U5fHRTqpnYbYlppOILk%2FRNrCXIpYBQRlprcadViFHjwSDf4yVjSePmYEGFBR5dhUs4aYbneh7Hxp7MSs2w47EriWwOQnjLxWChLQwjrMaLgVrFRDsKqPC6qLoKV6P%2F5JtlvfkULJt6yU354z4Qvfh9FvdJHLRHY4LobiAcNirSuJDtkZ9RA%2BKUnEWCbCCG%2FFic0IXYPVKKoWc%2FiHLzBetcTS4yBI%2Bg0IlAo%2BRfxn7zymQOntFwpb5J8YXi06aLSpWpkbrs5Z7bfyCYT0IhyDoc1LNLxZUlHY4qtkez515yWuRltF0hLL3Qp6KVdHhGzwQ%3D%3D

During handling of the above exception, another exception occurred:

Traceback (most recent call last):
  File "/mounts/work/lyk/anaconda3/envs/torch2/lib/python3.8/concurrent/futures/thread.py", line 57, in run
    result = self.fn(*self.args, **self.kwargs)
  File "/mounts/work/lyk/anaconda3/envs/torch2/lib/python3.8/site-packages/wandb/filesync/step_upload.py", line 288, in run_and_notify
    self._do_upload_sync(event)
  File "/mounts/work/lyk/anaconda3/envs/torch2/lib/python3.8/site-packages/wandb/filesync/step_upload.py", line 330, in _do_upload_sync
    job.run()
  File "/mounts/work/lyk/anaconda3/envs/torch2/lib/python3.8/site-packages/wandb/filesync/upload_job.py", line 57, in run
    self.push()
  File "/mounts/work/lyk/anaconda3/envs/torch2/lib/python3.8/site-packages/wandb/filesync/upload_job.py", line 125, in push
    self._api.upload_file_retry(
  File "/mounts/work/lyk/anaconda3/envs/torch2/lib/python3.8/site-packages/wandb/apis/normalize.py", line 51, in wrapper
    raise CommError(message, error)
wandb.errors.CommError: <Response [403]>
2024-05-13 22:40:29,900 ERROR   Thread-11 :2329230 [step_upload.py:_handle_event():200] Failed to upload file: /nfs/datx/lyk/HiFT/wandb/run-20240513_224021-4xcljpov/files/output.log
Traceback (most recent call last):
  File "/mounts/work/lyk/anaconda3/envs/torch2/lib/python3.8/site-packages/wandb/apis/normalize.py", line 41, in wrapper
    return func(*args, **kwargs)
  File "/mounts/work/lyk/anaconda3/envs/torch2/lib/python3.8/site-packages/wandb/sdk/lib/retry.py", line 212, in wrapped_fn
    return retrier(*args, **kargs)
  File "/mounts/work/lyk/anaconda3/envs/torch2/lib/python3.8/site-packages/wandb/sdk/lib/retry.py", line 131, in __call__
    result = self._call_fn(*args, **kwargs)
  File "/mounts/work/lyk/anaconda3/envs/torch2/lib/python3.8/site-packages/wandb/sdk/internal/internal_api.py", line 2787, in upload_file
    wandb._sentry.reraise(e)
  File "/mounts/work/lyk/anaconda3/envs/torch2/lib/python3.8/site-packages/wandb/analytics/sentry.py", line 154, in reraise
    raise exc.with_traceback(sys.exc_info()[2])
  File "/mounts/work/lyk/anaconda3/envs/torch2/lib/python3.8/site-packages/wandb/sdk/internal/internal_api.py", line 2759, in upload_file
    response.raise_for_status()
  File "/mounts/work/lyk/anaconda3/envs/torch2/lib/python3.8/site-packages/requests/models.py", line 1021, in raise_for_status
    raise HTTPError(http_error_msg, response=self)
requests.exceptions.HTTPError: 403 Client Error: Forbidden for url: https://storage.googleapis.com/wandb-production.appspot.com/neuzxm/huggingface/4xcljpov/output.log?Expires=1715719229&GoogleAccessId=gorilla-files-url-signer-man%40wandb-production.iam.gserviceaccount.com&Signature=xP897xTk2L40j6WcTZKxfvBCAKT3VLSYtCiHce66lMyV5qUKZvHbGX0xIHGxF%2Bp7WVg1m4U0hRV%2BvI%2F%2By78QD3mdJN8wJx7cLaHnOfwLQW4Y1mJFiUC5rk%2BaJ3Xq6zgMuXQppLWL5KniPMCXuUNu88KcLlH2nzG5q9uo16MnQx3SPmr%2FWcQQbe0DE3zXRjSXalQW7wbzr0AShY8Vd%2FPZLclfgvrrtzgSl6ymRUH5p%2FTzHdtz4W7qI%2BRNUOqU9Mp0R0qcPfER51jTBvZEq9cnv9Q3qOLlLQWaG%2F4gSEMn4rA1GUvU9Ng5q4QZW207X61Psi6V29N3FdOR3ou77U8L5w%3D%3D

During handling of the above exception, another exception occurred:

Traceback (most recent call last):
  File "/mounts/work/lyk/anaconda3/envs/torch2/lib/python3.8/concurrent/futures/thread.py", line 57, in run
    result = self.fn(*self.args, **self.kwargs)
  File "/mounts/work/lyk/anaconda3/envs/torch2/lib/python3.8/site-packages/wandb/filesync/step_upload.py", line 288, in run_and_notify
    self._do_upload_sync(event)
  File "/mounts/work/lyk/anaconda3/envs/torch2/lib/python3.8/site-packages/wandb/filesync/step_upload.py", line 330, in _do_upload_sync
    job.run()
  File "/mounts/work/lyk/anaconda3/envs/torch2/lib/python3.8/site-packages/wandb/filesync/upload_job.py", line 57, in run
    self.push()
  File "/mounts/work/lyk/anaconda3/envs/torch2/lib/python3.8/site-packages/wandb/filesync/upload_job.py", line 125, in push
    self._api.upload_file_retry(
  File "/mounts/work/lyk/anaconda3/envs/torch2/lib/python3.8/site-packages/wandb/apis/normalize.py", line 51, in wrapper
    raise CommError(message, error)
wandb.errors.CommError: <Response [403]>
2024-05-13 22:40:29,900 ERROR   Thread-11 :2329230 [step_upload.py:_handle_event():200] Failed to upload file: /nfs/datx/lyk/HiFT/wandb/run-20240513_224021-4xcljpov/files/conda-environment.yaml
Traceback (most recent call last):
  File "/mounts/work/lyk/anaconda3/envs/torch2/lib/python3.8/site-packages/wandb/apis/normalize.py", line 41, in wrapper
    return func(*args, **kwargs)
  File "/mounts/work/lyk/anaconda3/envs/torch2/lib/python3.8/site-packages/wandb/sdk/lib/retry.py", line 212, in wrapped_fn
    return retrier(*args, **kargs)
  File "/mounts/work/lyk/anaconda3/envs/torch2/lib/python3.8/site-packages/wandb/sdk/lib/retry.py", line 131, in __call__
    result = self._call_fn(*args, **kwargs)
  File "/mounts/work/lyk/anaconda3/envs/torch2/lib/python3.8/site-packages/wandb/sdk/internal/internal_api.py", line 2787, in upload_file
    wandb._sentry.reraise(e)
  File "/mounts/work/lyk/anaconda3/envs/torch2/lib/python3.8/site-packages/wandb/analytics/sentry.py", line 154, in reraise
    raise exc.with_traceback(sys.exc_info()[2])
  File "/mounts/work/lyk/anaconda3/envs/torch2/lib/python3.8/site-packages/wandb/sdk/internal/internal_api.py", line 2759, in upload_file
    response.raise_for_status()
  File "/mounts/work/lyk/anaconda3/envs/torch2/lib/python3.8/site-packages/requests/models.py", line 1021, in raise_for_status
    raise HTTPError(http_error_msg, response=self)
requests.exceptions.HTTPError: 403 Client Error: Forbidden for url: https://storage.googleapis.com/wandb-production.appspot.com/neuzxm/huggingface/4xcljpov/conda-environment.yaml?Expires=1715719229&GoogleAccessId=gorilla-files-url-signer-man%40wandb-production.iam.gserviceaccount.com&Signature=XORCGDtdVH36hqJ1ZjLwx7FOjZCS3n%2FhWK27S%2BMOnpxEsFNj7pridgc3DJUTdQH%2FM6V0O8rj7Yt2ivm9U8QujAUW%2BhZWfTBaaWz66qUlxT3yaVvu5UA5WmUG%2BPgWs8kE%2Bxrit2IFk7fvQADBs%2B7%2BXbQJ5aNgtwxHLZUnSc9J9ESCYIX84OpGc157naLfDoEknpg1xTnfaO1yVfnEYbnVO5SqNXq0HGLt3B8FeoTA%2FULR8YvHpOEMA%2F2tbbVLrJKKN8hq%2FD9bf1swhz%2BQ1ZKxR9HPWCd%2Fv3DhGLEU7Yht5sh36SncHJGLXAUa%2FfflVZ7%2F4lrC7woAvt3V0EVo%2BNj8pg%3D%3D

During handling of the above exception, another exception occurred:

Traceback (most recent call last):
  File "/mounts/work/lyk/anaconda3/envs/torch2/lib/python3.8/concurrent/futures/thread.py", line 57, in run
    result = self.fn(*self.args, **self.kwargs)
  File "/mounts/work/lyk/anaconda3/envs/torch2/lib/python3.8/site-packages/wandb/filesync/step_upload.py", line 288, in run_and_notify
    self._do_upload_sync(event)
  File "/mounts/work/lyk/anaconda3/envs/torch2/lib/python3.8/site-packages/wandb/filesync/step_upload.py", line 330, in _do_upload_sync
    job.run()
  File "/mounts/work/lyk/anaconda3/envs/torch2/lib/python3.8/site-packages/wandb/filesync/upload_job.py", line 57, in run
    self.push()
  File "/mounts/work/lyk/anaconda3/envs/torch2/lib/python3.8/site-packages/wandb/filesync/upload_job.py", line 125, in push
    self._api.upload_file_retry(
  File "/mounts/work/lyk/anaconda3/envs/torch2/lib/python3.8/site-packages/wandb/apis/normalize.py", line 51, in wrapper
    raise CommError(message, error)
wandb.errors.CommError: <Response [403]>
2024-05-13 22:40:30,100 INFO    Thread-11 :2329230 [sender.py:transition_state():617] send defer: 11
2024-05-13 22:40:30,101 DEBUG   HandlerThread:2329230 [handler.py:handle_request():146] handle_request: defer
2024-05-13 22:40:30,101 INFO    HandlerThread:2329230 [handler.py:handle_request_defer():172] handle defer: 11
2024-05-13 22:40:30,102 DEBUG   SenderThread:2329230 [sender.py:send_request():409] send_request: defer
2024-05-13 22:40:30,102 INFO    SenderThread:2329230 [sender.py:send_request_defer():613] handle sender defer: 11
2024-05-13 22:40:30,102 INFO    SenderThread:2329230 [file_pusher.py:join():181] waiting for file pusher
2024-05-13 22:40:30,102 INFO    SenderThread:2329230 [sender.py:transition_state():617] send defer: 12
2024-05-13 22:40:30,102 DEBUG   HandlerThread:2329230 [handler.py:handle_request():146] handle_request: defer
2024-05-13 22:40:30,102 INFO    HandlerThread:2329230 [handler.py:handle_request_defer():172] handle defer: 12
2024-05-13 22:40:30,103 DEBUG   SenderThread:2329230 [sender.py:send_request():409] send_request: defer
2024-05-13 22:40:30,103 INFO    SenderThread:2329230 [sender.py:send_request_defer():613] handle sender defer: 12
2024-05-13 22:40:30,103 INFO    SenderThread:2329230 [file_stream.py:finish():595] file stream finish called
2024-05-13 22:40:30,448 INFO    SenderThread:2329230 [file_stream.py:finish():599] file stream finish is done
2024-05-13 22:40:30,449 INFO    SenderThread:2329230 [sender.py:transition_state():617] send defer: 13
2024-05-13 22:40:30,449 DEBUG   HandlerThread:2329230 [handler.py:handle_request():146] handle_request: defer
2024-05-13 22:40:30,449 INFO    HandlerThread:2329230 [handler.py:handle_request_defer():172] handle defer: 13
2024-05-13 22:40:30,450 DEBUG   SenderThread:2329230 [sender.py:send_request():409] send_request: defer
2024-05-13 22:40:30,450 INFO    SenderThread:2329230 [sender.py:send_request_defer():613] handle sender defer: 13
2024-05-13 22:40:30,450 INFO    SenderThread:2329230 [sender.py:transition_state():617] send defer: 14
2024-05-13 22:40:30,450 DEBUG   HandlerThread:2329230 [handler.py:handle_request():146] handle_request: defer
2024-05-13 22:40:30,451 DEBUG   SenderThread:2329230 [sender.py:send():382] send: final
2024-05-13 22:40:30,451 INFO    HandlerThread:2329230 [handler.py:handle_request_defer():172] handle defer: 14
2024-05-13 22:40:30,451 DEBUG   SenderThread:2329230 [sender.py:send():382] send: footer
2024-05-13 22:40:30,451 DEBUG   SenderThread:2329230 [sender.py:send_request():409] send_request: defer
2024-05-13 22:40:30,451 INFO    SenderThread:2329230 [sender.py:send_request_defer():613] handle sender defer: 14
2024-05-13 22:40:30,452 DEBUG   HandlerThread:2329230 [handler.py:handle_request():146] handle_request: poll_exit
2024-05-13 22:40:30,453 DEBUG   SenderThread:2329230 [sender.py:send_request():409] send_request: poll_exit
2024-05-13 22:40:30,453 DEBUG   HandlerThread:2329230 [handler.py:handle_request():146] handle_request: poll_exit
2024-05-13 22:40:30,454 DEBUG   SenderThread:2329230 [sender.py:send_request():409] send_request: poll_exit
2024-05-13 22:40:30,454 DEBUG   HandlerThread:2329230 [handler.py:handle_request():146] handle_request: server_info
2024-05-13 22:40:30,455 DEBUG   SenderThread:2329230 [sender.py:send_request():409] send_request: server_info
2024-05-13 22:40:30,457 DEBUG   HandlerThread:2329230 [handler.py:handle_request():146] handle_request: get_summary
2024-05-13 22:40:30,457 DEBUG   HandlerThread:2329230 [handler.py:handle_request():146] handle_request: sampled_history
2024-05-13 22:40:30,457 DEBUG   HandlerThread:2329230 [handler.py:handle_request():146] handle_request: internal_messages
2024-05-13 22:40:30,458 DEBUG   HandlerThread:2329230 [handler.py:handle_request():146] handle_request: job_info
2024-05-13 22:40:30,591 DEBUG   SenderThread:2329230 [sender.py:send_request():409] send_request: job_info
2024-05-13 22:40:30,591 INFO    MainThread:2329230 [wandb_run.py:_footer_history_summary_info():3837] rendering history
2024-05-13 22:40:30,591 INFO    MainThread:2329230 [wandb_run.py:_footer_history_summary_info():3869] rendering summary
2024-05-13 22:40:30,591 INFO    MainThread:2329230 [wandb_run.py:_footer_sync_info():3796] logging synced files
2024-05-13 22:40:30,592 DEBUG   HandlerThread:2329230 [handler.py:handle_request():146] handle_request: shutdown
2024-05-13 22:40:30,592 INFO    HandlerThread:2329230 [handler.py:finish():866] shutting down handler
2024-05-13 22:40:31,458 INFO    WriterThread:2329230 [datastore.py:close():294] close: /nfs/datx/lyk/HiFT/wandb/run-20240513_224021-4xcljpov/run-4xcljpov.wandb
2024-05-13 22:40:31,591 INFO    SenderThread:2329230 [sender.py:finish():1548] shutting down sender
2024-05-13 22:40:31,591 INFO    SenderThread:2329230 [file_pusher.py:finish():175] shutting down file pusher
2024-05-13 22:40:31,591 INFO    SenderThread:2329230 [file_pusher.py:join():181] waiting for file pusher
