2024-05-14 01:42:41,631 INFO    StreamThr :2412291 [internal.py:wandb_internal():86] W&B internal server running at pid: 2412291, started at: 2024-05-14 01:42:41.630327
2024-05-14 01:42:41,633 DEBUG   HandlerThread:2412291 [handler.py:handle_request():146] handle_request: status
2024-05-14 01:42:41,636 INFO    WriterThread:2412291 [datastore.py:open_for_write():85] open: /nfs/datx/lyk/HiFT/wandb/run-20240514_014241-uo5si8h8/run-uo5si8h8.wandb
2024-05-14 01:42:41,637 DEBUG   SenderThread:2412291 [sender.py:send():382] send: header
2024-05-14 01:42:41,637 DEBUG   SenderThread:2412291 [sender.py:send():382] send: run
2024-05-14 01:42:42,029 INFO    SenderThread:2412291 [dir_watcher.py:__init__():211] watching files in: /nfs/datx/lyk/HiFT/wandb/run-20240514_014241-uo5si8h8/files
2024-05-14 01:42:42,029 INFO    SenderThread:2412291 [sender.py:_start_run_threads():1136] run started: uo5si8h8 with start time 1715643761.632124
2024-05-14 01:42:42,037 DEBUG   HandlerThread:2412291 [handler.py:handle_request():146] handle_request: check_version
2024-05-14 01:42:42,037 DEBUG   SenderThread:2412291 [sender.py:send_request():409] send_request: check_version
2024-05-14 01:42:42,101 DEBUG   HandlerThread:2412291 [handler.py:handle_request():146] handle_request: run_start
2024-05-14 01:42:42,135 DEBUG   HandlerThread:2412291 [system_info.py:__init__():32] System info init
2024-05-14 01:42:42,135 DEBUG   HandlerThread:2412291 [system_info.py:__init__():47] System info init done
2024-05-14 01:42:42,135 INFO    HandlerThread:2412291 [system_monitor.py:start():194] Starting system monitor
2024-05-14 01:42:42,135 INFO    SystemMonitor:2412291 [system_monitor.py:_start():158] Starting system asset monitoring threads
2024-05-14 01:42:42,136 INFO    HandlerThread:2412291 [system_monitor.py:probe():214] Collecting system info
2024-05-14 01:42:42,138 INFO    SystemMonitor:2412291 [interfaces.py:start():190] Started cpu monitoring
2024-05-14 01:42:42,138 INFO    SystemMonitor:2412291 [interfaces.py:start():190] Started disk monitoring
2024-05-14 01:42:42,139 INFO    SystemMonitor:2412291 [interfaces.py:start():190] Started gpu monitoring
2024-05-14 01:42:42,141 INFO    SystemMonitor:2412291 [interfaces.py:start():190] Started memory monitoring
2024-05-14 01:42:42,141 INFO    SystemMonitor:2412291 [interfaces.py:start():190] Started network monitoring
2024-05-14 01:42:42,203 DEBUG   HandlerThread:2412291 [system_info.py:probe():196] Probing system
2024-05-14 01:42:42,213 DEBUG   HandlerThread:2412291 [gitlib.py:_init_repo():56] git repository is invalid
2024-05-14 01:42:42,213 DEBUG   HandlerThread:2412291 [system_info.py:probe():244] Probing system done
2024-05-14 01:42:42,213 DEBUG   HandlerThread:2412291 [system_monitor.py:probe():223] {'os': 'Linux-5.15.0-97-generic-x86_64-with-glibc2.10', 'python': '3.8.5', 'heartbeatAt': '2024-05-13T23:42:42.203725', 'startedAt': '2024-05-13T23:42:41.592705', 'docker': None, 'cuda': None, 'args': ('--model_type', 'llama', '--HiTaskType', 'CAUSAL_LM', '--optim', 'lamb_32bit', '--deepspeed', 'dsconfig/zero0_config.json', '--model_name_or_path', '/mounts/work/lyk/hierFT/llama2-7b', '--dataset_dir', 'data/alpaca_data', '--validation_split_percentage', '0.01', '--per_device_train_batch_size', '8', '--per_device_eval_batch_size', '8', '--do_train', '--do_eval', '--seed', '12345', '--fp16', '--num_train_epochs', '1', '--lr_scheduler_type', 'cosine', '--learning_rate', '2e-5', '--warmup_ratio', '0', '--weight_decay', '0', '--logging_strategy', 'steps', '--logging_steps', '10', '--save_strategy', 'steps', '--save_total_limit', '3', '--evaluation_strategy', 'steps', '--eval_steps', '100', '--save_steps', '200', '--preprocessing_num_workers', '4', '--max_seq_length', '512', '--output_dir', 'outputs/instruct_tuning/model', '--overwrite_output_dir', '--logging_first_step', 'True', '--lora_rank', '8', '--torch_dtype', 'float16', '--ddp_find_unused_parameters', 'False', '--load_best_model_at_end', '--hier_tuning', '--group_element', '1', '--optimizer_strategy', 'down2up'), 'state': 'running', 'program': 'examples/instruct_tuning.py', 'codePathLocal': 'examples/instruct_tuning.py', 'codePath': 'examples/instruct_tuning.py', 'host': 'rho2', 'username': 'yongkang', 'executable': '/mounts/work/lyk/anaconda3/envs/torch2/bin/python', 'cpu_count': 32, 'cpu_count_logical': 64, 'cpu_freq': {'current': 2227.907828125, 'min': 1500.0, 'max': 3000.0}, 'cpu_freq_per_core': [{'current': 1500.0, 'min': 1500.0, 'max': 3000.0}, {'current': 1500.0, 'min': 1500.0, 'max': 3000.0}, {'current': 1500.0, 'min': 1500.0, 'max': 3000.0}, {'current': 1500.0, 'min': 1500.0, 'max': 3000.0}, {'current': 3000.0, 'min': 1500.0, 'max': 3000.0}, {'current': 3000.0, 'min': 1500.0, 'max': 3000.0}, {'current': 1500.0, 'min': 1500.0, 'max': 3000.0}, {'current': 3700.341, 'min': 1500.0, 'max': 3000.0}, {'current': 1500.0, 'min': 1500.0, 'max': 3000.0}, {'current': 1500.0, 'min': 1500.0, 'max': 3000.0}, {'current': 1500.0, 'min': 1500.0, 'max': 3000.0}, {'current': 3000.0, 'min': 1500.0, 'max': 3000.0}, {'current': 1500.0, 'min': 1500.0, 'max': 3000.0}, {'current': 1500.0, 'min': 1500.0, 'max': 3000.0}, {'current': 3000.0, 'min': 1500.0, 'max': 3000.0}, {'current': 3699.489, 'min': 1500.0, 'max': 3000.0}, {'current': 1500.0, 'min': 1500.0, 'max': 3000.0}, {'current': 3000.0, 'min': 1500.0, 'max': 3000.0}, {'current': 1500.0, 'min': 1500.0, 'max': 3000.0}, {'current': 1500.0, 'min': 1500.0, 'max': 3000.0}, {'current': 1500.0, 'min': 1500.0, 'max': 3000.0}, {'current': 3645.479, 'min': 1500.0, 'max': 3000.0}, {'current': 1500.0, 'min': 1500.0, 'max': 3000.0}, {'current': 3000.0, 'min': 1500.0, 'max': 3000.0}, {'current': 3645.775, 'min': 1500.0, 'max': 3000.0}, {'current': 1500.0, 'min': 1500.0, 'max': 3000.0}, {'current': 1500.0, 'min': 1500.0, 'max': 3000.0}, {'current': 3000.0, 'min': 1500.0, 'max': 3000.0}, {'current': 3646.333, 'min': 1500.0, 'max': 3000.0}, {'current': 3115.079, 'min': 1500.0, 'max': 3000.0}, {'current': 1500.0, 'min': 1500.0, 'max': 3000.0}, {'current': 3000.0, 'min': 1500.0, 'max': 3000.0}, {'current': 3700.342, 'min': 1500.0, 'max': 3000.0}, {'current': 1500.0, 'min': 1500.0, 'max': 3000.0}, {'current': 1500.0, 'min': 1500.0, 'max': 3000.0}, {'current': 1500.0, 'min': 1500.0, 'max': 3000.0}, {'current': 1500.0, 'min': 1500.0, 'max': 3000.0}, {'current': 1500.0, 'min': 1500.0, 'max': 3000.0}, {'current': 1500.0, 'min': 1500.0, 'max': 3000.0}, {'current': 3000.0, 'min': 1500.0, 'max': 3000.0}, {'current': 1500.0, 'min': 1500.0, 'max': 3000.0}, {'current': 3700.344, 'min': 1500.0, 'max': 3000.0}, {'current': 1500.0, 'min': 1500.0, 'max': 3000.0}, {'current': 3000.0, 'min': 1500.0, 'max': 3000.0}, {'current': 1500.0, 'min': 1500.0, 'max': 3000.0}, {'current': 1500.0, 'min': 1500.0, 'max': 3000.0}, {'current': 1500.0, 'min': 1500.0, 'max': 3000.0}, {'current': 1500.0, 'min': 1500.0, 'max': 3000.0}, {'current': 3648.676, 'min': 1500.0, 'max': 3000.0}, {'current': 1500.0, 'min': 1500.0, 'max': 3000.0}, {'current': 1500.0, 'min': 1500.0, 'max': 3000.0}, {'current': 1500.0, 'min': 1500.0, 'max': 3000.0}, {'current': 1500.0, 'min': 1500.0, 'max': 3000.0}, {'current': 1500.0, 'min': 1500.0, 'max': 3000.0}, {'current': 1500.0, 'min': 1500.0, 'max': 3000.0}, {'current': 3000.0, 'min': 1500.0, 'max': 3000.0}, {'current': 3000.0, 'min': 1500.0, 'max': 3000.0}, {'current': 3000.0, 'min': 1500.0, 'max': 3000.0}, {'current': 1500.0, 'min': 1500.0, 'max': 3000.0}, {'current': 1500.0, 'min': 1500.0, 'max': 3000.0}, {'current': 3000.0, 'min': 1500.0, 'max': 3000.0}, {'current': 2200.0, 'min': 1500.0, 'max': 3000.0}, {'current': 1500.0, 'min': 1500.0, 'max': 3000.0}, {'current': 1500.0, 'min': 1500.0, 'max': 3000.0}], 'disk': {'/': {'total': 878.1072120666504, 'used': 56.620277404785156}}, 'gpu': 'NVIDIA RTX A6000', 'gpu_count': 8, 'gpu_devices': [{'name': 'NVIDIA RTX A6000', 'memory_total': 51527024640}, {'name': 'NVIDIA RTX A6000', 'memory_total': 51527024640}, {'name': 'NVIDIA RTX A6000', 'memory_total': 51527024640}, {'name': 'NVIDIA RTX A6000', 'memory_total': 51527024640}, {'name': 'NVIDIA RTX A6000', 'memory_total': 51527024640}, {'name': 'NVIDIA RTX A6000', 'memory_total': 51527024640}, {'name': 'NVIDIA RTX A6000', 'memory_total': 51527024640}, {'name': 'NVIDIA RTX A6000', 'memory_total': 51527024640}], 'memory': {'total': 251.7312126159668}}
2024-05-14 01:42:42,214 INFO    HandlerThread:2412291 [system_monitor.py:probe():224] Finished collecting system info
2024-05-14 01:42:42,214 INFO    HandlerThread:2412291 [system_monitor.py:probe():227] Publishing system info
2024-05-14 01:42:42,214 DEBUG   HandlerThread:2412291 [system_info.py:_save_pip():52] Saving list of pip packages installed into the current environment
2024-05-14 01:42:42,215 DEBUG   HandlerThread:2412291 [system_info.py:_save_pip():68] Saving pip packages done
2024-05-14 01:42:42,216 DEBUG   HandlerThread:2412291 [system_info.py:_save_conda():75] Saving list of conda packages installed into the current environment
2024-05-14 01:42:43,032 INFO    Thread-12 :2412291 [dir_watcher.py:_on_file_created():271] file/dir created: /nfs/datx/lyk/HiFT/wandb/run-20240514_014241-uo5si8h8/files/conda-environment.yaml
2024-05-14 01:42:43,033 INFO    Thread-12 :2412291 [dir_watcher.py:_on_file_created():271] file/dir created: /nfs/datx/lyk/HiFT/wandb/run-20240514_014241-uo5si8h8/files/requirements.txt
2024-05-14 01:42:46,039 INFO    Thread-12 :2412291 [dir_watcher.py:_on_file_modified():288] file/dir modified: /nfs/datx/lyk/HiFT/wandb/run-20240514_014241-uo5si8h8/files/conda-environment.yaml
2024-05-14 01:42:46,080 DEBUG   HandlerThread:2412291 [system_info.py:_save_conda():87] Saving conda packages done
2024-05-14 01:42:46,082 INFO    HandlerThread:2412291 [system_monitor.py:probe():229] Finished publishing system info
2024-05-14 01:42:46,092 DEBUG   SenderThread:2412291 [sender.py:send():382] send: files
2024-05-14 01:42:46,093 INFO    SenderThread:2412291 [sender.py:_save_file():1392] saving file wandb-metadata.json with policy now
2024-05-14 01:42:46,107 DEBUG   HandlerThread:2412291 [handler.py:handle_request():146] handle_request: stop_status
2024-05-14 01:42:46,108 DEBUG   SenderThread:2412291 [sender.py:send_request():409] send_request: stop_status
2024-05-14 01:42:46,110 DEBUG   HandlerThread:2412291 [handler.py:handle_request():146] handle_request: internal_messages
2024-05-14 01:42:46,296 DEBUG   SenderThread:2412291 [sender.py:send():382] send: telemetry
2024-05-14 01:42:46,296 DEBUG   SenderThread:2412291 [sender.py:send():382] send: config
2024-05-14 01:42:46,297 DEBUG   SenderThread:2412291 [sender.py:send():382] send: metric
2024-05-14 01:42:46,297 DEBUG   SenderThread:2412291 [sender.py:send():382] send: telemetry
2024-05-14 01:42:46,297 DEBUG   SenderThread:2412291 [sender.py:send():382] send: metric
2024-05-14 01:42:46,297 WARNING SenderThread:2412291 [sender.py:send_metric():1343] Seen metric with glob (shouldn't happen)
2024-05-14 01:42:46,297 DEBUG   SenderThread:2412291 [sender.py:send():382] send: telemetry
2024-05-14 01:42:46,533 ERROR   wandb-upload_0:2412291 [internal_api.py:upload_file():2761] upload_file exception https://storage.googleapis.com/wandb-production.appspot.com/neuzxm/huggingface/uo5si8h8/wandb-metadata.json?Expires=1715730166&GoogleAccessId=gorilla-files-url-signer-man%40wandb-production.iam.gserviceaccount.com&Signature=MX%2BQZcnLnrAU6PrfIlvBQq5bz4zUP9G0j2%2B3CnUZOYEkd%2BVKlz5vlttVk6UuN2p8EOP%2FrriE6jYW6Gv03u%2BM0CI3L9q7JR89JCxR7jqjEZHmf1wwx5dj94fkUzQvqk7wu431DPYdFGG2TDsCGvbcovutR92BHaUzczww3AEHCRYn0GeC66GSDsUbgnk%2BGUTsZN87aUJXbsiWDCNi9Ie2NIXGe8Zcc0B8mYtIK2srkeDoUvob3Sau8u3t9677oi67jGDU6yyOMmz3Rl0aDTdMlh0OE%2B9jzr0O2JCdV69NK8ObtZZXlXRgPmFe8MGTcHWpeolMqdc36dhHi%2FsV1phRKw%3D%3D: 403 Client Error: Forbidden for url: https://storage.googleapis.com/wandb-production.appspot.com/neuzxm/huggingface/uo5si8h8/wandb-metadata.json?Expires=1715730166&GoogleAccessId=gorilla-files-url-signer-man%40wandb-production.iam.gserviceaccount.com&Signature=MX%2BQZcnLnrAU6PrfIlvBQq5bz4zUP9G0j2%2B3CnUZOYEkd%2BVKlz5vlttVk6UuN2p8EOP%2FrriE6jYW6Gv03u%2BM0CI3L9q7JR89JCxR7jqjEZHmf1wwx5dj94fkUzQvqk7wu431DPYdFGG2TDsCGvbcovutR92BHaUzczww3AEHCRYn0GeC66GSDsUbgnk%2BGUTsZN87aUJXbsiWDCNi9Ie2NIXGe8Zcc0B8mYtIK2srkeDoUvob3Sau8u3t9677oi67jGDU6yyOMmz3Rl0aDTdMlh0OE%2B9jzr0O2JCdV69NK8ObtZZXlXRgPmFe8MGTcHWpeolMqdc36dhHi%2FsV1phRKw%3D%3D
2024-05-14 01:42:46,533 ERROR   wandb-upload_0:2412291 [internal_api.py:upload_file():2763] upload_file request headers: {'User-Agent': 'python-requests/2.31.0', 'Accept-Encoding': 'gzip, deflate, br', 'Accept': '*/*', 'Connection': 'keep-alive', 'Content-Length': '10147'}
2024-05-14 01:42:46,533 ERROR   wandb-upload_0:2412291 [internal_api.py:upload_file():2765] upload_file response body: b"<?xml version='1.0' encoding='UTF-8'?><Error><Code>AccessDenied</Code><Message>Access denied.</Message><Details>We're sorry, but this service is not available in your location</Details></Error>"
2024-05-14 01:42:46,620 ERROR   wandb-upload_0:2412291 [upload_job.py:push():134] Failed to upload file: /tmp/tmpb3l5a0v_wandb/q73g3qcv-wandb-metadata.json
Traceback (most recent call last):
  File "/mounts/work/lyk/anaconda3/envs/torch2/lib/python3.8/site-packages/wandb/apis/normalize.py", line 41, in wrapper
    return func(*args, **kwargs)
  File "/mounts/work/lyk/anaconda3/envs/torch2/lib/python3.8/site-packages/wandb/sdk/lib/retry.py", line 212, in wrapped_fn
    return retrier(*args, **kargs)
  File "/mounts/work/lyk/anaconda3/envs/torch2/lib/python3.8/site-packages/wandb/sdk/lib/retry.py", line 131, in __call__
    result = self._call_fn(*args, **kwargs)
  File "/mounts/work/lyk/anaconda3/envs/torch2/lib/python3.8/site-packages/wandb/sdk/internal/internal_api.py", line 2787, in upload_file
    wandb._sentry.reraise(e)
  File "/mounts/work/lyk/anaconda3/envs/torch2/lib/python3.8/site-packages/wandb/analytics/sentry.py", line 154, in reraise
    raise exc.with_traceback(sys.exc_info()[2])
  File "/mounts/work/lyk/anaconda3/envs/torch2/lib/python3.8/site-packages/wandb/sdk/internal/internal_api.py", line 2759, in upload_file
    response.raise_for_status()
  File "/mounts/work/lyk/anaconda3/envs/torch2/lib/python3.8/site-packages/requests/models.py", line 1021, in raise_for_status
    raise HTTPError(http_error_msg, response=self)
requests.exceptions.HTTPError: 403 Client Error: Forbidden for url: https://storage.googleapis.com/wandb-production.appspot.com/neuzxm/huggingface/uo5si8h8/wandb-metadata.json?Expires=1715730166&GoogleAccessId=gorilla-files-url-signer-man%40wandb-production.iam.gserviceaccount.com&Signature=MX%2BQZcnLnrAU6PrfIlvBQq5bz4zUP9G0j2%2B3CnUZOYEkd%2BVKlz5vlttVk6UuN2p8EOP%2FrriE6jYW6Gv03u%2BM0CI3L9q7JR89JCxR7jqjEZHmf1wwx5dj94fkUzQvqk7wu431DPYdFGG2TDsCGvbcovutR92BHaUzczww3AEHCRYn0GeC66GSDsUbgnk%2BGUTsZN87aUJXbsiWDCNi9Ie2NIXGe8Zcc0B8mYtIK2srkeDoUvob3Sau8u3t9677oi67jGDU6yyOMmz3Rl0aDTdMlh0OE%2B9jzr0O2JCdV69NK8ObtZZXlXRgPmFe8MGTcHWpeolMqdc36dhHi%2FsV1phRKw%3D%3D

During handling of the above exception, another exception occurred:

Traceback (most recent call last):
  File "/mounts/work/lyk/anaconda3/envs/torch2/lib/python3.8/site-packages/wandb/filesync/upload_job.py", line 125, in push
    self._api.upload_file_retry(
  File "/mounts/work/lyk/anaconda3/envs/torch2/lib/python3.8/site-packages/wandb/apis/normalize.py", line 51, in wrapper
    raise CommError(message, error)
wandb.errors.CommError: <Response [403]>
2024-05-14 01:42:46,644 ERROR   Thread-11 :2412291 [step_upload.py:_handle_event():200] Failed to upload file: /tmp/tmpb3l5a0v_wandb/q73g3qcv-wandb-metadata.json
Traceback (most recent call last):
  File "/mounts/work/lyk/anaconda3/envs/torch2/lib/python3.8/site-packages/wandb/apis/normalize.py", line 41, in wrapper
    return func(*args, **kwargs)
  File "/mounts/work/lyk/anaconda3/envs/torch2/lib/python3.8/site-packages/wandb/sdk/lib/retry.py", line 212, in wrapped_fn
    return retrier(*args, **kargs)
  File "/mounts/work/lyk/anaconda3/envs/torch2/lib/python3.8/site-packages/wandb/sdk/lib/retry.py", line 131, in __call__
    result = self._call_fn(*args, **kwargs)
  File "/mounts/work/lyk/anaconda3/envs/torch2/lib/python3.8/site-packages/wandb/sdk/internal/internal_api.py", line 2787, in upload_file
    wandb._sentry.reraise(e)
  File "/mounts/work/lyk/anaconda3/envs/torch2/lib/python3.8/site-packages/wandb/analytics/sentry.py", line 154, in reraise
    raise exc.with_traceback(sys.exc_info()[2])
  File "/mounts/work/lyk/anaconda3/envs/torch2/lib/python3.8/site-packages/wandb/sdk/internal/internal_api.py", line 2759, in upload_file
    response.raise_for_status()
  File "/mounts/work/lyk/anaconda3/envs/torch2/lib/python3.8/site-packages/requests/models.py", line 1021, in raise_for_status
    raise HTTPError(http_error_msg, response=self)
requests.exceptions.HTTPError: 403 Client Error: Forbidden for url: https://storage.googleapis.com/wandb-production.appspot.com/neuzxm/huggingface/uo5si8h8/wandb-metadata.json?Expires=1715730166&GoogleAccessId=gorilla-files-url-signer-man%40wandb-production.iam.gserviceaccount.com&Signature=MX%2BQZcnLnrAU6PrfIlvBQq5bz4zUP9G0j2%2B3CnUZOYEkd%2BVKlz5vlttVk6UuN2p8EOP%2FrriE6jYW6Gv03u%2BM0CI3L9q7JR89JCxR7jqjEZHmf1wwx5dj94fkUzQvqk7wu431DPYdFGG2TDsCGvbcovutR92BHaUzczww3AEHCRYn0GeC66GSDsUbgnk%2BGUTsZN87aUJXbsiWDCNi9Ie2NIXGe8Zcc0B8mYtIK2srkeDoUvob3Sau8u3t9677oi67jGDU6yyOMmz3Rl0aDTdMlh0OE%2B9jzr0O2JCdV69NK8ObtZZXlXRgPmFe8MGTcHWpeolMqdc36dhHi%2FsV1phRKw%3D%3D

During handling of the above exception, another exception occurred:

Traceback (most recent call last):
  File "/mounts/work/lyk/anaconda3/envs/torch2/lib/python3.8/concurrent/futures/thread.py", line 57, in run
    result = self.fn(*self.args, **self.kwargs)
  File "/mounts/work/lyk/anaconda3/envs/torch2/lib/python3.8/site-packages/wandb/filesync/step_upload.py", line 288, in run_and_notify
    self._do_upload_sync(event)
  File "/mounts/work/lyk/anaconda3/envs/torch2/lib/python3.8/site-packages/wandb/filesync/step_upload.py", line 330, in _do_upload_sync
    job.run()
  File "/mounts/work/lyk/anaconda3/envs/torch2/lib/python3.8/site-packages/wandb/filesync/upload_job.py", line 57, in run
    self.push()
  File "/mounts/work/lyk/anaconda3/envs/torch2/lib/python3.8/site-packages/wandb/filesync/upload_job.py", line 125, in push
    self._api.upload_file_retry(
  File "/mounts/work/lyk/anaconda3/envs/torch2/lib/python3.8/site-packages/wandb/apis/normalize.py", line 51, in wrapper
    raise CommError(message, error)
wandb.errors.CommError: <Response [403]>
2024-05-14 01:42:47,041 INFO    Thread-12 :2412291 [dir_watcher.py:_on_file_created():271] file/dir created: /nfs/datx/lyk/HiFT/wandb/run-20240514_014241-uo5si8h8/files/wandb-metadata.json
2024-05-14 01:42:47,041 INFO    Thread-12 :2412291 [dir_watcher.py:_on_file_created():271] file/dir created: /nfs/datx/lyk/HiFT/wandb/run-20240514_014241-uo5si8h8/files/output.log
2024-05-14 01:42:47,299 DEBUG   HandlerThread:2412291 [handler.py:handle_request():146] handle_request: status_report
2024-05-14 01:42:47,427 DEBUG   SenderThread:2412291 [sender.py:send():382] send: exit
2024-05-14 01:42:47,427 INFO    SenderThread:2412291 [sender.py:send_exit():589] handling exit code: 1
2024-05-14 01:42:47,428 INFO    SenderThread:2412291 [sender.py:send_exit():591] handling runtime: 5
2024-05-14 01:42:47,430 INFO    SenderThread:2412291 [sender.py:_save_file():1392] saving file wandb-summary.json with policy end
2024-05-14 01:42:47,430 INFO    SenderThread:2412291 [sender.py:send_exit():597] send defer
2024-05-14 01:42:47,430 DEBUG   HandlerThread:2412291 [handler.py:handle_request():146] handle_request: defer
2024-05-14 01:42:47,430 INFO    HandlerThread:2412291 [handler.py:handle_request_defer():172] handle defer: 0
2024-05-14 01:42:47,430 DEBUG   SenderThread:2412291 [sender.py:send_request():409] send_request: defer
2024-05-14 01:42:47,431 INFO    SenderThread:2412291 [sender.py:send_request_defer():613] handle sender defer: 0
2024-05-14 01:42:47,431 INFO    SenderThread:2412291 [sender.py:transition_state():617] send defer: 1
2024-05-14 01:42:47,431 DEBUG   HandlerThread:2412291 [handler.py:handle_request():146] handle_request: defer
2024-05-14 01:42:47,431 INFO    HandlerThread:2412291 [handler.py:handle_request_defer():172] handle defer: 1
2024-05-14 01:42:47,431 DEBUG   SenderThread:2412291 [sender.py:send_request():409] send_request: defer
2024-05-14 01:42:47,431 INFO    SenderThread:2412291 [sender.py:send_request_defer():613] handle sender defer: 1
2024-05-14 01:42:47,431 INFO    SenderThread:2412291 [sender.py:transition_state():617] send defer: 2
2024-05-14 01:42:47,431 DEBUG   HandlerThread:2412291 [handler.py:handle_request():146] handle_request: defer
2024-05-14 01:42:47,431 INFO    HandlerThread:2412291 [handler.py:handle_request_defer():172] handle defer: 2
2024-05-14 01:42:47,431 INFO    HandlerThread:2412291 [system_monitor.py:finish():203] Stopping system monitor
2024-05-14 01:42:47,432 DEBUG   SystemMonitor:2412291 [system_monitor.py:_start():172] Starting system metrics aggregation loop
2024-05-14 01:42:47,432 INFO    HandlerThread:2412291 [interfaces.py:finish():202] Joined cpu monitor
2024-05-14 01:42:47,432 DEBUG   SystemMonitor:2412291 [system_monitor.py:_start():179] Finished system metrics aggregation loop
2024-05-14 01:42:47,433 INFO    HandlerThread:2412291 [interfaces.py:finish():202] Joined disk monitor
2024-05-14 01:42:47,433 DEBUG   SystemMonitor:2412291 [system_monitor.py:_start():183] Publishing last batch of metrics
2024-05-14 01:42:48,047 INFO    Thread-12 :2412291 [dir_watcher.py:_on_file_created():271] file/dir created: /nfs/datx/lyk/HiFT/wandb/run-20240514_014241-uo5si8h8/files/wandb-summary.json
2024-05-14 01:42:48,065 INFO    HandlerThread:2412291 [interfaces.py:finish():202] Joined gpu monitor
2024-05-14 01:42:48,065 INFO    HandlerThread:2412291 [interfaces.py:finish():202] Joined memory monitor
2024-05-14 01:42:48,065 INFO    HandlerThread:2412291 [interfaces.py:finish():202] Joined network monitor
2024-05-14 01:42:48,065 DEBUG   SenderThread:2412291 [sender.py:send_request():409] send_request: defer
2024-05-14 01:42:48,065 INFO    SenderThread:2412291 [sender.py:send_request_defer():613] handle sender defer: 2
2024-05-14 01:42:48,065 INFO    SenderThread:2412291 [sender.py:transition_state():617] send defer: 3
2024-05-14 01:42:48,066 DEBUG   SenderThread:2412291 [sender.py:send():382] send: stats
2024-05-14 01:42:48,066 DEBUG   HandlerThread:2412291 [handler.py:handle_request():146] handle_request: defer
2024-05-14 01:42:48,066 INFO    HandlerThread:2412291 [handler.py:handle_request_defer():172] handle defer: 3
2024-05-14 01:42:48,066 DEBUG   SenderThread:2412291 [sender.py:send_request():409] send_request: defer
2024-05-14 01:42:48,066 INFO    SenderThread:2412291 [sender.py:send_request_defer():613] handle sender defer: 3
2024-05-14 01:42:48,066 INFO    SenderThread:2412291 [sender.py:transition_state():617] send defer: 4
2024-05-14 01:42:48,067 DEBUG   HandlerThread:2412291 [handler.py:handle_request():146] handle_request: defer
2024-05-14 01:42:48,067 INFO    HandlerThread:2412291 [handler.py:handle_request_defer():172] handle defer: 4
2024-05-14 01:42:48,067 DEBUG   SenderThread:2412291 [sender.py:send_request():409] send_request: defer
2024-05-14 01:42:48,067 INFO    SenderThread:2412291 [sender.py:send_request_defer():613] handle sender defer: 4
2024-05-14 01:42:48,067 INFO    SenderThread:2412291 [sender.py:transition_state():617] send defer: 5
2024-05-14 01:42:48,067 DEBUG   HandlerThread:2412291 [handler.py:handle_request():146] handle_request: defer
2024-05-14 01:42:48,067 INFO    HandlerThread:2412291 [handler.py:handle_request_defer():172] handle defer: 5
2024-05-14 01:42:48,067 DEBUG   SenderThread:2412291 [sender.py:send():382] send: summary
2024-05-14 01:42:48,074 INFO    SenderThread:2412291 [sender.py:_save_file():1392] saving file wandb-summary.json with policy end
2024-05-14 01:42:48,074 DEBUG   SenderThread:2412291 [sender.py:send_request():409] send_request: defer
2024-05-14 01:42:48,074 INFO    SenderThread:2412291 [sender.py:send_request_defer():613] handle sender defer: 5
2024-05-14 01:42:48,074 INFO    SenderThread:2412291 [sender.py:transition_state():617] send defer: 6
2024-05-14 01:42:48,074 DEBUG   HandlerThread:2412291 [handler.py:handle_request():146] handle_request: defer
2024-05-14 01:42:48,074 INFO    HandlerThread:2412291 [handler.py:handle_request_defer():172] handle defer: 6
2024-05-14 01:42:48,074 DEBUG   SenderThread:2412291 [sender.py:send_request():409] send_request: defer
2024-05-14 01:42:48,074 INFO    SenderThread:2412291 [sender.py:send_request_defer():613] handle sender defer: 6
2024-05-14 01:42:48,078 DEBUG   HandlerThread:2412291 [handler.py:handle_request():146] handle_request: status_report
2024-05-14 01:42:48,262 INFO    SenderThread:2412291 [sender.py:transition_state():617] send defer: 7
2024-05-14 01:42:48,262 DEBUG   HandlerThread:2412291 [handler.py:handle_request():146] handle_request: defer
2024-05-14 01:42:48,262 INFO    HandlerThread:2412291 [handler.py:handle_request_defer():172] handle defer: 7
2024-05-14 01:42:48,262 DEBUG   SenderThread:2412291 [sender.py:send_request():409] send_request: defer
2024-05-14 01:42:48,262 INFO    SenderThread:2412291 [sender.py:send_request_defer():613] handle sender defer: 7
2024-05-14 01:42:48,427 DEBUG   HandlerThread:2412291 [handler.py:handle_request():146] handle_request: poll_exit
2024-05-14 01:42:49,048 INFO    Thread-12 :2412291 [dir_watcher.py:_on_file_modified():288] file/dir modified: /nfs/datx/lyk/HiFT/wandb/run-20240514_014241-uo5si8h8/files/config.yaml
2024-05-14 01:42:49,048 INFO    Thread-12 :2412291 [dir_watcher.py:_on_file_modified():288] file/dir modified: /nfs/datx/lyk/HiFT/wandb/run-20240514_014241-uo5si8h8/files/output.log
2024-05-14 01:42:49,048 INFO    Thread-12 :2412291 [dir_watcher.py:_on_file_modified():288] file/dir modified: /nfs/datx/lyk/HiFT/wandb/run-20240514_014241-uo5si8h8/files/wandb-summary.json
2024-05-14 01:42:49,403 INFO    SenderThread:2412291 [sender.py:transition_state():617] send defer: 8
2024-05-14 01:42:49,404 DEBUG   SenderThread:2412291 [sender.py:send_request():409] send_request: poll_exit
2024-05-14 01:42:49,404 DEBUG   HandlerThread:2412291 [handler.py:handle_request():146] handle_request: defer
2024-05-14 01:42:49,404 INFO    HandlerThread:2412291 [handler.py:handle_request_defer():172] handle defer: 8
2024-05-14 01:42:49,404 DEBUG   SenderThread:2412291 [sender.py:send_request():409] send_request: defer
2024-05-14 01:42:49,404 INFO    SenderThread:2412291 [sender.py:send_request_defer():613] handle sender defer: 8
2024-05-14 01:42:49,404 INFO    SenderThread:2412291 [job_builder.py:build():298] Attempting to build job artifact
2024-05-14 01:42:49,406 INFO    SenderThread:2412291 [job_builder.py:_get_source_type():439] no source found
2024-05-14 01:42:49,406 INFO    SenderThread:2412291 [sender.py:transition_state():617] send defer: 9
2024-05-14 01:42:49,406 DEBUG   HandlerThread:2412291 [handler.py:handle_request():146] handle_request: defer
2024-05-14 01:42:49,406 INFO    HandlerThread:2412291 [handler.py:handle_request_defer():172] handle defer: 9
2024-05-14 01:42:49,406 DEBUG   SenderThread:2412291 [sender.py:send_request():409] send_request: defer
2024-05-14 01:42:49,406 INFO    SenderThread:2412291 [sender.py:send_request_defer():613] handle sender defer: 9
2024-05-14 01:42:49,406 INFO    SenderThread:2412291 [dir_watcher.py:finish():358] shutting down directory watcher
2024-05-14 01:42:49,429 DEBUG   HandlerThread:2412291 [handler.py:handle_request():146] handle_request: poll_exit
2024-05-14 01:42:50,050 INFO    SenderThread:2412291 [dir_watcher.py:_on_file_modified():288] file/dir modified: /nfs/datx/lyk/HiFT/wandb/run-20240514_014241-uo5si8h8/files/output.log
2024-05-14 01:42:50,051 INFO    SenderThread:2412291 [dir_watcher.py:finish():388] scan: /nfs/datx/lyk/HiFT/wandb/run-20240514_014241-uo5si8h8/files
2024-05-14 01:42:50,051 INFO    SenderThread:2412291 [dir_watcher.py:finish():402] scan save: /nfs/datx/lyk/HiFT/wandb/run-20240514_014241-uo5si8h8/files/wandb-summary.json wandb-summary.json
2024-05-14 01:42:50,052 INFO    SenderThread:2412291 [dir_watcher.py:finish():402] scan save: /nfs/datx/lyk/HiFT/wandb/run-20240514_014241-uo5si8h8/files/requirements.txt requirements.txt
2024-05-14 01:42:50,052 INFO    SenderThread:2412291 [dir_watcher.py:finish():402] scan save: /nfs/datx/lyk/HiFT/wandb/run-20240514_014241-uo5si8h8/files/conda-environment.yaml conda-environment.yaml
2024-05-14 01:42:50,060 INFO    SenderThread:2412291 [dir_watcher.py:finish():402] scan save: /nfs/datx/lyk/HiFT/wandb/run-20240514_014241-uo5si8h8/files/config.yaml config.yaml
2024-05-14 01:42:50,060 INFO    SenderThread:2412291 [dir_watcher.py:finish():402] scan save: /nfs/datx/lyk/HiFT/wandb/run-20240514_014241-uo5si8h8/files/wandb-metadata.json wandb-metadata.json
2024-05-14 01:42:50,060 INFO    SenderThread:2412291 [dir_watcher.py:finish():402] scan save: /nfs/datx/lyk/HiFT/wandb/run-20240514_014241-uo5si8h8/files/output.log output.log
2024-05-14 01:42:50,060 INFO    SenderThread:2412291 [sender.py:transition_state():617] send defer: 10
2024-05-14 01:42:50,060 DEBUG   SenderThread:2412291 [sender.py:send_request():409] send_request: poll_exit
2024-05-14 01:42:50,061 DEBUG   HandlerThread:2412291 [handler.py:handle_request():146] handle_request: defer
2024-05-14 01:42:50,061 INFO    HandlerThread:2412291 [handler.py:handle_request_defer():172] handle defer: 10
2024-05-14 01:42:50,065 DEBUG   SenderThread:2412291 [sender.py:send_request():409] send_request: defer
2024-05-14 01:42:50,065 INFO    SenderThread:2412291 [sender.py:send_request_defer():613] handle sender defer: 10
2024-05-14 01:42:50,065 INFO    SenderThread:2412291 [file_pusher.py:finish():175] shutting down file pusher
2024-05-14 01:42:50,320 ERROR   wandb-upload_1:2412291 [internal_api.py:upload_file():2761] upload_file exception https://storage.googleapis.com/wandb-production.appspot.com/neuzxm/huggingface/uo5si8h8/requirements.txt?Expires=1715730170&GoogleAccessId=gorilla-files-url-signer-man%40wandb-production.iam.gserviceaccount.com&Signature=izC0ZNZ3BI4sIsK%2BrC%2BfIc2v8gLNkNOVc2fJYSahgPQZGB1NtwZVXWk9aAczz7hagI4%2B40e698%2FaIXeNdEQ%2F4nUGRhY2rXk4y5vKFK9JelSnsGrPJ6pxk1%2FDLi9Nw16QWrnLUCM7Z%2Fx%2FGyq5H7Wcjt4IUTmA599byxyAavYjXaLo5fqKHg2k4DwvmK8dyRB2tOvZe5z7AqueSTPDWpfaqI7NLKqDB0vpk%2BKGMK6h3UJWNucQWlFmet4pKoZFj%2F87cjvP5awFxuojLfrCR3kjC3gLGlRUz%2FcM8Qt%2BDzl6psEman%2BMBnuwe%2BIPrBW2%2Fs%2FGl6eKtB3yDAvODF2qZLOxtA%3D%3D: 403 Client Error: Forbidden for url: https://storage.googleapis.com/wandb-production.appspot.com/neuzxm/huggingface/uo5si8h8/requirements.txt?Expires=1715730170&GoogleAccessId=gorilla-files-url-signer-man%40wandb-production.iam.gserviceaccount.com&Signature=izC0ZNZ3BI4sIsK%2BrC%2BfIc2v8gLNkNOVc2fJYSahgPQZGB1NtwZVXWk9aAczz7hagI4%2B40e698%2FaIXeNdEQ%2F4nUGRhY2rXk4y5vKFK9JelSnsGrPJ6pxk1%2FDLi9Nw16QWrnLUCM7Z%2Fx%2FGyq5H7Wcjt4IUTmA599byxyAavYjXaLo5fqKHg2k4DwvmK8dyRB2tOvZe5z7AqueSTPDWpfaqI7NLKqDB0vpk%2BKGMK6h3UJWNucQWlFmet4pKoZFj%2F87cjvP5awFxuojLfrCR3kjC3gLGlRUz%2FcM8Qt%2BDzl6psEman%2BMBnuwe%2BIPrBW2%2Fs%2FGl6eKtB3yDAvODF2qZLOxtA%3D%3D
2024-05-14 01:42:50,320 ERROR   wandb-upload_1:2412291 [internal_api.py:upload_file():2763] upload_file request headers: {'User-Agent': 'python-requests/2.31.0', 'Accept-Encoding': 'gzip, deflate, br', 'Accept': '*/*', 'Connection': 'keep-alive', 'Content-Length': '2434'}
2024-05-14 01:42:50,320 ERROR   wandb-upload_1:2412291 [internal_api.py:upload_file():2765] upload_file response body: b"<?xml version='1.0' encoding='UTF-8'?><Error><Code>AccessDenied</Code><Message>Access denied.</Message><Details>We're sorry, but this service is not available in your location</Details></Error>"
2024-05-14 01:42:50,338 ERROR   wandb-upload_1:2412291 [upload_job.py:push():134] Failed to upload file: /nfs/datx/lyk/HiFT/wandb/run-20240514_014241-uo5si8h8/files/requirements.txt
Traceback (most recent call last):
  File "/mounts/work/lyk/anaconda3/envs/torch2/lib/python3.8/site-packages/wandb/apis/normalize.py", line 41, in wrapper
    return func(*args, **kwargs)
  File "/mounts/work/lyk/anaconda3/envs/torch2/lib/python3.8/site-packages/wandb/sdk/lib/retry.py", line 212, in wrapped_fn
    return retrier(*args, **kargs)
  File "/mounts/work/lyk/anaconda3/envs/torch2/lib/python3.8/site-packages/wandb/sdk/lib/retry.py", line 131, in __call__
    result = self._call_fn(*args, **kwargs)
  File "/mounts/work/lyk/anaconda3/envs/torch2/lib/python3.8/site-packages/wandb/sdk/internal/internal_api.py", line 2787, in upload_file
    wandb._sentry.reraise(e)
  File "/mounts/work/lyk/anaconda3/envs/torch2/lib/python3.8/site-packages/wandb/analytics/sentry.py", line 154, in reraise
    raise exc.with_traceback(sys.exc_info()[2])
  File "/mounts/work/lyk/anaconda3/envs/torch2/lib/python3.8/site-packages/wandb/sdk/internal/internal_api.py", line 2759, in upload_file
    response.raise_for_status()
  File "/mounts/work/lyk/anaconda3/envs/torch2/lib/python3.8/site-packages/requests/models.py", line 1021, in raise_for_status
    raise HTTPError(http_error_msg, response=self)
requests.exceptions.HTTPError: 403 Client Error: Forbidden for url: https://storage.googleapis.com/wandb-production.appspot.com/neuzxm/huggingface/uo5si8h8/requirements.txt?Expires=1715730170&GoogleAccessId=gorilla-files-url-signer-man%40wandb-production.iam.gserviceaccount.com&Signature=izC0ZNZ3BI4sIsK%2BrC%2BfIc2v8gLNkNOVc2fJYSahgPQZGB1NtwZVXWk9aAczz7hagI4%2B40e698%2FaIXeNdEQ%2F4nUGRhY2rXk4y5vKFK9JelSnsGrPJ6pxk1%2FDLi9Nw16QWrnLUCM7Z%2Fx%2FGyq5H7Wcjt4IUTmA599byxyAavYjXaLo5fqKHg2k4DwvmK8dyRB2tOvZe5z7AqueSTPDWpfaqI7NLKqDB0vpk%2BKGMK6h3UJWNucQWlFmet4pKoZFj%2F87cjvP5awFxuojLfrCR3kjC3gLGlRUz%2FcM8Qt%2BDzl6psEman%2BMBnuwe%2BIPrBW2%2Fs%2FGl6eKtB3yDAvODF2qZLOxtA%3D%3D

During handling of the above exception, another exception occurred:

Traceback (most recent call last):
  File "/mounts/work/lyk/anaconda3/envs/torch2/lib/python3.8/site-packages/wandb/filesync/upload_job.py", line 125, in push
    self._api.upload_file_retry(
  File "/mounts/work/lyk/anaconda3/envs/torch2/lib/python3.8/site-packages/wandb/apis/normalize.py", line 51, in wrapper
    raise CommError(message, error)
wandb.errors.CommError: <Response [403]>
2024-05-14 01:42:50,357 ERROR   wandb-upload_0:2412291 [internal_api.py:upload_file():2761] upload_file exception https://storage.googleapis.com/wandb-production.appspot.com/neuzxm/huggingface/uo5si8h8/wandb-summary.json?Expires=1715730170&GoogleAccessId=gorilla-files-url-signer-man%40wandb-production.iam.gserviceaccount.com&Signature=TFnhE9FWHq3sEbVnFWYWT8R0HdFm%2BA7Z%2Fm8L7CVIx%2BaSrxqN%2F%2BTryWR82qg32xQCfYxLrKS%2FXRFHEOi10Sf43Z6Je7Od67f8U5sw2QbWfABugD6wQbZfTzFRAvFLPaHgZS3NrLouZP9YRBRXYZN2QMPzzlgQuzrGstyHdfdoGayRmG3sC%2BcoLtvnuBvhTMx%2BSUeTfXtSTbnP7W0X5C443RR9ohyW2nSaeouXx36PwaRLSEoPOLd0V8%2BJ2UYm9914POrbLMGnMM3OzkT%2Fu4pq%2ByG2KHmE6LwEt06S7Gd%2FGZhPs3pKuh4onS%2FR69jnBG%2FiBikI12BPzlyCjXkO5KXL%2BQ%3D%3D: 403 Client Error: Forbidden for url: https://storage.googleapis.com/wandb-production.appspot.com/neuzxm/huggingface/uo5si8h8/wandb-summary.json?Expires=1715730170&GoogleAccessId=gorilla-files-url-signer-man%40wandb-production.iam.gserviceaccount.com&Signature=TFnhE9FWHq3sEbVnFWYWT8R0HdFm%2BA7Z%2Fm8L7CVIx%2BaSrxqN%2F%2BTryWR82qg32xQCfYxLrKS%2FXRFHEOi10Sf43Z6Je7Od67f8U5sw2QbWfABugD6wQbZfTzFRAvFLPaHgZS3NrLouZP9YRBRXYZN2QMPzzlgQuzrGstyHdfdoGayRmG3sC%2BcoLtvnuBvhTMx%2BSUeTfXtSTbnP7W0X5C443RR9ohyW2nSaeouXx36PwaRLSEoPOLd0V8%2BJ2UYm9914POrbLMGnMM3OzkT%2Fu4pq%2ByG2KHmE6LwEt06S7Gd%2FGZhPs3pKuh4onS%2FR69jnBG%2FiBikI12BPzlyCjXkO5KXL%2BQ%3D%3D
2024-05-14 01:42:50,357 ERROR   wandb-upload_0:2412291 [internal_api.py:upload_file():2763] upload_file request headers: {'User-Agent': 'python-requests/2.31.0', 'Accept-Encoding': 'gzip, deflate, br', 'Accept': '*/*', 'Connection': 'keep-alive', 'Content-Length': '26'}
2024-05-14 01:42:50,357 ERROR   wandb-upload_0:2412291 [internal_api.py:upload_file():2765] upload_file response body: b"<?xml version='1.0' encoding='UTF-8'?><Error><Code>AccessDenied</Code><Message>Access denied.</Message><Details>We're sorry, but this service is not available in your location</Details></Error>"
2024-05-14 01:42:50,359 ERROR   Thread-11 :2412291 [step_upload.py:_handle_event():200] Failed to upload file: /nfs/datx/lyk/HiFT/wandb/run-20240514_014241-uo5si8h8/files/requirements.txt
Traceback (most recent call last):
  File "/mounts/work/lyk/anaconda3/envs/torch2/lib/python3.8/site-packages/wandb/apis/normalize.py", line 41, in wrapper
    return func(*args, **kwargs)
  File "/mounts/work/lyk/anaconda3/envs/torch2/lib/python3.8/site-packages/wandb/sdk/lib/retry.py", line 212, in wrapped_fn
    return retrier(*args, **kargs)
  File "/mounts/work/lyk/anaconda3/envs/torch2/lib/python3.8/site-packages/wandb/sdk/lib/retry.py", line 131, in __call__
    result = self._call_fn(*args, **kwargs)
  File "/mounts/work/lyk/anaconda3/envs/torch2/lib/python3.8/site-packages/wandb/sdk/internal/internal_api.py", line 2787, in upload_file
    wandb._sentry.reraise(e)
  File "/mounts/work/lyk/anaconda3/envs/torch2/lib/python3.8/site-packages/wandb/analytics/sentry.py", line 154, in reraise
    raise exc.with_traceback(sys.exc_info()[2])
  File "/mounts/work/lyk/anaconda3/envs/torch2/lib/python3.8/site-packages/wandb/sdk/internal/internal_api.py", line 2759, in upload_file
    response.raise_for_status()
  File "/mounts/work/lyk/anaconda3/envs/torch2/lib/python3.8/site-packages/requests/models.py", line 1021, in raise_for_status
    raise HTTPError(http_error_msg, response=self)
requests.exceptions.HTTPError: 403 Client Error: Forbidden for url: https://storage.googleapis.com/wandb-production.appspot.com/neuzxm/huggingface/uo5si8h8/requirements.txt?Expires=1715730170&GoogleAccessId=gorilla-files-url-signer-man%40wandb-production.iam.gserviceaccount.com&Signature=izC0ZNZ3BI4sIsK%2BrC%2BfIc2v8gLNkNOVc2fJYSahgPQZGB1NtwZVXWk9aAczz7hagI4%2B40e698%2FaIXeNdEQ%2F4nUGRhY2rXk4y5vKFK9JelSnsGrPJ6pxk1%2FDLi9Nw16QWrnLUCM7Z%2Fx%2FGyq5H7Wcjt4IUTmA599byxyAavYjXaLo5fqKHg2k4DwvmK8dyRB2tOvZe5z7AqueSTPDWpfaqI7NLKqDB0vpk%2BKGMK6h3UJWNucQWlFmet4pKoZFj%2F87cjvP5awFxuojLfrCR3kjC3gLGlRUz%2FcM8Qt%2BDzl6psEman%2BMBnuwe%2BIPrBW2%2Fs%2FGl6eKtB3yDAvODF2qZLOxtA%3D%3D

During handling of the above exception, another exception occurred:

Traceback (most recent call last):
  File "/mounts/work/lyk/anaconda3/envs/torch2/lib/python3.8/concurrent/futures/thread.py", line 57, in run
    result = self.fn(*self.args, **self.kwargs)
  File "/mounts/work/lyk/anaconda3/envs/torch2/lib/python3.8/site-packages/wandb/filesync/step_upload.py", line 288, in run_and_notify
    self._do_upload_sync(event)
  File "/mounts/work/lyk/anaconda3/envs/torch2/lib/python3.8/site-packages/wandb/filesync/step_upload.py", line 330, in _do_upload_sync
    job.run()
  File "/mounts/work/lyk/anaconda3/envs/torch2/lib/python3.8/site-packages/wandb/filesync/upload_job.py", line 57, in run
    self.push()
  File "/mounts/work/lyk/anaconda3/envs/torch2/lib/python3.8/site-packages/wandb/filesync/upload_job.py", line 125, in push
    self._api.upload_file_retry(
  File "/mounts/work/lyk/anaconda3/envs/torch2/lib/python3.8/site-packages/wandb/apis/normalize.py", line 51, in wrapper
    raise CommError(message, error)
wandb.errors.CommError: <Response [403]>
2024-05-14 01:42:50,375 ERROR   wandb-upload_4:2412291 [internal_api.py:upload_file():2761] upload_file exception https://storage.googleapis.com/wandb-production.appspot.com/neuzxm/huggingface/uo5si8h8/output.log?Expires=1715730170&GoogleAccessId=gorilla-files-url-signer-man%40wandb-production.iam.gserviceaccount.com&Signature=K5gRx2lHPv1lW5n8pWmLvA%2BvPhbRkkGlvDf%2Fo%2BZ1CglU6ugA49Pf4XlVBYCJ%2B4x2M2QKy0q2mjlcxYuDd1IN%2Bbp%2FWjiEh1bPVG23KVOB5LMI3YTQ4qZBlTCEpcKpNlkY10gnvQWe6EDwiaqavVHQsbHUNvZJul4rp1Hf3T%2F2Z3ohrgbMv2vLf3YznM%2BrTigj6rNpRDmYNGAcxNQLkRvSZxVvb5GY03L1Vs3vhU6EU2UgmyOFQl0cHTjVl5NSs3mXy7hjNNn3boq52dwZr1Sku96X6shSk2U9KdWpBrLZYuPYihdoi7EVGThxV%2BCpiz9dy8mOxYxS3%2BSD4Ffp8zFsDQ%3D%3D: 403 Client Error: Forbidden for url: https://storage.googleapis.com/wandb-production.appspot.com/neuzxm/huggingface/uo5si8h8/output.log?Expires=1715730170&GoogleAccessId=gorilla-files-url-signer-man%40wandb-production.iam.gserviceaccount.com&Signature=K5gRx2lHPv1lW5n8pWmLvA%2BvPhbRkkGlvDf%2Fo%2BZ1CglU6ugA49Pf4XlVBYCJ%2B4x2M2QKy0q2mjlcxYuDd1IN%2Bbp%2FWjiEh1bPVG23KVOB5LMI3YTQ4qZBlTCEpcKpNlkY10gnvQWe6EDwiaqavVHQsbHUNvZJul4rp1Hf3T%2F2Z3ohrgbMv2vLf3YznM%2BrTigj6rNpRDmYNGAcxNQLkRvSZxVvb5GY03L1Vs3vhU6EU2UgmyOFQl0cHTjVl5NSs3mXy7hjNNn3boq52dwZr1Sku96X6shSk2U9KdWpBrLZYuPYihdoi7EVGThxV%2BCpiz9dy8mOxYxS3%2BSD4Ffp8zFsDQ%3D%3D
2024-05-14 01:42:50,375 ERROR   wandb-upload_0:2412291 [upload_job.py:push():134] Failed to upload file: /nfs/datx/lyk/HiFT/wandb/run-20240514_014241-uo5si8h8/files/wandb-summary.json
Traceback (most recent call last):
  File "/mounts/work/lyk/anaconda3/envs/torch2/lib/python3.8/site-packages/wandb/apis/normalize.py", line 41, in wrapper
    return func(*args, **kwargs)
  File "/mounts/work/lyk/anaconda3/envs/torch2/lib/python3.8/site-packages/wandb/sdk/lib/retry.py", line 212, in wrapped_fn
    return retrier(*args, **kargs)
  File "/mounts/work/lyk/anaconda3/envs/torch2/lib/python3.8/site-packages/wandb/sdk/lib/retry.py", line 131, in __call__
    result = self._call_fn(*args, **kwargs)
  File "/mounts/work/lyk/anaconda3/envs/torch2/lib/python3.8/site-packages/wandb/sdk/internal/internal_api.py", line 2787, in upload_file
    wandb._sentry.reraise(e)
  File "/mounts/work/lyk/anaconda3/envs/torch2/lib/python3.8/site-packages/wandb/analytics/sentry.py", line 154, in reraise
    raise exc.with_traceback(sys.exc_info()[2])
  File "/mounts/work/lyk/anaconda3/envs/torch2/lib/python3.8/site-packages/wandb/sdk/internal/internal_api.py", line 2759, in upload_file
    response.raise_for_status()
  File "/mounts/work/lyk/anaconda3/envs/torch2/lib/python3.8/site-packages/requests/models.py", line 1021, in raise_for_status
    raise HTTPError(http_error_msg, response=self)
requests.exceptions.HTTPError: 403 Client Error: Forbidden for url: https://storage.googleapis.com/wandb-production.appspot.com/neuzxm/huggingface/uo5si8h8/wandb-summary.json?Expires=1715730170&GoogleAccessId=gorilla-files-url-signer-man%40wandb-production.iam.gserviceaccount.com&Signature=TFnhE9FWHq3sEbVnFWYWT8R0HdFm%2BA7Z%2Fm8L7CVIx%2BaSrxqN%2F%2BTryWR82qg32xQCfYxLrKS%2FXRFHEOi10Sf43Z6Je7Od67f8U5sw2QbWfABugD6wQbZfTzFRAvFLPaHgZS3NrLouZP9YRBRXYZN2QMPzzlgQuzrGstyHdfdoGayRmG3sC%2BcoLtvnuBvhTMx%2BSUeTfXtSTbnP7W0X5C443RR9ohyW2nSaeouXx36PwaRLSEoPOLd0V8%2BJ2UYm9914POrbLMGnMM3OzkT%2Fu4pq%2ByG2KHmE6LwEt06S7Gd%2FGZhPs3pKuh4onS%2FR69jnBG%2FiBikI12BPzlyCjXkO5KXL%2BQ%3D%3D

During handling of the above exception, another exception occurred:

Traceback (most recent call last):
  File "/mounts/work/lyk/anaconda3/envs/torch2/lib/python3.8/site-packages/wandb/filesync/upload_job.py", line 125, in push
    self._api.upload_file_retry(
  File "/mounts/work/lyk/anaconda3/envs/torch2/lib/python3.8/site-packages/wandb/apis/normalize.py", line 51, in wrapper
    raise CommError(message, error)
wandb.errors.CommError: <Response [403]>
2024-05-14 01:42:50,375 ERROR   wandb-upload_4:2412291 [internal_api.py:upload_file():2763] upload_file request headers: {'User-Agent': 'python-requests/2.31.0', 'Accept-Encoding': 'gzip, deflate, br', 'Accept': '*/*', 'Connection': 'keep-alive', 'Content-Length': '3521'}
2024-05-14 01:42:50,376 ERROR   wandb-upload_4:2412291 [internal_api.py:upload_file():2765] upload_file response body: b"<?xml version='1.0' encoding='UTF-8'?><Error><Code>AccessDenied</Code><Message>Access denied.</Message><Details>We're sorry, but this service is not available in your location</Details></Error>"
2024-05-14 01:42:50,384 ERROR   wandb-upload_2:2412291 [internal_api.py:upload_file():2761] upload_file exception https://storage.googleapis.com/wandb-production.appspot.com/neuzxm/huggingface/uo5si8h8/conda-environment.yaml?Expires=1715730170&GoogleAccessId=gorilla-files-url-signer-man%40wandb-production.iam.gserviceaccount.com&Signature=l1CvcOskDwx4atXZLxzNJ%2BKsXfKwOhNrNA69RB7Gkrzh9DcmyApYqkNrEV8SaJxL1IjSNKpFN2yOjQ225PcpW7akIbYoo5baOsrJaPswQ7E4TvGHA%2BbOtfP%2FwAtw3D6ZKcfkVToFy4iFAVjbfB%2BsUs4AaCbDF1bnQpd7AMOyQhZyB%2BzDqyYYZcxiGlaQM6qVCyYJMeMM%2FwVnp9TMofRih10sx7CJKUlaDg%2BBJ%2BibY9vepfBvashYmgq%2B%2F84wNklXONmyV8f%2FkHH1aLsYFAUoxtrjXSex2fP4FGKrPWBXB2GT96WINCltVAJ33JLz%2FnEeJIuNTOlPWZ6n2FKd5wXbRA%3D%3D: 403 Client Error: Forbidden for url: https://storage.googleapis.com/wandb-production.appspot.com/neuzxm/huggingface/uo5si8h8/conda-environment.yaml?Expires=1715730170&GoogleAccessId=gorilla-files-url-signer-man%40wandb-production.iam.gserviceaccount.com&Signature=l1CvcOskDwx4atXZLxzNJ%2BKsXfKwOhNrNA69RB7Gkrzh9DcmyApYqkNrEV8SaJxL1IjSNKpFN2yOjQ225PcpW7akIbYoo5baOsrJaPswQ7E4TvGHA%2BbOtfP%2FwAtw3D6ZKcfkVToFy4iFAVjbfB%2BsUs4AaCbDF1bnQpd7AMOyQhZyB%2BzDqyYYZcxiGlaQM6qVCyYJMeMM%2FwVnp9TMofRih10sx7CJKUlaDg%2BBJ%2BibY9vepfBvashYmgq%2B%2F84wNklXONmyV8f%2FkHH1aLsYFAUoxtrjXSex2fP4FGKrPWBXB2GT96WINCltVAJ33JLz%2FnEeJIuNTOlPWZ6n2FKd5wXbRA%3D%3D
2024-05-14 01:42:50,384 ERROR   wandb-upload_2:2412291 [internal_api.py:upload_file():2763] upload_file request headers: {'User-Agent': 'python-requests/2.31.0', 'Accept-Encoding': 'gzip, deflate, br', 'Accept': '*/*', 'Connection': 'keep-alive', 'Content-Length': '5415'}
2024-05-14 01:42:50,384 ERROR   wandb-upload_2:2412291 [internal_api.py:upload_file():2765] upload_file response body: b"<?xml version='1.0' encoding='UTF-8'?><Error><Code>AccessDenied</Code><Message>Access denied.</Message><Details>We're sorry, but this service is not available in your location</Details></Error>"
2024-05-14 01:42:50,400 ERROR   wandb-upload_3:2412291 [internal_api.py:upload_file():2761] upload_file exception https://storage.googleapis.com/wandb-production.appspot.com/neuzxm/huggingface/uo5si8h8/config.yaml?Expires=1715730170&GoogleAccessId=gorilla-files-url-signer-man%40wandb-production.iam.gserviceaccount.com&Signature=nUPBV70lVWSYbAs4WJLVsTiclmNID6Mjo3jY3V%2BgE7rqhatoK%2FqT%2Fs6i5h9A0k8NUa05bRGBHPEDfWQFJwnjsHDpClENxlNVypf5hd15HhKt%2BrMs3vG7i13YWwYjGs8HRbdyxwevWTyJX4mpDyjvXv6VdA8gZPR0BYpoFxiUztx0htgl8CJ8zURoaS20gjYKzvDzMb3RBHbOfJiZnU1jKidg550Zm3acrV%2FyBDWdPq%2FkW0LIscVsVcUv59lAVtLeNXbgwkyyvCrEDuVVlYtBvTd0dq7vm%2Bp5O8%2BlLkfBglsXiX3g1s%2FHEP%2Bopf4aj0likQZtI7aGlqXo5AwNV9YRVA%3D%3D: 403 Client Error: Forbidden for url: https://storage.googleapis.com/wandb-production.appspot.com/neuzxm/huggingface/uo5si8h8/config.yaml?Expires=1715730170&GoogleAccessId=gorilla-files-url-signer-man%40wandb-production.iam.gserviceaccount.com&Signature=nUPBV70lVWSYbAs4WJLVsTiclmNID6Mjo3jY3V%2BgE7rqhatoK%2FqT%2Fs6i5h9A0k8NUa05bRGBHPEDfWQFJwnjsHDpClENxlNVypf5hd15HhKt%2BrMs3vG7i13YWwYjGs8HRbdyxwevWTyJX4mpDyjvXv6VdA8gZPR0BYpoFxiUztx0htgl8CJ8zURoaS20gjYKzvDzMb3RBHbOfJiZnU1jKidg550Zm3acrV%2FyBDWdPq%2FkW0LIscVsVcUv59lAVtLeNXbgwkyyvCrEDuVVlYtBvTd0dq7vm%2Bp5O8%2BlLkfBglsXiX3g1s%2FHEP%2Bopf4aj0likQZtI7aGlqXo5AwNV9YRVA%3D%3D
2024-05-14 01:42:50,400 ERROR   wandb-upload_3:2412291 [internal_api.py:upload_file():2763] upload_file request headers: {'User-Agent': 'python-requests/2.31.0', 'Accept-Encoding': 'gzip, deflate, br', 'Accept': '*/*', 'Connection': 'keep-alive', 'Content-Length': '9675'}
2024-05-14 01:42:50,401 ERROR   wandb-upload_3:2412291 [internal_api.py:upload_file():2765] upload_file response body: b"<?xml version='1.0' encoding='UTF-8'?><Error><Code>AccessDenied</Code><Message>Access denied.</Message><Details>We're sorry, but this service is not available in your location</Details></Error>"
2024-05-14 01:42:50,429 DEBUG   HandlerThread:2412291 [handler.py:handle_request():146] handle_request: poll_exit
2024-05-14 01:42:50,429 DEBUG   SenderThread:2412291 [sender.py:send_request():409] send_request: poll_exit
2024-05-14 01:42:50,433 ERROR   Thread-11 :2412291 [step_upload.py:_handle_event():200] Failed to upload file: /nfs/datx/lyk/HiFT/wandb/run-20240514_014241-uo5si8h8/files/wandb-summary.json
Traceback (most recent call last):
  File "/mounts/work/lyk/anaconda3/envs/torch2/lib/python3.8/site-packages/wandb/apis/normalize.py", line 41, in wrapper
    return func(*args, **kwargs)
  File "/mounts/work/lyk/anaconda3/envs/torch2/lib/python3.8/site-packages/wandb/sdk/lib/retry.py", line 212, in wrapped_fn
    return retrier(*args, **kargs)
  File "/mounts/work/lyk/anaconda3/envs/torch2/lib/python3.8/site-packages/wandb/sdk/lib/retry.py", line 131, in __call__
    result = self._call_fn(*args, **kwargs)
  File "/mounts/work/lyk/anaconda3/envs/torch2/lib/python3.8/site-packages/wandb/sdk/internal/internal_api.py", line 2787, in upload_file
    wandb._sentry.reraise(e)
  File "/mounts/work/lyk/anaconda3/envs/torch2/lib/python3.8/site-packages/wandb/analytics/sentry.py", line 154, in reraise
    raise exc.with_traceback(sys.exc_info()[2])
  File "/mounts/work/lyk/anaconda3/envs/torch2/lib/python3.8/site-packages/wandb/sdk/internal/internal_api.py", line 2759, in upload_file
    response.raise_for_status()
  File "/mounts/work/lyk/anaconda3/envs/torch2/lib/python3.8/site-packages/requests/models.py", line 1021, in raise_for_status
    raise HTTPError(http_error_msg, response=self)
requests.exceptions.HTTPError: 403 Client Error: Forbidden for url: https://storage.googleapis.com/wandb-production.appspot.com/neuzxm/huggingface/uo5si8h8/wandb-summary.json?Expires=1715730170&GoogleAccessId=gorilla-files-url-signer-man%40wandb-production.iam.gserviceaccount.com&Signature=TFnhE9FWHq3sEbVnFWYWT8R0HdFm%2BA7Z%2Fm8L7CVIx%2BaSrxqN%2F%2BTryWR82qg32xQCfYxLrKS%2FXRFHEOi10Sf43Z6Je7Od67f8U5sw2QbWfABugD6wQbZfTzFRAvFLPaHgZS3NrLouZP9YRBRXYZN2QMPzzlgQuzrGstyHdfdoGayRmG3sC%2BcoLtvnuBvhTMx%2BSUeTfXtSTbnP7W0X5C443RR9ohyW2nSaeouXx36PwaRLSEoPOLd0V8%2BJ2UYm9914POrbLMGnMM3OzkT%2Fu4pq%2ByG2KHmE6LwEt06S7Gd%2FGZhPs3pKuh4onS%2FR69jnBG%2FiBikI12BPzlyCjXkO5KXL%2BQ%3D%3D

During handling of the above exception, another exception occurred:

Traceback (most recent call last):
  File "/mounts/work/lyk/anaconda3/envs/torch2/lib/python3.8/concurrent/futures/thread.py", line 57, in run
    result = self.fn(*self.args, **self.kwargs)
  File "/mounts/work/lyk/anaconda3/envs/torch2/lib/python3.8/site-packages/wandb/filesync/step_upload.py", line 288, in run_and_notify
    self._do_upload_sync(event)
  File "/mounts/work/lyk/anaconda3/envs/torch2/lib/python3.8/site-packages/wandb/filesync/step_upload.py", line 330, in _do_upload_sync
    job.run()
  File "/mounts/work/lyk/anaconda3/envs/torch2/lib/python3.8/site-packages/wandb/filesync/upload_job.py", line 57, in run
    self.push()
  File "/mounts/work/lyk/anaconda3/envs/torch2/lib/python3.8/site-packages/wandb/filesync/upload_job.py", line 125, in push
    self._api.upload_file_retry(
  File "/mounts/work/lyk/anaconda3/envs/torch2/lib/python3.8/site-packages/wandb/apis/normalize.py", line 51, in wrapper
    raise CommError(message, error)
wandb.errors.CommError: <Response [403]>
2024-05-14 01:42:50,434 ERROR   wandb-upload_4:2412291 [upload_job.py:push():134] Failed to upload file: /nfs/datx/lyk/HiFT/wandb/run-20240514_014241-uo5si8h8/files/output.log
Traceback (most recent call last):
  File "/mounts/work/lyk/anaconda3/envs/torch2/lib/python3.8/site-packages/wandb/apis/normalize.py", line 41, in wrapper
    return func(*args, **kwargs)
  File "/mounts/work/lyk/anaconda3/envs/torch2/lib/python3.8/site-packages/wandb/sdk/lib/retry.py", line 212, in wrapped_fn
    return retrier(*args, **kargs)
  File "/mounts/work/lyk/anaconda3/envs/torch2/lib/python3.8/site-packages/wandb/sdk/lib/retry.py", line 131, in __call__
    result = self._call_fn(*args, **kwargs)
  File "/mounts/work/lyk/anaconda3/envs/torch2/lib/python3.8/site-packages/wandb/sdk/internal/internal_api.py", line 2787, in upload_file
    wandb._sentry.reraise(e)
  File "/mounts/work/lyk/anaconda3/envs/torch2/lib/python3.8/site-packages/wandb/analytics/sentry.py", line 154, in reraise
    raise exc.with_traceback(sys.exc_info()[2])
  File "/mounts/work/lyk/anaconda3/envs/torch2/lib/python3.8/site-packages/wandb/sdk/internal/internal_api.py", line 2759, in upload_file
    response.raise_for_status()
  File "/mounts/work/lyk/anaconda3/envs/torch2/lib/python3.8/site-packages/requests/models.py", line 1021, in raise_for_status
    raise HTTPError(http_error_msg, response=self)
requests.exceptions.HTTPError: 403 Client Error: Forbidden for url: https://storage.googleapis.com/wandb-production.appspot.com/neuzxm/huggingface/uo5si8h8/output.log?Expires=1715730170&GoogleAccessId=gorilla-files-url-signer-man%40wandb-production.iam.gserviceaccount.com&Signature=K5gRx2lHPv1lW5n8pWmLvA%2BvPhbRkkGlvDf%2Fo%2BZ1CglU6ugA49Pf4XlVBYCJ%2B4x2M2QKy0q2mjlcxYuDd1IN%2Bbp%2FWjiEh1bPVG23KVOB5LMI3YTQ4qZBlTCEpcKpNlkY10gnvQWe6EDwiaqavVHQsbHUNvZJul4rp1Hf3T%2F2Z3ohrgbMv2vLf3YznM%2BrTigj6rNpRDmYNGAcxNQLkRvSZxVvb5GY03L1Vs3vhU6EU2UgmyOFQl0cHTjVl5NSs3mXy7hjNNn3boq52dwZr1Sku96X6shSk2U9KdWpBrLZYuPYihdoi7EVGThxV%2BCpiz9dy8mOxYxS3%2BSD4Ffp8zFsDQ%3D%3D

During handling of the above exception, another exception occurred:

Traceback (most recent call last):
  File "/mounts/work/lyk/anaconda3/envs/torch2/lib/python3.8/site-packages/wandb/filesync/upload_job.py", line 125, in push
    self._api.upload_file_retry(
  File "/mounts/work/lyk/anaconda3/envs/torch2/lib/python3.8/site-packages/wandb/apis/normalize.py", line 51, in wrapper
    raise CommError(message, error)
wandb.errors.CommError: <Response [403]>
2024-05-14 01:42:50,435 ERROR   wandb-upload_2:2412291 [upload_job.py:push():134] Failed to upload file: /nfs/datx/lyk/HiFT/wandb/run-20240514_014241-uo5si8h8/files/conda-environment.yaml
Traceback (most recent call last):
  File "/mounts/work/lyk/anaconda3/envs/torch2/lib/python3.8/site-packages/wandb/apis/normalize.py", line 41, in wrapper
    return func(*args, **kwargs)
  File "/mounts/work/lyk/anaconda3/envs/torch2/lib/python3.8/site-packages/wandb/sdk/lib/retry.py", line 212, in wrapped_fn
    return retrier(*args, **kargs)
  File "/mounts/work/lyk/anaconda3/envs/torch2/lib/python3.8/site-packages/wandb/sdk/lib/retry.py", line 131, in __call__
    result = self._call_fn(*args, **kwargs)
  File "/mounts/work/lyk/anaconda3/envs/torch2/lib/python3.8/site-packages/wandb/sdk/internal/internal_api.py", line 2787, in upload_file
    wandb._sentry.reraise(e)
  File "/mounts/work/lyk/anaconda3/envs/torch2/lib/python3.8/site-packages/wandb/analytics/sentry.py", line 154, in reraise
    raise exc.with_traceback(sys.exc_info()[2])
  File "/mounts/work/lyk/anaconda3/envs/torch2/lib/python3.8/site-packages/wandb/sdk/internal/internal_api.py", line 2759, in upload_file
    response.raise_for_status()
  File "/mounts/work/lyk/anaconda3/envs/torch2/lib/python3.8/site-packages/requests/models.py", line 1021, in raise_for_status
    raise HTTPError(http_error_msg, response=self)
requests.exceptions.HTTPError: 403 Client Error: Forbidden for url: https://storage.googleapis.com/wandb-production.appspot.com/neuzxm/huggingface/uo5si8h8/conda-environment.yaml?Expires=1715730170&GoogleAccessId=gorilla-files-url-signer-man%40wandb-production.iam.gserviceaccount.com&Signature=l1CvcOskDwx4atXZLxzNJ%2BKsXfKwOhNrNA69RB7Gkrzh9DcmyApYqkNrEV8SaJxL1IjSNKpFN2yOjQ225PcpW7akIbYoo5baOsrJaPswQ7E4TvGHA%2BbOtfP%2FwAtw3D6ZKcfkVToFy4iFAVjbfB%2BsUs4AaCbDF1bnQpd7AMOyQhZyB%2BzDqyYYZcxiGlaQM6qVCyYJMeMM%2FwVnp9TMofRih10sx7CJKUlaDg%2BBJ%2BibY9vepfBvashYmgq%2B%2F84wNklXONmyV8f%2FkHH1aLsYFAUoxtrjXSex2fP4FGKrPWBXB2GT96WINCltVAJ33JLz%2FnEeJIuNTOlPWZ6n2FKd5wXbRA%3D%3D

During handling of the above exception, another exception occurred:

Traceback (most recent call last):
  File "/mounts/work/lyk/anaconda3/envs/torch2/lib/python3.8/site-packages/wandb/filesync/upload_job.py", line 125, in push
    self._api.upload_file_retry(
  File "/mounts/work/lyk/anaconda3/envs/torch2/lib/python3.8/site-packages/wandb/apis/normalize.py", line 51, in wrapper
    raise CommError(message, error)
wandb.errors.CommError: <Response [403]>
2024-05-14 01:42:50,435 ERROR   wandb-upload_3:2412291 [upload_job.py:push():134] Failed to upload file: /nfs/datx/lyk/HiFT/wandb/run-20240514_014241-uo5si8h8/files/config.yaml
Traceback (most recent call last):
  File "/mounts/work/lyk/anaconda3/envs/torch2/lib/python3.8/site-packages/wandb/apis/normalize.py", line 41, in wrapper
    return func(*args, **kwargs)
  File "/mounts/work/lyk/anaconda3/envs/torch2/lib/python3.8/site-packages/wandb/sdk/lib/retry.py", line 212, in wrapped_fn
    return retrier(*args, **kargs)
  File "/mounts/work/lyk/anaconda3/envs/torch2/lib/python3.8/site-packages/wandb/sdk/lib/retry.py", line 131, in __call__
    result = self._call_fn(*args, **kwargs)
  File "/mounts/work/lyk/anaconda3/envs/torch2/lib/python3.8/site-packages/wandb/sdk/internal/internal_api.py", line 2787, in upload_file
    wandb._sentry.reraise(e)
  File "/mounts/work/lyk/anaconda3/envs/torch2/lib/python3.8/site-packages/wandb/analytics/sentry.py", line 154, in reraise
    raise exc.with_traceback(sys.exc_info()[2])
  File "/mounts/work/lyk/anaconda3/envs/torch2/lib/python3.8/site-packages/wandb/sdk/internal/internal_api.py", line 2759, in upload_file
    response.raise_for_status()
  File "/mounts/work/lyk/anaconda3/envs/torch2/lib/python3.8/site-packages/requests/models.py", line 1021, in raise_for_status
    raise HTTPError(http_error_msg, response=self)
requests.exceptions.HTTPError: 403 Client Error: Forbidden for url: https://storage.googleapis.com/wandb-production.appspot.com/neuzxm/huggingface/uo5si8h8/config.yaml?Expires=1715730170&GoogleAccessId=gorilla-files-url-signer-man%40wandb-production.iam.gserviceaccount.com&Signature=nUPBV70lVWSYbAs4WJLVsTiclmNID6Mjo3jY3V%2BgE7rqhatoK%2FqT%2Fs6i5h9A0k8NUa05bRGBHPEDfWQFJwnjsHDpClENxlNVypf5hd15HhKt%2BrMs3vG7i13YWwYjGs8HRbdyxwevWTyJX4mpDyjvXv6VdA8gZPR0BYpoFxiUztx0htgl8CJ8zURoaS20gjYKzvDzMb3RBHbOfJiZnU1jKidg550Zm3acrV%2FyBDWdPq%2FkW0LIscVsVcUv59lAVtLeNXbgwkyyvCrEDuVVlYtBvTd0dq7vm%2Bp5O8%2BlLkfBglsXiX3g1s%2FHEP%2Bopf4aj0likQZtI7aGlqXo5AwNV9YRVA%3D%3D

During handling of the above exception, another exception occurred:

Traceback (most recent call last):
  File "/mounts/work/lyk/anaconda3/envs/torch2/lib/python3.8/site-packages/wandb/filesync/upload_job.py", line 125, in push
    self._api.upload_file_retry(
  File "/mounts/work/lyk/anaconda3/envs/torch2/lib/python3.8/site-packages/wandb/apis/normalize.py", line 51, in wrapper
    raise CommError(message, error)
wandb.errors.CommError: <Response [403]>
2024-05-14 01:42:50,492 ERROR   Thread-11 :2412291 [step_upload.py:_handle_event():200] Failed to upload file: /nfs/datx/lyk/HiFT/wandb/run-20240514_014241-uo5si8h8/files/conda-environment.yaml
Traceback (most recent call last):
  File "/mounts/work/lyk/anaconda3/envs/torch2/lib/python3.8/site-packages/wandb/apis/normalize.py", line 41, in wrapper
    return func(*args, **kwargs)
  File "/mounts/work/lyk/anaconda3/envs/torch2/lib/python3.8/site-packages/wandb/sdk/lib/retry.py", line 212, in wrapped_fn
    return retrier(*args, **kargs)
  File "/mounts/work/lyk/anaconda3/envs/torch2/lib/python3.8/site-packages/wandb/sdk/lib/retry.py", line 131, in __call__
    result = self._call_fn(*args, **kwargs)
  File "/mounts/work/lyk/anaconda3/envs/torch2/lib/python3.8/site-packages/wandb/sdk/internal/internal_api.py", line 2787, in upload_file
    wandb._sentry.reraise(e)
  File "/mounts/work/lyk/anaconda3/envs/torch2/lib/python3.8/site-packages/wandb/analytics/sentry.py", line 154, in reraise
    raise exc.with_traceback(sys.exc_info()[2])
  File "/mounts/work/lyk/anaconda3/envs/torch2/lib/python3.8/site-packages/wandb/sdk/internal/internal_api.py", line 2759, in upload_file
    response.raise_for_status()
  File "/mounts/work/lyk/anaconda3/envs/torch2/lib/python3.8/site-packages/requests/models.py", line 1021, in raise_for_status
    raise HTTPError(http_error_msg, response=self)
requests.exceptions.HTTPError: 403 Client Error: Forbidden for url: https://storage.googleapis.com/wandb-production.appspot.com/neuzxm/huggingface/uo5si8h8/conda-environment.yaml?Expires=1715730170&GoogleAccessId=gorilla-files-url-signer-man%40wandb-production.iam.gserviceaccount.com&Signature=l1CvcOskDwx4atXZLxzNJ%2BKsXfKwOhNrNA69RB7Gkrzh9DcmyApYqkNrEV8SaJxL1IjSNKpFN2yOjQ225PcpW7akIbYoo5baOsrJaPswQ7E4TvGHA%2BbOtfP%2FwAtw3D6ZKcfkVToFy4iFAVjbfB%2BsUs4AaCbDF1bnQpd7AMOyQhZyB%2BzDqyYYZcxiGlaQM6qVCyYJMeMM%2FwVnp9TMofRih10sx7CJKUlaDg%2BBJ%2BibY9vepfBvashYmgq%2B%2F84wNklXONmyV8f%2FkHH1aLsYFAUoxtrjXSex2fP4FGKrPWBXB2GT96WINCltVAJ33JLz%2FnEeJIuNTOlPWZ6n2FKd5wXbRA%3D%3D

During handling of the above exception, another exception occurred:

Traceback (most recent call last):
  File "/mounts/work/lyk/anaconda3/envs/torch2/lib/python3.8/concurrent/futures/thread.py", line 57, in run
    result = self.fn(*self.args, **self.kwargs)
  File "/mounts/work/lyk/anaconda3/envs/torch2/lib/python3.8/site-packages/wandb/filesync/step_upload.py", line 288, in run_and_notify
    self._do_upload_sync(event)
  File "/mounts/work/lyk/anaconda3/envs/torch2/lib/python3.8/site-packages/wandb/filesync/step_upload.py", line 330, in _do_upload_sync
    job.run()
  File "/mounts/work/lyk/anaconda3/envs/torch2/lib/python3.8/site-packages/wandb/filesync/upload_job.py", line 57, in run
    self.push()
  File "/mounts/work/lyk/anaconda3/envs/torch2/lib/python3.8/site-packages/wandb/filesync/upload_job.py", line 125, in push
    self._api.upload_file_retry(
  File "/mounts/work/lyk/anaconda3/envs/torch2/lib/python3.8/site-packages/wandb/apis/normalize.py", line 51, in wrapper
    raise CommError(message, error)
wandb.errors.CommError: <Response [403]>
2024-05-14 01:42:50,492 ERROR   Thread-11 :2412291 [step_upload.py:_handle_event():200] Failed to upload file: /nfs/datx/lyk/HiFT/wandb/run-20240514_014241-uo5si8h8/files/config.yaml
Traceback (most recent call last):
  File "/mounts/work/lyk/anaconda3/envs/torch2/lib/python3.8/site-packages/wandb/apis/normalize.py", line 41, in wrapper
    return func(*args, **kwargs)
  File "/mounts/work/lyk/anaconda3/envs/torch2/lib/python3.8/site-packages/wandb/sdk/lib/retry.py", line 212, in wrapped_fn
    return retrier(*args, **kargs)
  File "/mounts/work/lyk/anaconda3/envs/torch2/lib/python3.8/site-packages/wandb/sdk/lib/retry.py", line 131, in __call__
    result = self._call_fn(*args, **kwargs)
  File "/mounts/work/lyk/anaconda3/envs/torch2/lib/python3.8/site-packages/wandb/sdk/internal/internal_api.py", line 2787, in upload_file
    wandb._sentry.reraise(e)
  File "/mounts/work/lyk/anaconda3/envs/torch2/lib/python3.8/site-packages/wandb/analytics/sentry.py", line 154, in reraise
    raise exc.with_traceback(sys.exc_info()[2])
  File "/mounts/work/lyk/anaconda3/envs/torch2/lib/python3.8/site-packages/wandb/sdk/internal/internal_api.py", line 2759, in upload_file
    response.raise_for_status()
  File "/mounts/work/lyk/anaconda3/envs/torch2/lib/python3.8/site-packages/requests/models.py", line 1021, in raise_for_status
    raise HTTPError(http_error_msg, response=self)
requests.exceptions.HTTPError: 403 Client Error: Forbidden for url: https://storage.googleapis.com/wandb-production.appspot.com/neuzxm/huggingface/uo5si8h8/config.yaml?Expires=1715730170&GoogleAccessId=gorilla-files-url-signer-man%40wandb-production.iam.gserviceaccount.com&Signature=nUPBV70lVWSYbAs4WJLVsTiclmNID6Mjo3jY3V%2BgE7rqhatoK%2FqT%2Fs6i5h9A0k8NUa05bRGBHPEDfWQFJwnjsHDpClENxlNVypf5hd15HhKt%2BrMs3vG7i13YWwYjGs8HRbdyxwevWTyJX4mpDyjvXv6VdA8gZPR0BYpoFxiUztx0htgl8CJ8zURoaS20gjYKzvDzMb3RBHbOfJiZnU1jKidg550Zm3acrV%2FyBDWdPq%2FkW0LIscVsVcUv59lAVtLeNXbgwkyyvCrEDuVVlYtBvTd0dq7vm%2Bp5O8%2BlLkfBglsXiX3g1s%2FHEP%2Bopf4aj0likQZtI7aGlqXo5AwNV9YRVA%3D%3D

During handling of the above exception, another exception occurred:

Traceback (most recent call last):
  File "/mounts/work/lyk/anaconda3/envs/torch2/lib/python3.8/concurrent/futures/thread.py", line 57, in run
    result = self.fn(*self.args, **self.kwargs)
  File "/mounts/work/lyk/anaconda3/envs/torch2/lib/python3.8/site-packages/wandb/filesync/step_upload.py", line 288, in run_and_notify
    self._do_upload_sync(event)
  File "/mounts/work/lyk/anaconda3/envs/torch2/lib/python3.8/site-packages/wandb/filesync/step_upload.py", line 330, in _do_upload_sync
    job.run()
  File "/mounts/work/lyk/anaconda3/envs/torch2/lib/python3.8/site-packages/wandb/filesync/upload_job.py", line 57, in run
    self.push()
  File "/mounts/work/lyk/anaconda3/envs/torch2/lib/python3.8/site-packages/wandb/filesync/upload_job.py", line 125, in push
    self._api.upload_file_retry(
  File "/mounts/work/lyk/anaconda3/envs/torch2/lib/python3.8/site-packages/wandb/apis/normalize.py", line 51, in wrapper
    raise CommError(message, error)
wandb.errors.CommError: <Response [403]>
2024-05-14 01:42:50,493 ERROR   Thread-11 :2412291 [step_upload.py:_handle_event():200] Failed to upload file: /nfs/datx/lyk/HiFT/wandb/run-20240514_014241-uo5si8h8/files/output.log
Traceback (most recent call last):
  File "/mounts/work/lyk/anaconda3/envs/torch2/lib/python3.8/site-packages/wandb/apis/normalize.py", line 41, in wrapper
    return func(*args, **kwargs)
  File "/mounts/work/lyk/anaconda3/envs/torch2/lib/python3.8/site-packages/wandb/sdk/lib/retry.py", line 212, in wrapped_fn
    return retrier(*args, **kargs)
  File "/mounts/work/lyk/anaconda3/envs/torch2/lib/python3.8/site-packages/wandb/sdk/lib/retry.py", line 131, in __call__
    result = self._call_fn(*args, **kwargs)
  File "/mounts/work/lyk/anaconda3/envs/torch2/lib/python3.8/site-packages/wandb/sdk/internal/internal_api.py", line 2787, in upload_file
    wandb._sentry.reraise(e)
  File "/mounts/work/lyk/anaconda3/envs/torch2/lib/python3.8/site-packages/wandb/analytics/sentry.py", line 154, in reraise
    raise exc.with_traceback(sys.exc_info()[2])
  File "/mounts/work/lyk/anaconda3/envs/torch2/lib/python3.8/site-packages/wandb/sdk/internal/internal_api.py", line 2759, in upload_file
    response.raise_for_status()
  File "/mounts/work/lyk/anaconda3/envs/torch2/lib/python3.8/site-packages/requests/models.py", line 1021, in raise_for_status
    raise HTTPError(http_error_msg, response=self)
requests.exceptions.HTTPError: 403 Client Error: Forbidden for url: https://storage.googleapis.com/wandb-production.appspot.com/neuzxm/huggingface/uo5si8h8/output.log?Expires=1715730170&GoogleAccessId=gorilla-files-url-signer-man%40wandb-production.iam.gserviceaccount.com&Signature=K5gRx2lHPv1lW5n8pWmLvA%2BvPhbRkkGlvDf%2Fo%2BZ1CglU6ugA49Pf4XlVBYCJ%2B4x2M2QKy0q2mjlcxYuDd1IN%2Bbp%2FWjiEh1bPVG23KVOB5LMI3YTQ4qZBlTCEpcKpNlkY10gnvQWe6EDwiaqavVHQsbHUNvZJul4rp1Hf3T%2F2Z3ohrgbMv2vLf3YznM%2BrTigj6rNpRDmYNGAcxNQLkRvSZxVvb5GY03L1Vs3vhU6EU2UgmyOFQl0cHTjVl5NSs3mXy7hjNNn3boq52dwZr1Sku96X6shSk2U9KdWpBrLZYuPYihdoi7EVGThxV%2BCpiz9dy8mOxYxS3%2BSD4Ffp8zFsDQ%3D%3D

During handling of the above exception, another exception occurred:

Traceback (most recent call last):
  File "/mounts/work/lyk/anaconda3/envs/torch2/lib/python3.8/concurrent/futures/thread.py", line 57, in run
    result = self.fn(*self.args, **self.kwargs)
  File "/mounts/work/lyk/anaconda3/envs/torch2/lib/python3.8/site-packages/wandb/filesync/step_upload.py", line 288, in run_and_notify
    self._do_upload_sync(event)
  File "/mounts/work/lyk/anaconda3/envs/torch2/lib/python3.8/site-packages/wandb/filesync/step_upload.py", line 330, in _do_upload_sync
    job.run()
  File "/mounts/work/lyk/anaconda3/envs/torch2/lib/python3.8/site-packages/wandb/filesync/upload_job.py", line 57, in run
    self.push()
  File "/mounts/work/lyk/anaconda3/envs/torch2/lib/python3.8/site-packages/wandb/filesync/upload_job.py", line 125, in push
    self._api.upload_file_retry(
  File "/mounts/work/lyk/anaconda3/envs/torch2/lib/python3.8/site-packages/wandb/apis/normalize.py", line 51, in wrapper
    raise CommError(message, error)
wandb.errors.CommError: <Response [403]>
2024-05-14 01:42:50,693 INFO    Thread-11 :2412291 [sender.py:transition_state():617] send defer: 11
2024-05-14 01:42:50,693 DEBUG   HandlerThread:2412291 [handler.py:handle_request():146] handle_request: defer
2024-05-14 01:42:50,693 INFO    HandlerThread:2412291 [handler.py:handle_request_defer():172] handle defer: 11
2024-05-14 01:42:50,694 DEBUG   SenderThread:2412291 [sender.py:send_request():409] send_request: defer
2024-05-14 01:42:50,694 INFO    SenderThread:2412291 [sender.py:send_request_defer():613] handle sender defer: 11
2024-05-14 01:42:50,694 INFO    SenderThread:2412291 [file_pusher.py:join():181] waiting for file pusher
2024-05-14 01:42:50,694 INFO    SenderThread:2412291 [sender.py:transition_state():617] send defer: 12
2024-05-14 01:42:50,694 DEBUG   HandlerThread:2412291 [handler.py:handle_request():146] handle_request: defer
2024-05-14 01:42:50,694 INFO    HandlerThread:2412291 [handler.py:handle_request_defer():172] handle defer: 12
2024-05-14 01:42:50,695 DEBUG   SenderThread:2412291 [sender.py:send_request():409] send_request: defer
2024-05-14 01:42:50,695 INFO    SenderThread:2412291 [sender.py:send_request_defer():613] handle sender defer: 12
2024-05-14 01:42:50,695 INFO    SenderThread:2412291 [file_stream.py:finish():595] file stream finish called
2024-05-14 01:42:51,020 INFO    SenderThread:2412291 [file_stream.py:finish():599] file stream finish is done
2024-05-14 01:42:51,020 INFO    SenderThread:2412291 [sender.py:transition_state():617] send defer: 13
2024-05-14 01:42:51,020 DEBUG   HandlerThread:2412291 [handler.py:handle_request():146] handle_request: defer
2024-05-14 01:42:51,020 INFO    HandlerThread:2412291 [handler.py:handle_request_defer():172] handle defer: 13
2024-05-14 01:42:51,021 DEBUG   SenderThread:2412291 [sender.py:send_request():409] send_request: defer
2024-05-14 01:42:51,021 INFO    SenderThread:2412291 [sender.py:send_request_defer():613] handle sender defer: 13
2024-05-14 01:42:51,021 INFO    SenderThread:2412291 [sender.py:transition_state():617] send defer: 14
2024-05-14 01:42:51,021 DEBUG   HandlerThread:2412291 [handler.py:handle_request():146] handle_request: defer
2024-05-14 01:42:51,021 INFO    HandlerThread:2412291 [handler.py:handle_request_defer():172] handle defer: 14
2024-05-14 01:42:51,021 DEBUG   SenderThread:2412291 [sender.py:send():382] send: final
2024-05-14 01:42:51,021 DEBUG   SenderThread:2412291 [sender.py:send():382] send: footer
2024-05-14 01:42:51,021 DEBUG   SenderThread:2412291 [sender.py:send_request():409] send_request: defer
2024-05-14 01:42:51,021 INFO    SenderThread:2412291 [sender.py:send_request_defer():613] handle sender defer: 14
2024-05-14 01:42:51,022 DEBUG   HandlerThread:2412291 [handler.py:handle_request():146] handle_request: poll_exit
2024-05-14 01:42:51,022 DEBUG   SenderThread:2412291 [sender.py:send_request():409] send_request: poll_exit
2024-05-14 01:42:51,023 DEBUG   HandlerThread:2412291 [handler.py:handle_request():146] handle_request: poll_exit
2024-05-14 01:42:51,023 DEBUG   SenderThread:2412291 [sender.py:send_request():409] send_request: poll_exit
2024-05-14 01:42:51,023 DEBUG   HandlerThread:2412291 [handler.py:handle_request():146] handle_request: server_info
2024-05-14 01:42:51,024 DEBUG   HandlerThread:2412291 [handler.py:handle_request():146] handle_request: get_summary
2024-05-14 01:42:51,024 DEBUG   SenderThread:2412291 [sender.py:send_request():409] send_request: server_info
2024-05-14 01:42:51,027 DEBUG   HandlerThread:2412291 [handler.py:handle_request():146] handle_request: sampled_history
2024-05-14 01:42:51,027 DEBUG   HandlerThread:2412291 [handler.py:handle_request():146] handle_request: internal_messages
2024-05-14 01:42:51,028 DEBUG   HandlerThread:2412291 [handler.py:handle_request():146] handle_request: job_info
2024-05-14 01:42:51,161 DEBUG   SenderThread:2412291 [sender.py:send_request():409] send_request: job_info
2024-05-14 01:42:51,161 INFO    MainThread:2412291 [wandb_run.py:_footer_history_summary_info():3837] rendering history
2024-05-14 01:42:51,162 INFO    MainThread:2412291 [wandb_run.py:_footer_history_summary_info():3869] rendering summary
2024-05-14 01:42:51,162 INFO    MainThread:2412291 [wandb_run.py:_footer_sync_info():3796] logging synced files
2024-05-14 01:42:51,162 DEBUG   HandlerThread:2412291 [handler.py:handle_request():146] handle_request: shutdown
2024-05-14 01:42:51,162 INFO    HandlerThread:2412291 [handler.py:finish():866] shutting down handler
2024-05-14 01:42:52,028 INFO    WriterThread:2412291 [datastore.py:close():294] close: /nfs/datx/lyk/HiFT/wandb/run-20240514_014241-uo5si8h8/run-uo5si8h8.wandb
2024-05-14 01:42:52,161 INFO    SenderThread:2412291 [sender.py:finish():1548] shutting down sender
2024-05-14 01:42:52,161 INFO    SenderThread:2412291 [file_pusher.py:finish():175] shutting down file pusher
2024-05-14 01:42:52,162 INFO    SenderThread:2412291 [file_pusher.py:join():181] waiting for file pusher
