2024-05-13 22:55:35,195 INFO    StreamThr :2341611 [internal.py:wandb_internal():86] W&B internal server running at pid: 2341611, started at: 2024-05-13 22:55:35.193130
2024-05-13 22:55:35,196 DEBUG   HandlerThread:2341611 [handler.py:handle_request():146] handle_request: status
2024-05-13 22:55:35,204 INFO    WriterThread:2341611 [datastore.py:open_for_write():85] open: /nfs/datx/lyk/HiFT/wandb/run-20240513_225535-3l9pao8u/run-3l9pao8u.wandb
2024-05-13 22:55:35,205 DEBUG   SenderThread:2341611 [sender.py:send():382] send: header
2024-05-13 22:55:35,205 DEBUG   SenderThread:2341611 [sender.py:send():382] send: run
2024-05-13 22:55:35,563 INFO    SenderThread:2341611 [dir_watcher.py:__init__():211] watching files in: /nfs/datx/lyk/HiFT/wandb/run-20240513_225535-3l9pao8u/files
2024-05-13 22:55:35,563 INFO    SenderThread:2341611 [sender.py:_start_run_threads():1136] run started: 3l9pao8u with start time 1715633735.200663
2024-05-13 22:55:35,573 DEBUG   HandlerThread:2341611 [handler.py:handle_request():146] handle_request: check_version
2024-05-13 22:55:35,574 DEBUG   SenderThread:2341611 [sender.py:send_request():409] send_request: check_version
2024-05-13 22:55:35,635 DEBUG   HandlerThread:2341611 [handler.py:handle_request():146] handle_request: run_start
2024-05-13 22:55:35,645 DEBUG   HandlerThread:2341611 [system_info.py:__init__():32] System info init
2024-05-13 22:55:35,645 DEBUG   HandlerThread:2341611 [system_info.py:__init__():47] System info init done
2024-05-13 22:55:35,645 INFO    HandlerThread:2341611 [system_monitor.py:start():194] Starting system monitor
2024-05-13 22:55:35,646 INFO    SystemMonitor:2341611 [system_monitor.py:_start():158] Starting system asset monitoring threads
2024-05-13 22:55:35,647 INFO    HandlerThread:2341611 [system_monitor.py:probe():214] Collecting system info
2024-05-13 22:55:35,647 INFO    SystemMonitor:2341611 [interfaces.py:start():190] Started cpu monitoring
2024-05-13 22:55:35,647 INFO    SystemMonitor:2341611 [interfaces.py:start():190] Started disk monitoring
2024-05-13 22:55:35,648 INFO    SystemMonitor:2341611 [interfaces.py:start():190] Started gpu monitoring
2024-05-13 22:55:35,649 INFO    SystemMonitor:2341611 [interfaces.py:start():190] Started memory monitoring
2024-05-13 22:55:35,649 INFO    SystemMonitor:2341611 [interfaces.py:start():190] Started network monitoring
2024-05-13 22:55:35,713 DEBUG   HandlerThread:2341611 [system_info.py:probe():196] Probing system
2024-05-13 22:55:35,718 DEBUG   HandlerThread:2341611 [gitlib.py:_init_repo():56] git repository is invalid
2024-05-13 22:55:35,718 DEBUG   HandlerThread:2341611 [system_info.py:probe():244] Probing system done
2024-05-13 22:55:35,718 DEBUG   HandlerThread:2341611 [system_monitor.py:probe():223] {'os': 'Linux-5.15.0-97-generic-x86_64-with-glibc2.10', 'python': '3.8.5', 'heartbeatAt': '2024-05-13T20:55:35.713679', 'startedAt': '2024-05-13T20:55:35.165666', 'docker': None, 'cuda': None, 'args': ('--model_type', 'llama', '--HiTaskType', 'CAUSAL_LM', '--optim', 'lamb', '--deepspeed', 'dsconfig/zero0_config.json', '--model_name_or_path', '/mounts/work/lyk/hierFT/llama2-7b', '--dataset_dir', 'data/alpaca_data', '--validation_split_percentage', '0.01', '--per_device_train_batch_size', '8', '--per_device_eval_batch_size', '8', '--do_train', '--do_eval', '--seed', '12345', '--fp16', '--num_train_epochs', '1', '--lr_scheduler_type', 'cosine', '--learning_rate', '2e-5', '--warmup_ratio', '0', '--weight_decay', '0', '--logging_strategy', 'steps', '--logging_steps', '10', '--save_strategy', 'steps', '--save_total_limit', '3', '--evaluation_strategy', 'steps', '--eval_steps', '100', '--save_steps', '200', '--preprocessing_num_workers', '4', '--max_seq_length', '512', '--output_dir', 'outputs/instruct_tuning/model', '--overwrite_output_dir', '--logging_first_step', 'True', '--lora_rank', '8', '--torch_dtype', 'float16', '--ddp_find_unused_parameters', 'False', '--load_best_model_at_end', '--hier_tuning', '--group_element', '1', '--optimizer_strategy', 'down2up'), 'state': 'running', 'program': 'examples/instruct_tuning.py', 'codePathLocal': 'examples/instruct_tuning.py', 'codePath': 'examples/instruct_tuning.py', 'host': 'rho2', 'username': 'yongkang', 'executable': '/mounts/work/lyk/anaconda3/envs/torch2/bin/python', 'cpu_count': 32, 'cpu_count_logical': 64, 'cpu_freq': {'current': 2134.1414375, 'min': 1500.0, 'max': 3000.0}, 'cpu_freq_per_core': [{'current': 3607.084, 'min': 1500.0, 'max': 3000.0}, {'current': 3522.113, 'min': 1500.0, 'max': 3000.0}, {'current': 1500.0, 'min': 1500.0, 'max': 3000.0}, {'current': 1500.0, 'min': 1500.0, 'max': 3000.0}, {'current': 1500.0, 'min': 1500.0, 'max': 3000.0}, {'current': 3000.0, 'min': 1500.0, 'max': 3000.0}, {'current': 1500.0, 'min': 1500.0, 'max': 3000.0}, {'current': 3000.0, 'min': 1500.0, 'max': 3000.0}, {'current': 1500.0, 'min': 1500.0, 'max': 3000.0}, {'current': 3670.524, 'min': 1500.0, 'max': 3000.0}, {'current': 1500.0, 'min': 1500.0, 'max': 3000.0}, {'current': 3000.0, 'min': 1500.0, 'max': 3000.0}, {'current': 1500.0, 'min': 1500.0, 'max': 3000.0}, {'current': 1500.0, 'min': 1500.0, 'max': 3000.0}, {'current': 3000.0, 'min': 1500.0, 'max': 3000.0}, {'current': 1500.0, 'min': 1500.0, 'max': 3000.0}, {'current': 1500.0, 'min': 1500.0, 'max': 3000.0}, {'current': 3000.0, 'min': 1500.0, 'max': 3000.0}, {'current': 1500.0, 'min': 1500.0, 'max': 3000.0}, {'current': 1500.0, 'min': 1500.0, 'max': 3000.0}, {'current': 1500.0, 'min': 1500.0, 'max': 3000.0}, {'current': 1500.0, 'min': 1500.0, 'max': 3000.0}, {'current': 1500.0, 'min': 1500.0, 'max': 3000.0}, {'current': 1500.0, 'min': 1500.0, 'max': 3000.0}, {'current': 1500.0, 'min': 1500.0, 'max': 3000.0}, {'current': 2200.0, 'min': 1500.0, 'max': 3000.0}, {'current': 1500.0, 'min': 1500.0, 'max': 3000.0}, {'current': 3671.18, 'min': 1500.0, 'max': 3000.0}, {'current': 3670.924, 'min': 1500.0, 'max': 3000.0}, {'current': 1500.0, 'min': 1500.0, 'max': 3000.0}, {'current': 3000.0, 'min': 1500.0, 'max': 3000.0}, {'current': 3000.0, 'min': 1500.0, 'max': 3000.0}, {'current': 1500.0, 'min': 1500.0, 'max': 3000.0}, {'current': 3000.0, 'min': 1500.0, 'max': 3000.0}, {'current': 3000.0, 'min': 1500.0, 'max': 3000.0}, {'current': 3000.0, 'min': 1500.0, 'max': 3000.0}, {'current': 1500.0, 'min': 1500.0, 'max': 3000.0}, {'current': 3671.636, 'min': 1500.0, 'max': 3000.0}, {'current': 1500.0, 'min': 1500.0, 'max': 3000.0}, {'current': 3000.0, 'min': 1500.0, 'max': 3000.0}, {'current': 1500.0, 'min': 1500.0, 'max': 3000.0}, {'current': 1500.0, 'min': 1500.0, 'max': 3000.0}, {'current': 1500.0, 'min': 1500.0, 'max': 3000.0}, {'current': 1500.0, 'min': 1500.0, 'max': 3000.0}, {'current': 2200.0, 'min': 1500.0, 'max': 3000.0}, {'current': 1500.0, 'min': 1500.0, 'max': 3000.0}, {'current': 3671.411, 'min': 1500.0, 'max': 3000.0}, {'current': 1500.0, 'min': 1500.0, 'max': 3000.0}, {'current': 3671.105, 'min': 1500.0, 'max': 3000.0}, {'current': 1500.0, 'min': 1500.0, 'max': 3000.0}, {'current': 1500.0, 'min': 1500.0, 'max': 3000.0}, {'current': 1500.0, 'min': 1500.0, 'max': 3000.0}, {'current': 1500.0, 'min': 1500.0, 'max': 3000.0}, {'current': 3000.0, 'min': 1500.0, 'max': 3000.0}, {'current': 1500.0, 'min': 1500.0, 'max': 3000.0}, {'current': 3671.029, 'min': 1500.0, 'max': 3000.0}, {'current': 1500.0, 'min': 1500.0, 'max': 3000.0}, {'current': 1500.0, 'min': 1500.0, 'max': 3000.0}, {'current': 1500.0, 'min': 1500.0, 'max': 3000.0}, {'current': 1500.0, 'min': 1500.0, 'max': 3000.0}, {'current': 1500.0, 'min': 1500.0, 'max': 3000.0}, {'current': 1500.0, 'min': 1500.0, 'max': 3000.0}, {'current': 1500.0, 'min': 1500.0, 'max': 3000.0}, {'current': 3671.024, 'min': 1500.0, 'max': 3000.0}], 'disk': {'/': {'total': 878.1072120666504, 'used': 56.61064147949219}}, 'gpu': 'NVIDIA RTX A6000', 'gpu_count': 8, 'gpu_devices': [{'name': 'NVIDIA RTX A6000', 'memory_total': 51527024640}, {'name': 'NVIDIA RTX A6000', 'memory_total': 51527024640}, {'name': 'NVIDIA RTX A6000', 'memory_total': 51527024640}, {'name': 'NVIDIA RTX A6000', 'memory_total': 51527024640}, {'name': 'NVIDIA RTX A6000', 'memory_total': 51527024640}, {'name': 'NVIDIA RTX A6000', 'memory_total': 51527024640}, {'name': 'NVIDIA RTX A6000', 'memory_total': 51527024640}, {'name': 'NVIDIA RTX A6000', 'memory_total': 51527024640}], 'memory': {'total': 251.7312126159668}}
2024-05-13 22:55:35,719 INFO    HandlerThread:2341611 [system_monitor.py:probe():224] Finished collecting system info
2024-05-13 22:55:35,719 INFO    HandlerThread:2341611 [system_monitor.py:probe():227] Publishing system info
2024-05-13 22:55:35,719 DEBUG   HandlerThread:2341611 [system_info.py:_save_pip():52] Saving list of pip packages installed into the current environment
2024-05-13 22:55:35,720 DEBUG   HandlerThread:2341611 [system_info.py:_save_pip():68] Saving pip packages done
2024-05-13 22:55:35,720 DEBUG   HandlerThread:2341611 [system_info.py:_save_conda():75] Saving list of conda packages installed into the current environment
2024-05-13 22:55:36,565 INFO    Thread-12 :2341611 [dir_watcher.py:_on_file_created():271] file/dir created: /nfs/datx/lyk/HiFT/wandb/run-20240513_225535-3l9pao8u/files/conda-environment.yaml
2024-05-13 22:55:36,566 INFO    Thread-12 :2341611 [dir_watcher.py:_on_file_created():271] file/dir created: /nfs/datx/lyk/HiFT/wandb/run-20240513_225535-3l9pao8u/files/requirements.txt
2024-05-13 22:55:39,241 DEBUG   HandlerThread:2341611 [system_info.py:_save_conda():87] Saving conda packages done
2024-05-13 22:55:39,243 INFO    HandlerThread:2341611 [system_monitor.py:probe():229] Finished publishing system info
2024-05-13 22:55:39,256 DEBUG   SenderThread:2341611 [sender.py:send():382] send: files
2024-05-13 22:55:39,257 INFO    SenderThread:2341611 [sender.py:_save_file():1392] saving file wandb-metadata.json with policy now
2024-05-13 22:55:39,266 DEBUG   HandlerThread:2341611 [handler.py:handle_request():146] handle_request: stop_status
2024-05-13 22:55:39,266 DEBUG   SenderThread:2341611 [sender.py:send():382] send: telemetry
2024-05-13 22:55:39,267 DEBUG   SenderThread:2341611 [sender.py:send_request():409] send_request: stop_status
2024-05-13 22:55:39,269 DEBUG   HandlerThread:2341611 [handler.py:handle_request():146] handle_request: internal_messages
2024-05-13 22:55:39,483 DEBUG   SenderThread:2341611 [sender.py:send():382] send: config
2024-05-13 22:55:39,484 DEBUG   SenderThread:2341611 [sender.py:send():382] send: metric
2024-05-13 22:55:39,484 DEBUG   SenderThread:2341611 [sender.py:send():382] send: telemetry
2024-05-13 22:55:39,484 DEBUG   SenderThread:2341611 [sender.py:send():382] send: metric
2024-05-13 22:55:39,484 WARNING SenderThread:2341611 [sender.py:send_metric():1343] Seen metric with glob (shouldn't happen)
2024-05-13 22:55:39,484 DEBUG   SenderThread:2341611 [sender.py:send():382] send: telemetry
2024-05-13 22:55:39,568 INFO    Thread-12 :2341611 [dir_watcher.py:_on_file_modified():288] file/dir modified: /nfs/datx/lyk/HiFT/wandb/run-20240513_225535-3l9pao8u/files/conda-environment.yaml
2024-05-13 22:55:39,568 INFO    Thread-12 :2341611 [dir_watcher.py:_on_file_created():271] file/dir created: /nfs/datx/lyk/HiFT/wandb/run-20240513_225535-3l9pao8u/files/output.log
2024-05-13 22:55:39,568 INFO    Thread-12 :2341611 [dir_watcher.py:_on_file_created():271] file/dir created: /nfs/datx/lyk/HiFT/wandb/run-20240513_225535-3l9pao8u/files/wandb-metadata.json
2024-05-13 22:55:39,709 ERROR   wandb-upload_0:2341611 [internal_api.py:upload_file():2761] upload_file exception https://storage.googleapis.com/wandb-production.appspot.com/neuzxm/huggingface/3l9pao8u/wandb-metadata.json?Expires=1715720139&GoogleAccessId=gorilla-files-url-signer-man%40wandb-production.iam.gserviceaccount.com&Signature=Sw8nUhV8pEJFEr8iIN563cJN9zwjQsqeY34%2Bbb1FkiFOG7VF8dFQB6TMWsW6f%2B1NO3SN2l%2Fhgz6BfXkuznboQu%2Baktzlg19CIXQs04Y2tQzXXZCeQKdClu0Mcs6ZVvxRgFup6AccpJGKbYy6JkLFGuRBWlAP4hM5uVAoGUjfNh4xt80xOrHzHNv%2BMaz0JT06DvdoJp00VlzTxQHcLNCvKujQq0PBB4%2FrSXSiXPJa5JIGSg4R9IluhHf7tzA3TQwvqxGr9XDMvRGSEeXz6%2Bu%2FOlOLj%2FXUzUR%2F3QMa8TIc3aCcbVmH7xiw32lIjifRgZxOXrr9EArhLqhmDwPr7sNi3Q%3D%3D: 403 Client Error: Forbidden for url: https://storage.googleapis.com/wandb-production.appspot.com/neuzxm/huggingface/3l9pao8u/wandb-metadata.json?Expires=1715720139&GoogleAccessId=gorilla-files-url-signer-man%40wandb-production.iam.gserviceaccount.com&Signature=Sw8nUhV8pEJFEr8iIN563cJN9zwjQsqeY34%2Bbb1FkiFOG7VF8dFQB6TMWsW6f%2B1NO3SN2l%2Fhgz6BfXkuznboQu%2Baktzlg19CIXQs04Y2tQzXXZCeQKdClu0Mcs6ZVvxRgFup6AccpJGKbYy6JkLFGuRBWlAP4hM5uVAoGUjfNh4xt80xOrHzHNv%2BMaz0JT06DvdoJp00VlzTxQHcLNCvKujQq0PBB4%2FrSXSiXPJa5JIGSg4R9IluhHf7tzA3TQwvqxGr9XDMvRGSEeXz6%2Bu%2FOlOLj%2FXUzUR%2F3QMa8TIc3aCcbVmH7xiw32lIjifRgZxOXrr9EArhLqhmDwPr7sNi3Q%3D%3D
2024-05-13 22:55:39,709 ERROR   wandb-upload_0:2341611 [internal_api.py:upload_file():2763] upload_file request headers: {'User-Agent': 'python-requests/2.31.0', 'Accept-Encoding': 'gzip, deflate, br', 'Accept': '*/*', 'Connection': 'keep-alive', 'Content-Length': '10139'}
2024-05-13 22:55:39,709 ERROR   wandb-upload_0:2341611 [internal_api.py:upload_file():2765] upload_file response body: b"<?xml version='1.0' encoding='UTF-8'?><Error><Code>AccessDenied</Code><Message>Access denied.</Message><Details>We're sorry, but this service is not available in your location</Details></Error>"
2024-05-13 22:55:39,755 ERROR   wandb-upload_0:2341611 [upload_job.py:push():134] Failed to upload file: /tmp/tmpp665gpl_wandb/xx50353f-wandb-metadata.json
Traceback (most recent call last):
  File "/mounts/work/lyk/anaconda3/envs/torch2/lib/python3.8/site-packages/wandb/apis/normalize.py", line 41, in wrapper
    return func(*args, **kwargs)
  File "/mounts/work/lyk/anaconda3/envs/torch2/lib/python3.8/site-packages/wandb/sdk/lib/retry.py", line 212, in wrapped_fn
    return retrier(*args, **kargs)
  File "/mounts/work/lyk/anaconda3/envs/torch2/lib/python3.8/site-packages/wandb/sdk/lib/retry.py", line 131, in __call__
    result = self._call_fn(*args, **kwargs)
  File "/mounts/work/lyk/anaconda3/envs/torch2/lib/python3.8/site-packages/wandb/sdk/internal/internal_api.py", line 2787, in upload_file
    wandb._sentry.reraise(e)
  File "/mounts/work/lyk/anaconda3/envs/torch2/lib/python3.8/site-packages/wandb/analytics/sentry.py", line 154, in reraise
    raise exc.with_traceback(sys.exc_info()[2])
  File "/mounts/work/lyk/anaconda3/envs/torch2/lib/python3.8/site-packages/wandb/sdk/internal/internal_api.py", line 2759, in upload_file
    response.raise_for_status()
  File "/mounts/work/lyk/anaconda3/envs/torch2/lib/python3.8/site-packages/requests/models.py", line 1021, in raise_for_status
    raise HTTPError(http_error_msg, response=self)
requests.exceptions.HTTPError: 403 Client Error: Forbidden for url: https://storage.googleapis.com/wandb-production.appspot.com/neuzxm/huggingface/3l9pao8u/wandb-metadata.json?Expires=1715720139&GoogleAccessId=gorilla-files-url-signer-man%40wandb-production.iam.gserviceaccount.com&Signature=Sw8nUhV8pEJFEr8iIN563cJN9zwjQsqeY34%2Bbb1FkiFOG7VF8dFQB6TMWsW6f%2B1NO3SN2l%2Fhgz6BfXkuznboQu%2Baktzlg19CIXQs04Y2tQzXXZCeQKdClu0Mcs6ZVvxRgFup6AccpJGKbYy6JkLFGuRBWlAP4hM5uVAoGUjfNh4xt80xOrHzHNv%2BMaz0JT06DvdoJp00VlzTxQHcLNCvKujQq0PBB4%2FrSXSiXPJa5JIGSg4R9IluhHf7tzA3TQwvqxGr9XDMvRGSEeXz6%2Bu%2FOlOLj%2FXUzUR%2F3QMa8TIc3aCcbVmH7xiw32lIjifRgZxOXrr9EArhLqhmDwPr7sNi3Q%3D%3D

During handling of the above exception, another exception occurred:

Traceback (most recent call last):
  File "/mounts/work/lyk/anaconda3/envs/torch2/lib/python3.8/site-packages/wandb/filesync/upload_job.py", line 125, in push
    self._api.upload_file_retry(
  File "/mounts/work/lyk/anaconda3/envs/torch2/lib/python3.8/site-packages/wandb/apis/normalize.py", line 51, in wrapper
    raise CommError(message, error)
wandb.errors.CommError: <Response [403]>
2024-05-13 22:55:39,779 ERROR   Thread-11 :2341611 [step_upload.py:_handle_event():200] Failed to upload file: /tmp/tmpp665gpl_wandb/xx50353f-wandb-metadata.json
Traceback (most recent call last):
  File "/mounts/work/lyk/anaconda3/envs/torch2/lib/python3.8/site-packages/wandb/apis/normalize.py", line 41, in wrapper
    return func(*args, **kwargs)
  File "/mounts/work/lyk/anaconda3/envs/torch2/lib/python3.8/site-packages/wandb/sdk/lib/retry.py", line 212, in wrapped_fn
    return retrier(*args, **kargs)
  File "/mounts/work/lyk/anaconda3/envs/torch2/lib/python3.8/site-packages/wandb/sdk/lib/retry.py", line 131, in __call__
    result = self._call_fn(*args, **kwargs)
  File "/mounts/work/lyk/anaconda3/envs/torch2/lib/python3.8/site-packages/wandb/sdk/internal/internal_api.py", line 2787, in upload_file
    wandb._sentry.reraise(e)
  File "/mounts/work/lyk/anaconda3/envs/torch2/lib/python3.8/site-packages/wandb/analytics/sentry.py", line 154, in reraise
    raise exc.with_traceback(sys.exc_info()[2])
  File "/mounts/work/lyk/anaconda3/envs/torch2/lib/python3.8/site-packages/wandb/sdk/internal/internal_api.py", line 2759, in upload_file
    response.raise_for_status()
  File "/mounts/work/lyk/anaconda3/envs/torch2/lib/python3.8/site-packages/requests/models.py", line 1021, in raise_for_status
    raise HTTPError(http_error_msg, response=self)
requests.exceptions.HTTPError: 403 Client Error: Forbidden for url: https://storage.googleapis.com/wandb-production.appspot.com/neuzxm/huggingface/3l9pao8u/wandb-metadata.json?Expires=1715720139&GoogleAccessId=gorilla-files-url-signer-man%40wandb-production.iam.gserviceaccount.com&Signature=Sw8nUhV8pEJFEr8iIN563cJN9zwjQsqeY34%2Bbb1FkiFOG7VF8dFQB6TMWsW6f%2B1NO3SN2l%2Fhgz6BfXkuznboQu%2Baktzlg19CIXQs04Y2tQzXXZCeQKdClu0Mcs6ZVvxRgFup6AccpJGKbYy6JkLFGuRBWlAP4hM5uVAoGUjfNh4xt80xOrHzHNv%2BMaz0JT06DvdoJp00VlzTxQHcLNCvKujQq0PBB4%2FrSXSiXPJa5JIGSg4R9IluhHf7tzA3TQwvqxGr9XDMvRGSEeXz6%2Bu%2FOlOLj%2FXUzUR%2F3QMa8TIc3aCcbVmH7xiw32lIjifRgZxOXrr9EArhLqhmDwPr7sNi3Q%3D%3D

During handling of the above exception, another exception occurred:

Traceback (most recent call last):
  File "/mounts/work/lyk/anaconda3/envs/torch2/lib/python3.8/concurrent/futures/thread.py", line 57, in run
    result = self.fn(*self.args, **self.kwargs)
  File "/mounts/work/lyk/anaconda3/envs/torch2/lib/python3.8/site-packages/wandb/filesync/step_upload.py", line 288, in run_and_notify
    self._do_upload_sync(event)
  File "/mounts/work/lyk/anaconda3/envs/torch2/lib/python3.8/site-packages/wandb/filesync/step_upload.py", line 330, in _do_upload_sync
    job.run()
  File "/mounts/work/lyk/anaconda3/envs/torch2/lib/python3.8/site-packages/wandb/filesync/upload_job.py", line 57, in run
    self.push()
  File "/mounts/work/lyk/anaconda3/envs/torch2/lib/python3.8/site-packages/wandb/filesync/upload_job.py", line 125, in push
    self._api.upload_file_retry(
  File "/mounts/work/lyk/anaconda3/envs/torch2/lib/python3.8/site-packages/wandb/apis/normalize.py", line 51, in wrapper
    raise CommError(message, error)
wandb.errors.CommError: <Response [403]>
2024-05-13 22:55:40,366 DEBUG   HandlerThread:2341611 [handler.py:handle_request():146] handle_request: status_report
2024-05-13 22:55:40,412 DEBUG   SenderThread:2341611 [sender.py:send():382] send: exit
2024-05-13 22:55:40,412 INFO    SenderThread:2341611 [sender.py:send_exit():589] handling exit code: 1
2024-05-13 22:55:40,412 INFO    SenderThread:2341611 [sender.py:send_exit():591] handling runtime: 4
2024-05-13 22:55:40,415 INFO    SenderThread:2341611 [sender.py:_save_file():1392] saving file wandb-summary.json with policy end
2024-05-13 22:55:40,416 INFO    SenderThread:2341611 [sender.py:send_exit():597] send defer
2024-05-13 22:55:40,416 DEBUG   HandlerThread:2341611 [handler.py:handle_request():146] handle_request: defer
2024-05-13 22:55:40,416 INFO    HandlerThread:2341611 [handler.py:handle_request_defer():172] handle defer: 0
2024-05-13 22:55:40,417 DEBUG   SenderThread:2341611 [sender.py:send_request():409] send_request: defer
2024-05-13 22:55:40,417 INFO    SenderThread:2341611 [sender.py:send_request_defer():613] handle sender defer: 0
2024-05-13 22:55:40,417 INFO    SenderThread:2341611 [sender.py:transition_state():617] send defer: 1
2024-05-13 22:55:40,417 DEBUG   HandlerThread:2341611 [handler.py:handle_request():146] handle_request: defer
2024-05-13 22:55:40,417 INFO    HandlerThread:2341611 [handler.py:handle_request_defer():172] handle defer: 1
2024-05-13 22:55:40,418 DEBUG   SenderThread:2341611 [sender.py:send_request():409] send_request: defer
2024-05-13 22:55:40,418 INFO    SenderThread:2341611 [sender.py:send_request_defer():613] handle sender defer: 1
2024-05-13 22:55:40,418 INFO    SenderThread:2341611 [sender.py:transition_state():617] send defer: 2
2024-05-13 22:55:40,418 DEBUG   HandlerThread:2341611 [handler.py:handle_request():146] handle_request: defer
2024-05-13 22:55:40,418 INFO    HandlerThread:2341611 [handler.py:handle_request_defer():172] handle defer: 2
2024-05-13 22:55:40,418 INFO    HandlerThread:2341611 [system_monitor.py:finish():203] Stopping system monitor
2024-05-13 22:55:40,419 INFO    HandlerThread:2341611 [interfaces.py:finish():202] Joined cpu monitor
2024-05-13 22:55:40,419 INFO    HandlerThread:2341611 [interfaces.py:finish():202] Joined disk monitor
2024-05-13 22:55:40,420 DEBUG   SystemMonitor:2341611 [system_monitor.py:_start():172] Starting system metrics aggregation loop
2024-05-13 22:55:40,420 DEBUG   SystemMonitor:2341611 [system_monitor.py:_start():179] Finished system metrics aggregation loop
2024-05-13 22:55:40,420 DEBUG   SystemMonitor:2341611 [system_monitor.py:_start():183] Publishing last batch of metrics
2024-05-13 22:55:40,569 INFO    Thread-12 :2341611 [dir_watcher.py:_on_file_created():271] file/dir created: /nfs/datx/lyk/HiFT/wandb/run-20240513_225535-3l9pao8u/files/wandb-summary.json
2024-05-13 22:55:41,110 INFO    HandlerThread:2341611 [interfaces.py:finish():202] Joined gpu monitor
2024-05-13 22:55:41,110 INFO    HandlerThread:2341611 [interfaces.py:finish():202] Joined memory monitor
2024-05-13 22:55:41,110 INFO    HandlerThread:2341611 [interfaces.py:finish():202] Joined network monitor
2024-05-13 22:55:41,111 DEBUG   SenderThread:2341611 [sender.py:send_request():409] send_request: defer
2024-05-13 22:55:41,111 INFO    SenderThread:2341611 [sender.py:send_request_defer():613] handle sender defer: 2
2024-05-13 22:55:41,111 INFO    SenderThread:2341611 [sender.py:transition_state():617] send defer: 3
2024-05-13 22:55:41,112 DEBUG   SenderThread:2341611 [sender.py:send():382] send: stats
2024-05-13 22:55:41,113 DEBUG   HandlerThread:2341611 [handler.py:handle_request():146] handle_request: defer
2024-05-13 22:55:41,113 INFO    HandlerThread:2341611 [handler.py:handle_request_defer():172] handle defer: 3
2024-05-13 22:55:41,113 DEBUG   SenderThread:2341611 [sender.py:send_request():409] send_request: defer
2024-05-13 22:55:41,113 INFO    SenderThread:2341611 [sender.py:send_request_defer():613] handle sender defer: 3
2024-05-13 22:55:41,113 INFO    SenderThread:2341611 [sender.py:transition_state():617] send defer: 4
2024-05-13 22:55:41,113 DEBUG   HandlerThread:2341611 [handler.py:handle_request():146] handle_request: defer
2024-05-13 22:55:41,114 INFO    HandlerThread:2341611 [handler.py:handle_request_defer():172] handle defer: 4
2024-05-13 22:55:41,114 DEBUG   SenderThread:2341611 [sender.py:send_request():409] send_request: defer
2024-05-13 22:55:41,114 INFO    SenderThread:2341611 [sender.py:send_request_defer():613] handle sender defer: 4
2024-05-13 22:55:41,114 INFO    SenderThread:2341611 [sender.py:transition_state():617] send defer: 5
2024-05-13 22:55:41,114 DEBUG   HandlerThread:2341611 [handler.py:handle_request():146] handle_request: defer
2024-05-13 22:55:41,114 INFO    HandlerThread:2341611 [handler.py:handle_request_defer():172] handle defer: 5
2024-05-13 22:55:41,115 DEBUG   SenderThread:2341611 [sender.py:send():382] send: summary
2024-05-13 22:55:41,116 INFO    SenderThread:2341611 [sender.py:_save_file():1392] saving file wandb-summary.json with policy end
2024-05-13 22:55:41,116 DEBUG   SenderThread:2341611 [sender.py:send_request():409] send_request: defer
2024-05-13 22:55:41,116 INFO    SenderThread:2341611 [sender.py:send_request_defer():613] handle sender defer: 5
2024-05-13 22:55:41,116 INFO    SenderThread:2341611 [sender.py:transition_state():617] send defer: 6
2024-05-13 22:55:41,117 DEBUG   HandlerThread:2341611 [handler.py:handle_request():146] handle_request: defer
2024-05-13 22:55:41,117 INFO    HandlerThread:2341611 [handler.py:handle_request_defer():172] handle defer: 6
2024-05-13 22:55:41,117 DEBUG   SenderThread:2341611 [sender.py:send_request():409] send_request: defer
2024-05-13 22:55:41,117 INFO    SenderThread:2341611 [sender.py:send_request_defer():613] handle sender defer: 6
2024-05-13 22:55:41,122 DEBUG   HandlerThread:2341611 [handler.py:handle_request():146] handle_request: status_report
2024-05-13 22:55:41,311 INFO    SenderThread:2341611 [sender.py:transition_state():617] send defer: 7
2024-05-13 22:55:41,311 DEBUG   HandlerThread:2341611 [handler.py:handle_request():146] handle_request: defer
2024-05-13 22:55:41,311 INFO    HandlerThread:2341611 [handler.py:handle_request_defer():172] handle defer: 7
2024-05-13 22:55:41,312 DEBUG   SenderThread:2341611 [sender.py:send_request():409] send_request: defer
2024-05-13 22:55:41,312 INFO    SenderThread:2341611 [sender.py:send_request_defer():613] handle sender defer: 7
2024-05-13 22:55:41,411 DEBUG   HandlerThread:2341611 [handler.py:handle_request():146] handle_request: poll_exit
2024-05-13 22:55:41,572 INFO    Thread-12 :2341611 [dir_watcher.py:_on_file_modified():288] file/dir modified: /nfs/datx/lyk/HiFT/wandb/run-20240513_225535-3l9pao8u/files/wandb-summary.json
2024-05-13 22:55:41,572 INFO    Thread-12 :2341611 [dir_watcher.py:_on_file_modified():288] file/dir modified: /nfs/datx/lyk/HiFT/wandb/run-20240513_225535-3l9pao8u/files/output.log
2024-05-13 22:55:41,572 INFO    Thread-12 :2341611 [dir_watcher.py:_on_file_modified():288] file/dir modified: /nfs/datx/lyk/HiFT/wandb/run-20240513_225535-3l9pao8u/files/config.yaml
2024-05-13 22:55:42,417 INFO    SenderThread:2341611 [sender.py:transition_state():617] send defer: 8
2024-05-13 22:55:42,418 DEBUG   SenderThread:2341611 [sender.py:send_request():409] send_request: poll_exit
2024-05-13 22:55:42,418 DEBUG   HandlerThread:2341611 [handler.py:handle_request():146] handle_request: defer
2024-05-13 22:55:42,418 INFO    HandlerThread:2341611 [handler.py:handle_request_defer():172] handle defer: 8
2024-05-13 22:55:42,419 DEBUG   SenderThread:2341611 [sender.py:send_request():409] send_request: defer
2024-05-13 22:55:42,419 INFO    SenderThread:2341611 [sender.py:send_request_defer():613] handle sender defer: 8
2024-05-13 22:55:42,419 INFO    SenderThread:2341611 [job_builder.py:build():298] Attempting to build job artifact
2024-05-13 22:55:42,421 INFO    SenderThread:2341611 [job_builder.py:_get_source_type():439] no source found
2024-05-13 22:55:42,421 INFO    SenderThread:2341611 [sender.py:transition_state():617] send defer: 9
2024-05-13 22:55:42,421 DEBUG   HandlerThread:2341611 [handler.py:handle_request():146] handle_request: defer
2024-05-13 22:55:42,421 INFO    HandlerThread:2341611 [handler.py:handle_request_defer():172] handle defer: 9
2024-05-13 22:55:42,422 DEBUG   SenderThread:2341611 [sender.py:send_request():409] send_request: defer
2024-05-13 22:55:42,422 INFO    SenderThread:2341611 [sender.py:send_request_defer():613] handle sender defer: 9
2024-05-13 22:55:42,422 INFO    SenderThread:2341611 [dir_watcher.py:finish():358] shutting down directory watcher
2024-05-13 22:55:42,574 INFO    SenderThread:2341611 [dir_watcher.py:_on_file_modified():288] file/dir modified: /nfs/datx/lyk/HiFT/wandb/run-20240513_225535-3l9pao8u/files/output.log
2024-05-13 22:55:42,574 INFO    SenderThread:2341611 [dir_watcher.py:finish():388] scan: /nfs/datx/lyk/HiFT/wandb/run-20240513_225535-3l9pao8u/files
2024-05-13 22:55:42,574 INFO    SenderThread:2341611 [dir_watcher.py:finish():402] scan save: /nfs/datx/lyk/HiFT/wandb/run-20240513_225535-3l9pao8u/files/wandb-summary.json wandb-summary.json
2024-05-13 22:55:42,574 INFO    SenderThread:2341611 [dir_watcher.py:finish():402] scan save: /nfs/datx/lyk/HiFT/wandb/run-20240513_225535-3l9pao8u/files/requirements.txt requirements.txt
2024-05-13 22:55:42,575 INFO    SenderThread:2341611 [dir_watcher.py:finish():402] scan save: /nfs/datx/lyk/HiFT/wandb/run-20240513_225535-3l9pao8u/files/conda-environment.yaml conda-environment.yaml
2024-05-13 22:55:42,577 INFO    SenderThread:2341611 [dir_watcher.py:finish():402] scan save: /nfs/datx/lyk/HiFT/wandb/run-20240513_225535-3l9pao8u/files/config.yaml config.yaml
2024-05-13 22:55:42,579 INFO    SenderThread:2341611 [dir_watcher.py:finish():402] scan save: /nfs/datx/lyk/HiFT/wandb/run-20240513_225535-3l9pao8u/files/wandb-metadata.json wandb-metadata.json
2024-05-13 22:55:42,579 INFO    SenderThread:2341611 [dir_watcher.py:finish():402] scan save: /nfs/datx/lyk/HiFT/wandb/run-20240513_225535-3l9pao8u/files/output.log output.log
2024-05-13 22:55:42,580 INFO    SenderThread:2341611 [sender.py:transition_state():617] send defer: 10
2024-05-13 22:55:42,581 DEBUG   HandlerThread:2341611 [handler.py:handle_request():146] handle_request: defer
2024-05-13 22:55:42,581 INFO    HandlerThread:2341611 [handler.py:handle_request_defer():172] handle defer: 10
2024-05-13 22:55:42,583 DEBUG   SenderThread:2341611 [sender.py:send_request():409] send_request: defer
2024-05-13 22:55:42,583 INFO    SenderThread:2341611 [sender.py:send_request_defer():613] handle sender defer: 10
2024-05-13 22:55:42,584 INFO    SenderThread:2341611 [file_pusher.py:finish():175] shutting down file pusher
2024-05-13 22:55:42,840 ERROR   wandb-upload_1:2341611 [internal_api.py:upload_file():2761] upload_file exception https://storage.googleapis.com/wandb-production.appspot.com/neuzxm/huggingface/3l9pao8u/requirements.txt?Expires=1715720142&GoogleAccessId=gorilla-files-url-signer-man%40wandb-production.iam.gserviceaccount.com&Signature=Ojbmv4FONIFJRunO2PPywWv14OJEMn9VWnJZDpvpmWjfs0J9du8VeHhHh44YfLC8z%2BZs0dTGTymYeREdUB%2Bz9M0nThG8uWDPoqYqXW1r%2BycxB2jCW4osE4ZfzoU7dS0KrmZZjU1Yhun2NWUu9m4RS1e2t1Ro3HrxhATpPYsirNtOPk2cOko1CjpGc2Im6e3FGRXPZMBRibK04vQA%2B7DRHrDoV2U4iJHAzUk8KJgDj6%2FcxTPCTXPK%2FvE2%2FXVlfpI8POFVoW4IoffZ7fJ3tDjYscZ0%2BvYyXexF1k8ZelJu396yjlF94AM8t9cPNlyo8HSaYLZSYQvj%2Fa%2BGrY9gWXiKdg%3D%3D: 403 Client Error: Forbidden for url: https://storage.googleapis.com/wandb-production.appspot.com/neuzxm/huggingface/3l9pao8u/requirements.txt?Expires=1715720142&GoogleAccessId=gorilla-files-url-signer-man%40wandb-production.iam.gserviceaccount.com&Signature=Ojbmv4FONIFJRunO2PPywWv14OJEMn9VWnJZDpvpmWjfs0J9du8VeHhHh44YfLC8z%2BZs0dTGTymYeREdUB%2Bz9M0nThG8uWDPoqYqXW1r%2BycxB2jCW4osE4ZfzoU7dS0KrmZZjU1Yhun2NWUu9m4RS1e2t1Ro3HrxhATpPYsirNtOPk2cOko1CjpGc2Im6e3FGRXPZMBRibK04vQA%2B7DRHrDoV2U4iJHAzUk8KJgDj6%2FcxTPCTXPK%2FvE2%2FXVlfpI8POFVoW4IoffZ7fJ3tDjYscZ0%2BvYyXexF1k8ZelJu396yjlF94AM8t9cPNlyo8HSaYLZSYQvj%2Fa%2BGrY9gWXiKdg%3D%3D
2024-05-13 22:55:42,840 ERROR   wandb-upload_1:2341611 [internal_api.py:upload_file():2763] upload_file request headers: {'User-Agent': 'python-requests/2.31.0', 'Accept-Encoding': 'gzip, deflate, br', 'Accept': '*/*', 'Connection': 'keep-alive', 'Content-Length': '2434'}
2024-05-13 22:55:42,840 ERROR   wandb-upload_1:2341611 [internal_api.py:upload_file():2765] upload_file response body: b"<?xml version='1.0' encoding='UTF-8'?><Error><Code>AccessDenied</Code><Message>Access denied.</Message><Details>We're sorry, but this service is not available in your location</Details></Error>"
2024-05-13 22:55:42,860 ERROR   wandb-upload_1:2341611 [upload_job.py:push():134] Failed to upload file: /nfs/datx/lyk/HiFT/wandb/run-20240513_225535-3l9pao8u/files/requirements.txt
Traceback (most recent call last):
  File "/mounts/work/lyk/anaconda3/envs/torch2/lib/python3.8/site-packages/wandb/apis/normalize.py", line 41, in wrapper
    return func(*args, **kwargs)
  File "/mounts/work/lyk/anaconda3/envs/torch2/lib/python3.8/site-packages/wandb/sdk/lib/retry.py", line 212, in wrapped_fn
    return retrier(*args, **kargs)
  File "/mounts/work/lyk/anaconda3/envs/torch2/lib/python3.8/site-packages/wandb/sdk/lib/retry.py", line 131, in __call__
    result = self._call_fn(*args, **kwargs)
  File "/mounts/work/lyk/anaconda3/envs/torch2/lib/python3.8/site-packages/wandb/sdk/internal/internal_api.py", line 2787, in upload_file
    wandb._sentry.reraise(e)
  File "/mounts/work/lyk/anaconda3/envs/torch2/lib/python3.8/site-packages/wandb/analytics/sentry.py", line 154, in reraise
    raise exc.with_traceback(sys.exc_info()[2])
  File "/mounts/work/lyk/anaconda3/envs/torch2/lib/python3.8/site-packages/wandb/sdk/internal/internal_api.py", line 2759, in upload_file
    response.raise_for_status()
  File "/mounts/work/lyk/anaconda3/envs/torch2/lib/python3.8/site-packages/requests/models.py", line 1021, in raise_for_status
    raise HTTPError(http_error_msg, response=self)
requests.exceptions.HTTPError: 403 Client Error: Forbidden for url: https://storage.googleapis.com/wandb-production.appspot.com/neuzxm/huggingface/3l9pao8u/requirements.txt?Expires=1715720142&GoogleAccessId=gorilla-files-url-signer-man%40wandb-production.iam.gserviceaccount.com&Signature=Ojbmv4FONIFJRunO2PPywWv14OJEMn9VWnJZDpvpmWjfs0J9du8VeHhHh44YfLC8z%2BZs0dTGTymYeREdUB%2Bz9M0nThG8uWDPoqYqXW1r%2BycxB2jCW4osE4ZfzoU7dS0KrmZZjU1Yhun2NWUu9m4RS1e2t1Ro3HrxhATpPYsirNtOPk2cOko1CjpGc2Im6e3FGRXPZMBRibK04vQA%2B7DRHrDoV2U4iJHAzUk8KJgDj6%2FcxTPCTXPK%2FvE2%2FXVlfpI8POFVoW4IoffZ7fJ3tDjYscZ0%2BvYyXexF1k8ZelJu396yjlF94AM8t9cPNlyo8HSaYLZSYQvj%2Fa%2BGrY9gWXiKdg%3D%3D

During handling of the above exception, another exception occurred:

Traceback (most recent call last):
  File "/mounts/work/lyk/anaconda3/envs/torch2/lib/python3.8/site-packages/wandb/filesync/upload_job.py", line 125, in push
    self._api.upload_file_retry(
  File "/mounts/work/lyk/anaconda3/envs/torch2/lib/python3.8/site-packages/wandb/apis/normalize.py", line 51, in wrapper
    raise CommError(message, error)
wandb.errors.CommError: <Response [403]>
2024-05-13 22:55:42,879 ERROR   wandb-upload_0:2341611 [internal_api.py:upload_file():2761] upload_file exception https://storage.googleapis.com/wandb-production.appspot.com/neuzxm/huggingface/3l9pao8u/wandb-summary.json?Expires=1715720142&GoogleAccessId=gorilla-files-url-signer-man%40wandb-production.iam.gserviceaccount.com&Signature=pJR%2FORDAdIhiB6QqDmD387PJAPdITLihIMDugifEqDTDgemx6P7fb%2B7uB9oqje%2BOkKx%2B7UabMm62V8t87VXdkcY1lM05NyQfQu%2FUpqy55iHTmP6weJ4EMlqfmpNA4P2OVnDMUI4zFl0YX6%2F79KNjImIiv%2Fvheea8UGQVC2h7Z8GGrFtV5tWAKcCZ9uS3ih1SyPOTKUtCfPEipbgjJFd5LCX4XjQ1x%2F3ZoFBx6NBFvHYwmL6p5JKjDj4p4lvhwYdlC4K2TOL%2FUuu%2F8LbbMzfNsguAAcwf7nJIr3adX3N1qG%2BcJnM1CmNm73Xu%2B2eKNw5jtBCpN%2Fb%2FkczDI8njBUXovQ%3D%3D: 403 Client Error: Forbidden for url: https://storage.googleapis.com/wandb-production.appspot.com/neuzxm/huggingface/3l9pao8u/wandb-summary.json?Expires=1715720142&GoogleAccessId=gorilla-files-url-signer-man%40wandb-production.iam.gserviceaccount.com&Signature=pJR%2FORDAdIhiB6QqDmD387PJAPdITLihIMDugifEqDTDgemx6P7fb%2B7uB9oqje%2BOkKx%2B7UabMm62V8t87VXdkcY1lM05NyQfQu%2FUpqy55iHTmP6weJ4EMlqfmpNA4P2OVnDMUI4zFl0YX6%2F79KNjImIiv%2Fvheea8UGQVC2h7Z8GGrFtV5tWAKcCZ9uS3ih1SyPOTKUtCfPEipbgjJFd5LCX4XjQ1x%2F3ZoFBx6NBFvHYwmL6p5JKjDj4p4lvhwYdlC4K2TOL%2FUuu%2F8LbbMzfNsguAAcwf7nJIr3adX3N1qG%2BcJnM1CmNm73Xu%2B2eKNw5jtBCpN%2Fb%2FkczDI8njBUXovQ%3D%3D
2024-05-13 22:55:42,879 ERROR   wandb-upload_0:2341611 [internal_api.py:upload_file():2763] upload_file request headers: {'User-Agent': 'python-requests/2.31.0', 'Accept-Encoding': 'gzip, deflate, br', 'Accept': '*/*', 'Connection': 'keep-alive', 'Content-Length': '26'}
2024-05-13 22:55:42,879 ERROR   wandb-upload_0:2341611 [internal_api.py:upload_file():2765] upload_file response body: b"<?xml version='1.0' encoding='UTF-8'?><Error><Code>AccessDenied</Code><Message>Access denied.</Message><Details>We're sorry, but this service is not available in your location</Details></Error>"
2024-05-13 22:55:42,892 ERROR   wandb-upload_2:2341611 [internal_api.py:upload_file():2761] upload_file exception https://storage.googleapis.com/wandb-production.appspot.com/neuzxm/huggingface/3l9pao8u/conda-environment.yaml?Expires=1715720142&GoogleAccessId=gorilla-files-url-signer-man%40wandb-production.iam.gserviceaccount.com&Signature=sotpyAuf3gV3NW%2F0Tkkr14muzAOwcj9%2BwKCqdlnUahKX%2Fi%2FKq5I8MzAYCzieVjtSJ9dLU5kM9N6KHdQrTI%2FUzn00vbaSe3r8jVgfDVgz3kbwndfvISLlxfLtfz5ibfos5nf3KzV9RivXAlVKcmSZABvqPMOHSNWqhBG53XS7krxSGbUfRqDxAP%2BB%2By%2Fi0JE2QhWoUI3QnW2f0F32AtcxLa2R6esCcaSQquh6iFg8Rd%2FaIBHukC%2F%2BnuCtOilP884hk%2FfLD1GGAD3%2B3IdIGSzX6sKsWNCEwjMrZgbZaOrRxfFCGLOt3%2BWkik%2F20c9K8%2FRivoc1Rpmr3FqwgwFk69debQ%3D%3D: 403 Client Error: Forbidden for url: https://storage.googleapis.com/wandb-production.appspot.com/neuzxm/huggingface/3l9pao8u/conda-environment.yaml?Expires=1715720142&GoogleAccessId=gorilla-files-url-signer-man%40wandb-production.iam.gserviceaccount.com&Signature=sotpyAuf3gV3NW%2F0Tkkr14muzAOwcj9%2BwKCqdlnUahKX%2Fi%2FKq5I8MzAYCzieVjtSJ9dLU5kM9N6KHdQrTI%2FUzn00vbaSe3r8jVgfDVgz3kbwndfvISLlxfLtfz5ibfos5nf3KzV9RivXAlVKcmSZABvqPMOHSNWqhBG53XS7krxSGbUfRqDxAP%2BB%2By%2Fi0JE2QhWoUI3QnW2f0F32AtcxLa2R6esCcaSQquh6iFg8Rd%2FaIBHukC%2F%2BnuCtOilP884hk%2FfLD1GGAD3%2B3IdIGSzX6sKsWNCEwjMrZgbZaOrRxfFCGLOt3%2BWkik%2F20c9K8%2FRivoc1Rpmr3FqwgwFk69debQ%3D%3D
2024-05-13 22:55:42,892 ERROR   wandb-upload_2:2341611 [internal_api.py:upload_file():2763] upload_file request headers: {'User-Agent': 'python-requests/2.31.0', 'Accept-Encoding': 'gzip, deflate, br', 'Accept': '*/*', 'Connection': 'keep-alive', 'Content-Length': '5415'}
2024-05-13 22:55:42,892 ERROR   wandb-upload_2:2341611 [internal_api.py:upload_file():2765] upload_file response body: b"<?xml version='1.0' encoding='UTF-8'?><Error><Code>AccessDenied</Code><Message>Access denied.</Message><Details>We're sorry, but this service is not available in your location</Details></Error>"
2024-05-13 22:55:42,912 ERROR   Thread-11 :2341611 [step_upload.py:_handle_event():200] Failed to upload file: /nfs/datx/lyk/HiFT/wandb/run-20240513_225535-3l9pao8u/files/requirements.txt
Traceback (most recent call last):
  File "/mounts/work/lyk/anaconda3/envs/torch2/lib/python3.8/site-packages/wandb/apis/normalize.py", line 41, in wrapper
    return func(*args, **kwargs)
  File "/mounts/work/lyk/anaconda3/envs/torch2/lib/python3.8/site-packages/wandb/sdk/lib/retry.py", line 212, in wrapped_fn
    return retrier(*args, **kargs)
  File "/mounts/work/lyk/anaconda3/envs/torch2/lib/python3.8/site-packages/wandb/sdk/lib/retry.py", line 131, in __call__
    result = self._call_fn(*args, **kwargs)
  File "/mounts/work/lyk/anaconda3/envs/torch2/lib/python3.8/site-packages/wandb/sdk/internal/internal_api.py", line 2787, in upload_file
    wandb._sentry.reraise(e)
  File "/mounts/work/lyk/anaconda3/envs/torch2/lib/python3.8/site-packages/wandb/analytics/sentry.py", line 154, in reraise
    raise exc.with_traceback(sys.exc_info()[2])
  File "/mounts/work/lyk/anaconda3/envs/torch2/lib/python3.8/site-packages/wandb/sdk/internal/internal_api.py", line 2759, in upload_file
    response.raise_for_status()
  File "/mounts/work/lyk/anaconda3/envs/torch2/lib/python3.8/site-packages/requests/models.py", line 1021, in raise_for_status
    raise HTTPError(http_error_msg, response=self)
requests.exceptions.HTTPError: 403 Client Error: Forbidden for url: https://storage.googleapis.com/wandb-production.appspot.com/neuzxm/huggingface/3l9pao8u/requirements.txt?Expires=1715720142&GoogleAccessId=gorilla-files-url-signer-man%40wandb-production.iam.gserviceaccount.com&Signature=Ojbmv4FONIFJRunO2PPywWv14OJEMn9VWnJZDpvpmWjfs0J9du8VeHhHh44YfLC8z%2BZs0dTGTymYeREdUB%2Bz9M0nThG8uWDPoqYqXW1r%2BycxB2jCW4osE4ZfzoU7dS0KrmZZjU1Yhun2NWUu9m4RS1e2t1Ro3HrxhATpPYsirNtOPk2cOko1CjpGc2Im6e3FGRXPZMBRibK04vQA%2B7DRHrDoV2U4iJHAzUk8KJgDj6%2FcxTPCTXPK%2FvE2%2FXVlfpI8POFVoW4IoffZ7fJ3tDjYscZ0%2BvYyXexF1k8ZelJu396yjlF94AM8t9cPNlyo8HSaYLZSYQvj%2Fa%2BGrY9gWXiKdg%3D%3D

During handling of the above exception, another exception occurred:

Traceback (most recent call last):
  File "/mounts/work/lyk/anaconda3/envs/torch2/lib/python3.8/concurrent/futures/thread.py", line 57, in run
    result = self.fn(*self.args, **self.kwargs)
  File "/mounts/work/lyk/anaconda3/envs/torch2/lib/python3.8/site-packages/wandb/filesync/step_upload.py", line 288, in run_and_notify
    self._do_upload_sync(event)
  File "/mounts/work/lyk/anaconda3/envs/torch2/lib/python3.8/site-packages/wandb/filesync/step_upload.py", line 330, in _do_upload_sync
    job.run()
  File "/mounts/work/lyk/anaconda3/envs/torch2/lib/python3.8/site-packages/wandb/filesync/upload_job.py", line 57, in run
    self.push()
  File "/mounts/work/lyk/anaconda3/envs/torch2/lib/python3.8/site-packages/wandb/filesync/upload_job.py", line 125, in push
    self._api.upload_file_retry(
  File "/mounts/work/lyk/anaconda3/envs/torch2/lib/python3.8/site-packages/wandb/apis/normalize.py", line 51, in wrapper
    raise CommError(message, error)
wandb.errors.CommError: <Response [403]>
2024-05-13 22:55:42,913 ERROR   wandb-upload_0:2341611 [upload_job.py:push():134] Failed to upload file: /nfs/datx/lyk/HiFT/wandb/run-20240513_225535-3l9pao8u/files/wandb-summary.json
Traceback (most recent call last):
  File "/mounts/work/lyk/anaconda3/envs/torch2/lib/python3.8/site-packages/wandb/apis/normalize.py", line 41, in wrapper
    return func(*args, **kwargs)
  File "/mounts/work/lyk/anaconda3/envs/torch2/lib/python3.8/site-packages/wandb/sdk/lib/retry.py", line 212, in wrapped_fn
    return retrier(*args, **kargs)
  File "/mounts/work/lyk/anaconda3/envs/torch2/lib/python3.8/site-packages/wandb/sdk/lib/retry.py", line 131, in __call__
    result = self._call_fn(*args, **kwargs)
  File "/mounts/work/lyk/anaconda3/envs/torch2/lib/python3.8/site-packages/wandb/sdk/internal/internal_api.py", line 2787, in upload_file
    wandb._sentry.reraise(e)
  File "/mounts/work/lyk/anaconda3/envs/torch2/lib/python3.8/site-packages/wandb/analytics/sentry.py", line 154, in reraise
    raise exc.with_traceback(sys.exc_info()[2])
  File "/mounts/work/lyk/anaconda3/envs/torch2/lib/python3.8/site-packages/wandb/sdk/internal/internal_api.py", line 2759, in upload_file
    response.raise_for_status()
  File "/mounts/work/lyk/anaconda3/envs/torch2/lib/python3.8/site-packages/requests/models.py", line 1021, in raise_for_status
    raise HTTPError(http_error_msg, response=self)
requests.exceptions.HTTPError: 403 Client Error: Forbidden for url: https://storage.googleapis.com/wandb-production.appspot.com/neuzxm/huggingface/3l9pao8u/wandb-summary.json?Expires=1715720142&GoogleAccessId=gorilla-files-url-signer-man%40wandb-production.iam.gserviceaccount.com&Signature=pJR%2FORDAdIhiB6QqDmD387PJAPdITLihIMDugifEqDTDgemx6P7fb%2B7uB9oqje%2BOkKx%2B7UabMm62V8t87VXdkcY1lM05NyQfQu%2FUpqy55iHTmP6weJ4EMlqfmpNA4P2OVnDMUI4zFl0YX6%2F79KNjImIiv%2Fvheea8UGQVC2h7Z8GGrFtV5tWAKcCZ9uS3ih1SyPOTKUtCfPEipbgjJFd5LCX4XjQ1x%2F3ZoFBx6NBFvHYwmL6p5JKjDj4p4lvhwYdlC4K2TOL%2FUuu%2F8LbbMzfNsguAAcwf7nJIr3adX3N1qG%2BcJnM1CmNm73Xu%2B2eKNw5jtBCpN%2Fb%2FkczDI8njBUXovQ%3D%3D

During handling of the above exception, another exception occurred:

Traceback (most recent call last):
  File "/mounts/work/lyk/anaconda3/envs/torch2/lib/python3.8/site-packages/wandb/filesync/upload_job.py", line 125, in push
    self._api.upload_file_retry(
  File "/mounts/work/lyk/anaconda3/envs/torch2/lib/python3.8/site-packages/wandb/apis/normalize.py", line 51, in wrapper
    raise CommError(message, error)
wandb.errors.CommError: <Response [403]>
2024-05-13 22:55:42,913 ERROR   wandb-upload_2:2341611 [upload_job.py:push():134] Failed to upload file: /nfs/datx/lyk/HiFT/wandb/run-20240513_225535-3l9pao8u/files/conda-environment.yaml
Traceback (most recent call last):
  File "/mounts/work/lyk/anaconda3/envs/torch2/lib/python3.8/site-packages/wandb/apis/normalize.py", line 41, in wrapper
    return func(*args, **kwargs)
  File "/mounts/work/lyk/anaconda3/envs/torch2/lib/python3.8/site-packages/wandb/sdk/lib/retry.py", line 212, in wrapped_fn
    return retrier(*args, **kargs)
  File "/mounts/work/lyk/anaconda3/envs/torch2/lib/python3.8/site-packages/wandb/sdk/lib/retry.py", line 131, in __call__
    result = self._call_fn(*args, **kwargs)
  File "/mounts/work/lyk/anaconda3/envs/torch2/lib/python3.8/site-packages/wandb/sdk/internal/internal_api.py", line 2787, in upload_file
    wandb._sentry.reraise(e)
  File "/mounts/work/lyk/anaconda3/envs/torch2/lib/python3.8/site-packages/wandb/analytics/sentry.py", line 154, in reraise
    raise exc.with_traceback(sys.exc_info()[2])
  File "/mounts/work/lyk/anaconda3/envs/torch2/lib/python3.8/site-packages/wandb/sdk/internal/internal_api.py", line 2759, in upload_file
    response.raise_for_status()
  File "/mounts/work/lyk/anaconda3/envs/torch2/lib/python3.8/site-packages/requests/models.py", line 1021, in raise_for_status
    raise HTTPError(http_error_msg, response=self)
requests.exceptions.HTTPError: 403 Client Error: Forbidden for url: https://storage.googleapis.com/wandb-production.appspot.com/neuzxm/huggingface/3l9pao8u/conda-environment.yaml?Expires=1715720142&GoogleAccessId=gorilla-files-url-signer-man%40wandb-production.iam.gserviceaccount.com&Signature=sotpyAuf3gV3NW%2F0Tkkr14muzAOwcj9%2BwKCqdlnUahKX%2Fi%2FKq5I8MzAYCzieVjtSJ9dLU5kM9N6KHdQrTI%2FUzn00vbaSe3r8jVgfDVgz3kbwndfvISLlxfLtfz5ibfos5nf3KzV9RivXAlVKcmSZABvqPMOHSNWqhBG53XS7krxSGbUfRqDxAP%2BB%2By%2Fi0JE2QhWoUI3QnW2f0F32AtcxLa2R6esCcaSQquh6iFg8Rd%2FaIBHukC%2F%2BnuCtOilP884hk%2FfLD1GGAD3%2B3IdIGSzX6sKsWNCEwjMrZgbZaOrRxfFCGLOt3%2BWkik%2F20c9K8%2FRivoc1Rpmr3FqwgwFk69debQ%3D%3D

During handling of the above exception, another exception occurred:

Traceback (most recent call last):
  File "/mounts/work/lyk/anaconda3/envs/torch2/lib/python3.8/site-packages/wandb/filesync/upload_job.py", line 125, in push
    self._api.upload_file_retry(
  File "/mounts/work/lyk/anaconda3/envs/torch2/lib/python3.8/site-packages/wandb/apis/normalize.py", line 51, in wrapper
    raise CommError(message, error)
wandb.errors.CommError: <Response [403]>
2024-05-13 22:55:42,951 ERROR   Thread-11 :2341611 [step_upload.py:_handle_event():200] Failed to upload file: /nfs/datx/lyk/HiFT/wandb/run-20240513_225535-3l9pao8u/files/wandb-summary.json
Traceback (most recent call last):
  File "/mounts/work/lyk/anaconda3/envs/torch2/lib/python3.8/site-packages/wandb/apis/normalize.py", line 41, in wrapper
    return func(*args, **kwargs)
  File "/mounts/work/lyk/anaconda3/envs/torch2/lib/python3.8/site-packages/wandb/sdk/lib/retry.py", line 212, in wrapped_fn
    return retrier(*args, **kargs)
  File "/mounts/work/lyk/anaconda3/envs/torch2/lib/python3.8/site-packages/wandb/sdk/lib/retry.py", line 131, in __call__
    result = self._call_fn(*args, **kwargs)
  File "/mounts/work/lyk/anaconda3/envs/torch2/lib/python3.8/site-packages/wandb/sdk/internal/internal_api.py", line 2787, in upload_file
    wandb._sentry.reraise(e)
  File "/mounts/work/lyk/anaconda3/envs/torch2/lib/python3.8/site-packages/wandb/analytics/sentry.py", line 154, in reraise
    raise exc.with_traceback(sys.exc_info()[2])
  File "/mounts/work/lyk/anaconda3/envs/torch2/lib/python3.8/site-packages/wandb/sdk/internal/internal_api.py", line 2759, in upload_file
    response.raise_for_status()
  File "/mounts/work/lyk/anaconda3/envs/torch2/lib/python3.8/site-packages/requests/models.py", line 1021, in raise_for_status
    raise HTTPError(http_error_msg, response=self)
requests.exceptions.HTTPError: 403 Client Error: Forbidden for url: https://storage.googleapis.com/wandb-production.appspot.com/neuzxm/huggingface/3l9pao8u/wandb-summary.json?Expires=1715720142&GoogleAccessId=gorilla-files-url-signer-man%40wandb-production.iam.gserviceaccount.com&Signature=pJR%2FORDAdIhiB6QqDmD387PJAPdITLihIMDugifEqDTDgemx6P7fb%2B7uB9oqje%2BOkKx%2B7UabMm62V8t87VXdkcY1lM05NyQfQu%2FUpqy55iHTmP6weJ4EMlqfmpNA4P2OVnDMUI4zFl0YX6%2F79KNjImIiv%2Fvheea8UGQVC2h7Z8GGrFtV5tWAKcCZ9uS3ih1SyPOTKUtCfPEipbgjJFd5LCX4XjQ1x%2F3ZoFBx6NBFvHYwmL6p5JKjDj4p4lvhwYdlC4K2TOL%2FUuu%2F8LbbMzfNsguAAcwf7nJIr3adX3N1qG%2BcJnM1CmNm73Xu%2B2eKNw5jtBCpN%2Fb%2FkczDI8njBUXovQ%3D%3D

During handling of the above exception, another exception occurred:

Traceback (most recent call last):
  File "/mounts/work/lyk/anaconda3/envs/torch2/lib/python3.8/concurrent/futures/thread.py", line 57, in run
    result = self.fn(*self.args, **self.kwargs)
  File "/mounts/work/lyk/anaconda3/envs/torch2/lib/python3.8/site-packages/wandb/filesync/step_upload.py", line 288, in run_and_notify
    self._do_upload_sync(event)
  File "/mounts/work/lyk/anaconda3/envs/torch2/lib/python3.8/site-packages/wandb/filesync/step_upload.py", line 330, in _do_upload_sync
    job.run()
  File "/mounts/work/lyk/anaconda3/envs/torch2/lib/python3.8/site-packages/wandb/filesync/upload_job.py", line 57, in run
    self.push()
  File "/mounts/work/lyk/anaconda3/envs/torch2/lib/python3.8/site-packages/wandb/filesync/upload_job.py", line 125, in push
    self._api.upload_file_retry(
  File "/mounts/work/lyk/anaconda3/envs/torch2/lib/python3.8/site-packages/wandb/apis/normalize.py", line 51, in wrapper
    raise CommError(message, error)
wandb.errors.CommError: <Response [403]>
2024-05-13 22:55:42,952 ERROR   Thread-11 :2341611 [step_upload.py:_handle_event():200] Failed to upload file: /nfs/datx/lyk/HiFT/wandb/run-20240513_225535-3l9pao8u/files/conda-environment.yaml
Traceback (most recent call last):
  File "/mounts/work/lyk/anaconda3/envs/torch2/lib/python3.8/site-packages/wandb/apis/normalize.py", line 41, in wrapper
    return func(*args, **kwargs)
  File "/mounts/work/lyk/anaconda3/envs/torch2/lib/python3.8/site-packages/wandb/sdk/lib/retry.py", line 212, in wrapped_fn
    return retrier(*args, **kargs)
  File "/mounts/work/lyk/anaconda3/envs/torch2/lib/python3.8/site-packages/wandb/sdk/lib/retry.py", line 131, in __call__
    result = self._call_fn(*args, **kwargs)
  File "/mounts/work/lyk/anaconda3/envs/torch2/lib/python3.8/site-packages/wandb/sdk/internal/internal_api.py", line 2787, in upload_file
    wandb._sentry.reraise(e)
  File "/mounts/work/lyk/anaconda3/envs/torch2/lib/python3.8/site-packages/wandb/analytics/sentry.py", line 154, in reraise
    raise exc.with_traceback(sys.exc_info()[2])
  File "/mounts/work/lyk/anaconda3/envs/torch2/lib/python3.8/site-packages/wandb/sdk/internal/internal_api.py", line 2759, in upload_file
    response.raise_for_status()
  File "/mounts/work/lyk/anaconda3/envs/torch2/lib/python3.8/site-packages/requests/models.py", line 1021, in raise_for_status
    raise HTTPError(http_error_msg, response=self)
requests.exceptions.HTTPError: 403 Client Error: Forbidden for url: https://storage.googleapis.com/wandb-production.appspot.com/neuzxm/huggingface/3l9pao8u/conda-environment.yaml?Expires=1715720142&GoogleAccessId=gorilla-files-url-signer-man%40wandb-production.iam.gserviceaccount.com&Signature=sotpyAuf3gV3NW%2F0Tkkr14muzAOwcj9%2BwKCqdlnUahKX%2Fi%2FKq5I8MzAYCzieVjtSJ9dLU5kM9N6KHdQrTI%2FUzn00vbaSe3r8jVgfDVgz3kbwndfvISLlxfLtfz5ibfos5nf3KzV9RivXAlVKcmSZABvqPMOHSNWqhBG53XS7krxSGbUfRqDxAP%2BB%2By%2Fi0JE2QhWoUI3QnW2f0F32AtcxLa2R6esCcaSQquh6iFg8Rd%2FaIBHukC%2F%2BnuCtOilP884hk%2FfLD1GGAD3%2B3IdIGSzX6sKsWNCEwjMrZgbZaOrRxfFCGLOt3%2BWkik%2F20c9K8%2FRivoc1Rpmr3FqwgwFk69debQ%3D%3D

During handling of the above exception, another exception occurred:

Traceback (most recent call last):
  File "/mounts/work/lyk/anaconda3/envs/torch2/lib/python3.8/concurrent/futures/thread.py", line 57, in run
    result = self.fn(*self.args, **self.kwargs)
  File "/mounts/work/lyk/anaconda3/envs/torch2/lib/python3.8/site-packages/wandb/filesync/step_upload.py", line 288, in run_and_notify
    self._do_upload_sync(event)
  File "/mounts/work/lyk/anaconda3/envs/torch2/lib/python3.8/site-packages/wandb/filesync/step_upload.py", line 330, in _do_upload_sync
    job.run()
  File "/mounts/work/lyk/anaconda3/envs/torch2/lib/python3.8/site-packages/wandb/filesync/upload_job.py", line 57, in run
    self.push()
  File "/mounts/work/lyk/anaconda3/envs/torch2/lib/python3.8/site-packages/wandb/filesync/upload_job.py", line 125, in push
    self._api.upload_file_retry(
  File "/mounts/work/lyk/anaconda3/envs/torch2/lib/python3.8/site-packages/wandb/apis/normalize.py", line 51, in wrapper
    raise CommError(message, error)
wandb.errors.CommError: <Response [403]>
2024-05-13 22:55:43,172 ERROR   wandb-upload_4:2341611 [internal_api.py:upload_file():2761] upload_file exception https://storage.googleapis.com/wandb-production.appspot.com/neuzxm/huggingface/3l9pao8u/output.log?Expires=1715720142&GoogleAccessId=gorilla-files-url-signer-man%40wandb-production.iam.gserviceaccount.com&Signature=OIOYUe2IEw6DpzhRzl0gBKNA8c1v%2B6c2IRpUMiUmXKuVPwTwt7PC86BoZdJXSAZvQQW1qQxXA7NMc8FXKLY%2BqqV%2Bh3ysUrcThwdLtfZaUdJug2tsCjDpZNloHnfAxlFATnMMvLvljKYUchh4jgWsyNqHj3MQCYiLacjs9%2FhJaGSoUUanARD%2FTPD4I5lWgSYICGvI2ypJ1YNUCdCWVwMaLJRxB1hsY1M39Sx7uLU7MnaZco4U%2F5xkjygoS4BNJ6Li8awdKQo2Rv3Vh0%2BgM2akQc6J9c1yCTJ6AvkEPnLBaAfFfU507gxYt4JE5ZpFXwxv2XL02c5PIJIUK55XoFbfNg%3D%3D: 403 Client Error: Forbidden for url: https://storage.googleapis.com/wandb-production.appspot.com/neuzxm/huggingface/3l9pao8u/output.log?Expires=1715720142&GoogleAccessId=gorilla-files-url-signer-man%40wandb-production.iam.gserviceaccount.com&Signature=OIOYUe2IEw6DpzhRzl0gBKNA8c1v%2B6c2IRpUMiUmXKuVPwTwt7PC86BoZdJXSAZvQQW1qQxXA7NMc8FXKLY%2BqqV%2Bh3ysUrcThwdLtfZaUdJug2tsCjDpZNloHnfAxlFATnMMvLvljKYUchh4jgWsyNqHj3MQCYiLacjs9%2FhJaGSoUUanARD%2FTPD4I5lWgSYICGvI2ypJ1YNUCdCWVwMaLJRxB1hsY1M39Sx7uLU7MnaZco4U%2F5xkjygoS4BNJ6Li8awdKQo2Rv3Vh0%2BgM2akQc6J9c1yCTJ6AvkEPnLBaAfFfU507gxYt4JE5ZpFXwxv2XL02c5PIJIUK55XoFbfNg%3D%3D
2024-05-13 22:55:43,172 ERROR   wandb-upload_4:2341611 [internal_api.py:upload_file():2763] upload_file request headers: {'User-Agent': 'python-requests/2.31.0', 'Accept-Encoding': 'gzip, deflate, br', 'Accept': '*/*', 'Connection': 'keep-alive', 'Content-Length': '3521'}
2024-05-13 22:55:43,172 ERROR   wandb-upload_4:2341611 [internal_api.py:upload_file():2765] upload_file response body: b"<?xml version='1.0' encoding='UTF-8'?><Error><Code>AccessDenied</Code><Message>Access denied.</Message><Details>We're sorry, but this service is not available in your location</Details></Error>"
2024-05-13 22:55:43,187 ERROR   wandb-upload_3:2341611 [internal_api.py:upload_file():2761] upload_file exception https://storage.googleapis.com/wandb-production.appspot.com/neuzxm/huggingface/3l9pao8u/config.yaml?Expires=1715720143&GoogleAccessId=gorilla-files-url-signer-man%40wandb-production.iam.gserviceaccount.com&Signature=kcQSkQzN8YxSoJH%2Fg%2FoLRLGICZzRe6AcsyK1S6MTOQMz%2FYW6D%2B1tz5BavLueW1HfB5J6XmYBcEaLPC4gUv2cLhsQHXeBednJxYIv6sGukLgM8EEWDhyAtDqWaXE43TtgZ9Rxaf2srO60PCk6cTdkRLGPH7pi5qGQq6wVyg7oLDK0qSJsDhqVtXi5oWVH8de2QaRQSX0k4NbPRtKge%2Fe25o6N7TvrDLRLQgdt4TKyHCVGeEip0ZuxmQAiTH0SSNBWo0DdTd3O6AG12zpplhcq8LZp1XwTDLvs7M7mEHlc%2F%2F9hq1B%2FMDK9nMvkjxbVuW78JN1c6n4PLeFeTY7q8DIZ3w%3D%3D: 403 Client Error: Forbidden for url: https://storage.googleapis.com/wandb-production.appspot.com/neuzxm/huggingface/3l9pao8u/config.yaml?Expires=1715720143&GoogleAccessId=gorilla-files-url-signer-man%40wandb-production.iam.gserviceaccount.com&Signature=kcQSkQzN8YxSoJH%2Fg%2FoLRLGICZzRe6AcsyK1S6MTOQMz%2FYW6D%2B1tz5BavLueW1HfB5J6XmYBcEaLPC4gUv2cLhsQHXeBednJxYIv6sGukLgM8EEWDhyAtDqWaXE43TtgZ9Rxaf2srO60PCk6cTdkRLGPH7pi5qGQq6wVyg7oLDK0qSJsDhqVtXi5oWVH8de2QaRQSX0k4NbPRtKge%2Fe25o6N7TvrDLRLQgdt4TKyHCVGeEip0ZuxmQAiTH0SSNBWo0DdTd3O6AG12zpplhcq8LZp1XwTDLvs7M7mEHlc%2F%2F9hq1B%2FMDK9nMvkjxbVuW78JN1c6n4PLeFeTY7q8DIZ3w%3D%3D
2024-05-13 22:55:43,187 ERROR   wandb-upload_3:2341611 [internal_api.py:upload_file():2763] upload_file request headers: {'User-Agent': 'python-requests/2.31.0', 'Accept-Encoding': 'gzip, deflate, br', 'Accept': '*/*', 'Connection': 'keep-alive', 'Content-Length': '9669'}
2024-05-13 22:55:43,187 ERROR   wandb-upload_3:2341611 [internal_api.py:upload_file():2765] upload_file response body: b"<?xml version='1.0' encoding='UTF-8'?><Error><Code>AccessDenied</Code><Message>Access denied.</Message><Details>We're sorry, but this service is not available in your location</Details></Error>"
2024-05-13 22:55:43,190 ERROR   wandb-upload_4:2341611 [upload_job.py:push():134] Failed to upload file: /nfs/datx/lyk/HiFT/wandb/run-20240513_225535-3l9pao8u/files/output.log
Traceback (most recent call last):
  File "/mounts/work/lyk/anaconda3/envs/torch2/lib/python3.8/site-packages/wandb/apis/normalize.py", line 41, in wrapper
    return func(*args, **kwargs)
  File "/mounts/work/lyk/anaconda3/envs/torch2/lib/python3.8/site-packages/wandb/sdk/lib/retry.py", line 212, in wrapped_fn
    return retrier(*args, **kargs)
  File "/mounts/work/lyk/anaconda3/envs/torch2/lib/python3.8/site-packages/wandb/sdk/lib/retry.py", line 131, in __call__
    result = self._call_fn(*args, **kwargs)
  File "/mounts/work/lyk/anaconda3/envs/torch2/lib/python3.8/site-packages/wandb/sdk/internal/internal_api.py", line 2787, in upload_file
    wandb._sentry.reraise(e)
  File "/mounts/work/lyk/anaconda3/envs/torch2/lib/python3.8/site-packages/wandb/analytics/sentry.py", line 154, in reraise
    raise exc.with_traceback(sys.exc_info()[2])
  File "/mounts/work/lyk/anaconda3/envs/torch2/lib/python3.8/site-packages/wandb/sdk/internal/internal_api.py", line 2759, in upload_file
    response.raise_for_status()
  File "/mounts/work/lyk/anaconda3/envs/torch2/lib/python3.8/site-packages/requests/models.py", line 1021, in raise_for_status
    raise HTTPError(http_error_msg, response=self)
requests.exceptions.HTTPError: 403 Client Error: Forbidden for url: https://storage.googleapis.com/wandb-production.appspot.com/neuzxm/huggingface/3l9pao8u/output.log?Expires=1715720142&GoogleAccessId=gorilla-files-url-signer-man%40wandb-production.iam.gserviceaccount.com&Signature=OIOYUe2IEw6DpzhRzl0gBKNA8c1v%2B6c2IRpUMiUmXKuVPwTwt7PC86BoZdJXSAZvQQW1qQxXA7NMc8FXKLY%2BqqV%2Bh3ysUrcThwdLtfZaUdJug2tsCjDpZNloHnfAxlFATnMMvLvljKYUchh4jgWsyNqHj3MQCYiLacjs9%2FhJaGSoUUanARD%2FTPD4I5lWgSYICGvI2ypJ1YNUCdCWVwMaLJRxB1hsY1M39Sx7uLU7MnaZco4U%2F5xkjygoS4BNJ6Li8awdKQo2Rv3Vh0%2BgM2akQc6J9c1yCTJ6AvkEPnLBaAfFfU507gxYt4JE5ZpFXwxv2XL02c5PIJIUK55XoFbfNg%3D%3D

During handling of the above exception, another exception occurred:

Traceback (most recent call last):
  File "/mounts/work/lyk/anaconda3/envs/torch2/lib/python3.8/site-packages/wandb/filesync/upload_job.py", line 125, in push
    self._api.upload_file_retry(
  File "/mounts/work/lyk/anaconda3/envs/torch2/lib/python3.8/site-packages/wandb/apis/normalize.py", line 51, in wrapper
    raise CommError(message, error)
wandb.errors.CommError: <Response [403]>
2024-05-13 22:55:43,219 ERROR   Thread-11 :2341611 [step_upload.py:_handle_event():200] Failed to upload file: /nfs/datx/lyk/HiFT/wandb/run-20240513_225535-3l9pao8u/files/output.log
Traceback (most recent call last):
  File "/mounts/work/lyk/anaconda3/envs/torch2/lib/python3.8/site-packages/wandb/apis/normalize.py", line 41, in wrapper
    return func(*args, **kwargs)
  File "/mounts/work/lyk/anaconda3/envs/torch2/lib/python3.8/site-packages/wandb/sdk/lib/retry.py", line 212, in wrapped_fn
    return retrier(*args, **kargs)
  File "/mounts/work/lyk/anaconda3/envs/torch2/lib/python3.8/site-packages/wandb/sdk/lib/retry.py", line 131, in __call__
    result = self._call_fn(*args, **kwargs)
  File "/mounts/work/lyk/anaconda3/envs/torch2/lib/python3.8/site-packages/wandb/sdk/internal/internal_api.py", line 2787, in upload_file
    wandb._sentry.reraise(e)
  File "/mounts/work/lyk/anaconda3/envs/torch2/lib/python3.8/site-packages/wandb/analytics/sentry.py", line 154, in reraise
    raise exc.with_traceback(sys.exc_info()[2])
  File "/mounts/work/lyk/anaconda3/envs/torch2/lib/python3.8/site-packages/wandb/sdk/internal/internal_api.py", line 2759, in upload_file
    response.raise_for_status()
  File "/mounts/work/lyk/anaconda3/envs/torch2/lib/python3.8/site-packages/requests/models.py", line 1021, in raise_for_status
    raise HTTPError(http_error_msg, response=self)
requests.exceptions.HTTPError: 403 Client Error: Forbidden for url: https://storage.googleapis.com/wandb-production.appspot.com/neuzxm/huggingface/3l9pao8u/output.log?Expires=1715720142&GoogleAccessId=gorilla-files-url-signer-man%40wandb-production.iam.gserviceaccount.com&Signature=OIOYUe2IEw6DpzhRzl0gBKNA8c1v%2B6c2IRpUMiUmXKuVPwTwt7PC86BoZdJXSAZvQQW1qQxXA7NMc8FXKLY%2BqqV%2Bh3ysUrcThwdLtfZaUdJug2tsCjDpZNloHnfAxlFATnMMvLvljKYUchh4jgWsyNqHj3MQCYiLacjs9%2FhJaGSoUUanARD%2FTPD4I5lWgSYICGvI2ypJ1YNUCdCWVwMaLJRxB1hsY1M39Sx7uLU7MnaZco4U%2F5xkjygoS4BNJ6Li8awdKQo2Rv3Vh0%2BgM2akQc6J9c1yCTJ6AvkEPnLBaAfFfU507gxYt4JE5ZpFXwxv2XL02c5PIJIUK55XoFbfNg%3D%3D

During handling of the above exception, another exception occurred:

Traceback (most recent call last):
  File "/mounts/work/lyk/anaconda3/envs/torch2/lib/python3.8/concurrent/futures/thread.py", line 57, in run
    result = self.fn(*self.args, **self.kwargs)
  File "/mounts/work/lyk/anaconda3/envs/torch2/lib/python3.8/site-packages/wandb/filesync/step_upload.py", line 288, in run_and_notify
    self._do_upload_sync(event)
  File "/mounts/work/lyk/anaconda3/envs/torch2/lib/python3.8/site-packages/wandb/filesync/step_upload.py", line 330, in _do_upload_sync
    job.run()
  File "/mounts/work/lyk/anaconda3/envs/torch2/lib/python3.8/site-packages/wandb/filesync/upload_job.py", line 57, in run
    self.push()
  File "/mounts/work/lyk/anaconda3/envs/torch2/lib/python3.8/site-packages/wandb/filesync/upload_job.py", line 125, in push
    self._api.upload_file_retry(
  File "/mounts/work/lyk/anaconda3/envs/torch2/lib/python3.8/site-packages/wandb/apis/normalize.py", line 51, in wrapper
    raise CommError(message, error)
wandb.errors.CommError: <Response [403]>
2024-05-13 22:55:43,220 ERROR   wandb-upload_3:2341611 [upload_job.py:push():134] Failed to upload file: /nfs/datx/lyk/HiFT/wandb/run-20240513_225535-3l9pao8u/files/config.yaml
Traceback (most recent call last):
  File "/mounts/work/lyk/anaconda3/envs/torch2/lib/python3.8/site-packages/wandb/apis/normalize.py", line 41, in wrapper
    return func(*args, **kwargs)
  File "/mounts/work/lyk/anaconda3/envs/torch2/lib/python3.8/site-packages/wandb/sdk/lib/retry.py", line 212, in wrapped_fn
    return retrier(*args, **kargs)
  File "/mounts/work/lyk/anaconda3/envs/torch2/lib/python3.8/site-packages/wandb/sdk/lib/retry.py", line 131, in __call__
    result = self._call_fn(*args, **kwargs)
  File "/mounts/work/lyk/anaconda3/envs/torch2/lib/python3.8/site-packages/wandb/sdk/internal/internal_api.py", line 2787, in upload_file
    wandb._sentry.reraise(e)
  File "/mounts/work/lyk/anaconda3/envs/torch2/lib/python3.8/site-packages/wandb/analytics/sentry.py", line 154, in reraise
    raise exc.with_traceback(sys.exc_info()[2])
  File "/mounts/work/lyk/anaconda3/envs/torch2/lib/python3.8/site-packages/wandb/sdk/internal/internal_api.py", line 2759, in upload_file
    response.raise_for_status()
  File "/mounts/work/lyk/anaconda3/envs/torch2/lib/python3.8/site-packages/requests/models.py", line 1021, in raise_for_status
    raise HTTPError(http_error_msg, response=self)
requests.exceptions.HTTPError: 403 Client Error: Forbidden for url: https://storage.googleapis.com/wandb-production.appspot.com/neuzxm/huggingface/3l9pao8u/config.yaml?Expires=1715720143&GoogleAccessId=gorilla-files-url-signer-man%40wandb-production.iam.gserviceaccount.com&Signature=kcQSkQzN8YxSoJH%2Fg%2FoLRLGICZzRe6AcsyK1S6MTOQMz%2FYW6D%2B1tz5BavLueW1HfB5J6XmYBcEaLPC4gUv2cLhsQHXeBednJxYIv6sGukLgM8EEWDhyAtDqWaXE43TtgZ9Rxaf2srO60PCk6cTdkRLGPH7pi5qGQq6wVyg7oLDK0qSJsDhqVtXi5oWVH8de2QaRQSX0k4NbPRtKge%2Fe25o6N7TvrDLRLQgdt4TKyHCVGeEip0ZuxmQAiTH0SSNBWo0DdTd3O6AG12zpplhcq8LZp1XwTDLvs7M7mEHlc%2F%2F9hq1B%2FMDK9nMvkjxbVuW78JN1c6n4PLeFeTY7q8DIZ3w%3D%3D

During handling of the above exception, another exception occurred:

Traceback (most recent call last):
  File "/mounts/work/lyk/anaconda3/envs/torch2/lib/python3.8/site-packages/wandb/filesync/upload_job.py", line 125, in push
    self._api.upload_file_retry(
  File "/mounts/work/lyk/anaconda3/envs/torch2/lib/python3.8/site-packages/wandb/apis/normalize.py", line 51, in wrapper
    raise CommError(message, error)
wandb.errors.CommError: <Response [403]>
2024-05-13 22:55:43,239 ERROR   Thread-11 :2341611 [step_upload.py:_handle_event():200] Failed to upload file: /nfs/datx/lyk/HiFT/wandb/run-20240513_225535-3l9pao8u/files/config.yaml
Traceback (most recent call last):
  File "/mounts/work/lyk/anaconda3/envs/torch2/lib/python3.8/site-packages/wandb/apis/normalize.py", line 41, in wrapper
    return func(*args, **kwargs)
  File "/mounts/work/lyk/anaconda3/envs/torch2/lib/python3.8/site-packages/wandb/sdk/lib/retry.py", line 212, in wrapped_fn
    return retrier(*args, **kargs)
  File "/mounts/work/lyk/anaconda3/envs/torch2/lib/python3.8/site-packages/wandb/sdk/lib/retry.py", line 131, in __call__
    result = self._call_fn(*args, **kwargs)
  File "/mounts/work/lyk/anaconda3/envs/torch2/lib/python3.8/site-packages/wandb/sdk/internal/internal_api.py", line 2787, in upload_file
    wandb._sentry.reraise(e)
  File "/mounts/work/lyk/anaconda3/envs/torch2/lib/python3.8/site-packages/wandb/analytics/sentry.py", line 154, in reraise
    raise exc.with_traceback(sys.exc_info()[2])
  File "/mounts/work/lyk/anaconda3/envs/torch2/lib/python3.8/site-packages/wandb/sdk/internal/internal_api.py", line 2759, in upload_file
    response.raise_for_status()
  File "/mounts/work/lyk/anaconda3/envs/torch2/lib/python3.8/site-packages/requests/models.py", line 1021, in raise_for_status
    raise HTTPError(http_error_msg, response=self)
requests.exceptions.HTTPError: 403 Client Error: Forbidden for url: https://storage.googleapis.com/wandb-production.appspot.com/neuzxm/huggingface/3l9pao8u/config.yaml?Expires=1715720143&GoogleAccessId=gorilla-files-url-signer-man%40wandb-production.iam.gserviceaccount.com&Signature=kcQSkQzN8YxSoJH%2Fg%2FoLRLGICZzRe6AcsyK1S6MTOQMz%2FYW6D%2B1tz5BavLueW1HfB5J6XmYBcEaLPC4gUv2cLhsQHXeBednJxYIv6sGukLgM8EEWDhyAtDqWaXE43TtgZ9Rxaf2srO60PCk6cTdkRLGPH7pi5qGQq6wVyg7oLDK0qSJsDhqVtXi5oWVH8de2QaRQSX0k4NbPRtKge%2Fe25o6N7TvrDLRLQgdt4TKyHCVGeEip0ZuxmQAiTH0SSNBWo0DdTd3O6AG12zpplhcq8LZp1XwTDLvs7M7mEHlc%2F%2F9hq1B%2FMDK9nMvkjxbVuW78JN1c6n4PLeFeTY7q8DIZ3w%3D%3D

During handling of the above exception, another exception occurred:

Traceback (most recent call last):
  File "/mounts/work/lyk/anaconda3/envs/torch2/lib/python3.8/concurrent/futures/thread.py", line 57, in run
    result = self.fn(*self.args, **self.kwargs)
  File "/mounts/work/lyk/anaconda3/envs/torch2/lib/python3.8/site-packages/wandb/filesync/step_upload.py", line 288, in run_and_notify
    self._do_upload_sync(event)
  File "/mounts/work/lyk/anaconda3/envs/torch2/lib/python3.8/site-packages/wandb/filesync/step_upload.py", line 330, in _do_upload_sync
    job.run()
  File "/mounts/work/lyk/anaconda3/envs/torch2/lib/python3.8/site-packages/wandb/filesync/upload_job.py", line 57, in run
    self.push()
  File "/mounts/work/lyk/anaconda3/envs/torch2/lib/python3.8/site-packages/wandb/filesync/upload_job.py", line 125, in push
    self._api.upload_file_retry(
  File "/mounts/work/lyk/anaconda3/envs/torch2/lib/python3.8/site-packages/wandb/apis/normalize.py", line 51, in wrapper
    raise CommError(message, error)
wandb.errors.CommError: <Response [403]>
2024-05-13 22:55:43,440 INFO    Thread-11 :2341611 [sender.py:transition_state():617] send defer: 11
2024-05-13 22:55:43,440 DEBUG   HandlerThread:2341611 [handler.py:handle_request():146] handle_request: defer
2024-05-13 22:55:43,440 INFO    HandlerThread:2341611 [handler.py:handle_request_defer():172] handle defer: 11
2024-05-13 22:55:43,441 DEBUG   SenderThread:2341611 [sender.py:send_request():409] send_request: defer
2024-05-13 22:55:43,441 INFO    SenderThread:2341611 [sender.py:send_request_defer():613] handle sender defer: 11
2024-05-13 22:55:43,441 INFO    SenderThread:2341611 [file_pusher.py:join():181] waiting for file pusher
2024-05-13 22:55:43,441 INFO    SenderThread:2341611 [sender.py:transition_state():617] send defer: 12
2024-05-13 22:55:43,441 DEBUG   HandlerThread:2341611 [handler.py:handle_request():146] handle_request: defer
2024-05-13 22:55:43,441 INFO    HandlerThread:2341611 [handler.py:handle_request_defer():172] handle defer: 12
2024-05-13 22:55:43,442 DEBUG   SenderThread:2341611 [sender.py:send_request():409] send_request: defer
2024-05-13 22:55:43,442 INFO    SenderThread:2341611 [sender.py:send_request_defer():613] handle sender defer: 12
2024-05-13 22:55:43,442 INFO    SenderThread:2341611 [file_stream.py:finish():595] file stream finish called
2024-05-13 22:55:43,633 INFO    SenderThread:2341611 [file_stream.py:finish():599] file stream finish is done
2024-05-13 22:55:43,633 INFO    SenderThread:2341611 [sender.py:transition_state():617] send defer: 13
2024-05-13 22:55:43,633 DEBUG   HandlerThread:2341611 [handler.py:handle_request():146] handle_request: defer
2024-05-13 22:55:43,634 INFO    HandlerThread:2341611 [handler.py:handle_request_defer():172] handle defer: 13
2024-05-13 22:55:43,634 DEBUG   SenderThread:2341611 [sender.py:send_request():409] send_request: defer
2024-05-13 22:55:43,634 INFO    SenderThread:2341611 [sender.py:send_request_defer():613] handle sender defer: 13
2024-05-13 22:55:43,634 INFO    SenderThread:2341611 [sender.py:transition_state():617] send defer: 14
2024-05-13 22:55:43,634 DEBUG   HandlerThread:2341611 [handler.py:handle_request():146] handle_request: defer
2024-05-13 22:55:43,634 INFO    HandlerThread:2341611 [handler.py:handle_request_defer():172] handle defer: 14
2024-05-13 22:55:43,635 DEBUG   SenderThread:2341611 [sender.py:send():382] send: final
2024-05-13 22:55:43,635 DEBUG   SenderThread:2341611 [sender.py:send():382] send: footer
2024-05-13 22:55:43,635 DEBUG   SenderThread:2341611 [sender.py:send_request():409] send_request: defer
2024-05-13 22:55:43,635 INFO    SenderThread:2341611 [sender.py:send_request_defer():613] handle sender defer: 14
2024-05-13 22:55:43,636 DEBUG   HandlerThread:2341611 [handler.py:handle_request():146] handle_request: poll_exit
2024-05-13 22:55:43,637 DEBUG   SenderThread:2341611 [sender.py:send_request():409] send_request: poll_exit
2024-05-13 22:55:43,637 DEBUG   HandlerThread:2341611 [handler.py:handle_request():146] handle_request: server_info
2024-05-13 22:55:43,638 DEBUG   SenderThread:2341611 [sender.py:send_request():409] send_request: server_info
2024-05-13 22:55:43,640 DEBUG   HandlerThread:2341611 [handler.py:handle_request():146] handle_request: get_summary
2024-05-13 22:55:43,641 DEBUG   HandlerThread:2341611 [handler.py:handle_request():146] handle_request: sampled_history
2024-05-13 22:55:43,641 DEBUG   HandlerThread:2341611 [handler.py:handle_request():146] handle_request: internal_messages
2024-05-13 22:55:43,641 DEBUG   HandlerThread:2341611 [handler.py:handle_request():146] handle_request: job_info
2024-05-13 22:55:43,779 DEBUG   SenderThread:2341611 [sender.py:send_request():409] send_request: job_info
2024-05-13 22:55:43,780 INFO    MainThread:2341611 [wandb_run.py:_footer_history_summary_info():3837] rendering history
2024-05-13 22:55:43,780 INFO    MainThread:2341611 [wandb_run.py:_footer_history_summary_info():3869] rendering summary
2024-05-13 22:55:43,780 INFO    MainThread:2341611 [wandb_run.py:_footer_sync_info():3796] logging synced files
2024-05-13 22:55:43,781 DEBUG   HandlerThread:2341611 [handler.py:handle_request():146] handle_request: shutdown
2024-05-13 22:55:43,781 INFO    HandlerThread:2341611 [handler.py:finish():866] shutting down handler
2024-05-13 22:55:44,642 INFO    WriterThread:2341611 [datastore.py:close():294] close: /nfs/datx/lyk/HiFT/wandb/run-20240513_225535-3l9pao8u/run-3l9pao8u.wandb
2024-05-13 22:55:44,780 INFO    SenderThread:2341611 [sender.py:finish():1548] shutting down sender
2024-05-13 22:55:44,780 INFO    SenderThread:2341611 [file_pusher.py:finish():175] shutting down file pusher
2024-05-13 22:55:44,780 INFO    SenderThread:2341611 [file_pusher.py:join():181] waiting for file pusher
